Workbook

Sheet H
A1: Meituan financial disclosure | P1: CEQ (*only account for E that we can consolidate)
A2: (RMB millions) | B2: Jan to Apr 2017 | C2: Jan to Apr 2018 | D2: YoY | F2: 1H 2017 | G2: 1H 2018 | H2: YoY | J2: May to Jun 2017 | K2: May to Jun 2018 | L2: YoY | N2: Comments | P2: Jan.-Apr. 2017 | Q2: Jan.-Apr. 2018 | R2: YoY
A3: Meituan hotels only:
A4: Room Nights | B4: 57 | C4: 87 | D4: =C4/B4-1 -> 0.52631579 | F4: 89.4 | G4: 133.5 | H4: =G4/F4-1 -> 0.49328859 | J4: =F4-B4 -> 32.4 | K4: =G4-C4 -> 46.5 | L4: =K4/J4-1 -> 0.43518519 | N4: Slight deceleration of RNs growth
A5: GMV | B5: 9964 | C5: 16255 | D5: =C5/B5-1 -> 0.63137294 | G5: 23000 | K5: =G5-C5 -> 6745
A6: ADR | B6: =B5/B4 -> 174.80702 | C6: =C5/C4 -> 186.83908 | D6: =C6/B6-1 -> 0.068830549 | G6: =G5/G4 -> 172.28464 | K6: =K5/K4 -> 145.05376 | N6: ADR mgmt. stated is increasing
A7: Take-rate | B7: 0.072 | C7: 0.072 | D7: =C7/B7-1 -> 0 | H7: Increasing
A9: Active Hotels | B9: 0.3 | C9: 0.3 | D9: =C9/B9-1 -> 0
A11: Revenue | B11: 720 | C11: 1176 | D11: =C11/B11-1 -> 0.63333333
A12: Cost of Revenue | B12: 91 | C12: 182 | D12: =C12/B12-1 -> 1
A14: Gross Profit | B14: 629 | C14: 994 | D14: =C14/B14-1 -> 0.58028617
A15: Gross Margin | B15: 0.873 | C15: 0.845 | D15: =C15/B15-1 -> -0.03207331
A17: 1Q2018 RN mkt share | C17: 0.336 | D17: #1
A18: % of transactions from cross-sell | C18: 0.8
A20: China hotel online penetration | C20: 20.17 | D20: 0.32
A22: Total Meituan Group:
A23: Total revenues | B23: 8120 | C23: 15824 | D23: =C23/B23-1 -> 0.94876847 | F23: 13779 | G23: 26348 | H23: =G23/F23-1 -> 0.91218521 | J23: =F23-B23 -> 5659 | K23: =G23-C23 -> 10524 | L23: =K23/J23-1 -> 0.85969253
A24: Total operating loss | B24: -769 | C24: -2526 | D24: =C24/B24-1 -> 2.2847854 | F24: -1250 | G24: -3900 | H24: =G24/F24-1 -> 2.12 | J24: =F24-B24 -> -481 | K24: =G24-C24 -> -1374 | L24: =K24/J24-1 -> 1.8565489 | N24: Slight improvement in profitability
A25: Total adjusted EBITDA | B25: -263 | C25: -1727 | D25: =C25/B25-1 -> 5.5665399 | F25: -493 | G25: -2707 | H25: =G25/F25-1 -> 4.4908722 | J25: =F25-B25 -> -230 | K25: =G25-C25 -> -980 | L25: =K25/J25-1 -> 3.2608696
A27: In-store, hotel & travel:
A28: GMV | B28: 50.5 | C28: 55.1 | D28: =C28/B28-1 -> 0.091089109 | F28: 74.9 | G28: 82.8 | H28: =G28/F28-1 -> 0.10547397 | J28: =F28-B28 -> 24.4 | K28: =G28-C28 -> 27.7 | L28: =K28/J28-1 -> 0.1352459
A29: Revenues | B29: 3041 | C29: 4351 | D29: =C29/B29-1 -> 0.43077935 | F29: =4727033/1000 -> 4727.033 | G29: 6811 | H29: =G29/F29-1 -> 0.44086153 | J29: =F29-B29 -> 1686.033 | K29: =G29-C29 -> 2460 | L29: =K29/J29-1 -> 0.45904618
A30: Gross profit/loss | B30: 2670 | C30: 3829 | D30: =C30/B30-1 -> 0.4340824 | F30: =4183770/1000 -> 4183.77 | G30: 6090 | H30: =G30/F30-1 -> 0.45562495 | J30: =F30-B30 -> 1513.77 | K30: =G30-C30 -> 2261 | L30: =K30/J30-1 -> 0.49362188
A31: Gross margin | B31: =B30/B29 -> 0.87800066 | C31: =C30/C29 -> 0.88002758 | F31: =F30/F29 -> 0.88507315 | G31: =G30/G29 -> 0.89414183 | J31: =J30/J29 -> 0.8978294 | K31: =K30/K29 -> 0.91910569
A33: * Hotel entering maturity stage and margins are stable bc of economies of scale
A34: * Traffic source: 80% of hotel transactions and 74% of lifestyle transactions from food delivery/in-store dining
A35: * Hotel RN mkt share 33.6% in 1Q2018 - they said they are the largest hotel booking platform in China
A36: * Expanding steadily to mid to high-end hotels to satisfy consumer needs

Sheet Key Financial Data
B1: 总则： | C1: 黑色数字为历史数字，请自行输入或导入；绿色数字为计算项，无需改动；蓝色字体部分需要做出合理估计、或者需要从会计报表附注中查找、等；
A2: Unit: Thousand | W2: =W5/K5-1 -> 1.2436707
B3: 17Q1 | C3: 17Q2 | D3: 17Q3 | E3: 17Q4 | F3: 18Q1 | G3: 18Q2 | H3: 18Q3 | I3: 18Q4 | J3: 19Q1 | K3: 19Q2 | L3: 19Q3 | M3: 19Q4 | N3: 20Q1 | O3: 20Q2 | P3: 20Q3 | Q3: 20Q4 | R3: 21Q1 | S3: 21Q2 | T3: 21Q3 | U3: 21Q4 | V3: 22Q1 | W3: 22Q2 | X3: 22Q3 | Y3: 22Q4 | Z3: 23Q1 | AA3: 23Q2 | AB3: 23Q3 | AC3: 23Q4 | AD3: 24Q1 | AE3: 24Q2 | AF3: 24Q3 | AG3: 24Q4 | AH3: 25Q1 | AI3: 25Q2 | AJ3: 25Q3 | AK3: 25Q4 | AL3: 26Q1 | AM3: 26Q2 | AN3: 2017 1H | AO3: 2017 2H | AP3: 2018 1H | AQ3: 2018 2H | AR3: 2019 1H | AS3: 2020 1H | AU3: 2017 YTD-Q3 | AV3: 2018 YTD-Q3 | AX3: 2015 FY | AY3: 2016 FY | AZ3: 2017 FY | BA3: 2018 FY | BB3: 2019 FY | BC3: 2020 FY | BD3: 2021 FY | BE3: 2022 FY | BF3: 2023FY
A4: P&L | F4: (倒减) | X4: =X5/L5-1 -> 1.2775783 | Y4: =Y5/M5-1 -> 1.1353931 | Z4: =Z5/J5-1 -> 2.057211 | AA4: =AA5/K5-1 -> 1.9936226 | AB4: =AB5/L5-1 -> 1.7812591 | AC4: =AC5/M5-1 -> 1.6172061 | AD4: =AD5/J5-1 -> 2.8217247 | AO4: (倒减) | AU4: (加总) | AV4: (加总)
A5: Revenues | D5: 9673796 | E5: 10475378 | F5: =AP5-G5 -> 11275063 | G5: 15072764 | H5: 19075999 | I5: 19803452 | J5: 19173512 | K5: 22703137 | L5: 27493629 | M5: 28158253 | N5: 16753887 | O5: 24721837 | P5: 35401282 | Q5: 37917504 | R5: 37016262 | S5: 43759232 | T5: 48829370 | U5: 49523133 | V5: 46268754 | W5: 50938363 | X5: 62618892 | Y5: 60128939 | Z5: 58617472 | AA5: 67964624 | AB5: 76466907 | AC5: 73695951 | AD5: 73275884 | AE5: 82251077 | AF5: 93577319 | AG5: 88487296 | AH5: 86557126 | AI5: 91840480 | AJ5: 95488113 | AK5: 92096429 | AL5: 91038906 | AM5: 104643044 | AN5: 13778813 | AO5: =AZ5-AN5 -> 20149174 | AP5: 26347827 | AQ5: =BA5-AP5 -> 38879451 | AR5: 41876649 | AU5: =D5+AN5 -> 23452609 | AV5: =H5+AP5 -> 45423826 | AX5: 4018959 | AY5: 12988077 | AZ5: 33927987 | BA5: 65227278 | BB5: 97528531 | BC5: 114794510 | BD5: 179127997 | BE5: 219954948
A6: Cost of revenues | D6: -6240679 | E6: -7123869 | F6: =AP6-G6 -> -8063090 | G6: -12232014 | H6: -14504758 | I6: -15322458 | J6: -14104172 | K6: -14762502 | L6: -17901345 | M6: -18440124 | N6: -11557421 | O6: -16146879 | P6: -24578273 | Q6: -28461795 | R6: -29816095 | S6: -31245861 | T6: -38051383 | U6: -37540530 | V6: -35528467 | W6: -35363935 | X6: -44114024 | Y6: -43195543 | Z6: -38800047 | AA6: -42566619 | AB6: -49484515 | AC6: -48702612 | AD6: -47579144 | AE6: -48361233 | AF6: -56823456 | AG6: -55043149 | AH6: -54143437 | AI6: -61426477 | AJ6: -70307050 | AK6: -67969156 | AL6: -65068834 | AM6: -69548247 | AN6: -8343935 | AO6: =AZ6-AN6 -> -13364548 | AP6: -20295104 | AQ6: =BA6-AP6 -> -29827216 | AR6: -28866674 | AU6: =D6+AN6 -> -14584614 | AV6: =H6+AP6 -> -34799862 | AX6: -1239504 | AY6: -7046841 | AZ6: -21708483 | BA6: -50122320 | BB6: -65208143 | BC6: -80744368 | BD6: -136653869 | BE6: -158201969
A8: Gross profit | D8: =D5+D6 -> 3433117 | E8: =E5+E6 -> 3351509 | F8: =AP8-G8 -> 3211973 | G8: =G5+G6 -> 2840750 | H8: =H5+H6 -> 4571241 | I8: =I5+I6 -> 4480994 | J8: =J5+J6 -> 5069340 | K8: =K5+K6 -> 7940635 | L8: =L5+L6 -> 9592284 | M8: =M5+M6 -> 9718129 | N8: =N5+N6 -> 5196466 | ... Y8: =Y5+Y6 -> 16933396 | Z8: 19817425 | AA8: 25398005 | AB8: =AB5+AB6 -> 26982392 | AC8: =AC5+AC6 -> 24993339 | AD8: =AD5+AD6 -> 25696740 | AE8: =AE5+AE6 -> 33889844 | AF8: =AF5+AF6 -> 36753863 | AG8: =AG5+AG6 -> 33444147 | AH8: =AH5+AH6 -> 32413689 | AI8: =AI5+AI6 -> 30414003 | AJ8: 25181063 | AK8: =AK5+AK6 -> 24127273 | AL8: =AL5+AL6 -> 25970072 | AM8: =AM5+AM6 -> 35094797 | AN8: =AN5+AN6 -> 5434878 | AO8: =AZ8-AN8 -> 6784626 | AP8: =AP5+AP6 -> 6052723 | AQ8: =BA8-AP8 -> 9052235 | AR8: =AR5+AR6 -> 13009975 | AT8: =AT5+AT6 -> 0 | AU8: =D8+AN8 -> 8867995 | AV8: =H8+AP8 -> 10623964 | AW8: =AW5+AW6 -> 0 | AX8: =AX5+AX6 -> 2779455 | AY8: =AY5+AY6 -> 5941236 | AZ8: =AZ5+AZ6 -> 12219504 | BA8: =BA5+BA6 -> 15104958 | BB8: =BB5+BB6 -> 32320388 | BC8: =BC5+BC6 -> 34050142 | BD8: =BD5+BD6 -> 42474128 | BE8: =BE5+BE6 -> 61752979
A9: Selling and marketing expenses | D9: -3183558 | E9: -3362229 | F9: =AP9-G9 -> -2846353 | G9: -3868230 | H9: -4622267 | I9: -4535051 | J9: -3706112 | K9: -4149110 | L9: -5614750 | M9: -5349095 | N9: -3199439 | O9: -4172332 | P9: -5835574 | Q9: -7675340 | R9: -7206408 | S9: -10848627 | T9: -11388227 | U9: -11239904 | V9: -9105728 | W9: -8986036 | X9: -10886422 | Y9: -10766926 | Z9: -10433070 | AA9: -14553195 | AB9: -16905422 | AC9: -16725310 | AD9: -13888302 | AE9: -14832448 | AF9: -17953163 | AG9: -17301322 | AH9: -15550016 | AI9: -22518913 | AJ9: -34266826 | AK9: -31725691 | AL9: -22968519 | AM9: -24723345 | AN9: -4362901 | AO9: =AZ9-AN9 -> -6545787 | AP9: -6714583 | AQ9: =BA9-AP9 -> -9157318 | AR9: -7855222 | AU9: =D9+AN9 -> -7546459 | AV9: =H9+AP9 -> -11336850 | AX9: -7140962 | AY9: -8337132 | AZ9: -10908688 | BA9: -15871901 | BB9: -18819067 | BC9: -20882685 | BD9: -40683166 | BE9: -39745979
A10: Research and development expenses | D10: -1026987 | E10: -1149301 | F10: =AP10-G10 -> -1382740 | G10: -1703837 | H10: -2003497 | I10: -1981826 | J10: -2036100 | K10: -2032330 | L10: -2137349 | M10: -2239885 | N10: -2296458 | O10: -2376737 | P10: -2970120 | Q10: -3249199 | R10: -3477290 | S10: -3900794 | T10: -4715550 | U10: -4581961 | V10: -4879033 | W10: -5203533 | X10: -5414371 | Y10: -5242928 | Z10: -5047387 | AA10: -5407176 | AB10: -5321157 | AC10: -5425285 | AD10: -5000153 | AE10: -5339680 | AF10: -5293483 | AG10: -5420285 | AH10: -5772030 | AI10: -6260087 | AJ10: -6936845 | AK10: -7029303 | AL10: -7043098 | AM10: -7670045 | AN10: -1470346 | AO10: =AZ10-AN10 -> -2176288 | AP10: -3086577 | AQ10: =BA10-AP10 -> -3985323 | AR10: -4068430 | AU10: =D10+AN10 -> -2497333 | AV10: =H10+AP10 -> -5090074 | AX10: -1204033 | AY10: -2366674 | AZ10: -3646634 | BA10: -7071900 | BB10: -8445664 | BC10: -10892514 | BD10: -16675595 | BE10: -20739865
A11: General and administrative expenses | D11: -524435 | E11: -914441 | F11: =AP11-G11 -> -667281 | G11: -996210 | H11: -1238040 | I11: -2846080 | J11: -1075193 | K11: -1038298 | L11: -1055969 | M11: -1564478 | N11: =-(1069741+237542) -> -1307283 | O11: =-1158092-45676 -> -1203768 | P11: =-1415119-130285 -> -1545404 | Q11: =-1950943-54187 -> -2005130 | R11: =-1737403+33775 -> -1703628 | S11: =-2053024-104355 -> -2157379 | T11: -2387116 | U11: =-2435083-52489 -> -2487572 | V11: =-2312289-153316 -> -2465605 | W11: =-2503552-50437 -> -2553989 | X11: -2505272 | Y11: -2450697 | Z11: -1994953 | AA11: -2139084 | AB11: -2537785 | AC11: -2700281 | AD11: -2298323 | AE11: -2694931 | AF11: -2797760 | AG11: -2938189 | AH11: -2627017 | AI11: -2678950 | AJ11: -2957804 | AK11: -3652661 | AL11: -2938393 | AM11: -3238070 | AN11: -732532 | AO11: =AZ11-AN11 -> -1438876 | AP11: -1663491 | AQ11: =BA11-AP11 -> -4168201 | AR11: -2050511 | AU11: =D11+AN11 -> -1256967 | AV11: =H11+AP11 -> -2901531 | AX11: -2905420 | AY11: -1722605 | AZ11: -2171408 | BA11: -5831692 | BB11: -4984639 | BC11: =-5593895-467690 -> -6061585 | BD11: =-8612626-259953 -> -8872579 | BE11: -9771810
A12: Share-based compensation | D12: -231222 | F12: =AP12-G12 -> -294678 | G12: -387580 | H12: -539632 | I12: -643223 | J12: -438068 | K12: -515501 | L12: -537169 | M12: -700133 | N12: -691676 | O12: -705420 | P12: -838709 | Q12: -1041671 | R12: -937902 | S12: -1140658 | T12: -1481159 | U12: -1634141 | V12: -1618334 | W12: -2357747 | X12: -2445766 | Y12: -2321115 | Z12: -1936848 | AA12: -2450640 | AB12: -2138443 | AC12: -1857422 | AD12: -1851012 | AE12: -2069327 | AF12: -1890022 | AG12: -1772332 | AH12: -1707846 | AI12: -1387416 | AJ12: -1558306 | AK12: -1348299 | AL12: -1383006 | AM12: -1918583 | AN12: -279881 | AO12: =AZ12-AN12 -> -691219 | AP12: -682258 | AQ12: =BA12-AP12 -> -1182855 | AR12: -953569 | AU12: =D12+AN12 -> -511103 | AV12: =H12+AP12 -> -1221890 | AX12: -2599378 | AY12: -913075 | AZ12: -971100 | BA12: -1865113 | BB12: -2190871 | BC12: -3277476 | BD12: -5193860 | BE12: -468620
T13: =T8/T5 -> 0.22072755 | X13: =X8/X5 -> 0.29551574 | Y13: =Y8/Y5 -> 0.28161807 | Z13: =Z8/Z5 -> 0.33808051 | AA13: =AA8/AA5 -> 0.37369448 | AB13: =AB8/AB5 -> 0.35286365 | AC13: =AC8/AC5 -> 0.33914128 | AD13: =AD8/AD5 -> 0.35068482 | AE13: =AE8/AE5 -> 0.41202918 | ... AM13: =AM8/AM5 -> 0.3353763
A15: Operating Income (Loss) - comparable to Ctrip | D15: =SUM(D8,D9,D10,D11) -> -1301863 | E15: =SUM(E8,E9,E10,E11) -> -2074462 | F15: =AP15-G15 -> -1684401 | G15: =SUM(G8,G9,G10,G11) -> -3727527 | H15: =SUM(H8,H9,H10,H11) -> -3292563 | I15: =SUM(I8,I9,I10,I11) -> -4881963 | J15: =SUM(J8,J9,J10,J11) -> -1748065 | K15: =SUM(K8,K9,K10,K11) -> 720897 | L15: =SUM(L8,L9,L10,L11) -> 784216 | M15: =SUM(M8,M9,M10,M11) -> 564671 | N15: =SUM(N8,N9,N10,N11) -> -1606714 | ... AN15: =SUM(AN8,AN9,AN10,AN11) -> -1130901 | AO15: =AZ15-AN15 -> -3376325 | AP15: =SUM(AP8,AP9,AP10,AP11) -> -5411928 | AQ15: =SUM(AQ8,AQ9,AQ10,AQ11) -> -8258607 | AR15: =SUM(AR8,AR9,AR10,AR11) -> -964188 | AT15: =SUM(AT8,AT9,AT10,AT11) -> 0 | AU15: =D15+AN15 -> -2432764 | AV15: =H15+AP15 -> -8704491 | AW15: =SUM(AW8,AW9,AW10,AW11) -> 0 | AX15: =SUM(AX8,AX9,AX10,AX11) -> -8470960 | AY15: =SUM(AY8,AY9,AY10,AY11) -> -6485175 | AZ15: =SUM(AZ8,AZ9,AZ10,AZ11) -> -4507226 | BA15: =SUM(BA8,BA9,BA10,BA11) -> -13670535 | BB15: =SUM(BB8,BB9,BB10,BB11) -> 71018 | BC15: =SUM(BC8,BC9,BC10,BC11) -> -3786642 | BD15: =SUM(BD8,BD9,BD10,BD11) -> -23757212 | BE15: =SUM(BE8,BE9,BE10,BE11) -> -8504675
A16: Non-GAAP Operating Income(Loss) - comparable to Ctrip | D16: =D15-D12 -> -1070641 | E16: =E15-E12 -> -2074462 | F16: =F15-F12 -> -1389723 | G16: =G15-G12 -> -3339947 | H16: =H15-H12 -> -2752931 | I16: =I15-I12 -> -4238740 | J16: =J15-J12 -> -1309997 | K16: =K15-K12 -> 1236398 | ... AN16: =AN15-AN12 -> -851020 | AO16: =AZ16-AN16 -> -2685106 | AP16: =AP15-AP12 -> -4729670 | AQ16: =AQ15-AQ12 -> -7075752 | AR16: =AR15-AR12 -> -10619 | AU16: =D16+AN16 -> -1921661 | AV16: =H16+AP16 -> -7482601 | AX16: =AX15-AX12 -> -5871582 | AY16: =AY15-AY12 -> -5572100 | AZ16: =AZ15-AZ12 -> -3536126 | BA16: =BA15-BA12 -> -11805422 | BB16: =BB15-BB12 -> 2261889 | BC16: =BC15-BC12 -> -509166 | BD16: =BD15-BD12 -> -18563352 | BE16: =BE15-BE12 -> -8036055
A17: Fair value changes on investments measured at fair value through profit or loss | D17: 484045 | E17: 241006 | F17: =AP17-G17 -> 471066 | G17: 715216 | H17: -340553 | I17: 990653 | J17: 165292 | K17: -323651 | L17: 163615 | M17: 72443 | N17: -508261 | O17: 346689 | P17: 5779364 | Q17: -661883 | R17: 42034 | S17: 164748 | T17: -117990 | U17: 726955 | V17: -802894 | W17: -292183 | X17: -105922 | Y17: 187942 | Z17: 164029 | AA17: 103761 | AB17: 28089 | AC17: -61652 | AD17: -517116 | AE17: -120037 | AF17: 765239 | AG17: 12835 | AH17: 804820 | AI17: 481537 | AJ17: -389928 | AK17: 1496964 | AL17: 392441 | AM17: 54814 | AN17: -252177 | AO17: =AZ17-AN17 -> 725051 | AP17: 1186282 | AQ17: =BA17-AP17 -> 650100 | AR17: 1186282 | AU17: =D17+AN17 -> 231868 | AV17: =H17+AP17 -> 845729 | AX17: 46953 | AY17: 23550 | AZ17: 472874 | BA17: 1836382 | BB17: 77699 | BC17: 4955909 | BD17: 815747 | BE17: -1013057
A18: Other gains, net | D18: -227558 | E18: 302857 | F18: =AP18-G18 -> 164911 | G18: 160894 | H18: 265759 | I18: 156792 | J18: 279131 | K18: 854043 | L18: 611223 | M18: 786746 | N18: 399445 | O18: 1005835 | P18: 472408 | Q18: 1283147 | R18: 378118 | S18: 976976 | T18: -2134851 | U18: 594023 | V18: 928731 | W18: 968475 | X18: 1679376 | Y18: 588455 | Z18: 1335024 | AA18: 1505916 | AB18: 1388793 | AC18: 2085740 | AD18: 1391932 | AE18: 630572 | AF18: 2485778 | AG18: -933297 | AH18: 1418138 | AI18: 807979 | AJ18: -96233 | AK18: 1147736 | AL18: 598697 | AM18: 3493946 | AN18: 132961 | AO18: =AZ18-AN18 -> 75299 | AP18: 325805 | AQ18: =BA18-AP18 -> 422551 | AR18: 1133174 | AU18: =D18+AN18 -> -94597 | AV18: =H18+AP18 -> 591564 | AX18: -49928 | AY18: 206212 | AZ18: 208260 | BA18: 748356 | BB18: 2531143 | BC18: 3160835 | BD18: -185734 | BE18: 4165037
A19: Meituan Reported Operating Income (Loss) | D19: =SUM(D15,D17,D18) -> -1045376 | E19: =SUM(E15,E17,E18) -> -1530599 | F19: =AP19-G19 -> -1048424 | G19: =SUM(G15,G17,G18) -> -2851417 | H19: =SUM(H15,H17,H18) -> -3367357 | I19: =SUM(I15,I17,I18) -> -3734518 | J19: =SUM(J15,J17,J18) -> -1303642 | K19: =SUM(K15,K17,K18) -> 1251289 | L19: =SUM(L15,L17,L18) -> 1559054 | M19: =SUM(M15,M17,M18) -> 1423860 | N19: =SUM(N15,N17,N18) -> -1715530 | ... AC19: =SUM(AC15,AC17,AC18) -> 2166551 | AE19: =SUM(AE15,AE17,AE18) -> 11533320 | AF19: =SUM(AF15,AF17,AF18) -> 13960474 | AG19: =SUM(AG15,AG17,AG18) -> 6863889 | AH19: =SUM(AH15,AH17,AH18) -> 10687584 | AI19: =SUM(AI15,AI17,AI18) -> 245569 | AJ19: =SUM(AJ15,AJ17,AJ18) -> -19466573 | AK19: -16074247 | AL19: -6469811 | AM19: 2691166 | AN19: =SUM(AN15,AN17,AN18) -> -1250117 | AO19: =SUM(AO15,AO17,AO18) -> -2575975 | AP19: =SUM(AP15,AP17,AP18) -> -3899841 | AQ19: =SUM(AQ15,AQ17,AQ18) -> -7185956 | AR19: =SUM(AR15,AR17,AR18) -> 1355268 | AT19: =SUM(AT15,AT17,AT18) -> 0 | AU19: =D19+AN19 -> -2295493 | AV19: =H19+AP19 -> -7267198 | AW19: =SUM(AW15,AW17,AW18) -> 0 | AX19: =SUM(AX15,AX17,AX18) -> -8473935 | AY19: =SUM(AY15,AY17,AY18) -> -6255413 | AZ19: =SUM(AZ15,AZ17,AZ18) -> -3826092 | BA19: =SUM(BA15,BA17,BA18) -> -11085797 | BB19: =SUM(BB15,BB17,BB18) -> 2679860 | BC19: =SUM(BC15,BC17,BC18) -> 4330102 | BD19: =SUM(BD15,BD17,BD18) -> -23127199 | BE19: -5820448
A20: Meituan reported Adjusted EBITDA | D20: -839675 | E20: -1358685 | F20: =AP20-G20 -> -1116486 | G20: -1590839 | H20: -1171905 | I20: -854601 | J20: 458874 | K20: 2330809 | L20: 2285301 | M20: 2178650 | N20: 41311 | O20: 2610255 | P20: 2675399 | Q20: -589128 | R20: -2382683 | S20: -1239986 | T20: -4061659 | U20: -2009748 | V20: -1840771 | W20: 3802741 | X20: 4801736 | Y20: 2960883 | Z20: 6262060 | AA20: 7682351 | AB20: 6189201 | AC20: 3744406 | AD20: 8070343 | AE20: 14997268 | AF20: 14529197 | AG20: 11522592 | AH20: 12301686 | AI20: 2781961 | AJ20: -14841897 | AK20: -14024955 | AL20: -3049429 | AM20: 4098050 | AN20: -493451 | AO20: =AZ20-AN20 -> -2198360 | AP20: -2707325 | AQ20: =BA20-AP20 -> -2026506 | AR20: 2789683 | AX20: -5693387 | AY20: -4998311 | AZ20: -2691811 | BA20: -4733831 | BB20: 7253634 | BC20: 4737837 | BD20: -9694076 | BE20: 9724589
T21: =T20/T5 -> -0.083180655 | W21: =W20/W5 -> 0.074653773 | X21: =X20/X5 -> 0.076681906 | Y21: =Y20/Y5 -> 0.049242229 | Z21: =Z20/Z5 -> 0.10682924 | AA21: =AA20/AA5 -> 0.11303455 | AB21: =AB20/AB5 -> 0.080939602 | AC21: =AC20/AC5 -> 0.050808843 | AD21: =AD20/AD5 -> 0.11013641 | ... AM21: =AM20/AM5 -> 0.039162183
A22: Finance income | D22: 11892 | E22: 36179 | F22: =AP22-G22 -> 47178 | G22: 61991 | H22: 68451 | I22: 116427 | J22: 52922 | K22: 21541 | L22: 38235 | M22: 53519 | N22: 57930 | O22: 40352 | P22: 45678 | Q22: 69724 | R22: 77855 | S22: 112118 | T22: 198890 | U22: 157174 | V22: 110359 | W22: 190412 | X22: 209746 | Y22: 147391 | Z22: 184419 | AA22: 217189 | AB22: 201225 | AC22: 216153 | AD22: 279755 | AE22: 344494 | AF22: 313088 | AG22: 354470 | AH22: 491358 | AI22: 508307 | AJ22: 513372 | AK22: 498498 | AL22: 481926 | AM22: 505919 | AN22: 12814 | AO22: =AZ22-AN22 -> 48071 | AP22: 109169 | AQ22: =BA22-AP22 -> 184878 | AR22: -74463 | AU22: =D22+AN22 -> 24706 | AV22: =H22+AP22 -> 177620 | AX22: 13541 | AY22: 21681 | AZ22: 60885 | BA22: 294047 | BB22: 166217 | BC22: 213684 | BD22: 546037 | BE22: 657908
A23: Finance costs | D23: -2768 | E23: -13200 | F23: =AP23-G23 -> -8412 | G23: -5427 | H23: -15486 | I23: -15407 | J23: -46821 | K23: -50115 | L23: -49011 | M23: -45095 | N23: -48044 | O23: -60731 | P23: -111506 | Q23: -149735 | R23: -166052 | S23: -263269 | T23: -369942 | U23: -331672 | V23: -330317 | W23: -418612 | X23: -474728 | Y23: -405168 | Z23: -353479 | AA23: -354003 | AB23: -350950 | AC23: -366725 | AD23: -321863 | AE23: -285373 | AF23: -261651 | AG23: -468151 | AH23: -475120 | AI23: -430214 | AJ23: -413987 | AK23: -567481 | AL23: -786977 | AM23: -806365 | AN23: -3246 | AO23: =AZ23-AN23 -> -15968 | AP23: -13839 | AQ23: =BA23-AP23 -> -30893 | AR23: -96936 | AU23: =D23+AN23 -> -6014 | AV23: =H23+AP23 -> -29325 | AX23: -56561 | AY23: -55981 | AZ23: -19214 | BA23: -44732 | BB23: -191042 | BC23: -370016 | BD23: -1130935 | BE23: -1628825
A24: Fair value changes of convertible redeemable preferred shares | D24: -3283180 | E24: -663781 | F24: =AP24-G24 -> -20213076 | G24: -4637019 | H24: -79755963 | I24: 0 | J24: 0 | K24: 0 | L24: 0 | M24: 0 | N24: 0 | O24: 0 | P24: 0 | Q24: 0 | AN24: -11191863 | AO24: =AZ24-AN24 -> -3946961 | AP24: -24850095 | AQ24: =BA24-AP24 -> -79755963 | AR24: 0 | AU24: =D24+AN24 -> -14475043 | AV24: =H24+AP24 -> -104606058 | AX24: -725113 | AY24: -4313365 | AZ24: -15138824 | BA24: -104606058 | BB24: 0
A25: Share of gains of investments accounted for using equity method | D25: -19727 | E25: -31263 | F25: =AP25-G25 -> -575 | G25: 7425 | H25: 1758 | I25: -56875 | J25: 7530 | K25: 17848 | L25: 24329 | M25: 57646 | N25: 11128 | O25: 42881 | P25: 92698 | Q25: 117398 | R25: 2013 | S25: 38251 | T25: 273237 | U25: -163855 | V25: 46411 | W25: -400052 | X25: 485362 | Y25: -95873 | Z25: -49759 | AA25: 122406 | AB25: 434521 | AC25: 705484 | AD25: 314197 | AE25: 341204 | AF25: 213821 | AG25: 316482 | AH25: 18453 | AI25: 89223 | AJ25: 9541 | AK25: -38325 | AL25: -502001 | AM25: -86573 | AN25: 40572 | AO25: =AZ25-AN25 -> -50990 | AP25: 6850 | AQ25: =BA25-AP25 -> -55117 | AR25: 25378 | AU25: =D25+AN25 -> 20845 | AV25: =H25+AP25 -> 8608 | AX25: -661 | AY25: -28018 | AZ25: -10418 | BA25: -48267 | BB25: 107353 | BC25: 264105 | BD25: 145620 | BE25: 35858
A27: Gain (Loss) before income tax | D27: =SUM(D19,D22,D23,D24,D25) -> -4339159 | E27: =SUM(E19,E22,E23,E24,E25) -> -2202664 | F27: =AP27-G27 -> 14320747 | G27: =SUM(G19,G22,G23,G24,G25) -> -7424447 | H27: =SUM(H19,H22,H23,H24,H25) -> -83068597 | I27: =SUM(I19,I22,I23,I24,I25) -> -3690373 | J27: =SUM(J19,J22,J23,J24,J25) -> -1290011 | K27: =SUM(K19,K22,K23,K24,K25) -> 1240563 | L27: =SUM(L19,L22,L23,L24,L25) -> 1572607 | M27: =SUM(M19,M22,M23,M24,M25) -> 1489930 | N27: =SUM(N19,N22,N23,N24,N25) -> -1694516 | ... Y27: =SUM(Y19,Y22,Y23,Y24,Y25) -> -1104408 | Z27: 3366902 | AA27: 4688619 | AB27: 3643329 | AC27: 3643329 | AD27: 5481481 | AE27: 11657214 | AF27: 13950434 | AG27: 6896300 | AH27: 10600801 | AI27: 393666 | AJ27: -19650424 | AK27: -16181555 | AL27: -7276863 | AM27: 2304147 | AN27: 6896300 | AO27: 6896300 | AP27: 6896300 | AQ27: 6896300 | AR27: 6896300 | AS27: 6896300 | AT27: 6896300 | AU27: 6896300 | AV27: 6896300 | AW27: 6896300 | AX27: =SUM(AX19,AX22,AX23,AX24,AX25) -> -9242729 | AY27: =SUM(AY19,AY22,AY23,AY24,AY25) -> -10631096 | AZ27: =SUM(AZ19,AZ22,AZ23,AZ24,AZ25) -> -18933663 | BA27: =SUM(BA19,BA22,BA23,BA24,BA25) -> -115490807 | BB27: =SUM(BB19,BB22,BB23,BB24,BB25) -> 2762388 | BC27: =SUM(BC19,BC22,BC23,BC24,BC25) -> 4437875 | BD27: =SUM(BD19,BD22,BD23,BD24,BD25) -> -23566477 | BE27: -6755517
A28: Income tax expenses | D28: -30746 | E28: 21846 | F28: =AP28-G28 -> 158503 | G28: -292034 | H28: -144478 | I28: 276121 | J28: -143319 | K28: -226024 | L28: -127235 | M28: -29645 | N28: 115238 | O28: 13034 | P28: -429552 | Q28: 571017 | R28: 10955 | S28: 8230 | T28: 6036 | U28: 5058 | V28: 55223 | W28: 5063 | X28: 8209 | Y28: 1699 | Z28: -8411 | AA28: -9972 | AB28: -50095 | AC28: -96059 | AD28: -112502 | AE28: -304876 | AF28: -1085480 | AG28: -674249 | AH28: -543921 | AI28: -28370 | AJ28: 1018336 | AK28: 1037273 | AL28: 449605 | AM28: -148925 | AN28: -45318 | AO28: =AZ28-AN28 -> -8900 | AP28: -133531 | AQ28: =BA28-AP28 -> 131643 | AR28: -369343 | AU28: =D28+AN28 -> -76064 | AV28: =H28+AP28 -> -278009 | AX28: 11648 | AY28: -267903 | AZ28: -54218 | BA28: -1888 | BB28: -526223 | BC28: 269737 | BD28: 30279 | BE28: 70194
A30: Loss for the year/period from contuning operations | D30: =SUM(D27,D28) -> -4369905 | E30: =SUM(E27,E28) -> -2180818 | F30: =AP30-G30 -> 14479250 | G30: =SUM(G27,G28) -> -7716481 | H30: =SUM(H27,H28) -> -83213075 | I30: =SUM(I27,I28) -> -3414252 | J30: =SUM(J27,J28) -> -1433330 | K30: =SUM(K27,K28) -> 1014539 | L30: =SUM(L27,L28) -> 1445372 | M30: =SUM(M27,M28) -> 1460285 | N30: =SUM(N27,N28) -> -1579278 | ... AC30: =SUM(AC27,AC28) -> 3547270 | AD30: 5368979 | AE30: 11352338 | AF30: 12864954 | AG30: 6222051 | AH30: =AH27+AH28 -> 10056880 | AI30: =AI27+AI28 -> 365296 | AJ30: -18632088 | AK30: -15144282 | AL30: -6827258 | AM30: 2155222 | AN30: =SUM(AN27,AN28) -> 6850982 | AO30: =AZ30-AN30 -> -25838863 | AP30: =SUM(AP27,AP28) -> 6762769 | AQ30: =SUM(AQ27,AQ28) -> 7027943 | AR30: =SUM(AR27,AR28) -> 6526957 | AT30: =SUM(AT27,AT28) -> 6896300 | AU30: =D30+AN30 -> 2481077 | AV30: =H30+AP30 -> -76450306 | AW30: =SUM(AW27,AW28) -> 6896300 | AX30: =SUM(AX27,AX28) -> -9231081 | AY30: =SUM(AY27,AY28) -> -10898999 | AZ30: =SUM(AZ27,AZ28) -> -18987881 | BA30: =SUM(BA27,BA28) -> -115492695 | BB30: =SUM(BB27,BB28) -> 2236165 | BC30: =SUM(BC27,BC28) -> 4707612 | BD30: =SUM(BD27,BD28) -> -23536198 | BE30: -6685323
A31: (Loss)/profit from discontuning operation | AX31: -1288257 | AY31: 5104001
A33: Gain (Loss) for the period | D33: =SUM(D30,D31) -> -4369905 | E33: =SUM(E30,E31) -> -2180818 | F33: =AP33-G33 -> 14479250 | G33: =SUM(G30,G31) -> -7716481 | H33: =SUM(H30,H31) -> -83213075 | I33: =SUM(I30,I31) -> -3414252 | J33: =SUM(J30,J31) -> -1433330 | K33: =SUM(K30,K31) -> 1014539 | L33: =SUM(L30,L31) -> 1445372 | M33: =SUM(M30,M31) -> 1460285 | N33: =SUM(N30,N31) -> -1579278 | ... AC33: =SUM(AC30,AC31) -> 3547270 | AD33: 5368979 | AE33: 11352338 | AF33: 12864954 | AG33: 6222051 | AH33: =AH30 -> 10056880 | AI33: =AI30 -> 365296 | AJ33: =AJ30 -> -18632088 | AK33: -15144282 | AL33: -6827258 | AM33: 2155222 | AN33: =SUM(AN30,AN31) -> 6850982 | AO33: =SUM(AO30,AO31) -> -25838863 | AP33: =SUM(AP30,AP31) -> 6762769 | AQ33: =SUM(AQ30,AQ31) -> 7027943 | AR33: =SUM(AR30,AR31) -> 6526957 | AS33: =SUM(AS30,AS31) -> 0 | AT33: =SUM(AT30,AT31) -> 6896300 | AU33: =SUM(AU30,AU31) -> 2481077 | ... BC33: =SUM(BC30,BC31) -> 4707612 | BD33: -23536198 | BE33: -6685323
A34: Loss for the period attributable to:
A35: Equity holders of the Company | D35: -4351661 | F35: =AP35-G35 -> -21051147 | G35: -7705707 | H35: -83295010 | J35: -1431777 | K35: 877415 | L35: 1335202 | M35: =BB35-SUM(J35:L35) -> 1457929 | N35: -1578336 | O35: 2209747 | P35: 6321603 | Q35: =BC35-SUM(N35:P35) -> -2244701 | R35: -4847283 | S35: -3357323 | T35: -9994660 | U35: =U33-U36 -> -5339113 | V35: =V33-V36 -> -5702489 | W35: =W33-W36 -> -1116519 | X35: 1216442 | Y35: -1083544 | Z35: 3358233 | AK35: -23355015 | AN35: -12403508 | AP35: -28756854 | AR35: -554362 | AU35: =D35+AN35 -> -16755169 | AV35: =H35+AP35 -> -112051864 | AX35: -10519338 | AY35: -5789900 | AZ35: -18916617 | BA35: -115477171 | BB35: 2238769 | BC35: 4708313 | BD35: -23538379 | BE35: -6686110
A36: Non-controlling interests | D36: -18244 | F36: =AP36-G36 -> -122757 | G36: -10774 | H36: -2146 | J36: -1553 | K36: -1587 | L36: -1820 | M36: =BB36-SUM(J36:L36) -> 2320 | N36: -942 | O36: 434 | P36: -602 | Q36: =BC36-SUM(N36:P36) -> 409 | R36: 1021 | S36: 948 | T36: 250 | U36: =BD36-R36-S36-T36 -> -38 | V36: -77 | W36: 492 | X36: 369 | Y36: 3 | Z36: 258 | AK36: 821 | AN36: -33650 | AP36: -133531 | AR36: -369343 | AU36: =D36+AN36 -> -51894 | AV36: =H36+AP36 -> -135677 | AX36: 0 | AY36: -5098 | AZ36: -71264 | BA36: -15524 | BB36: -2640 | BC36: -701 | BD36: 2181 | BE36: 787
A37: Fair value (gains)/losses on investments | D37: -547092 | F37: =AP37-G37 -> -475274 | G37: -715216 | H37: -340553 | I37: 984359 | J37: -211158 | K37: 278157 | L37: 163615 | M37: 72443 | N37: 508261 | O37: -347393 | P37: -5779364 | Q37: -191031 | R37: 42034 | S37: 164748 | T37: -580615 | U37: -471908 | V37: -575657 | W37: -292183 | X37: -533376 | Y37: 390604 | Z37: 113490 | AA37: 103761 | AB37: -95835 | AC37: -98933 | AD37: 359322 | AE37: -62507 | AF37: -567679 | AG37: 78069 | AH37: -777438 | AI37: -355455 | AJ37: 335243 | AK37: -1537272 | AL37: 389746 | AM37: -1604473 | AN37: 291045 | AP37: -1190490 | AR37: 66999 | AU37: =D37+AN37 -> -256047 | AV37: =H37+AP37 -> -1531043 | AX37: -46953 | AY37: 25789 | AZ37: -541731 | BA37: -1834296 | BB37: -169059 | BC37: -5809527 | BD37: -1247255 | BE37: 193472
A38: Non-GAAP Loss for the period attributable to Equity holders of the Company - comparable to Ctrip | D38: =D35+D37-D12 -> -4667531 | F38: =AP38-G38 -> -21231743 | G38: =G35+G37-G12 -> -8033343 | H38: =H35+H37-H12 -> -83095931 | J38: =J35+J37-J12 -> -1204867 | K38: =K35+K37-K12 -> 1671073 | L38: =L35+L37-L12 -> 2035986 | M38: =M35+M37-M12 -> 2230505 | N38: =N35+N37-N12 -> -378399 | O38: =O35+O37-O12 -> 2567774 | P38: =P35+P37-P12 -> 1380948 | Q38: =Q35+Q37-Q12 -> -1394061 | ... AV38: =AV35+AV37-AV12 -> -112361017 | AX38: =AX35+AX37-AX12 -> -7966913 | AY38: =AY35+AY37-AY12 -> -4851036 | AZ38: =AZ35+AZ37-AZ12 -> -18487248 | BA38: =BA35+BA37-BA12 -> -115446354 | BB38: =BB35+BB37-BB12 -> 4260581 | BC38: =BC35+BC37-BC12 -> 2176262 | BD38: =BD35+BD37-BD12 -> -19591774 | BE38: =BE35+BE37-BE12 -> -6024018
A39: EPS to equity shareholoders
A40: Basic EPS | AN40: -8.21 | AP40: -18.53 | AR40: -0.1 | AX40: -9.89 | AY40: -3.98 | AZ40: -12.37 | BA40: -42.4 | BB40: 0.39 | BC40: 0.81 | BD40: -3.9 | BE40: -1.09
A41: Diluted EPS | AN41: -8.21 | AP41: -18.53 | AR41: -0.1 | AX41: -9.89 | AY41: -3.98 | AZ41: -12.37 | BA41: -42.4 | BB41: 0.38 | BC41: 0.78 | BD41: -3.9 | BE41: -1.09
A43: YoY Growth | AP43: =IFERROR(AN5/#REF!-1,"")
A44: Revenues | H44: =H5/D5-1 -> 0.97192488 | I44: =I5/E5-1 -> 0.89047612 | J44: =J5/F5-1 -> 0.70052371 | K44: =K5/G5-1 -> 0.50623582 | L44: =L5/H5-1 -> 0.44126811 | M44: =M5/I5-1 -> 0.42188609 | N44: =N5/J5-1 -> -0.12619623 | O44: =O5/K5-1 -> 0.088917228 | ... AM44: =AM5/AI5-1 -> 0.13940001 | AN44: =AN5/N5-1 -> -0.17757515 | AO44: =AO5/O5-1 -> -0.18496453 | AP44: =AP5/P5-1 -> -0.25573805 | AQ44: =AQ5/Q5-1 -> 0.025369471 | AR44: =AR5/AN5-1 -> 2.0392058 | AS44: =AS5/AO5-1 -> -1 | AT44: =AT5/AP5-1 -> -1 | AU44: =AU5/AQ5-1 -> -0.39678652 | AV44: =AV5/AR5-1 -> 0.084705369 | AW44: =AW5/AS5-1 -> #DIV/0! | AY44: =AY5/AX5-1 -> 2.2317018 | AZ44: =AZ5/AY5-1 -> 1.612241 | BA44: =BA5/AZ5-1 -> 0.92252131 | BB44: =BB5/BA5-1 -> 0.49521081 | BC44: =BC5/BB5-1 -> 0.17703516 | BD44: =BD5/BC5-1 -> 0.56042303 | BE44: =BE5/BD5-1 -> 0.22792055
A45: Revenues Yo2Y | R45: =R5/J5-1 -> 0.93059373 | S45: =S5/K5-1 -> 0.92745311 | T45: =T5/L5-1 -> 0.77602491 | U45: =U5/M5-1 -> 0.75874309 | V45: =V5/J5-1 -> 1.4131601 | W45: =W5/K5-1 -> 1.2436707 | X45: =X5/L5-1 -> 1.2775783 | Y45: =Y5/M5-1 -> 1.1353931 | Z45: =Z5/J5-1 -> 2.057211 | AA45: =AA5/K5-1 -> 1.9936226 | AB45: =AB5/L5-1 -> 1.7812591 | AC45: =AC5/M5-1 -> 1.6172061 | AD45: =AD5/J5-1 -> 2.8217247 | AE45: =AE5/K5-1 -> 2.6228948 | AF45: =AF5/L5-1 -> 2.4036001 | AG45: =AG5/M5-1 -> 2.1424995 | AH45: =AH5/J5-1 -> 3.5144117 | AI45: =AI5/K5-1 -> 3.0452771 | AJ45: =AJ5/L5-1 -> 2.4730996 | AK45: =AK5/M5-1 -> 2.2706727 | AL45: =AL5/N5-1 -> 4.4338976 | AM45: =AM5/O5-1 -> 3.2328183 | BD45: =BD5/BB5-1 -> 0.83667277 | BE45: =BE5/BC5-1 -> 0.9160755
A46: Revenuea QoQ Growth | E46: =E5/D5-1 -> 0.082861164 | F46: =F5/E5-1 -> 0.076339489 | G46: =G5/F5-1 -> 0.33682304 | H46: =H5/G5-1 -> 0.26559395 | I46: =I5/H5-1 -> 0.038134464 | J46: =J5/I5-1 -> -0.031809606 | K46: =K5/J5-1 -> 0.1840886 | L46: =L5/K5-1 -> 0.21100573 | ... AM46: =AM5/AL5-1 -> 0.14943213 | AN46: =AN5/Q5-1 -> -0.63661076 | AO46: =AO5/AN5-1 -> 0.46233017 | AP46: =AP5/AO5-1 -> 0.30763807 | AQ46: =AQ5/AP5-1 -> 0.47562268 | AR46: =AR5/AQ5-1 -> 0.077089514 | AS46: =AS5/AR5-1 -> -1 | AT46: =AT5/AS5-1 -> #DIV/0! | AU46: =AU5/AT5-1 -> #DIV/0! | AV46: =AV5/AU5-1 -> 0.93683466 | AW46: =AW5/AV5-1 -> -1
...

Sheet Segment Reporting
B1: 总则： | C1: 蓝色数字为历史数字，请自行输入或导入；黑色数字为计算项，无需改动；红色字体部分需要做出合理估计、或者需要从会计报表附注中查找、等；
B3: 17Q1 | C3: 17Q2 | D3: 17Q3 | E3: 17Q4 | F3: 18Q1 | G3: 18Q2 | H3: 18Q3 | I3: 18Q4 | J3: 19Q1 | K3: 19Q2 | L3: 19Q3 | M3: 19Q4 | N3: 20Q1 | O3: 20Q2 | P3: 20Q3 | Q3: 20Q4 | R3: 21Q1 | S3: 21Q2 | T3: 21Q3 | U3: 21Q4 | V3: 22Q1 | W3: 22Q2 | X3: 22Q3 | Y3: 22Q4 | Z3: 23Q1 | AA3: 23Q2 | AB3: 23Q3 | AC3: 23Q4 | AD3: 24Q1 | AE3: 24Q2 | AF3: 24Q3 | AG3: 24Q4 | AJ3: 2017 1H | AK3: 2017 2H | AL3: 2018 1H | AM3: 2018 2H | AN3: 2019 1H | AO3: 2020 1H | AQ3: 2017YTD-Q3 | AR3: 2018YTD-Q3 | AT3: 2015 | AU3: 2016 | AV3: 2017 | AW3: 2018 | AX3: 2019 | AY3: 2020 | AZ3: 2021 | BA3: 2022
A4: Food Delivery | AK4: (倒减)
A5: Numer of Food delivery orders (million) | D5: 1204.1 | E5: =AV5-AJ5-D5 -> 1354.4 | F5: =AL5-G5 -> 1224.4 | G5: 1549.2 | H5: 1787.5 | I5: 1832.3 | J5: 1662.6 | K5: 2085.1 | L5: 2469.1 | M5: 2505.3 | N5: 1374.5 | O5: 2228.9 | P5: 3212.7 | Q5: 3331.3 | R5: 2902.7 | S5: 3541.4 | T5: 4013 | U5: 3910.6 | V5: 3361.6 | AJ5: 1531.5 | AK5: =AV5-AJ5 -> 2558.5 | AL5: 2773.6 | AM5: =AW5-AL5 -> 3619.8 | AN5: =1662.6+2085.1 -> 3747.7 | AQ5: =AJ5+D5 -> 2735.6 | AR5: =AL5+H5 -> 4561.1 | AT5: 637 | AU5: 1585 | AV5: 4090 | AW5: 6393.4 | AX5: 8722.1 | AY5: 10147.4 | AZ5: 14367.6
A6: Gross Transaction Value (RMB bn) | D6: 51.8 | E6: =AV6-AJ6-D6 -> 57 | F6: =AL6-G6 -> 54.5 | G6: 68.2 | H6: 80 | I6: 80.2 | J6: 75.6 | K6: 93.1 | L6: 111.9 | M6: 112.1 | N6: 71.504 | O6: 108.8271 | P6: 152.2325 | Q6: 156.2873 | R6: =142735.4*10^(-3) -> 142.7354 | S6: =173603.3/1000 -> 173.6033 | T6: 197.098 | U6: 188.6208 | AJ6: 62.3 | AK6: =AV6-AJ6 -> 108.8 | AL6: 122.7 | AM6: =AW6-AL6 -> 160.1 | AN6: =75.6+93.1 -> 168.7 | AQ6: =AJ6+D6 -> 114.1 | AR6: =AL6+H6 -> 202.7 | AT6: 15.6 | AU6: 58.7 | AV6: 171.1 | AW6: 282.8 | AX6: 392.7 | AY6: 488.8512 | AZ6: 702.0574
A7: Average Order Value (RMB) | D7: =D6*1000/D5 -> 43.019683 | E7: =E6*1000/E5 -> 42.085056 | F7: =F6*1000/F5 -> 44.511598 | G7: =G6*1000/G5 -> 44.022721 | H7: =H6*1000/H5 -> 44.755245 | I7: =I6*1000/I5 -> 43.770125 | J7: =J6*1000/J5 -> 45.470949 | K7: =K6*1000/K5 -> 44.650137 | ... U7: =U6*1000/U5 -> 48.233212 | AJ7: =AJ6*1000/AJ5 -> 40.679073 | AK7: =AK6*1000/AK5 -> 42.524917 | AL7: =AL6*1000/AL5 -> 44.238535 | AM7: =AM6*1000/AM5 -> 44.228963 | AN7: =AN6*1000/AN5 -> 45.014275 | AQ7: =AQ6*1000/AQ5 -> 41.709314 | AR7: =AR6*1000/AR5 -> 44.441034 | AT7: =AT6*1000/AT5 -> 24.489796 | AU7: =AU6*1000/AU5 -> 37.0347 | AV7: =AV6*1000/AV5 -> 41.833741 | AW7: =AW6*1000/AW5 -> 44.233115 | AX7: =AX6*1000/AX5 -> 45.023561 | AY7: =AY6*1000/AY5 -> 48.17502 | AZ7: =AZ6*1000/AZ5 -> 48.86393
A9: Commission (RMB '000) | M9: 13963448 | N9: 8563624 | O9: 12719014 | P9: 18251171 | Q9: 19058227 | R9: 18370710 | S9: 20353682 | T9: 23222843 | U9: =14254546+7768614 -> 22023160 | V9: =V10+V11 -> 20706770 | AJ9: 8138117 | AK9: =AV9-AJ9 -> 12145847 | AL9: 15219665 | AM9: =AW9-AL9 -> 20499543 | AN9: 21632175 | AT9: 174754 | AU9: 5208994 | AV9: 20283964 | AW9: 35719208 | AX9: 49646589 | AY9: 58592036 | AZ9: =AZ10+AZ11 -> 82750914
A10: - Food delivery services | Q10: 12664562 | R10: 12165172 | U10: 14254546 | V10: 13500013 | AD10: =U10/U16 -> 0.54559428 | AH10: =V10/V16 -> 0.5588512 | AY10: 39116411 | AZ10: 54203640
A11: - Commission | Q11: 6029499 | R11: 5809915 | U11: 7768614 | V11: 7206757 | AD11: =U11/U16 -> 0.29734454 | AH11: =V11/V16 -> 0.2983334 | AY11: 18502868 | AZ11: 28547274
A12: % of segment revenue | N12: =N9/N16 -> 0.90234376 | O12: =O9/O16 -> 0.87451395 | P12: =P9/P16 -> 0.88200518 | Q12: =Q9/Q16 -> 0.88486583 | R12: =R9/R16 -> 0.89284782 | S12: =S9/S16 -> 0.88015602 | T12: =T9/T16 -> 0.87684184 | U12: =U9/U16 -> 0.84293882 | V12: =V9/V16 -> 0.8571846
A13: Online Marketing Service (RMB '000) | M13: 1732259 | N13: 919519 | O13: 1795740 | P13: 2407888 | Q13: 2441964 | R13: 2192127 | S13: 2764255 | T13: 3255079 | U13: 3223472 | V13: 2639206 | AJ13: 213399 | AK13: =AV13-AJ13 -> 496804 | AL13: 703842 | AM13: =AW13-AL13 -> 1631157 | AN13: 1867796 | AT13: 0 | AU13: 82975 | AV13: 710203 | AW13: 2334999 | AX13: 5103794 | AY13: 7565111 | AZ13: 11434933
A14: % of segment revenue | N14: =N13/N16 -> 0.096889148 | O14: =O13/O16 -> 0.12346867 | P14: =P13/P16 -> 0.11636348 | Q14: =Q13/Q16 -> 0.11337941 | R14: =R13/R16 -> 0.10654111 | S14: =S13/S16 -> 0.11953492 | T14: =T13/T16 -> 0.12290439 | U14: =U13/U16 -> 0.12337874 | V14: =V13/V16 -> 0.10925348 | AJ14: =AJ13/AJ16 -> 0.025516115 | AK14: =AK13/AK16 -> 0.03921529 | AL14: =AL13/AL16 -> 0.04408842 | AM14: =AM13/AM16 -> 0.073545923 | AN14: =AN13/AN16 -> 0.079310171 | AT14: =AT13/AT16 -> 0 | AU14: =AU13/AU16 -> 0.015652728 | AV14: =AV13/AV16 -> 0.033767842 | AW14: =AW13/AW16 -> 0.06121684 | AX14: =AX13/AX16 -> 0.093061556 | AY14: =AY13/AY16 -> 0.11416396 | AZ14: =AZ13/AZ16 -> 0.11872829
A15: Other services and sales (RMB '000) | M15: 20003 | N15: 7280 | O15: 29341 | P15: 33757 | Q15: 37794 | R15: 12573 | S15: 7147 | T15: 6721 | U15: 880009 | V15: 810746 | AJ15: 11787 | AK15: =AV15-AJ15 -> 25979 | AL15: 40821 | AM15: =AW15-AL15 -> 48055 | AN15: 50552 | AT15: 0 | AU15: 9024 | AV15: 37766 | AW15: 88876 | AX15: 92822 | AY15: 108172 | AZ15: 2125931
A16: Revenue in Total (RMB '000) | D16: 6044214 | E16: 6624416 | F16: 7056361 | G16: =AL16-F16 -> 8907967 | H16: 11172478 | I16: 11006277 | J16: 10705803 | K16: 12844720 | L16: 15576972 | M16: 15715710 | N16: 9490423 | O16: 14544095 | P16: 20692816 | Q16: 21537985 | R16: 20575410 | S16: 23125084 | T16: 26484643 | U16: 26126641 | V16: 24156722 | AJ16: =SUM(AJ9,AJ13,AJ15) -> 8363303 | AK16: =SUM(AK9,AK13,AK15) -> 12668630 | AL16: =SUM(AL9,AL13,AL15) -> 15964328 | AM16: =SUM(AM9,AM13,AM15) -> 22178755 | AN16: =SUM(AN9,AN13,AN15) -> 23550523 | AQ16: =AJ16+D16 -> 14407517 | AR16: =AL16+H16 -> 27136806 | AT16: =SUM(AT9,AT13,AT15) -> 174754 | AU16: =SUM(AU9,AU13,AU15) -> 5300993 | AV16: =SUM(AV9,AV13,AV15) -> 21031933 | AW16: 38143083 | AX16: 54843205 | AY16: 66265319 | AZ16: 96311778
A17: % Total revenue | D17: =D16/D143 -> 0.62480271 | E17: =E16/E143 -> 0.63237966 | F17: =F16/F143 -> 0.62583783 | G17: =G16/G143 -> 0.59099758 | H17: =H16/H143 -> 0.58568246 | I17: =I16/I143 -> 0.55577568 | J17: =J16/J143 -> 0.55836422 | K17: =K16/K143 -> 0.56576851 | ... V17: =V16/V143 -> 0.5220958 | AJ17: =AJ16/AJ143 -> 0.60696832 | AK17: =AK16/AK143 -> 0.6287419 | AL17: =AL16/AL143 -> 0.60590682 | AM17: =AM16/AM143 -> 0.57044928 | AN17: =AN16/AN143 -> 0.5623784 | AQ17: =AQ16/AQ143 -> 0.6143247 | AR17: =AR16/AR143 -> 0.59741348 | AT17: =AT16/AT143 -> 0.043482404 | AU17: =AU16/AU143 -> 0.40814302 | AV17: =AV16/AV143 -> 0.61989923 | AW17: =AW16/AW143 -> 0.58477196 | AX17: =AX16/AX143 -> 0.56232986 | AY17: =AY16/AY143 -> 0.57725164 | AZ17: =AZ16/AZ143 -> 0.53767016
A18: Food Delivery Rider Cost (RMB'000) | AJ18: 7172635 | AK18: =AV18-AJ18 -> 11151430 | AL18: 13042195 | AM18: =AW18-AL18 -> 17473860 | AN18: 17745098 | AT18: 276779 | AU18: 5134840 | AV18: 18324065 | AW18: 30516055 | AX18: 41041513 | AY18: 48692295
A19: Average rider cost/order | AJ19: =AJ18/AJ5/1000 -> 4.6834052 | AK19: =AK18/AK5/1000 -> 4.3585812 | AL19: =AL18/AL5/1000 -> 4.7022624 | AM19: =AM18/AM5/1000 -> 4.8272999 | AN19: =AN18/AN5/1000 -> 4.7349302 | AT19: =AT18/AT5/1000 -> 0.43450392 | AU19: =AU18/AU5/1000 -> 3.2396467 | AV19: =AV18/AV5/1000 -> 4.4802115 | AW19: =AW18/AW5/1000 -> 4.7730558 | AX19: =AX18/AX5/1000 -> 4.7054623 | AY19: =AY18/AY5/1000 -> 4.7984996
A21: Cost of Revenues (RMB '000) | D21: -5566225 | E21: -6208427 | F21: =F22-F16 -> -6521266 | G21: =AL21-F21 -> -7497661 | H21: -9321403 | I21: -9534556 | J21: =J22-J16 -> -9165049 | K21: =K22-K16 -> -9984444 | L21: -12531750 | M21: -12928774 | Q21: -20655633 | AJ21: -7557862 | AK21: =AV21-AJ21 -> -11774652 | AL21: -14018927 | AM21: =AW21-AL21 -> -18855959 | AN21: -19149493 | AT21: -391010 | AU21: -5706544 | AV21: -19332514 | AW21: -32874886 | AX21: -44610017
A22: Gross Profit (Loss) (RMB '000) | D22: =SUM(D16,D21) -> 477989 | E22: =SUM(E16,E21) -> 415989 | F22: 535095 | G22: =AL22-F22 -> 1410306 | H22: =SUM(H16,H21) -> 1851075 | I22: =SUM(I16,I21) -> 1471721 | J22: 1540754 | K22: 2860276 | L22: 3045222 | M22: =SUM(M16,M21) -> 2786936 | Q22: =SUM(Q16,Q21) -> 882352 | AJ22: =SUM(AJ16,AJ21) -> 805441 | AK22: =SUM(AK16,AK21) -> 893978 | AL22: =SUM(AL16,AL21) -> 1945401 | AM22: =SUM(AM16,AM21) -> 3322796 | AN22: =SUM(AN16,AN21) -> 4401030 | AQ22: =AJ22+D22 -> 1283430 | AR22: =AL22+H22 -> 3796476 | AT22: =SUM(AT16,AT21) -> -216256 | AU22: =SUM(AU16,AU21) -> -405551 | AV22: =SUM(AV16,AV21) -> 1699419 | AW22: =SUM(AW16,AW21) -> 5268197 | AX22: =SUM(AX16,AX21) -> 10233188
A24: Operating Profit | J24: -154203 | K24: 756347 | L24: 330907 | M24: 482829 | N24: -70881 | O24: 1253421 | P24: 768477 | Q24: 882352 | R24: 1115885 | S24: 2447076 | T24: 876103 | U24: 1735577 | V24: 1577143 | AX24: 1415880 | AY24: 2833369 | AZ24: 6174641
A25: OPM | J25: =J24/J16 -> -0.014403684 | K25: =K24/K16 -> 0.058883884 | L25: =L24/L16 -> 0.021243346 | M25: =M24/M16 -> 0.030722697 | N25: =N24/N16 -> -0.0074686871 | O25: =O24/O16 -> 0.086180749 | P25: =P24/P16 -> 0.037137381 | Q25: =Q24/Q16 -> 0.040967249 | ... V25: =V24/V16 -> 0.065287956 | AX25: =AX24/AX16 -> 0.025816872 | AY25: =AY24/AY16 -> 0.042757947 | AZ25: =AZ24/AZ16 -> 0.064110965
A26: YoY Growth
A27: Number of Transactions | H27: =IFERROR(H5/D5-1,"") -> 0.48451125 | I27: =IFERROR(I5/E5-1,"") -> 0.35284997 | J27: =IFERROR(J5/F5-1,"") -> 0.35788958 | K27: =IFERROR(K5/G5-1,"") -> 0.34592048 | L27: =IFERROR(L5/H5-1,"") -> 0.38131469 | M27: =IFERROR(M5/I5-1,"") -> 0.36729793 | N27: =IFERROR(N5/J5-1,"") -> -0.17328281 | O27: =IFERROR(O5/K5-1,"") -> 0.068965517 | ... V27: =IFERROR(V5/R5-1,"") -> 0.15809419 | AL27: =IFERROR(AL5/AJ5-1,"") -> 0.81103493 | AM27: =IFERROR(AM5/AK5-1,"") -> 0.41481337 | AN27: =IFERROR(AN5/AL5-1,"") -> 0.35120421 | AU27: =IFERROR(AU5/AT5-1,"") -> 1.4882261 | AV27: =IFERROR(AV5/AU5-1,"") -> 1.5804416 | AW27: =IFERROR(AW5/AV5-1,"") -> 0.56317848 | AX27: =IFERROR(AX5/AW5-1,"") -> 0.36423499 | AY27: =IFERROR(AY5/AX5-1,"") -> 0.16341248 | AZ27: =IFERROR(AZ5/AY5-1,"") -> 0.41588978
A28: Gross Transaction Value | B28: =IFERROR(B6/#REF!,"") | C28: =IFERROR(C6/#REF!,"") | H28: =IFERROR(H6/D6-1,"") -> 0.54440154 | I28: =IFERROR(I6/E6-1,"") -> 0.40701754 | J28: =IFERROR(J6/F6-1,"") -> 0.38715596 | K28: =IFERROR(K6/G6-1,"") -> 0.36510264 | L28: =IFERROR(L6/H6-1,"") -> 0.39875 | M28: =IFERROR(M6/I6-1,"") -> 0.39775561 | N28: =IFERROR(N6/J6-1,"") -> -0.054179894 | O28: =IFERROR(O6/K6-1,"") -> 0.16892696 | ... V28: =IFERROR(V6/R6-1,"") -> -1 | AL28: =IFERROR(AL6/AJ6-1,"") -> 0.96950241 | AM28: =IFERROR(AM6/AK6-1,"") -> 0.47150735 | AN28: =IFERROR(AN6/AL6-1,"") -> 0.37489813 | AU28: =IFERROR(AU6/AT6-1,"") -> 2.7628205 | AV28: =IFERROR(AV6/AU6-1,"") -> 1.9148211 | AW28: =IFERROR(AW6/AV6-1,"") -> 0.6528346 | AX28: =IFERROR(AX6/AW6-1,"") -> 0.38861386 | AY28: =IFERROR(AY6/AX6-1,"") -> 0.24484645 | AZ28: =IFERROR(AZ6/AY6-1,"") -> 0.43613721
A29: Gross Transaction Value vs 2019 | R29: =R6/J6-1 -> 0.88803439 | S29: =S6/K6-1 -> 0.8646971 | T29: =T6/L6-1 -> 0.76137623 | U29: =U6/M6-1 -> 0.68261195 | V29: =V6/J6-1 -> -1 | AZ29: =AZ6/AX6-1 -> 0.78777031
A30: QoQ Growth | E30: =IFERROR(E5/D5-1,"") -> 0.12482352 | F30: =IFERROR(F5/E5-1,"") -> -0.095983461 | G30: =IFERROR(G5/F5-1,"") -> 0.26527279 | H30: =IFERROR(H5/G5-1,"") -> 0.15382133 | I30: =IFERROR(I5/H5-1,"") -> 0.025062937 | J30: =IFERROR(J5/I5-1,"") -> -0.092615838 | K30: =IFERROR(K5/J5-1,"") -> 0.25412005 | L30: =IFERROR(L5/K5-1,"") -> 0.18416383 | ... V30: =IFERROR(V5/U5-1,"") -> -0.14038766
A31: Average Order Value (RMB) | H31: =IFERROR(H7/D7-1,"") -> 0.04034344 | I31: =IFERROR(I7/E7-1,"") -> 0.040039601 | J31: =IFERROR(J7/F7-1,"") -> 0.021552846 | K31: =IFERROR(K7/G7-1,"") -> 0.014252078 | L31: =IFERROR(L7/H7-1,"") -> 0.012622261 | M31: =IFERROR(M7/I7-1,"") -> 0.022275818 | N31: =IFERROR(N7/J7-1,"") -> 0.1440673 | O31: =IFERROR(O7/K7-1,"") -> 0.093512318 | ... V31: =IFERROR(V7/R7-1,"") -> -1 | AL31: =IFERROR(AL7/AJ7-1,"") -> 0.087501059 | AM31: =IFERROR(AM7/AK7-1,"") -> 0.040071706 | AN31: =IFERROR(AN7/AL7-1,"") -> 0.017535406 | AU31: =IFERROR(AU7/AT7-1,"") -> 0.51225026 | AV31: =IFERROR(AV7/AU7-1,"") -> 0.12958227 | AW31: =IFERROR(AW7/AV7-1,"") -> 0.057355009 | AX31: =IFERROR(AX7/AW7-1,"") -> 0.017869992 | AY31: =IFERROR(AY7/AX7-1,"") -> 0.069995782 | AZ31: =IFERROR(AZ7/AY7-1,"") -> 0.014300145
A32: Commission | B32: =IFERROR(B9/#REF!,"") | C32: =IFERROR(C9/#REF!,"") | D32: =IFERROR(D9/B9,"") | F32: =IFERROR(F9/C9,"") | H32: =IFERROR(H9/F9-1,"") | I32: =IFERROR(I9/G9-1,"") | J32: =IFERROR(J9/H9-1,"") | R32: =R9/N9-1 -> 1.1452028 | S32: =S9/O9-1 -> 0.60025628 | T32: =T9/P9-1 -> 0.2724029 | U32: =U9/Q9-1 -> 0.15557234 | V32: =V9/R9-1 -> 0.12716221 | AL32: =IFERROR(AL9/AJ9-1,"") -> 0.87017034 | AM32: =IFERROR(AM9/AK9-1,"") -> 0.68778209 | AN32: =IFERROR(AN9/AL9-1,"") -> 0.42133056 | AU32: =IFERROR(AU9/AT9-1,"") -> 28.807581 | AV32: =IFERROR(AV9/AU9-1,"") -> 2.8940271 | AW32: =IFERROR(AW9/AV9-1,"") -> 0.76095797 | AX32: =IFERROR(AX9/AW9-1,"") -> 0.38991293 | AY32: =IFERROR(AY9/AX9-1,"") -> 0.18018251 | AZ32: =IFERROR(AZ9/AY9-1,"") -> 0.41232358
A33: - Food delivery services | U33: =U10/Q10-1 -> 0.12554591 | V33: =V10/R10-1 -> 0.10972644
A34: - Commission | U34: =U11/Q11-1 -> 0.28843441 | V34: =V11/R11-1 -> 0.24042383
A35: Online Marketing Service | B35: =IFERROR(B13/#REF!,"") | C35: =IFERROR(C13/#REF!,"") | D35: =IFERROR(D13/B13,"") | F35: =IFERROR(F13/C13,"") | H35: =IFERROR(H13/F13-1,"") | I35: =IFERROR(I13/G13-1,"") | J35: =IFERROR(J13/H13-1,"") | R35: =R13/N13-1 -> 1.3839932 | S35: =S13/O13-1 -> 0.53934033 | T35: =T13/P13-1 -> 0.35183987 | U35: =U13/Q13-1 -> 0.32003256 | V35: =V13/R13-1 -> 0.20394758 | AL35: =IFERROR(AL13/AJ13-1,"") -> 2.2982441 | AM35: =IFERROR(AM13/AK13-1,"") -> 2.2833009 | AN35: =IFERROR(AN13/AL13-1,"") -> 1.6537149 | AU35: =IFERROR(AU13/AT13-1,"") | AV35: =IFERROR(AV13/AU13-1,"") -> 7.5592407 | AW35: =IFERROR(AW13/AV13-1,"") -> 2.287791 | AX35: =IFERROR(AX13/AW13-1,"") -> 1.18578 | AY35: =IFERROR(AY13/AX13-1,"") -> 0.48225242 | AZ35: =IFERROR(AZ13/AY13-1,"") -> 0.51153539
A36: Other services and sales | B36: =IFERROR(B15/#REF!,"") | C36: =IFERROR(C15/#REF!,"") | D36: =IFERROR(D15/B15,"") | F36: =IFERROR(F15/C15,"") | H36: =IFERROR(H15/F15-1,"") | I36: =IFERROR(I15/G15-1,"") | J36: =IFERROR(J15/H15-1,"") | AL36: =IFERROR(AL15/AJ15-1,"") -> 2.4632222 | AM36: =IFERROR(AM15/AK15-1,"") -> 0.84976327 | AN36: =IFERROR(AN15/AL15-1,"") -> 0.23838221 | AU36: =IFERROR(AU15/AT15-1,"") | AV36: =IFERROR(AV15/AU15-1,"") -> 3.1850621 | AW36: =IFERROR(AW15/AV15-1,"") -> 1.3533337 | AX36: =IFERROR(AX15/AW15-1,"") -> 0.044398938 | AY36: =IFERROR(AY15/AX15-1,"") -> 0.16537028 | AZ36: =IFERROR(AZ15/AY15-1,"") -> 18.653247
A37: Revenue in Total | B37: =IFERROR(B16/#REF!,"") | C37: =IFERROR(C16/#REF!,"") | H37: =IFERROR(H16/D16-1,"") -> 0.84845838 | I37: =IFERROR(I16/E16-1,"") -> 0.66147129 | J37: =IFERROR(J16/F16-1,"") -> 0.51718471 | K37: =IFERROR(K16/G16-1,"") -> 0.44193619 | L37: =IFERROR(L16/H16-1,"") -> 0.39422714 | M37: =IFERROR(M16/I16-1,"") -> 0.42788611 | N37: =IFERROR(N16/J16-1,"") -> -0.11352535 | O37: =IFERROR(O16/K16-1,"") -> 0.13230144 | ... V37: =IFERROR(V16/R16-1,"") -> 0.17405787 | AL37: =IFERROR(AL16/AJ16-1,"") -> 0.90885443 | AM37: =IFERROR(AM16/AK16-1,"") -> 0.75068299 | AN37: =IFERROR(AN16/AL16-1,"") -> 0.47519664 | AV37: =IFERROR(AV16/AU16-1,"") -> 2.9675459 | AW37: =IFERROR(AW16/AV16-1,"") -> 0.81357952 | AX37: =IFERROR(AX16/AW16-1,"") -> 0.43782832 | AY37: =IFERROR(AY16/AX16-1,"") -> 0.20826854 | AZ37: =IFERROR(AZ16/AY16-1,"") -> 0.45342661
A38: Revenue in Total vs 2019 | R38: =R16/J16-1 -> 0.9218932 | S38: =S16/K16-1 -> 0.80035719 | T38: =T16/L16-1 -> 0.70024335 | U38: =U16/M16-1 -> 0.66245375 | V38: =V16/J16-1 -> 1.2564138
A40: Operating Income/Loss | N40: =N24/J24-1 -> -0.54033968 | O40: =O24/K24-1 -> 0.65720364 | P40: =P24/L24-1 -> 1.3223353 | Q40: =Q24/M24-1 -> 0.82746272 | R40: =R24/N24-1 -> -16.743076 | S40: =S24/O24-1 -> 0.9523177 | T40: =T24/P24-1 -> 0.14005104 | U40: =U24/Q24-1 -> 0.96698936 | V40: =V24/R24-1 -> 0.41335622 | AX40: =IFERROR(AX24/AW24-1,"") | AY40: =IFERROR(AY24/AX24-1,"") -> 1.0011364 | AZ40: =IFERROR(AZ24/AY24-1,"") -> 1.1792576
A42: Margins
A43: Commssion Rate | B43: =IFERROR(B9/B6,"") | C43: =IFERROR(C9/C6,"") | F43: =IFERROR(F9/F6,"") -> 0 | AJ43: =IFERROR(AJ9/(AJ6*1000000),"") -> 0.13062788 | AK43: =IFERROR(AK9/(AK6*1000000),"") -> 0.11163462 | AL43: =IFERROR(AL9/(AL6*1000000),"") -> 0.12403965 | AM43: =IFERROR(AM9/(AM6*1000000),"") -> 0.12804212 | AN43: =IFERROR(AN9/(AN6*1000000),"") -> 0.12822866 | AR43: =IFERROR(AR9/(AR6*1000000),"") -> 0 | AT43: =IFERROR(AT9/(AT6*1000000),"") -> 0.011202179 | AU43: =IFERROR(AU9/(AU6*1000000),"") -> 0.08873925 | AV43: =IFERROR(AV9/(AV6*1000000),"") -> 0.11855034 | AW43: =IFERROR(AW9/(AW6*1000000),"") -> 0.12630554 | AX43: =IFERROR(AX9/(AX6*1000000),"") -> 0.12642371 | AY43: =IFERROR(AY9/(AY6*1000000),"") -> 0.11985659 | AZ43: =IFERROR(AZ9/(AZ6*1000000),"") -> 0.11786916
A44: Monetization Rate | D44: =IFERROR(D16/(D6*1000000),"") -> 0.11668367 | E44: =IFERROR(E16/(E6*1000000),"") -> 0.11621782 | F44: =IFERROR(F16/(F6*1000000),"") -> 0.12947451 | G44: =IFERROR(G16/(G6*1000000),"") -> 0.13061535 | H44: =IFERROR(H16/(H6*1000000),"") -> 0.13965597 | I44: =IFERROR(I16/(I6*1000000),"") -> 0.13723537 | J44: =IFERROR(J16/(J6*1000000),"") -> 0.14161115 | K44: =IFERROR(K16/(K6*1000000),"") -> 0.13796692 | ... V44: =IFERROR(V16/(V6*1000000),"") | AJ44: =IFERROR(AJ16/(AJ6*1000000),"") -> 0.13424242 | AK44: =IFERROR(AK16/(AK6*1000000),"") -> 0.11643961 | AL44: =IFERROR(AL16/(AL6*1000000),"") -> 0.13010862 | AM44: =IFERROR(AM16/(AM6*1000000),"") -> 0.13853064 | AN44: =IFERROR(AN16/(AN6*1000000),"") -> 0.13960002 | AQ44: =IFERROR(AQ16/(AQ6*1000000),"") -> 0.12627096 | AT44: =IFERROR(AT16/(AT6*1000000),"") -> 0.011202179 | AU44: =IFERROR(AU16/(AU6*1000000),"") -> 0.090306525 | AV44: =IFERROR(AV16/(AV6*1000000),"") -> 0.12292188 | AW44: =IFERROR(AW16/(AW6*1000000),"") -> 0.13487653 | AX44: =IFERROR(AX16/(AX6*1000000),"") -> 0.13965675 | AY44: =IFERROR(AY16/(AY6*1000000),"") -> 0.13555315 | AZ44: =IFERROR(AZ16/(AZ6*1000000),"") -> 0.13718505
A45: Gross Margin | B45: =IFERROR(B22/B16,"") | C45: =IFERROR(C22/C16,"") | D45: =IFERROR(D22/D16,"") -> 0.079082078 | E45: =IFERROR(E22/E16,"") -> 0.062796328 | F45: =IFERROR(F22/F16,"") -> 0.075831579 | G45: =IFERROR(G22/G16,"") -> 0.15831963 | H45: =IFERROR(H22/H16,"") -> 0.16568169 | I45: =IFERROR(I22/I16,"") -> 0.13371651 | ... M45: =IFERROR(M22/M16,"") -> 0.1773344 | AJ45: =IFERROR(AJ22/AJ16,"") -> 0.096306567 | AK45: =IFERROR(AK22/AK16,"") -> 0.070566273 | AL45: =IFERROR(AL22/AL16,"") -> 0.12185925 | AM45: =IFERROR(AM22/AM16,"") -> 0.14981887 | AN45: =IFERROR(AN22/AN16,"") -> 0.1868761 | AQ45: =IFERROR(AQ22/AQ16,"") -> 0.089080582 | AR45: =IFERROR(AR22/AR16,"") -> 0.13990136 | AT45: =IFERROR(AT22/AT16,"") -> -1.2374881 | AU45: =IFERROR(AU22/AU16,"") -> -0.076504723 | AV45: =IFERROR(AV22/AV16,"") -> 0.080801845 | AW45: =IFERROR(AW22/AW16,"") -> 0.13811671 | AX45: =IFERROR(AX22/AX16,"") -> 0.1865899
A46: OPM | J46: =J24/J16 -> -0.014403684 | N46: =N24/N16 -> -0.0074686871 | O46: =O24/O16 -> 0.086180749 | P46: =P24/P16 -> 0.037137381 | Q46: =Q24/Q16 -> 0.040967249 | R46: =R24/R16 -> 0.054233913 | S46: =S24/S16 -> 0.10581912 | T46: =T24/T16 -> 0.033079661 | U46: =U24/U16 -> 0.066429397 | V46: =V24/V16 -> 0.065287956 | AX46: =AX24/AX16 -> 0.025816872 | AY46: =AY24/AY16 -> 0.042757947 | AZ46: =AZ24/AZ16 -> 0.064110965
...

Sheet Sheet5
L2: 拍的
C3: 19Q4 | D3: 20Q1 | E3: 20Q2 | F3: 20Q3 | G3: 20Q4 | H3: 21Q1 | I3: 22Q1 | J3: 22Q3 | K3: 23Q1 | L3: 23Q2
B4: 高星占比 | C4: 0.13 | D4: 0.15 | E4: 0.15 | F4: 0.15 | G4: 0.15 | H4: 0.167 | I4: 0.174 | J4: 0.15 | K4: 0.19 | L4: 0.15

Sheet New Segment Reporting
A2: Core Local Commerce | B2: 21Q2 | C2: 21Q3 | D2: 21Q4 | E2: 22Q1 | F2: 22Q2 | G2: 22Q3 | H2: 22Q4 | I2: 23Q1 | J2: 23Q2 | K2: 23Q3 | L2: 23Q4 | M2: 24Q1 | N2: 24Q2 | O2: 24Q3 | P2: 24Q4 | Q2: 25Q1 | R2: 25Q2 | S2: 25Q3 | T2: 25Q4 | U2: 26Q1 | V2: 26Q2
A3: Revenue | G3: =G8/C8-1 -> 0.24641 | H3: =H8/D8-1 -> 0.17386332
A4: Delivery Services | B4: 13861207 | C4: 15392015 | D4: 14990397 | E4: 14233209 | F4: 15950770 | G4: 20107197 | H4: 19772732 | I4: 16905291 | J4: 20374970 | K4: 22983696 | L4: 21927023 | M4: 21065057 | N4: 23021272 | O4: 27784111 | P4: 26194820 | Q4: 25722683 | R4: 23655555 | S4: 23021931 | T4: 23594886 | U4: 24081149 | V4: 26781224
A5: Commission | B5: 12170487 | C5: 13191289 | D5: 12878761 | E5: 11948724 | F5: 12478501 | G5: 16079265 | H5: 14636518 | I5: 15815292 | J5: 18402189 | K5: 20986527 | L5: 19426729 | M5: 20034039 | N5: 22108369 | O5: 26889908 | P5: 24066077 | Q5: 24051420 | R5: 24950978 | S5: 26375119 | T5: 23778171 | U5: 35608836 | V5: 39630201
A6: Online marketing services | B6: 7194528 | C6: 8001353 | D6: 8137460 | E6: 7004924 | F6: 7295796 | G6: 8637608 | H6: 7744751 | I6: 7746614 | J6: 10243600 | K6: 11369580 | L6: 10907096 | M6: 10307416 | N6: 12262733 | O6: 13423641 | P6: 12842276 | Q6: 11862473 | R6: 13547279 | S6: 14193343 | T6: 13136940
A7: Other services and sales | B7: 468840 | C7: 584115 | D7: 1027220 | E7: 992729 | F7: 1054176 | G7: 1503459 | H7: 1318663 | I7: 2418139 | J7: 2179187 | K7: 2351205 | L7: 2869794 | M7: 3219195 | N7: 3289484 | O7: 2085212 | P7: 2463659 | Q7: 2688138 | R7: 3193471 | S7: 3856473 | T7: 4324636 | U7: 4373301 | V7: 5119130
A8: Total Revenue | B8: =SUM(B4:B7) -> 33695062 | C8: =SUM(C4:C7) -> 37168772 | D8: =SUM(D4:D7) -> 37033838 | E8: 34179586 | F8: =SUM(F4:F7) -> 36779243 | G8: =SUM(G4:G7) -> 46327529 | H8: =SUM(H4:H7) -> 43472664 | I8: 42885336 | J8: 51199946 | K8: 57691008 | L8: =SUM(L4:L7) -> 55130642 | M8: 54625707 | N8: 60681858 | O8: 69373099 | P8: 65566832 | Q8: =SUM(Q4:Q7) -> 64324714 | R8: =SUM(R4:R7) -> 65347283 | S8: =SUM(S4:S7) -> 67446866 | T8: =SUM(T4:T7) -> 64834633 | U8: =SUM(U4:U7) -> 64063286 | V8: =SUM(V4:V7) -> 71530555
A10: Cost of Revenues, operating expenses and uncllocated items | C10: -33017764 | D10: -31916464 | E10: -29474445 | F10: -28518250 | G10: -37006236 | H10: -36257422 | I10: -33440266 | J10: -40061425 | K10: 47595177 | L10: 47111217 | M10: -44926860 | N10: -45448273 | O10: -54790696 | P10: 52666505 | Q10: -50833234 | R10: -61626153 | S10: -81517876 | T10: -74880316 | U10: =U12-U8 -> -66093228 | V10: =V12-V8 -> -65862280
A12: Operating Profit | B12: 5914471 | C12: =C8+C10 -> 4151008 | D12: =D8+D10 -> 5117374 | E12: 4705141 | F12: 8260993 | G12: =G8+G10 -> 9321293 | H12: =H8+H10 -> 7215242 | I12: 9445070 | J12: 11138521 | K12: 10095831 | L12: =L8-L10 -> 8019425 | M12: 9698847 | N12: 15233585 | O12: 14582403 | P12: 12900327 | Q12: 13491480 | R12: 3721130 | S12: -14071010 | T12: -10045683 | U12: -2029942 | V12: 5668275
A13: OPM | B13: =B12/B8 -> 0.17552931 | C13: =C12/C8 -> 0.11167999 | D13: =D12/D8 -> 0.13818103 | E13: =E12/E8 -> 0.13765939 | F13: =F12/F8 -> 0.2246102 | G13: =G12/G8 -> 0.20120419 | H13: =H12/H8 -> 0.16597193 | I13: =I12/I8 -> 0.22024008 | ... V13: =V12/V8 -> 0.07924271
A14: Rev YoY Growth | L14: =L8/H8-1 -> 0.26816801 | O14: =O8/K8-1 -> 0.20249414 | P14: =P8/L8-1 -> 0.18929926 | Q14: =Q8/M8-1 -> 0.17755389 | R14: =R8/N8-1 -> 0.076883358 | S14: =S8/O8-1 -> -0.027766282 | T14: =T8/P8-1 -> -0.011167216 | U14: =U8/Q8-1 -> -0.0040641922 | V14: =V8/R8-1 -> 0.094621715
S15: =S13-O13 -> -0.41882619 | T15: =T13-P13 -> -0.35169397 | U15: =U13-Q13 -> -0.24142674 | V15: =V13-R13 -> 0.022298797
A16: New Initiatives | B16: 21Q2 | C16: 21Q3 | D16: 21Q4 | E16: 22Q1 | F16: 22Q2 | G16: 22Q3 | H16: 22Q4 | I16: 23Q1 | J16: 23Q2 | K16: 23Q3 | L16: 23Q4 | M16: 24Q1 | N16: 24Q2 | O16: 24Q3 | P16: 24Q4 | Q16: 25Q1 | R16: 25Q2 | S16: 25Q3 | T16: 25Q4 | U16: 26Q1 | V16: 26Q2
A17: Commission | B17: 418123 | C17: 410618 | D17: 438259 | E17: 350159 | F17: 315518 | G17: 403673 | H17: 297341 | I17: 427765 | J17: 510284 | K17: 550181 | L17: 569576 | M17: 623234 | N17: 716909 | O17: 809773 | P17: 902420 | Q17: 1155584 | R17: 1520537 | S17: 1627723 | T17: 1939056 | U17: 2450084 | V17: 2753081
A18: Online marketing services | B18: 21168 | C18: 20357 | D18: 45169 | E18: 13958 | F18: 20891 | G18: 25821 | H18: 24841 | I18: 36203 | J18: 63577 | K18: 69641 | L18: 76905 | M18: 83482 | N18: 97115 | O18: 115499 | P18: 108230 | Q18: 84548 | R18: 102478 | S18: 133193 | T18: 138186
A19: Other services and sales | B19: 9624879 | C19: 11229623 | D19: 12005867 | E19: 11725051 | F19: 13822711 | G19: 15861869 | H19: 16334093 | I19: 15268168 | J19: 16190817 | K19: 18156077 | L19: 17918828 | M19: 17943461 | N19: 20755195 | O19: 23278948 | P19: 21909814 | Q19: 20992280 | R19: 24870182 | S19: 26280331 | T19: 25184554 | U19: 24525536 | V19: 30359408
A20: Total Revenue | B20: =SUM(B17:B19) -> 10064170 | C20: =SUM(C17:C19) -> 11660598 | D20: =SUM(D17:D19) -> 12489295 | E20: 12089168 | F20: =SUM(F17:F19) -> 14159120 | G20: =SUM(G17:G19) -> 16291363 | H20: =SUM(H17:H19) -> 16656275 | I20: 15732136 | J20: 16764678 | K20: 18775899 | L20: =SUM(L17:L19) -> 18565309 | M20: 18650177 | N20: 21569219 | O20: =24204220 -> 24204220 | P20: 22920464 | Q20: 22232412 | R20: 26493197 | S20: 28041247 | T20: =SUM(T17:T19) -> 27261796 | U20: =SUM(U17:U19) -> 26975620 | V20: =SUM(V17:V19) -> 33112489
A22: Cost of Revenues, operating expenses and uncllocated items | C22: -21688827 | D22: -21850963 | E22: -20542452 | F22: -20948666 | G22: -23062723 | H22: -23021295 | I22: -20761030 | J22: -21957600 | K22: 23887875 | L22: 23398001 | M22: -21407076 | N22: -22883578 | O22: -25230262 | P22: -25096478 | Q22: -24505679 | R22: -28374515 | S22: -29319156 | T22: -31911642 | U22: =U24-U20 -> -29091435 | V22: =V24-V20 -> -34851404
A24: Operating Profit | B24: -8785436 | C24: =C20+C22 -> -10028229 | D24: =D20+D22 -> -9361668 | E24: -8453284 | F24: =F20+F22 -> -6789546 | G24: =G20+G22 -> -6771360 | H24: =H20+H22 -> -6365020 | I24: -5028894 | J24: -5192922 | K24: -5111976 | L24: =L20-L22 -> -4832692 | M24: -2756899 | N24: -1314359 | O24: -1026042 | P24: -2176014 | Q24: -2273267 | R24: -1881318 | S24: -1277909 | T24: =T20+T22 -> -4649846 | U24: -2115815 | V24: -1738915
A25: OPM | B25: =B24/B20 -> -0.87294193 | C25: =C24/C20 -> -0.86000984 | D25: =D24/D20 -> -0.74957538 | E25: =E24/E20 -> -0.69924448 | F25: =F24/F20 -> -0.47951751 | G25: =G24/G20 -> -0.4156411 | H25: =H24/H20 -> -0.38213946 | I25: =I24/I20 -> -0.31965742 | ... V25: =V24/V20 -> -0.052515382
T26: =T25-P25 -> -0.07562511 | U26: =U25-Q25 -> 0.023815787 | V26: =V25-R25 -> 0.01849598
A27: Rev YoY | G27: =G20/C20-1 -> 0.39712929 | H27: =H20/D20-1 -> 0.33364413 | I27: =I20/E20-1 -> 0.3013415 | J27: =J20/F20-1 -> 0.18401977 | K27: =K20/G20-1 -> 0.15250633 | L27: =L20/H20-1 -> 0.1146135 | M27: =M20/I20-1 -> 0.18548282 | N27: =N20/J20-1 -> 0.28658713 | ... V27: =V20/R20-1 -> 0.24984874
A29: Core Local Commerce
A30: Revenue
A31: Delivery Services | P31: =P4/$P$8 -> 0.39951328 | Q31: =Q4/$P$8 -> 0.39231243 | R31: =R4/R$8 -> 0.36199753 | S31: =S4/S$8 -> 0.34133433 | T31: =T4/T$8 -> 0.36392411 | U31: =U4/U$8 -> 0.37589625 | V31: =V4/V$8 -> 0.37440258
A32: Commission | P32: =P5/$P$8 -> 0.36704651 | Q32: =Q5/$P$8 -> 0.36682297 | R32: =R5/R$8 -> 0.3818212 | S32: =S5/S$8 -> 0.39105033 | T32: =T5/T$8 -> 0.36675107 | U32: =U5/U$8 -> 0.55583843 | V32: =V5/V$8 -> 0.55403178
A33: Online marketing services | P33: =P6/$P$8 -> 0.19586543 | Q33: =Q6/$P$8 -> 0.18092186 | R33: =R6/R$8 -> 0.20731205 | S33: =S6/S$8 -> 0.2104374 | T33: =T6/T$8 -> 0.20262226 | U33: =U6/U$8 -> 0 | V33: =V6/V$8 -> 0
A34: Other services and sales | P34: =P7/$P$8 -> 0.037574776 | Q34: =Q7/$P$8 -> 0.040998443 | R34: =R7/R$8 -> 0.048869224 | S34: =S7/S$8 -> 0.057177942 | T34: =T7/T$8 -> 0.06670256 | U34: =U7/U$8 -> 0.068265324 | V34: =V7/V$8 -> 0.071565641
A35: Total Revenue | P35: =P8/$P$8 -> 1 | Q35: =Q8/$P$8 -> 0.9810557 | R35: =R8/R$8 -> 1 | S35: =S8/S$8 -> 1 | T35: =T8/T$8 -> 1 | U35: =U8/U$8 -> 1 | V35: =V8/V$8 -> 1
A36: YoY
A37: Delivery Services | P37: =P4/L4-1 -> 0.19463641 | Q37: =Q4/M4-1 -> 0.22110674 | R37: =R4/N4-1 -> 0.02755204 | S37: =S4/O4-1 -> -0.1713994 | T37: =T4/P4-1 -> -0.099253746 | U37: =U4/Q4-1 -> -0.063816593 | V37: =V4/R4-1 -> 0.13213256
A38: Commission | P38: =P5/L5-1 -> 0.23881262 | Q38: =Q5/M5-1 -> 0.20052776 | R38: =R5/N5-1 -> 0.12857615 | S38: =S5/O5-1 -> -0.01914432 | T38: =T5/P5-1 -> -0.011963146 | U38: =U5/Q5-1 -> 0.48052947 | V38: =V5/R5-1 -> 0.58832255
A39: Online marketing services | P39: =P6/L6-1 -> 0.17742394 | Q39: =Q6/M6-1 -> 0.15086778 | R39: =R6/N6-1 -> 0.10475202 | S39: =S6/O6-1 -> 0.057339287 | T39: =T6/P6-1 -> 0.022944842 | U39: =U6/Q6-1 -> -1 | V39: =V6/R6-1 -> -1
A40: Other services and sales | P40: =P7/L7-1 -> -0.14152061 | Q40: =Q7/M7-1 -> -0.16496578 | R40: =R7/N7-1 -> -0.02918786 | S40: =S7/O7-1 -> 0.84943929 | T40: =T7/P7-1 -> 0.75537118 | U40: =U7/Q7-1 -> 0.62688857 | V40: =V7/R7-1 -> 0.60299874
