Workbook
Name _1994: #REF!
Name _1994: #REF!
Name _1994: #REF!
Name _1994: #REF!
Name _1994: #REF!
Name _1994: #REF!
Name _1994: #REF!
Name _1994: #REF!
Name _1994: #REF!
Name _1994: #REF!
Name _1994: #REF!
Name _1994: #REF!
Name _1994: #REF!
Name _1994: #REF!
Name _1994: #REF!
Name _1995: #REF!
Name _1995: #REF!
Name _1995: #REF!
Name _1995: #REF!
Name _1995: #REF!
Name _1995: #REF!
Name _1995: #REF!
Name _1995: #REF!
Name _1995: #REF!
Name _1995: #REF!
Name _1995: #REF!
Name _1995: #REF!
Name _1995: #REF!
Name _1995: #REF!
Name _1995: #REF!
Name _1996: #REF!
Name _1996: #REF!
Name _1996: #REF!
Name _1996: #REF!
Name _1996: #REF!
Name _1996: #REF!
Name _1996: #REF!
Name _1996: #REF!
Name _1996: #REF!
Name _1996: #REF!
Name _1996: #REF!
Name _1996: #REF!
Name _1996: #REF!
Name _1996: #REF!
Name _1996: #REF!
Name _1997: #REF!
Name _1997: #REF!
Name _1997: #REF!
Name _1997: #REF!
Name _1997: #REF!
Name _1997: #REF!
Name _1997: #REF!
Name _1997: #REF!
Name _1997: #REF!
Name _1997: #REF!
Name _1997: #REF!
Name _1997: #REF!
Name _1997: #REF!
Name _1997: #REF!
Name _1997: #REF!

Sheet 同程艺龙
C2: Unit: RMB in million | D2: 2015 | E2: 2016 | F2: 2017 | G2: 2018 | H2: 2019 | J2: 2018Q1 | K2: 2018Q2 | L2: 2018H1 | M2: 2018Q3 | N2: 2018Q4 | O2: 2019Q1 | P2: 2019Q2 | Q2: 2019Q3 | R2: 2019Q4
C3: GMV Break Down (RMB in million) - combined basis | D3: =+D6+D18 -> 36831.5 | E3: =+E6+E18 -> 67795.6 | F3: =+F6+F18 -> 102313.6 | G3: 131500 | H3: =SUM(O3:R3) -> 166100 | J3: 29000 | K3: 28900 | L3: =+L6+L18 -> 57962.9 | M3: 39100 | N3: 34500 | O3: 35900 | P3: 41300 | Q3: 47600 | R3: 41300 | S3: in thousand initial, need to divide 1000 to get mm numbers
C4: Growth | E4: =E3/D3-1 -> 0.84069614 | F4: =F3/E3-1 -> 0.50914809 | G4: =G3/F3-1 -> 0.28526413 | H4: =H3/G3-1 -> 0.26311787 | O4: =O3/J3-1 -> 0.23793103 | P4: =P3/K3-1 -> 0.42906574 | Q4: =Q3/M3-1 -> 0.2173913 | R4: =R3/N3-1 -> 0.19710145
C6: 交通交易额 | D6: 22553.7 | E6: 50525.1 | F6: 80013.4 | H6: =SUM(O6:R6) -> 138642.96 | L6: 47231 | O6: =O246 -> 30607 | P6: =P3-P18 -> 34789.882 | Q6: =Q3-Q18 -> 39438.4 | R6: =R3-R18 -> 33807.675
C7: Growth | E7: =E6/D6-1 -> 1.2402134 | F7: =F6/E6-1 -> 0.58363665
C9: - 机票交易额 | D9: 14778.9 | E9: 28067.6 | F9: 39502.5 | L9: 22697.6
C10: -机票出售数量 segments | D10: 17.9 | E10: 35.4 | F10: 48.5 | L10: 31.1
C11: 机票交易额占交通交易额比例 | D11: =D9/D6 -> 0.65527607 | E11: =E9/E6 -> 0.55551795 | F11: =F9/F6 -> 0.49369856 | L11: =L9/L6 -> 0.48056573
C13: - 来自同城 | D13: 18824.6 | E13: 48068.6 | F13: 77977.7
C14: Growth | E14: =E13/D13-1 -> 1.5534991 | F14: =F13/E13-1 -> 0.622217
C15: - 来自艺龙 | D15: 3729.1 | E15: 2456.5 | F15: 2035.7
C16: Growth | E16: =E15/D15-1 -> -0.34126197 | F16: =F15/E15-1 -> -0.17130063
C18: 住宿交易额 | D18: 14277.8 | E18: 17270.5 | F18: 22300.2 | H18: =SUM(O18:R18) -> 27457.043 | L18: 10731.9 | O18: =O3-O6 -> 5293 | P18: =P70/P86 -> 6510.1176 | Q18: =Q70/Q86 -> 8161.6 | R18: =R70/R86 -> 7492.3253
C19: Growth | E19: =E18/D18-1 -> 0.20960512 | F19: =F18/E18-1 -> 0.29123071
R20: =R18/265 -> 28.272926
C21: - 来自同城 | D21: 901.4 | E21: 1379.7 | F21: 1784.5
C22: Growth | E22: =E21/D21-1 -> 0.53061904 | F22: =F21/E21-1 -> 0.29339712
C23: - 来自艺龙 | D23: 13376.4 | E23: 15890.7 | F23: 20515.7
C24: Growth | E24: =E23/D23-1 -> 0.18796537 | F24: =F23/E23-1 -> 0.29105074
C26: Rev Break Down (RMB in million) - 同程艺龙 combined basis
C27: Revenue (combined basis，同程+艺龙) | D27: =+D126+D201 -> 1606.647 | E27: =+E126+E201 -> 3639.522 | F27: =+F126+F201 -> 5226.09 | G27: 6090.8 | H27: =SUM(O27:R27) -> 7392.932 | J27: 1517.512 | K27: 1314.48 | L27: 2831.992 | M27: 1686.397 | N27: =G27-J27-K27-M27 -> 1572.411 | O27: 1783.411 | P27: 1590.898 | Q27: 2062.13 | R27: 1956.493 | S27: =N27*(1+0.275) -> 2004.824 | T27: =S27+Q27+P27+O27 -> 7441.263
C28: Growth | E28: =E27/D27-1 -> 1.2652904 | F28: =F27/E27-1 -> 0.43592758 | G28: =G27/F27-1 -> 0.16546022 | H28: =H27/G27-1 -> 0.21378669 | O28: =O27/J27-1 -> 0.17522036 | P28: =P27/K27-1 -> 0.21028696 | Q28: =Q27/M27-1 -> 0.22280222 | T28: =T27/G27-1 -> 0.22172178
C30: Cost of revenue | D30: =+D135+D208 -> -868.188 | E30: =+E135+E208 -> -1563.124 | F30: =+F135+F208 -> -1670.587 | H30: =SUM(O30:R30) -> 2317.746 | K30: 370.531 | M30: 479.543 | N30: 556.354 | O30: 498.27 | P30: 561.16 | Q30: 683.255 | R30: 575.061
C32: Gross profit | D32: =D27+D30 -> 738.459 | E32: =E27+E30 -> 2076.398 | F32: =F27+F30 -> 3555.503 | H32: =SUM(O32:R32) -> 5075.186 | K32: 943.949 | M32: 1206.854 | N32: 1016.044 | O32: 1285.141 | P32: 1029.738 | Q32: 1378.875 | R32: 1381.432
C33: Growth | E33: =E32/D32-1 -> 1.8117986 | F33: =F32/E32-1 -> 0.71234176
C34: Margin | D34: =D32/D$27 -> 0.45962741 | E34: =E32/E$27 -> 0.57051393 | F34: =F32/F$27 -> 0.68033712
C36: Total expense | D36: =+D39+D42+D45 -> -2248.992 | E36: =+E39+E42+E45 -> -4276.777 | F36: =+F39+F42+F45 -> -3032.678
C37: Growth | E37: =E36/D36-1 -> 0.90164171 | F37: =F36/E36-1 -> -0.29089639
C38: % of revenue | D38: =D36/D$27*-1 -> 1.3998047 | E38: =E36/E$27*-1 -> 1.175093 | F38: =F36/F$27*-1 -> 0.58029579
C39: R&D | D39: =+D154+D214 -> -563.35 | E39: =+E154+E214 -> -889.368 | F39: =+F154+F214 -> -1036.818 | K39: -317.5 | M39: -403.346 | N39: -439.855 | O39: -430.052 | P39: -352.154 | Q39: -359.587 | R39: -377.316
C40: Growth | E40: =E39/D39-1 -> 0.57871306 | F40: =F39/E39-1 -> 0.16579189
C41: % of revenue | D41: =D39/D$27*-1 -> 0.35063707 | E41: =E39/E$27*-1 -> 0.24436396 | F41: =F39/F$27*-1 -> 0.19839268
C42: S&M | D42: =+D156+D215 -> -1356.228 | E42: =+E156+E215 -> -2397.953 | F42: =+F156+F215 -> -1765.709 | K42: -464.096 | M42: -576.207 | N42: -559.02 | O42: -469.723 | P42: -407.187 | Q42: -627.565 | R42: -741.975
C43: Growth | E43: =E42/D42-1 -> 0.76810463 | F43: =F42/E42-1 -> -0.26365988
C44: % of revenue | D44: =D42/D$27*-1 -> 0.84413564 | E44: =E42/E$27*-1 -> 0.65886482 | F44: =F42/F$27*-1 -> 0.33786425
C45: G&A | D45: =+D158+D216 -> -329.414 | E45: =+E158+E216 -> -989.456 | F45: =+F158+F216 -> -230.151 | K45: -133.749 | M45: -163.476 | N45: -255.571 | O45: -228.322 | P45: -99.805 | Q45: -97.516 | R45: -199.51
C46: Growth | E46: =E45/D45-1 -> 2.0036853 | F46: =F45/E45-1 -> -0.76739643
C47: % of revenue | D47: =D45/D$27*-1 -> 0.20503197 | E47: =E45/E$27*-1 -> 0.27186427 | F47: =F45/F$27*-1 -> 0.044038851
C49: Operating (loss)/profit | D49: =+D163+D221 -> -1390.0943 | E49: =+E163+E221 -> -2190.4373 | F49: =+F163+F221 -> 597.55031 | K49: 63.617 | M49: 104.515 | N49: -167.296 | O49: 187.452 | P49: 218.174 | Q49: 347.219 | R49: 106.682
C50: Growth | E50: =E49/D49-1 -> 0.57574732 | F50: =F49/E49-1 -> -1.2727995
...

Sheet 同程艺龙 Peers
C2: 2019Q3
C3: Tongcheng-Elong | D3: Meituan In-store, Hotel & Travel | E3: Ctrip
B4: GMV (mn) | C4: =同程艺龙!Q3 -> 47600 | D4: 63900
B5: YoY Growth | C5: =同程艺龙!Q4 -> 0.2173913 | D5: 0.3
B6: Transportation | C6: =同程艺龙!Q6 -> 39438.4
B7: Accommodation | C7: =同程艺龙!Q18 -> 8161.6 | D7: =D36*D37 -> 21960 | G7: 同程控股
G8: 旅行社收入 | H8: 198
B9: Revenue | C9: =同程艺龙!Q27 -> 2062.13 | D9: 6181.117 | E9: =E11+E14+E17+E23+E20 -> 10499 | G9: 航空 | H9: 6.2
B10: YoY Growth | C10: =同程艺龙!Q28 -> 0.22280222 | D10: 0.39 | E10: =E9/9396-1 -> 0.11739038 | G10: 金服 | H10: 3.9
B11: Transportation Revenue | C11: =同程艺龙!Q66 -> 1139.621 | E11: 3721 | H11: =SUM(H8:H10) -> 208.1
B12: YoY Growth | C12: =同程艺龙!Q67 -> 0.01556922 | E12: 0.03
B13: as % of Total Revenue | C13: =C11/C9 -> 0.55264266 | E13: =E11/E9 -> 0.35441471
B14: Accommodation Revenue | C14: =同程艺龙!Q70 -> 693.736 | D14: =D7*D29 -> 1756.8 | E14: 4117
B15: YoY Growth | C15: =同程艺龙!Q71 -> 0.34517434 | D15: 0.444 | E15: 0.14
B16: as % of Total Revenue | C16: =C14/C9 -> 0.3364172 | D16: =D14/D9 -> 0.28422047 | E16: =E14/E9 -> 0.39213258
B17: Packaged Tour | E17: 1638
B18: YoY Growth | E18: 0.19
B19: as % of Total Revenue | E19: =E17/E9 -> 0.15601486
B20: Corporate Travel | E20: 335
B21: YoY Growth | E21: 0.26
B22: as % of Total Revenue | E22: =E20/E9 -> 0.031907801
B23: Others | C23: =同程艺龙!Q77 -> 228.773 | E23: 688
B24: YoY Growth | C24: =同程艺龙!Q78 -> 3.7145389 | E24: =688/503-1 -> 0.36779324
B25: as % of Total Revenue | C25: =C23/C9 -> 0.11094014 | E25: =E23/E9 -> 0.06553005
B27: Take Rate
B28: Transportation Revenue | C28: =C11/C6 -> 0.028896228
B29: Accommodation Revenue | C29: =C14/C7 -> 0.085 | D29: 0.08
B31: Gross Profit | C31: =同程艺龙!Q150 -> 1378.875 | E31: 8319
B32: Gross Margin | C32: =C31/C9 -> 0.66866541 | E32: =E31/E9 -> 0.79236118
B33: Operating Profit | C33: =同程艺龙!Q163 -> 347.219 | E33: 2242
B34: Operating Margin | C34: =C33/C9 -> 0.16837881 | E34: =E33/E9 -> 0.21354415
B36: Hotel Room Nights (mn) | C36: =C7/C37 -> 30.798491 | D36: 109.8
B37: ADR | C37: 265 | D37: 200

Sheet 同程艺龙Charts
I1: 2018Q3 | J1: 2019Q2 | K1: 2019Q3 | L1: 2019Q4
H2: Transportation | I2: 1122.15 | J2: 937.092 | K2: 1139.621 | L2: 1956.493
H3: Accommodation | I3: 515.722 | J3: 553.36 | K3: 693.736 | L3: 1181.997
H4: Others | I4: 48.525 | J4: 100.446 | K4: 228.773 | L4: 621.863
B30: Q1 | D30: Q2 | F30: Q3 | H30: Q4
B31: 2018 | C31: 2019 | D31: 2018 | E31: 2019 | F31: 2018 | G31: 2019 | H31: 2018 | I31: 2019
A32: GMV | B32: =同程艺龙!J3 -> 29000 | C32: =同程艺龙!O3 -> 35900 | D32: =同程艺龙!K3 -> 28900 | E32: =同程艺龙!P3 -> 41300 | F32: =同程艺龙!M3 -> 39100 | G32: =同程艺龙!Q3 -> 47600 | H32: =同程艺龙!N3 -> 34500 | I32: =同程艺龙!R3 -> 41300
A33: Revenue | B33: =同程艺龙!J27 -> 1517.512 | C33: =同程艺龙!O27 -> 1783.411 | D33: =同程艺龙!K27 -> 1314.48 | E33: =同程艺龙!P27 -> 1590.898 | F33: =同程艺龙!M27 -> 1686.397 | G33: =同程艺龙!Q27 -> 2062.13 | H33: =同程艺龙!N27 -> 1572.411 | I33: =同程艺龙!R27 -> 1956.493
A34: GMV YoY Growth | C34: =C32/B32-1 -> 0.23793103 | E34: =E32/D32-1 -> 0.42906574 | G34: =G32/F32-1 -> 0.2173913 | I34: =I32/H32-1 -> 0.19710145
A35: Revenue YoY Growth | C35: =C33/B33-1 -> 0.17522036 | E35: =E33/D33-1 -> 0.21028696 | G35: =G33/F33-1 -> 0.22280222 | I35: =I33/H33-1 -> 0.24426311
A36: Take Rate | B36: =B33/B32 -> 0.052328 | C36: =C33/C32 -> 0.049677187 | D36: =D33/D32 -> 0.045483737 | E36: =E33/E32 -> 0.038520533 | F36: =F33/F32 -> 0.043130358 | G36: =G33/G32 -> 0.043322059 | H36: =H33/H32 -> 0.04557713 | I36: =I33/I32 -> 0.047372712
B39: 2018Q2 | C39: 2018Q3 | D39: 2018Q4 | E39: 2019Q2 | F39: 2019Q3 | G39: 2019Q4
A40: Employee benefit expenses | B40: 55.89 | C40: 72.935 | D40: 137.136 | E40: 61.647 | F40: 68.342 | G40: 33.912
A41: Order processing cost | B41: 195.027 | C41: 240.546 | D41: 208.369 | E41: 243.566 | F41: 277.125 | G41: 223.966
A42: Cost of pre-purchased inventory risk taking products | B42: 28.823 | C42: 64.508 | D42: 57.562 | E42: 101.801 | F42: 151.619 | G42: 129.774
A43: Depreciations of PP&E | B43: 23.87 | C43: 26.186 | D43: 39.65 | E43: 31.165 | F43: 29.519 | G43: 29.084
A44: Procurement cost | B44: 35.639 | C44: 19.112 | D44: 20.578 | E44: 64.713 | F44: 77.336 | G44: 92.256
A45: Others | B45: 31.282 | C45: 56.256 | D45: 93.059 | E45: 58.268 | F45: 79.314 | G45: 66.06
B46: =同程艺龙!K126 -> 1314.48 | C46: =同程艺龙!M126 -> 1686.397 | D46: =同程艺龙!N126 -> 1572.398 | E46: =同程艺龙!P126 -> 1590.898 | F46: =同程艺龙!Q126 -> 2062.13 | G46: =同程艺龙!R126 -> 1956.493
B48: 2018Q2 | C48: 2018Q3 | D48: 2018Q4 | E48: 2019Q2 | F48: 2019Q3 | G48: 2019Q4
A49: Employee benefit expenses | B49: =B40/$B$46 -> 0.042518715 | C49: =C40/$C$46 -> 0.04324901 | D49: =D40/$D$46 -> 0.08721456 | E49: =E40/$E$46 -> 0.038749813 | F49: =F40/$F$46 -> 0.033141461 | G49: =G40/$G$46 -> 0.017333055
A50: Order processing cost | B50: =B41/$B$46 -> 0.14836818 | C50: =C41/$C$46 -> 0.14263901 | D50: =D41/$D$46 -> 0.1325167 | E50: =E41/$E$46 -> 0.1530997 | F50: =F41/$F$46 -> 0.13438774 | G50: =G41/$G$46 -> 0.11447319
A51: Cost of pre-purchased inventory risk taking products | B51: =B42/$B$46 -> 0.021927302 | C51: =C42/$C$46 -> 0.038251966 | D51: =D42/$D$46 -> 0.03660778 | E51: =E42/$E$46 -> 0.063989646 | F51: =F42/$F$46 -> 0.073525432 | G51: =G42/$G$46 -> 0.066329908
A52: Depreciations of PP&E | B52: =B43/$B$46 -> 0.018159272 | C52: =C43/$C$46 -> 0.015527779 | D52: =D43/$D$46 -> 0.025216262 | E52: =E43/$E$46 -> 0.019589565 | F52: =F43/$F$46 -> 0.01431481 | G52: =G43/$G$46 -> 0.014865374
A53: Procurement cost | B53: =B44/$B$46 -> 0.027112622 | C53: =C44/$C$46 -> 0.011333037 | D53: =D44/$D$46 -> 0.013087017 | E53: =E44/$E$46 -> 0.040677026 | F53: =F44/$F$46 -> 0.03750297 | G53: =G44/$G$46 -> 0.047153759
A54: Others | B54: =B45/$B$46 -> 0.023798004 | C54: =C45/$C$46 -> 0.033358693 | D54: =D45/$D$46 -> 0.059182853 | E54: =E45/$E$46 -> 0.036625855 | F54: =F45/$F$46 -> 0.038462173 | G54: =G45/$G$46 -> 0.033764496
B58: 2018Q2 | C58: 2018Q3 | D58: 2018Q4 | E58: 2019Q1 | F58: 2019Q2 | G58: 2019Q3 | H58: 2019Q4
A59: Gross Margin | B59: =同程艺龙!K152 -> 0.71811591 | C59: =同程艺龙!M152 -> 0.7156405 | D59: =同程艺龙!N152 -> 0.64617482 | E59: =同程艺龙!O152 -> 0.72060843 | F59: =同程艺龙!P152 -> 0.6472684 | G59: =同程艺龙!Q152 -> 0.66866541 | H59: =同程艺龙!R152 -> 0.70607562
A60: R&D Cost as % of Revenue | B60: =-同程艺龙!K155 -> 0.24154038 | C60: =-同程艺龙!M155 -> 0.23917618 | D60: =-同程艺龙!N155 -> 0.27973516 | E60: =-同程艺龙!O155 -> 0.24114015 | F60: =-同程艺龙!P155 -> 0.22135549 | G60: =-同程艺龙!Q155 -> 0.17437649 | H60: =-同程艺龙!R155 -> 0.19285323
A61: S&M Cost as % of Revenue | B61: =-同程艺龙!K157 -> 0.35306433 | C61: =-同程艺龙!M157 -> 0.34167933 | D61: =-同程艺龙!N157 -> 0.35552068 | E61: =-同程艺龙!O157 -> 0.2633846 | F61: =-同程艺龙!P157 -> 0.2559479 | G61: =-同程艺龙!Q157 -> 0.30432853 | H61: =-同程艺龙!R157 -> 0.37923724
A62: G&A Cost as % of Revenue | B62: =-同程艺龙!K159 -> 0.1017505 | C62: =-同程艺龙!M159 -> 0.096938028 | D62: =-同程艺龙!N159 -> 0.16253582 | E62: =-同程艺龙!O159 -> 0.12802545 | F62: =-同程艺龙!P159 -> 0.062735009 | G62: =-同程艺龙!Q159 -> 0.047288968 | H62: =-同程艺龙!R159 -> 0.10197328
A63: Operating Margin | B63: =同程艺龙!K164 -> 0.048397085 | C63: =同程艺龙!M164 -> 0.061975324 | D63: =同程艺龙!N164 -> -0.10639545 | E63: =同程艺龙!O164 -> 0.10510869 | F63: =同程艺龙!P164 -> 0.1371389 | G63: =同程艺龙!Q164 -> 0.16837881 | H63: =同程艺龙!R164 -> 0.054527156
B68: 2018Q1 | C68: 2018Q2 | D68: 2018Q3 | E68: 2018Q4 | F68: 2019Q1 | G68: 2019Q2 | H68: 2019Q3 | I68: 2019Q4
A69: Paying Ratio | B69: =同程艺龙!J100 -> 0.10342717 | C69: =同程艺龙!K100 -> 0.11435832 | D69: =同程艺龙!M100 -> 0.1095492 | E69: =同程艺龙!N100 -> 0.12838227 | F69: =同程艺龙!O100 -> 0.11590567 | G69: =同程艺龙!P100 -> 0.15253304 | H69: =同程艺龙!Q100 -> 0.12735043 | I69: =同程艺龙!R100 -> 0.13161729
B71: 2017 | C71: 2018 | D71: 2019Q1 | E71: 2019Q2 | F71: 2019Q3 | G71: 2019Q4
A72: MAU from Tencent | B72: =同程艺龙!F102 -> 79.6 | C72: =同程艺龙!G102 -> 140.5303 | D72: =同程艺龙!O102 -> 173.1 | E72: =同程艺龙!P102 -> 152.59027 | F72: =同程艺龙!Q102 -> 192.15 | G72: =同程艺龙!R102 -> 173.78835
A73: MAU from Own Channel | B73: =同程艺龙!F96-同程艺龙!F102 -> 41.6 | C73: =同程艺龙!G96-同程艺龙!G102 -> 34.669697 | D73: =同程艺龙!O96-同程艺龙!O102 -> 26.2 | E73: =同程艺龙!P96-同程艺龙!P102 -> 29.009733 | F73: =同程艺龙!Q96-同程艺龙!Q102 -> 41.85 | G73: =同程艺龙!R96-同程艺龙!R102 -> 32.111652
A74: % of Tencent Traffic | B74: =B72/SUM(B72:B73) -> 0.65676568 | C74: =C72/SUM(C72:C73) -> 0.8021136 | D74: =D72/SUM(D72:D73) -> 0.86853989 | E74: =E72/SUM(E72:E73) -> 0.84025477 | F74: =F72/SUM(F72:F73) -> 0.82115385 | G74: =G72/SUM(G72:G73) -> 0.84404249
B82: 2018 | C82: 2019Q1 | D82: 2019Q2 | E82: 2019Q3 | F82: 2019Q4
A83: Weixin Payment (Wallet) | B83: =同程艺龙!G107 -> 0.528 | C83: =同程艺龙!O107 -> 0.608 | D83: =同程艺龙!P107 -> 0.637 | E83: =同程艺龙!Q107 -> 0.65 | F83: =同程艺龙!R107 -> 0.657
...

Sheet DESP Quarterly
A1: Year | B1: Q1-15 | C1: Q2-15 | D1: Q3-15 | E1: Q4-15 | F1: Q1-16 | G1: Q2-16 | H1: Q3-16 | I1: Q4-16 | J1: Q1-17 | K1: Q2-17 | L1: Q3-17 | M1: Q4-17 | N1: Q1-18 | O1: Q2-18 | P1: Q3-18 | Q1: Q4-18 | R1: Q1-19 | S1: Q2-19 | T1: Q3-19 | U1: Q4-19
A2: Company Data (in million of USD, unless specified)
A3: Gross booking value | B3: 810.961 | C3: 868.562 | D3: 941.076 | E3: 970.195 | F3: 661.409 | G3: 755.433 | H3: 844.866 | I3: 998.526 | J3: 1019.102 | K3: 1061.026 | L3: 1116.022 | M3: 1258.398 | N3: 1231.497 | O3: 1184.355 | P3: 1092.3 | Q3: 1207.2 | R3: 1157.5 | S3: 1118.1 | T3: 1177.7 | U3: 1280.9
A4: YoY change | F4: =(F3-B3)/B3 -> -0.18441331 | G4: =(G3-C3)/C3 -> -0.13024862 | H4: =(H3-D3)/D3 -> -0.10223404 | I4: =(I3-E3)/E3 -> 0.029201346 | J4: =(J3-F3)/F3 -> 0.54080456 | K4: =(K3-G3)/G3 -> 0.40452694 | L4: =(L3-H3)/H3 -> 0.32094557 | M4: =(M3-I3)/I3 -> 0.26025562 | ... U4: =(U3-Q3)/Q3 -> 0.061050364
A5: Revenue | B5: 96.777 | C5: 102.509 | D5: 108.367 | E5: 114.058 | F5: 95.115 | G5: 98.797 | H5: 106.088 | I5: 111.162 | J5: 124.999 | K5: 123.462 | L5: 131.468 | M5: 144.011 | N5: 148.593 | O5: 128.259 | P5: 121.2 | Q5: 132.515 | R5: 133.114 | S5: 114.087 | T5: 132.048 | U5: 145.627
A6: Revenue recognition adjustment | J6: -3.321 | K6: -0.059 | L6: 1.31 | M6: 7.578
A7: Revenue after Adjustment | J7: =J5+J6 -> 121.678 | K7: =K5+K6 -> 123.403 | L7: =L5+L6 -> 132.778 | M7: =M5+M6 -> 151.589 | N7: =N5+N6 -> 148.593 | O7: =O5+O6 -> 128.259 | P7: =P5+P6 -> 121.2 | Q7: =Q5+Q6 -> 132.515 | ... U7: =U5+U6 -> 145.627
A8: Air | J8: =J46*J49/1000 -> 56.8176 | K8: =K46*K49/1000 -> 59.89 | L8: =L46*L49/1000 -> 58.8304 | M8: =M46*M49/1000 -> 66.1122 | N8: =N46*N49/1000 -> 60.8814 | O8: =O46*O49/1000 -> 53.1063 | P8: =P46*P49/1000 -> 50.5008 | Q8: =Q46*Q49/1000 -> 50.2911 | ... U8: =U46*U49/1000 -> 53.3876
J9: =J8/J7 -> 0.46695048 | K9: =K8/K7 -> 0.48532045 | L9: =L8/L7 -> 0.4430734 | M9: =M8/M7 -> 0.43612795 | N9: =N8/N7 -> 0.40971917 | O9: =O8/O7 -> 0.41405515 | P9: =P8/P7 -> 0.41667327 | Q9: =Q8/Q7 -> 0.37951251 | ... U9: =U8/U7 -> 0.36660509
A10: Packages, Hotels & Other Travel Products | J10: =J47*J50/1000 -> 64.9005 | K10: =K47*K50/1000 -> 63.543 | L10: =L47*L50/1000 -> 73.914 | M10: =M47*M50/1000 -> 85.4291 | N10: =N47*N50/1000 -> 87.7824 | O10: =O47*O50/1000 -> 75.0484 | P10: =P47*P50/1000 -> 70.742 | Q10: =Q47*Q50/1000 -> 82.2465 | ... U10: =U47*U50/1000 -> 92.2887
J11: =J10/J7 -> 0.53337908 | K11: =K10/K7 -> 0.51492265 | L11: =L10/L7 -> 0.55667355 | M11: =M10/M7 -> 0.56355738 | N11: =N10/N7 -> 0.5907573 | O11: =O10/O7 -> 0.58513165 | P11: =P10/P7 -> 0.58367987 | Q11: =Q10/Q7 -> 0.62065804 | ... U11: =U10/U7 -> 0.63373344
A12: Take rate | B12: =B5/B3 -> 0.11933619 | C12: =C5/C3 -> 0.11802151 | D12: =D5/D3 -> 0.11515223 | E12: =E5/E3 -> 0.11756193 | F12: =F5/F3 -> 0.14380663 | G12: =G5/G3 -> 0.13078195 | H12: =H5/H3 -> 0.12556784 | I12: =I5/I3 -> 0.11132609 | ... U12: =U5/U3 -> 0.11369115
A13: Cost of revenue | B13: -29.248 | C13: -27.61 | D13: -34.681 | E13: -62.674 | F13: -33.494 | G13: -33.752 | H13: -26.15 | I13: -33.279 | J13: -31.14 | K13: -35.087 | L13: -37.869 | M13: -38.383 | N13: -43.646 | O13: -42.088 | P13: -36.7 | Q13: -49.703 | R13: -45.245 | S13: -40.342 | T13: -42.591 | U13: -51.387
A14: Gross profit | B14: =B5+B13 -> 67.529 | C14: =C5+C13 -> 74.899 | D14: =D5+D13 -> 73.686 | E14: =E5+E13 -> 51.384 | F14: =F5+F13 -> 61.621 | G14: =G5+G13 -> 65.045 | H14: =H5+H13 -> 79.938 | I14: =I5+I13 -> 77.883 | J14: 90.538 | K14: 88.316 | L14: 94.909 | M14: 113.206 | N14: 104.947 | O14: 86.171 | P14: =P5+P13 -> 84.5 | Q14: =Q5+Q13 -> 82.812 | R14: =R5+R13 -> 87.869 | S14: =S5+S13 -> 73.745 | T14: =T5+T13 -> 89.457 | U14: =U5+U13 -> 94.24
A15: Gross margin | B15: =B14/B5 -> 0.69777943 | C15: =C14/C5 -> 0.7306578 | D15: =D14/D5 -> 0.67996715 | E15: =E14/E5 -> 0.45050764 | F15: =F14/F5 -> 0.64785786 | G15: =G14/G5 -> 0.65837019 | H15: =H14/H5 -> 0.75350652 | I15: =I14/I5 -> 0.70062611 | ... U15: =U14/U5 -> 0.64713274
A17: Operating expenses (GAAP)
A18: General and administrative | B18: -19.606 | C18: -16.991 | D18: -13.36 | E18: -28.224 | F18: -15.186 | G18: -13.96 | H18: -13.576 | I18: -21.961 | J18: -18.869 | K18: -18.618 | L18: -15.318 | M18: -19.821 | N18: -15.888 | O18: -16.986 | P18: -17.1 | Q18: -17.599 | R18: -20.638 | S18: -21.254 | T18: -25.09 | U18: -25.98
A19: as % of Revenue | J19: =J18/J7 -> -0.15507323 | K19: =K18/K7 -> -0.15087153 | L19: =L18/L7 -> -0.1153655 | M19: =M18/M7 -> -0.13075487 | N19: =N18/N7 -> -0.10692294 | O19: =O18/O7 -> -0.13243515 | P19: =P18/P7 -> -0.14108911 | Q19: =Q18/Q7 -> -0.13280761 | ... U19: =U18/U7 -> -0.17840098
A20: Technology and content | B20: -19.07 | C20: -20.055 | D20: -15.262 | E20: -19.148 | F20: -15.561 | G20: -15.943 | H20: -15.718 | I20: -16.03 | J20: -15.408 | K20: -17.644 | L20: -18.907 | M20: -19.349 | N20: -19.225 | O20: -18.732 | P20: -16.8 | Q20: -16.376 | R20: -18.713 | S20: -18.077 | T20: -17.922 | U20: -18.663
A21: as % of Revenue | J21: =J20/J7 -> -0.1266293 | K21: =K20/K7 -> -0.1429787 | L21: =L20/L7 -> -0.14239558 | M21: =M20/M7 -> -0.12764119 | N21: =N20/N7 -> -0.12938025 | O21: =O20/O7 -> -0.14604823 | P21: =P20/P7 -> -0.13861386 | Q21: =Q20/Q7 -> -0.12357846 | ... U21: =U20/U7 -> -0.12815618
A22: Selling and marketing expenses | B22: -45.178 | C22: -52.893 | D22: -36.185 | E22: -35.893 | F22: -28.577 | G22: -29.133 | H22: -31.374 | I22: -32.382 | J22: -35.546 | K22: -43.289 | L22: -41.097 | M22: -46.356 | N22: -46.41 | O22: -43.45 | P22: -41.6 | Q22: -42.925 | R22: -40.933 | S22: -50.701 | T22: -46.656 | U22: -49.604
A23: as % of Revenue | J23: =J22/J7 -> -0.29213169 | K23: =K22/K7 -> -0.35079374 | L23: =L22/L7 -> -0.30951664 | M23: =M22/M7 -> -0.30580055 | N23: =N22/N7 -> -0.31232965 | O23: =O22/O7 -> -0.33876765 | P23: =P22/P7 -> -0.34323432 | Q23: =Q22/Q7 -> -0.32392559 | ... U23: =U22/U7 -> -0.34062365
A24: Marketing and sales promotion expenses as % of GMV | B24: =-B22/B3 -> 0.055709214 | C24: =-C22/C3 -> 0.060897207 | D24: =-D22/D3 -> 0.038450667 | E24: =-E22/E3 -> 0.036995656 | F24: =-F22/F3 -> 0.043206246 | G24: =-G22/G3 -> 0.038564638 | H24: =-H22/H3 -> 0.037134883 | I24: =-I22/I3 -> 0.032429802 | ... U24: =-U22/U3 -> 0.038725896
A26: Total operating expenses | B26: =B18+B20+B22 -> -83.854 | C26: =C18+C20+C22 -> -89.939 | D26: =D18+D20+D22 -> -64.807 | E26: =E18+E20+E22 -> -83.265 | F26: =F18+F20+F22 -> -59.324 | G26: =G18+G20+G22 -> -59.036 | H26: =H18+H20+H22 -> -60.668 | I26: =I18+I20+I22 -> -70.373 | ... U26: =U18+U20+U22 -> -94.247
A27: Operating income/loss | B27: =B14+B26 -> -16.325 | C27: =C14+C26 -> -15.04 | D27: =D14+D26 -> 8.879 | E27: =E14+E26 -> -31.881 | F27: =F14+F26 -> 2.297 | G27: =G14+G26 -> 6.009 | H27: =H14+H26 -> 19.27 | I27: =I14+I26 -> 7.51 | ... U27: =U14+U26 -> -0.007
A29: Depreciation, amortization and impairment | B29: =-1.267-2.367 -> -3.634 | C29: =-1.371-2.371 -> -3.742 | D29: =-1.253-2.389 -> -3.642 | E29: =-1.261-2.16 -> -3.421 | F29: =-1.265-1.728 -> -2.993 | G29: =-1.255-1.918 -> -3.173 | H29: =-1.45-2.06 -> -3.51 | I29: =-1.111-2.129 -> -3.24 | J29: =-1.343-1.517 -> -2.86 | K29: =-1.362-2.039 -> -3.401 | L29: =-1.337-2.454 -> -3.791 | M29: =-1.033-2.741 -> -3.774 | N29: =-0.859-2.018 -> -2.877 | O29: =-1.475-2.228 -> -3.703 | P29: =-1.3-2.7 -> -4 | Q29: =-1.7-3.2 -> -4.9 | R29: =-0.8-3.8 -> -4.6 | S29: =-2.7-3.1 -> -5.8 | T29: =-2-4.2 -> -6.2 | U29: =-1.094-5.1 -> -6.194
A30: Share-based compensation | B30: -0.321 | C30: -0.374 | D30: -0.374 | E30: 0.208 | F30: -0.05 | G30: -0.05 | H30: -0.05 | I30: -0.424 | J30: -1.176 | K30: -0.93 | L30: -0.959 | M30: -1.224 | N30: -0.983 | O30: -1.266 | P30: -1.4 | Q30: -3.1 | R30: -3 | S30: =-3.2 -> -3.2 | T30: -3.4 | U30: =-2.105 -> -2.105
A31: Total operating expenses (GAAP) | B31: =B18+B20+B22+B29 -> -87.488 | C31: =C18+C20+C22+C29 -> -93.681 | D31: =D18+D20+D22+D29 -> -68.449 | E31: =E18+E20+E22+E29 -> -86.686 | F31: =F18+F20+F22+F29 -> -62.317 | G31: =G18+G20+G22+G29 -> -62.209 | H31: =H18+H20+H22+H29 -> -64.178 | I31: =I18+I20+I22+I29 -> -73.613 | ... U31: =U18+U20+U22+U29 -> -100.441
A32: Total operating expenses (non-GAAP) | B32: =B31-B30 -> -87.167 | C32: =C31-C30 -> -93.307 | D32: =D31-D30 -> -68.075 | E32: =E31-E30 -> -86.894 | F32: =F31-F30 -> -62.267 | G32: =G31-G30 -> -62.159 | H32: =H31-H30 -> -64.128 | I32: =I31-I30 -> -73.189 | ... U32: =U31-U30 -> -98.336
A34: Income (loss) from Operations (GAAP) | B34: -16.325 | C34: -15.04 | D34: 8.879 | E34: -31.881 | F34: 2.297 | G34: 6.009 | H34: 19.27 | I34: 7.51 | J34: 20.715 | K34: 8.765 | L34: 19.587 | M34: 27.68 | N34: 23.424 | O34: 7.003 | P34: 9.051 | Q34: 5.912 | R34: 7.585 | S34: -16.287 | T34: -0.211 | U34: -0.007
A35: OP Margin GAAP (OP/Revenue) | B35: =B34/B5 -> -0.16868677 | C35: =C34/C5 -> -0.14671882 | D35: =D34/D5 -> 0.081934537 | E35: =E34/E5 -> -0.27951569 | F35: =F34/F5 -> 0.024149714 | G35: =G34/G5 -> 0.060821685 | H35: =H34/H5 -> 0.18164166 | I35: =I34/I5 -> 0.067559058 | ... U35: =U34/U5 -> -4.8068009e-05
A37: Net income (GAAP) | B37: -26.221 | C37: -15.954 | D37: -1.652 | E37: -41.449 | F37: -0.735 | G37: 0.179 | H37: 14.353 | I37: 4 | J37: 12.141 | K37: 2.9 | L37: 12.334 | M37: 18.831 | N37: 16.358 | O37: 1.24 | P37: -1.474 | Q37: 3.03 | R37: 1.886 | S37: -16.467 | T37: -3.684 | U37: -2.645
A38: Net profit margin GAAP (/ Revenue) | B38: =B37/B5 -> -0.27094248 | C38: =C37/C5 -> -0.15563511 | D38: =D37/D5 -> -0.015244493 | E38: =E37/E5 -> -0.36340283 | F38: =F37/F5 -> -0.0077274878 | G38: =G37/G5 -> 0.0018117959 | H38: =H37/H5 -> 0.13529334 | I38: =I37/I5 -> 0.03598352 | ... U38: =U37/U5 -> -0.018162841
A40: Adjusted EBITDA | B40: -12.265 | C40: -10.999 | D40: 12.637 | E40: 28.44 | F40: 5.34 | G40: 9.232 | H40: 22.831 | I40: 11.173 | J40: 24.751 | K40: 13.097 | L40: 24.337 | M40: 32.678 | N40: 27.284 | O40: 11.972 | P40: 14.5 | Q40: 13.9 | R40: 15.2 | S40: -7.3 | T40: 9.4 | U40: 8.292
A41: Adjusted EBITDA margin | J41: =J40/J5 -> 0.19800958 | K41: =K40/K5 -> 0.10608122 | L41: =L40/L5 -> 0.18511729 | M41: =M40/M5 -> 0.22691322 | N41: =N40/N5 -> 0.18361565 | O41: =O40/O5 -> 0.093342378 | P41: =P40/P5 -> 0.11963696 | Q41: =Q40/Q5 -> 0.10489379 | ... U41: =U40/U5 -> 0.056939991
A43: Operating Metrics | P43: =P45/1000 -> 2.596 | Q43: =Q45/1000 -> 2.676 | R43: =R45/1000 -> 2.652 | S43: =S45/1000 -> 2.448 | T43: =T45/1000 -> 2.723 | U43: =U45/1000 -> 2.855
A44: ASPs | F44: =F3*1000/F45 -> 405.27512 | G44: =G3*1000/G45 -> 442.8095 | H44: =H3*1000/H45 -> 459.41599 | I44: =I3*1000/I45 -> 490.67617 | J44: =J3*1000/J45 -> 478.67637 | K44: =K3*1000/K45 -> 480.10226 | L44: =L3*1000/L45 -> 485.64926 | M44: =M3*1000/M45 -> 520.21414 | ... U44: =U3*1000/U45 -> 448.65149
A45: Number of transactions ('000) | F45: 1632 | G45: 1706 | H45: 1839 | I45: 2035 | J45: 2129 | K45: 2210 | L45: 2298 | M45: 2419 | N45: 2514 | O45: 2607 | P45: 2596 | Q45: 2676 | R45: 2652 | S45: 2448 | T45: 2723 | U45: 2855
A46: Air | J46: 1246 | K46: 1325 | L46: 1328 | M46: 1386 | N46: 1362 | O46: 1513 | P46: 1512 | Q46: 1557 | R46: 1517 | S46: 1459 | T46: 1586 | U46: 1658
A47: Package, Hotels & Other | J47: 883 | K47: 885 | L47: 970 | M47: 1033 | N47: 1152 | O47: 1094 | P47: 1085 | Q47: 1119 | R47: 1135 | S47: 989 | T47: 1137 | U47: 1197
...

Sheet DESP Annual
B1: Full year
A2: Year | B2: 2015 | C2: 2016 | D2: 2017 | E2: 2018 | F2: 2019
A3: Company Data
A4: Gross booking value | B4: 3596.26 | C4: 3260.234 | D4: 4454.548 | E4: 4715.235 | F4: =SUM('DESP Quarterly'!R3:U3) -> 4734.2
A5: YoY change | C5: =(C4-B4)/B4 -> -0.093437627 | D5: =(D4-C4)/C4 -> 0.36632769 | E5: =(E4-D4)/D4 -> 0.058521538 | F5: =(F4-E4)/E4 -> 0.0040220689
A6: Revenue | B6: =B7+B8 -> 425.538 | C6: =C7+C8 -> 407.335 | D6: =D7+D8 -> 523.94 | E6: =E7+E8 -> 530.614 | F6: =SUM('DESP Quarterly'!R5:U5) -> 524.876
A7: Air | B7: 219.817 | C7: 201.894 | D7: 241.015 | E7: 214.804 | F7: 201.6
A8: Packages, hotels, and other travel products | B8: 205.721 | C8: 205.441 | D8: 282.925 | E8: 315.81 | F8: 323.2
A9: Cost of revenue | B9: 154.213 | C9: 126.675 | D9: 142.479 | E9: 172.11 | F9: =SUM('DESP Quarterly'!R13:U13) -> -179.565
A10: Unallocated corporate expenses | B10: -20.021 | C10: -5.555
A12: % of hotel gross bookings supplied through Expedia | C12: 0.095
A14: Gross profit | B14: 267.498 | C14: 284.487 | D14: 381.461 | E14: 358.504 | F14: =SUM('DESP Quarterly'!R14:U14) -> 345.311
A15: Gross profit margin | B15: =B14/B6 -> 0.62861131 | C15: =C14/C6 -> 0.6984104 | D15: =D14/D6 -> 0.72806237 | E15: =E14/E6 -> 0.67563992 | F15: =F14/F6 -> 0.65789063
A17: Operating expenses (GAAP)
A18: General and administrative | B18: -78.181 | C18: -64.683 | D18: -72.626 | E18: -67.24 | F18: =SUM('DESP Quarterly'!R18:U18) -> -92.962
A19: Technology and content | B19: -73.535 | C19: -63.251 | D19: -71.308 | E19: -71.154 | F19: =SUM('DESP Quarterly'!R20:U20) -> -73.375
A20: Selling and marketing expenses | B20: -170.149 | C20: -121.466 | D20: -166.288 | E20: -174.357 | F20: =SUM('DESP Quarterly'!R22:U22) -> -187.894
A21: Marketing and sales promotion expenses as % of GMV | B21: =-B20/B4 -> 0.047312764 | C21: =-C20/C4 -> 0.037256835 | D21: =-D20/D4 -> 0.037329938 | E21: =-E20/E4 -> 0.036977372 | F21: =-F20/F4 -> 0.039688649
A23: Depreciation, amortization and impairment | B23: -5.512 | C23: -5.089 | D23: =-5.075-8.751 -> -13.826 | E23: =-5.348-10.14 -> -15.488 | F23: =SUM('DESP Quarterly'!R29:U29) -> -22.794
A24: Share-based compensation | B24: -0.861 | C24: -0.574 | D24: -4.289 | E24: -6.766 | F24: =SUM('DESP Quarterly'!R30:U30) -> -11.705
A25: Total operating expenses (GAAP) | B25: =B18+B19+B20+B23 -> -327.377 | C25: =C18+C19+C20+C23 -> -254.489 | D25: =D18+D19+D20+D23 -> -324.048 | E25: =E18+E19+E20+E23 -> -328.239 | F25: =F18+F19+F20+F23 -> -377.025
A26: Total operating expenses (non-GAAP) | B26: =B25+B24 -> -328.238 | C26: =C25+C24 -> -255.063 | D26: =D25+D24 -> -328.337 | E26: =E25+E24 -> -335.005 | F26: =F25+F24 -> -388.73
A28: Income (loss) from Operations (GAAP) | B28: -54.367 | C28: 35.087 | D28: 71.239 | E28: 45.39 | F28: =SUM('DESP Quarterly'!R34:U34) -> -8.92
A29: OP Margin GAAP (OP/revenue) | B29: =B28/B6 -> -0.12776062 | C29: =C28/C6 -> 0.086137945 | D29: =D28/D6 -> 0.13596786 | E29: =E28/E6 -> 0.085542409 | F29: =F28/F6 -> -0.01699449
A31: Net income (GAAP) | B31: -85.276 | C31: 17.797 | D31: 42.366 | E31: 19.154 | F31: =SUM('DESP Quarterly'!R37:U37) -> -20.91
A32: Net profit margin GAAP (/revenue) | B32: =B31/B6 -> -0.20039573 | C32: =C31/C6 -> 0.043691311 | D32: =D31/D6 -> 0.080860404 | E32: =E31/E6 -> 0.036097804 | F32: =F31/F6 -> -0.039837981
A34: Adjusted EBITDA | B34: -39.067 | C34: 48.585 | D34: 89.354 | E34: 67.329 | F34: =SUM('DESP Quarterly'!R40:U40) -> 25.592
A35: Adjusted EBITDA margin | B35: =B34/B6 -> -0.091806137 | C35: =C34/C6 -> 0.11927529 | D35: =D34/D6 -> 0.17054243 | E35: =E34/E6 -> 0.12688885 | F35: =F34/F6 -> 0.048758183
A37: Shares used in computing earnings per share-Diluted (thousands) | B37: 57078 | C37: 58609 | D37: 61548 | E37: 71254 | F37: 70689
A38: Earning per ADS
A39: - Basic | B39: -1.49 | C39: 0.3 | D39: 0.69 | E39: 0.28 | F39: -0.3
A40: - Diluted EPS | B40: -1.49 | C40: 0.3 | D40: 0.69 | E40: 0.27 | F40: -0.3
A45: Balance Sheet (in million, USD) | C45: 2016 | D45: 2017 | E45: 2018 | F45: 2019
A46: ASSETS
A47: Current assets:
A48: Cash | B48: 102.116 | C48: 75.968 | D48: 371.013 | E48: 346.48 | F48: 309.187
A49: Restricted cash | B49: 19.075 | C49: 22.738 | D49: 29.764 | E49: 5.709 | F49: 4.457
A50: Short-term investment | B50: 40.013 | C50: 0 | D50: 0 | E50: 0 | F50: 0
A51: Cash, Restricted cash and short-term investment | B51: =B50+B49+B48 -> 161.204 | C51: =C50+C49+C48 -> 98.706 | D51: =D50+D49+D48 -> 400.777 | E51: =E50+E49+E48 -> 352.189 | F51: =F50+F49+F48 -> 313.644
A52: Account receivable, net of allowance | C52: 121.098 | D52: 198.273 | E52: 228.448 | F52: 213.551
...

Sheet DESP Charts
A99: GMV | B99: Q4-17 | C99: Q1-18 | D99: Q2-18 | E99: Q3-18 | F99: Q4-18 | G99: Q1-19 | H99: Q2-19 | I99: Q3-19 | J99: Q4-19
A100: Argentina | B100: 451 | C100: 407 | D100: 312 | E100: 262 | F100: 269 | G100: 275 | H100: 216 | I100: 232 | J100: 304.6
A101: Brazil | B101: 441 | C101: 452 | D101: 435 | E101: 407.9 | F101: 496 | G101: 466 | H101: 452 | I101: 468 | J101: 492.5
A102: Rest of LATAM | B102: 367 | C102: 373 | D102: 437 | E102: 422.8 | F102: 443 | G102: 416 | H102: 450 | I102: 478 | J102: 483.4
B104: Q4-17 | C104: Q1-18 | D104: Q2-18 | E104: Q3-18 | F104: Q4-18 | G104: Q1-19 | H104: Q2-19 | I104: Q3-19 | J104: Q4-19
A105: GMV | B105: 1258.398 | C105: 1231.497 | D105: 1184.355 | E105: 1092.3 | F105: 1207.2 | G105: 1157.5 | H105: 1118.1 | I105: 1177.7 | J105: 1280.9
A106: Revenue | B106: 144.011 | C106: 148.593 | D106: 128.259 | E106: 121.2 | F106: 132.515 | G106: 133.114 | H106: 114.087 | I106: 132.048 | J106: 145.627
A107: GMV Growth | C107: ='DESP Quarterly'!N4 -> 0.20841388 | D107: ='DESP Quarterly'!O4 -> 0.11623561 | E107: ='DESP Quarterly'!P4 -> -0.021255853 | F107: =F105/B105-1 -> -0.040685061 | G107: =G105/C105-1 -> -0.060087032 | H107: =H105/D105-1 -> -0.055941842 | I107: =I105/E105-1 -> 0.078183649 | J107: =J105/F105-1 -> 0.061050364
A108: Revenue Growth | C108: ='DESP Quarterly'!N7/'DESP Quarterly'!J7-1 -> 0.22119857 | D108: ='DESP Quarterly'!O7/'DESP Quarterly'!K7-1 -> 0.039350745 | E108: ='DESP Quarterly'!P7/'DESP Quarterly'!L7-1 -> -0.08719818 | F108: =F106/B106-1 -> -0.079827235 | G108: =G106/C106-1 -> -0.10417045 | H108: =H106/D106-1 -> -0.11049517 | I108: =I106/E106-1 -> 0.08950495 | J108: =J106/F106-1 -> 0.098947289
A109: Blended Take Rate | B109: =B106/B105 -> 0.11443995 | C109: =C106/C105 -> 0.12066046 | D109: =D106/D105 -> 0.10829439 | E109: =E106/E105 -> 0.11095853 | F109: =F106/F105 -> 0.10977054 | G109: =G106/G105 -> 0.1150013 | H109: =H106/H105 -> 0.10203649 | I109: =I106/I105 -> 0.11212363 | J109: =J106/J105 -> 0.11369115
B110: Revenue Breakdown
A111: From Customers | B111: 0.25
A112: From Suppliers | B112: =1-B111 -> 0.75
B113: Q4-17 | C113: Q1-18 | D113: Q2-18 | E113: Q3-18 | F113: Q4-18 | G113: Q1-19 | H113: Q2-19 | I113: Q3-19 | J113: Q4-19
A114: Argentina GMV (as reported) | B114: 451 | C114: 407 | D114: 312 | E114: 262 | F114: 269 | G114: 275 | H114: 216 | I114: 232 | J114: 304.6
A115: Growth (as reported) | G115: =G114/C114-1 -> -0.32432432 | H115: =H114/D114-1 -> -0.30769231 | I115: =I114/E114-1 -> -0.11450382 | J115: =J114/F114-1 -> 0.13234201
A116: Growth (FX Neutral) | G116: =G117/C117-1 -> 0.33906634 | H116: =H117/D117-1 -> 0.29807692 | I116: =I117/E117-1 -> 0.46564885 | J116: =J117/F117-1 -> 0.81040892
A117: Argentina GMV (FX Neutral) | B117: 451 | C117: 407 | D117: 312 | E117: 262 | F117: 269 | G117: 545 | H117: 405 | I117: 384 | J117: 487
B119: Q4-17 | C119: Q1-18 | D119: Q2-18 | E119: Q3-18 | F119: Q4-18 | G119: Q1-19 | H119: Q2-19 | I119: Q3-19 | J119: Q4-19
A120: Brazil GMV (as reported) | B120: 441 | C120: 452 | D120: 435 | E120: 407.9 | F120: 496 | G120: 466 | H120: 452 | I120: 468 | J120: 492.5
A121: Growth (as reported) | G121: =G120/C120-1 -> 0.030973451 | H121: =H120/D120-1 -> 0.03908046 | I121: =I120/E120-1 -> 0.14734003 | J121: =J120/F120-1 -> -0.0070564516
A122: Growth (FX Neutral) | G122: =G123/C123-1 -> 0.19690265 | H122: =H123/D123-1 -> 0.12643678 | I122: =I123/E123-1 -> 0.19362745 | J122: =J123/F123-1 -> 0.072580645
A123: Brazil GMV (FX Neutral) | B123: 441 | C123: 452 | D123: 435 | E123: 408 | F123: 496 | G123: 541 | H123: 490 | I123: 487 | J123: 532
B125: Q4-17 | C125: Q1-18 | D125: Q2-18 | E125: Q3-18 | F125: Q4-18 | G125: Q1-19 | H125: Q2-19 | I125: Q3-19 | J125: Q4-19
A126: Rest of Latam GMV (as reported) | B126: 367 | C126: 373 | D126: 437 | E126: 422.8 | F126: 443 | G126: 416 | H126: 450 | I126: 478 | J126: 483.4
A127: Growth (as reported) | G127: =G126/C126-1 -> 0.1152815 | H127: =H126/D126-1 -> 0.029748284 | I127: =I126/E126-1 -> 0.13055818 | J127: =J126/F126-1 -> 0.091196388
A128: Growth (FX Neutral) | G128: =G129/C129-1 -> 0.17962466 | H128: =H129/D129-1 -> 0.077803204 | I128: =I129/E129-1 -> 0.16071429 | J128: =J129/F129-1 -> 0.1241535
A129: Rest of Latam GMV (FX Neutral) | B129: 367 | C129: 373 | D129: 437 | E129: 392 | F129: 443 | G129: 440 | H129: 471 | I129: 455 | J129: 498
B132: 2017 | C132: 2018 | D132: 2019
A133: Paid Traffic | B133: 0.35 | C133: 0.38 | D133: 0.31
A134: Non-Paid Traffic | B134: =1-B133 -> 0.65 | C134: =1-C133 -> 0.62 | D134: =1-D133 -> 0.69
B136: 2017 | C136: 2018 | D136: 2019
A137: App | B137: 0.27 | C137: 0.34 | D137: 0.37
A138: Site | B138: =1-B137 -> 0.73 | C138: =1-C137 -> 0.66 | D138: =1-D137 -> 0.63
B140: 2017 | C140: 2018 | D140: 2019
A141: Mobile | B141: 0.28 | C141: 0.34 | D141: 0.39
A142: Desktop | B142: =1-B141 -> 0.72 | C142: =1-C141 -> 0.66 | D142: =1-D141 -> 0.61
A145: Argentina | B145: Q4-17 | C145: Q1-18 | D145: Q2-18 | E145: Q3-18 | F145: Q4-18 | G145: Q1-19 | H145: Q2-19 | I145: Q3-19 | J145: Q4-19
A146: # of Transaction ('000) | B146: ='DESP Quarterly'!M55 -> 632 | C146: ='DESP Quarterly'!N55 -> 675 | D146: ='DESP Quarterly'!O55 -> 577 | E146: ='DESP Quarterly'!P55 -> 572 | F146: ='DESP Quarterly'!Q55 -> 558 | G146: ='DESP Quarterly'!R55 -> 618 | H146: ='DESP Quarterly'!S55 -> 496 | I146: ='DESP Quarterly'!T55 -> 551 | J146: ='DESP Quarterly'!U55 -> 629
A147: Transaction Growth | G147: =G146/C146-1 -> -0.084444444 | H147: =H146/D146-1 -> -0.14038128 | I147: =I146/E146-1 -> -0.036713287 | J147: =J146/F146-1 -> 0.12724014
...

Sheet MMYT (2)
A2: (in million, USD, except EPS data)
B3: MMYT | C3: MMYT | D3: MMYT | E3: MMYT | F3: MMYT | G3: MMYT | H3: MMYT | I3: MMYT | J3: MMYT | K3: MMYT | L3: MMYT | M3: MMYT | N3: MMYT | O3: MMYT | P3: MMYT | Q3: MMYT | R3: MMYT | S3: MMYT | T3: MMYT | U3: MMYT | V3: MMYT | W3: MMYT | X3: MMYT | Y3: MMYT | Z3: MMYT | AA3: MMYT | AB3: MMYT
A4: P&L | B4: 14Q1 | C4: 14Q2 | D4: 14Q3 | E4: 14Q4 | F4: 15Q1 | G4: 15Q2 | H4: 15Q3 | I4: 15Q4 | J4: 16Q1 | K4: 16Q2 | L4: 16Q3 | M4: 16Q4 | N4: 1Q17 | O4: 2Q17 | P4: 3Q17 | Q4: 4Q17 | R4: 1Q18 | S4: 2Q18 | T4: 3Q18 | U4: 4Q18 | V4: 1Q19 | W4: 2Q19 | X4: 3Q19 | Y4: 4Q19 | Z4: 1Q20 | AA4: 2Q20 | AB4: 3Q20 | AD4: 43555 | AE4: 43585 | AF4: 43616 | AG4: 43646 | AH4: 43677 | AI4: 43708 | AJ4: 43738 | AK4: 43769 | AL4: 43799 | AM4: 43830 | AN4: 43861 | AO4: 43890 | AP4: 43921
B5: 4QF14 | C5: 1QF15 | D5: 2QF15 | E5: 3QF15 | F5: 4QF15 | G5: 1QF16 | H5: 2QF16 | I5: 3QF16 | J5: 4QF16 | K5: 1QF17 | L5: 2QF17 | M5: 3QF17 | N5: 4QF17 | O5: 1QF18 | P5: 2QF18 | Q5: 3QF18 | R5: 4QF18 | S5: 1QF19 | T5: 2QF19 | U5: 3QF19 | V5: 4QF19 | W5: 1QF20 | X5: 2QF20 | Y5: 3QF20 | Z5: 4QF20 | AA5: 1QF21 | AB5: 2QF21 | AQ5: 43951 | AR5: 43982 | AS5: 44012 | AT5: 44043 | AU5: 44074 | AV5: 44104 | AW5: 44135
N6: Consolidated ibibo at the end of January | X6: 8月 | AB6: 8月
A7: Industry Data
A8: Travel Market | Y8: 67
A9: Online Travel Market | Y9: 23
A10: Online Penetration Rate (%) | W10: 9月 | X10: =+SUM(V18:X18)-AI17 -> 11553454 | Y10: =Y9/Y8 -> 0.34328358 | AA10: 9月 | AB10: =+SUM(Z18:AB18)-AU17 -> 3943000
AA11: Vs 2019 | AB11: =+AB10/X10 -> 0.34128322
A13: COVID cases in India - 现有确诊 | AQ13: 24640 | AR13: 93359 | AS13: 217663 | AT13: 563031 | AU13: 784017 | AV13: 941599 | AW13: 680087
A14: COVID cases in India - 累积确诊 | AQ14: 34682 | AR14: 189765 | AS14: 574926 | AT14: 1690546 | AU14: 3649639 | AV14: 6245404 | AW14: 7829226
A15: COVID cases in India - 新增累计确诊 | AR15: =+AR14-AQ14 -> 155083 | AS15: =+AS14-AR14 -> 385161 | AT15: =+AT14-AS14 -> 1115620 | AU15: =+AU14-AT14 -> 1959093 | AV15: =+AV14-AU14 -> 2595765 | AW15: =+AW14-AV14 -> 1583822
AE16: 464.47 | AF16: 586.34 | AH16: 825.64 | AI16: 943.58 | AK16: 1182.06 | AL16: 1311.54 | AN16: 127.83 | AO16: 251.5 | AR16: 331.94 | AT16: 372.85 | AU16: 401.17
A17: 累积 # of domestic air passengers | AD17: =+V18 -> 35453454 | AE17: =+AE16*100000 -> 46447000 | AF17: =+AF16*100000 -> 58634000 | AG17: =+V18+W18 -> 70680454 | AH17: =+AH16*100000 -> 82564000 | AI17: =+AI16*100000 -> 94358000 | AJ17: =+V18+W18+X18 -> 105911454 | AK17: =+AK16*100000 -> 118206000 | AL17: =+AL16*100000 -> 131154000 | AM17: =+V18+W18+X18+Y18 -> 144100000 | AN17: =+AN16*100000 -> 12783000 | AO17: =+AO16*100000 -> 25150000 | AP17: =+Z18 -> 32912000 | AQ17: N.A. | AR17: =+AR16*100000 -> 33194000 | AS17: =+Z18+AA18 -> 35178000 | AT17: =+AT16*100000 -> 37285000 | AU17: =+AU16*100000 -> 40117000 | AV17: =+Z18+AA18+AB18 -> 44060000
A18: Number of domestic air passengers (scheduled and non-scheduled) | B18: =5062143+4874364+5208065 -> 15144572 | C18: =5247143+5936825+5594898 -> 16778866 | D18: =5172742+5648739+5745441 -> 16566922 | E18: =5830052+5782353+6339272 -> 17951677 | F18: 18547627 | G18: 20291493 | H18: 20198401 | I18: 22070502 | J18: 23005883 | K18: 24570663 | L18: 25118743 | M18: 27190531 | N18: 27279358 | O18: 28876367 | P18: =9533226+9663380+9550493+32174+27747+32108 -> 28839128 | Q18: =10418436+10453411+11206075+32114+36059+36884 -> 32182979 | R18: 33790317 | S18: 34693820 | T18: 34447828 | U18: 36188079 | V18: 35453454 | W18: 35227000 | X18: 35231000 | Y18: =144100000-V18-W18-X18 -> 38188546 | Z18: 32912000 | AA18: =35178000-Z18 -> 2266000 | AB18: =44060000-Z18-AA18 -> 8882000 | AE18: =+AE17-AD17 -> 10993546 | AF18: =+AF17-AE17 -> 12187000 | AG18: =+AG17-AF17 -> 12046454 | AH18: =+AH17-AG17 -> 11883546 | AI18: =+AI17-AH17 -> 11794000 | AJ18: =+AJ17-AI17 -> 11553454 | AK18: =+AK17-AJ17 -> 12294546 | AL18: =+AL17-AK17 -> 12948000 | AM18: =+AM17-AL17 -> 12946000 | AN18: =+AN17 -> 12783000 | AO18: =+AO17-AN17 -> 12367000 | AP18: =+AP17-AO17 -> 7762000 | AR18: =+AR17-AP17 -> 282000 | AS18: =+AS17-AR17 -> 1984000 | AT18: =+AT17-AS17 -> 2107000 | AU18: =+AU17-AT17 -> 2832000 | AV18: =+AV17-AU17 -> 3943000
A19: YoY % growth rate | F19: =F18/B18-1 -> 0.2247046 | G19: =G18/C18-1 -> 0.2093483 | H19: =H18/D18-1 -> 0.21920059 | I19: =I18/E18-1 -> 0.22943957 | J19: =J18/F18-1 -> 0.240368 | K19: =K18/G18-1 -> 0.21088493 | L19: =L18/H18-1 -> 0.24360057 | M19: =M18/I18-1 -> 0.23198516 | ... AB19: =AB18/X18-1 -> -0.74789248 | AQ19: % of 2019 level | AR19: =+AR18/AF18 -> 0.023139411 | AS19: =+AS18/AG18 -> 0.16469577 | AT19: =+AT18/AH18 -> 0.17730398 | AU19: =+AU18/AI18 -> 0.2401221 | AV19: =+AV18/AJ18 -> 0.34128322
A20: Inbound (Domestic & Foreign) | M20: 7170031 | N20: 6778304 | O20: 7357808 | P20: 7091845 | Q20: 8029759 | R20: 7635602 | S20: 7828650 | T20: 7396880 | U20: 8503427 | V20: 7844578 | W20: 7750138 | X20: 7603221 | Y20: 8464724 | Z20: 6044021
A21: YoY % growth rate | Q21: =Q20/M20-1 -> 0.11990576 | R21: =R20/N20-1 -> 0.12647677 | S21: =S20/O20-1 -> 0.063992156 | T21: =T20/P20-1 -> 0.043012079 | U21: =U20/Q20-1 -> 0.058989068 | V21: =V20/R20-1 -> 0.027368634 | W21: =W20/S20-1 -> -0.010028804 | X21: =X20/T20-1 -> 0.02789568 | ... Z21: =Z20/V20-1 -> -0.22952885
A22: Outbound (Domestic & Foreign) | M22: 6672921 | N22: 7424671 | O22: 7252972 | P22: 7507393 | Q22: 7498821 | R22: 8209584 | S22: 7901884 | T22: 7901701 | U22: 7833113 | V22: 8548440 | W22: 7809958 | X22: 8133436 | Y22: 8023714 | Z22: 6523668
A23: YoY % growth rate | Q23: =Q22/M22-1 -> 0.12376889 | R23: =R22/N22-1 -> 0.10571687 | S23: =S22/O22-1 -> 0.089468428 | T23: =T22/P22-1 -> 0.052522627 | U23: =U22/Q22-1 -> 0.044579275 | V23: =V22/R22-1 -> 0.04127566 | W23: =W22/S22-1 -> -0.011633428 | X23: =X22/T22-1 -> 0.02932723 | ... Z23: =Z22/V22-1 -> -0.23685865
A24: Total cross border | M24: =M20+M22 -> 13842952 | N24: =N20+N22 -> 14202975 | O24: =O20+O22 -> 14610780 | P24: =P20+P22 -> 14599238 | Q24: =Q20+Q22 -> 15528580 | R24: =R20+R22 -> 15845186 | S24: =S20+S22 -> 15730534 | T24: =T20+T22 -> 15298581 | ... Z24: =Z20+Z22 -> 12567689
AD25: 1000000
A26: Number of international air passengers(scheduled) | F26: 12088595 | G26: 12153343 | H26: 11775585 | I26: 12623073 | J26: 13214818 | K26: 13296993 | L26: 13318377 | M26: 13842952 | N26: 14202975 | O26: =7351315+7245837 -> 14597152 | P26: =7101550+7513721 -> 14615271 | Q26: =8007419+7481372 -> 15488791 | R26: =7615097+8188071 -> 15803168 | S26: =7828650+7901884 -> 15730534 | T26: 15298581 | U26: 16336540 | V26: 16393018 | W26: 15560096 | X26: 15736657 | Y26: 16488438 | Z26: 12567689 | AD26: (mm) | AE26: 3Q19 | AF26: 4Q19 | AG26: 1Q20 | AH26: 2Q20 | AI26: 3Q20
A27: YoY % growth rate | J27: =J26/F26-1 -> 0.093164094 | K27: =K26/G26-1 -> 0.094101681 | L27: =L26/H26-1 -> 0.13101617 | M27: =M26/I26-1 -> 0.09663883 | N27: =N26/J26-1 -> 0.074776437 | O27: =O26/K26-1 -> 0.097778423 | P27: =P26/L26-1 -> 0.097376279 | Q27: =Q26/M26-1 -> 0.11889364 | ... Z27: =Z26/V26-1 -> -0.23335111 | AD27: # of domestic air passengers | AE27: =(+X18)/1000000 -> 35.231 | AF27: =(+Y18)/1000000 -> 38.188546 | AG27: =(+Z18)/1000000 -> 32.912 | AH27: =(+AA18)/1000000 -> 2.266 | AI27: =(+AB18)/1000000 -> 8.882
M28: =M18+M22 -> 33863452 | N28: =N18+N22 -> 34704029 | O28: =O18+O22 -> 36129339 | P28: =P18+P22 -> 36346521 | Q28: =Q18+Q22 -> 39681800 | R28: =R18+R22 -> 41999901 | S28: =S18+S22 -> 42595704 | T28: =T18+T22 -> 42349529 | ... Z28: =Z18+Z22 -> 39435668 | AD28: Est. MMYT domestic air passengers | AE28: =(+X40)/1000000 -> 9.16006 | AF28: =(+Y40)/1000000 -> 10.310907 | AG28: =(+Z40)/1000000 -> 9.017888 | AI28: =(+AB40)/1000000 -> 2.5307443
AD29: Market share % | AE29: =AE28/AE27 -> 0.26 | AF29: =AF28/AF27 -> 0.27 | AG29: =AG28/AG27 -> 0.274 | AI29: =AI28/AI27 -> 0.28492956
A30: Number of air passengers | F30: =F18+F26 -> 30636222 | G30: =G18+G26 -> 32444836 | H30: =H18+H26 -> 31973986 | I30: =I18+I26 -> 34693575 | J30: =J18+J26 -> 36220701 | K30: =K18+K26 -> 37867656 | L30: =L18+L26 -> 38437120 | M30: =M18+M26 -> 41033483 | ... Z30: =Z18+Z26 -> 45479689
A31: YoY % growth rate | J31: =J30/F30-1 -> 0.18228354 | K31: =K30/G30-1 -> 0.1671397 | L31: =L30/H30-1 -> 0.20213726 | M31: =M30/I30-1 -> 0.18274012 | N31: =N30/J30-1 -> 0.14526588 | O31: =O30/K30-1 -> 0.14803829 | P31: =P30/L30-1 -> 0.13053213 | Q31: =Q30/M30-1 -> 0.16177732 | ... Z31: =Z30/V30-1 -> -0.1228007 | BG31: 1000
A32: Number of roomnights
BE33: 1000
A34: Market Share
A35: % share of domestic air market | B35: 0.12 | C35: 0.13 | D35: 0.13 | E35: 0.15 | F35: 0.15 | G35: 0.15 | H35: 0.15 | I35: 0.15 | J35: 0.158 | K35: 0.162 | M35: 0.17 | O35: 0.23 | P35: 0.23 | Q35: 0.24 | S35: 0.24 | T35: 0.25 | X35: 0.26 | Y35: 0.27 | Z35: 0.274 | AB35: =+AB40/AB18 -> 0.28492956
A36: % share of outbound air market | K36: 0.5
A37: % share of domestic hotel transactions booked via OTAs | F37: 0.226 | I37: 0.25 | J37: 0.29 | K37: 0.28 | L37: 0.27
A38: % share of domestic hotel market(offline+online) | I38: 0.023 | M38: 0.05
A39: % share of OTA market | G39: 0.4
A40: Implied MMYT domestic air passengers | O40: =O35*O18 -> 6641564.4 | P40: =P35*P18 -> 6632999.4 | Q40: =Q35*Q18 -> 7723915 | S40: =S35*S18 -> 8326516.8 | T40: =T35*T18 -> 8611957 | X40: =X35*X18 -> 9160060 | Y40: =Y35*Y18 -> 10310907 | Z40: =Z35*Z18 -> 9017888 | AA40: =+AA55/AA41*1000000 -> 746980.79 | AB40: =+AB55/AB41*1000000 -> 2530744.3
A41: Segments / passengers | O41: =O55/O40*1000000 -> 1.1796769 | P41: =P55/P40*1000000 -> 1.16433 | Q41: =Q55/Q40*1000000 -> 1.0956879 | S41: =S55/S40*1000000 -> 1.1014209 | T41: =T55/T40*1000000 -> 1.1617568 | X41: =X55/X40*1000000 -> 1.2184418 | Y41: =Y55/Y40*1000000 -> 1.1296775 | Z41: =Z55/Z40*1000000 -> 0.95776306 | AA41: =+AVERAGE(X41:Y41) -> 1.1740596 | AB41: 0.927
A43: MMYT air volume - Full FY | R43: =SUM(R44:R45) -> 33.3 | V43: =SUM(V44:V45) -> 39.5 | Z43: =SUM(Z44:Z45) -> 42.2
...

Sheet MMYT charts (2)
AC3: Unit：mn | AD3: 16Q2 | AE3: 17Q2 | AF3: 17Q3 | AG3: 17Q4 | AH3: 18Q1 | AI3: 18Q2 | AJ3: 18Q3 | AK3: 18Q4 | AL3: 19Q1 | AM3: 19Q2 | AN3: 19Q3 | AO3: 19Q4 | AP3: 20Q1 | AQ3: 20Q2 | AR3: 20Q3
AC5: Air ticketing - flight segments | AD5: 4.7275 | AE5: ='MMYT (2)'!O213 -> 0 | AF5: ='MMYT (2)'!P213 -> 0 | AG5: ='MMYT (2)'!Q213 -> 0 | AH5: ='[29]MMYT (2)'!R55 -> 9.318 | AI5: ='[29]MMYT (2)'!S55 -> 9.171 | AJ5: ='[29]MMYT (2)'!T55 -> 10.005 | AK5: ='[29]MMYT (2)'!U55 -> 10.104 | AL5: ='[29]MMYT (2)'!V55 -> 10.205 | AM5: ='[29]MMYT (2)'!W55 -> 10.609 | AN5: ='[29]MMYT (2)'!X55 -> 11.161 | AO5: ='[29]MMYT (2)'!Y55 -> 11.648 | ... AR5: ='[29]MMYT (2)'!AB55 -> 2.346
AC6: YoY % growth rate | AE6: ='MMYT (2)'!O214 -> 1839.692 | AF6: ='MMYT (2)'!P214 -> 1793.97 | AG6: ='MMYT (2)'!Q214 -> 1801.831 | AH6: ='[29]MMYT (2)'!R56 -> 0.551 | AI6: ='[29]MMYT (2)'!S56 -> 0.17053185 | AJ6: ='[29]MMYT (2)'!T56 -> 0.29548103 | AK6: ='[29]MMYT (2)'!U56 -> 0.19390287 | AL6: ='[29]MMYT (2)'!V56 -> 0.095192101 | AM6: ='[29]MMYT (2)'!W56 -> 0.1567986 | AN6: ='[29]MMYT (2)'!X56 -> 0.11554223 | AO6: ='[29]MMYT (2)'!Y56 -> 0.15281077 | ... AR6: ='[29]MMYT (2)'!AB56 -> -0.78980378
AC7: Air ticheting (Pro Forma) growth rate | AE7: ='MMYT (2)'!O215 -> 0 | AF7: ='MMYT (2)'!P215 -> 0 | AG7: ='MMYT (2)'!Q215 -> 0 | AH7: ='[29]MMYT (2)'!R57 -> 0.4 | AI7: ='[29]MMYT (2)'!S57 -> 0.17053185 | AJ7: ='[29]MMYT (2)'!T57 -> 0.29548103 | AK7: ='[29]MMYT (2)'!U57 -> 0.19390287 | AL7: ='[29]MMYT (2)'!V57 -> 0.095192101 | AM7: ='[29]MMYT (2)'!W57 -> 0.1567986 | AN7: ='[29]MMYT (2)'!X57 -> 0.11554223 | AO7: ='[29]MMYT (2)'!Y57 -> 0.15281077 | ... AR7: ='[29]MMYT (2)'!AB57 -> -0.78980378
AC8: Total Roomnights | AD8: 2.3451 | AE8: ='MMYT (2)'!O217 -> 0 | AF8: ='MMYT (2)'!P217 -> 0 | AG8: ='MMYT (2)'!Q217 -> 0 | AH8: ='[29]MMYT (2)'!R59 -> 4.887 | AI8: ='[29]MMYT (2)'!S59 -> 6.746 | AJ8: ='[29]MMYT (2)'!T59 -> 6.706 | AK8: ='[29]MMYT (2)'!U59 -> 7.018 | AL8: ='[29]MMYT (2)'!V59 -> 6.141 | AM8: ='[29]MMYT (2)'!W59 -> 7.558 | AN8: ='[29]MMYT (2)'!X59 -> 7.51 | AO8: ='[29]MMYT (2)'!Y59 -> 8.472 | ... AR8: ='[29]MMYT (2)'!AB59 -> 0.855
AC9: YoY % growth rate | AE9: ='MMYT (2)'!O218 -> 0.655 | AF9: ='MMYT (2)'!P218 -> 0.589 | AG9: ='MMYT (2)'!Q218 -> 0.537 | AH9: ='[29]MMYT (2)'!R60 -> 0.37 | AI9: ='[29]MMYT (2)'!S60 -> 0.16314356 | AJ9: ='[29]MMYT (2)'!T60 -> 0.19069602 | AK9: ='[29]MMYT (2)'!U60 -> 0.25500715 | AL9: ='[29]MMYT (2)'!V60 -> 0.25659914 | AM9: ='[29]MMYT (2)'!W60 -> 0.12036763 | AN9: ='[29]MMYT (2)'!X60 -> 0.11989263 | AO9: ='[29]MMYT (2)'!Y60 -> 0.20718153 | ... AR9: ='[29]MMYT (2)'!AB60 -> -0.8861518
AC10: Standalone hotels booked online -room nights | AD10: 1.8814 | AE10: ='MMYT (2)'!O219 -> 0.254 | AF10: ='MMYT (2)'!P219 -> 0.25 | AG10: ='MMYT (2)'!Q219 -> 0.252 | AH10: ='[29]MMYT (2)'!R61 -> 4.712 | AI10: ='[29]MMYT (2)'!S61 -> 6.494 | AJ10: ='[29]MMYT (2)'!T61 -> 6.574 | AK10: ='[29]MMYT (2)'!U61 -> 6.851 | AL10: ='[29]MMYT (2)'!V61 -> 5.993 | AM10: ='[29]MMYT (2)'!W61 -> 7.38 | AN10: ='[29]MMYT (2)'!X61 -> 7.385 | AO10: ='[29]MMYT (2)'!Y61 -> 8.295 | ... AR10: ='[29]MMYT (2)'!AB61 -> 0.854
AC11: YoY % growth rate | AE11: ='MMYT (2)'!O220 -> 0.909 | AF11: ='MMYT (2)'!P220 -> 0.839 | AG11: ='MMYT (2)'!Q220 -> 0.789 | AH11: ='[29]MMYT (2)'!R62 -> 1.327 | AI11: ='[29]MMYT (2)'!S62 -> 0.18130719 | AJ11: ='[29]MMYT (2)'!T62 -> 0.21785847 | AK11: ='[29]MMYT (2)'!U62 -> 0.27058605 | AL11: ='[29]MMYT (2)'!V62 -> 0.27185908 | AM11: ='[29]MMYT (2)'!W62 -> 0.13643363 | AN11: ='[29]MMYT (2)'!X62 -> 0.12336477 | AO11: ='[29]MMYT (2)'!Y62 -> 0.21077215 | ... AR11: ='[29]MMYT (2)'!AB62 -> -0.88436019
AC12: Standalone hotels (Pro Forma) growth rate | AE12: ='MMYT (2)'!O221 -> 163.183 | AF12: ='MMYT (2)'!P221 -> 176.197 | AG12: ='MMYT (2)'!Q221 -> 190.738 | AH12: ='[29]MMYT (2)'!R63 -> 0.19 | AI12: ='[29]MMYT (2)'!S63 -> 0.18130719 | AJ12: ='[29]MMYT (2)'!T63 -> 0.21785847 | AK12: ='[29]MMYT (2)'!U63 -> 0.27058605 | AL12: ='[29]MMYT (2)'!V63 -> 0.27185908 | AM12: ='[29]MMYT (2)'!W63 -> 0.13643363 | AN12: ='[29]MMYT (2)'!X63 -> 0.12336477 | AO12: ='[29]MMYT (2)'!Y63 -> 0.21077215 | ... AR12: ='[29]MMYT (2)'!AB63 -> -0.88436019
AC13: Bus tickets sold | AE13: ='MMYT (2)'!O222 -> 0 | AF13: ='MMYT (2)'!P222 -> 0 | AG13: ='MMYT (2)'!Q222 -> 0 | AH13: ='[29]MMYT (2)'!R64 -> 11.013 | AI13: ='[29]MMYT (2)'!S64 -> 14.894 | AJ13: ='[29]MMYT (2)'!T64 -> 13.24 | AK13: ='[29]MMYT (2)'!U64 -> 16.219 | AL13: ='[29]MMYT (2)'!V64 -> 17.111 | AM13: ='[29]MMYT (2)'!W64 -> 20.98 | AN13: ='[29]MMYT (2)'!X64 -> 17.682 | AO13: ='[29]MMYT (2)'!Y64 -> 21.338 | ... AR13: ='[29]MMYT (2)'!AB64 -> 2.972
AC14: Bus tickets (Pro Forma) growth rate | AF14: ='MMYT (2)'!P224 -> 1793.97 | AG14: ='MMYT (2)'!Q224 -> 1801.831 | AH14: ='[29]MMYT (2)'!R66 -> 0.55 | AI14: ='[29]MMYT (2)'!S66 -> 0.54006825 | AJ14: ='[29]MMYT (2)'!T66 -> 0.53276221 | AK14: ='[29]MMYT (2)'!U66 -> 0.58265027 | AL14: ='[29]MMYT (2)'!V66 -> 0.55370925 | AM14: ='[29]MMYT (2)'!W66 -> 0.40862092 | AN14: ='[29]MMYT (2)'!X66 -> 0.33549849 | AO14: ='[29]MMYT (2)'!Y66 -> 0.31561749 | ... AR14: ='[29]MMYT (2)'!AB66 -> -0.83191947

Sheet BKNG
A2: (in million, USD, except EPS data) | B2: 182Q1
A3: P&L | B3: Priceline | C3: Priceline | D3: Priceline | E3: Priceline | F3: Priceline | G3: Priceline | H3: Priceline | I3: Priceline | J3: Priceline | K3: Priceline | L3: Priceline | M3: Priceline | N3: Priceline | O3: Priceline | P3: Priceline | Q3: Priceline | R3: Priceline | S3: Priceline | T3: Priceline | U3: Priceline | V3: Priceline | W3: Priceline | X3: Priceline | Y3: Priceline | Z3: Priceline | AA3: Priceline | AB3: Priceline | AC3: Priceline | AD3: Priceline | AE3: Priceline | AF3: Priceline | AG3: Priceline | AH3: Priceline | AI3: Priceline | AJ3: Priceline | AK3: Priceline | AL3: Priceline | AM3: Priceline | AN3: Priceline | AO3: Priceline | AP3: Priceline | AQ3: Priceline | AR3: Priceline | AS3: Priceline | AT3: Priceline | AU3: Priceline | AV3: Priceline | AW3: Priceline | AX3: Priceline | AY3: Priceline | AZ3: Priceline | BA3: Priceline | BB3: Priceline | BC3: Priceline | BD3: Priceline | BE3: Priceline | BF3: Priceline | BG3: Priceline | BH3: Priceline | BI3: Priceline | BJ3: Priceline | BK3: Priceline | BL3: Priceline | BN3: Priceline | BO3: Priceline | BP3: Priceline | BQ3: Priceline | BR3: Priceline | BS3: Priceline | BT3: Priceline | BU3: Priceline | BV3: Priceline | BW3: Priceline
B4: 1999 | C4: 2000 | D4: 2001 | E4: 2002 | F4: 2003 | G4: 2004 | H4: 2005 | I4: 2006 | J4: 2007 | K4: 2008 | L4: 2009 | M4: 2010 | N4: 2011 | O4: 2012 | P4: 2013 | Q4: 2014 | R4: 2015Q1 | S4: 2015Q2 | T4: 2015Q3 | U4: 2015Q4 | V4: 2015 | W4: 2016Q1 | X4: 2016Q2 | Y4: 2016Q3 | Z4: 2016Q4 | AA4: 2017Q1 | AB4: 2017Q2 | AC4: 2017Q3 | AD4: 2017Q4 | AE4: 2018Q1 | AF4: 2018Q2 | AG4: 2018Q3 | AH4: 2018Q4 | AI4: 2019Q1 | AJ4: 2019Q2 | AK4: 2019Q3 | AL4: 2019Q4 | AM4: 2020Q1 | AN4: 2020Q2 | AO4: 2020Q3 | AP4: 2020Q4 | AQ4: 2021Q1 | AR4: 2021Q2 | AS4: 2021Q3 | AT4: 2021Q4 | AU4: 2022Q1 | AV4: 2022Q2 | AW4: 2022Q3 | AX4: 2022Q4 | AY4: 2023Q1 | AZ4: 2023Q2 | BA4: 2023Q3 | BB4: 2023Q4 | BC4: 2024Q1 | BD4: 2024Q2 | BE4: 2024Q3 | BF4: 2024Q4 | BG4: 2025Q1 | BH4: 2025Q2 | BI4: 2025Q3 | BJ4: 2025Q4 | BK4: 2026Q1 | BL4: 2026Q2 | BN4: 2016 | BO4: 2017 | BP4: 2018 | BQ4: 2019 | BR4: 2020 | BS4: 2021 | BT4: 2022 | BU4: 2023 | BV4: 2024 | BW4: 2025
A5: Transaction volume
A6: Gross booking value(mn) | K6: =61%*M6 -> 8324.06 | L6: 9310 | M6: 13646 | N6: 21657 | O6: 28500 | P6: =9153+10118+10765+9138 -> 39174 | Q6: 50300 | R6: 13775 | S6: 14960 | T6: 14778 | U6: 12015 | V6: 55528 | W6: 16653 | X6: 17862 | Y6: 18460 | Z6: 15112 | AA6: 20687 | AB6: 20797 | AC6: 21762 | AD6: 17980 | AE6: 25009 | AF6: 23896 | AG6: 24274 | AH6: 19552 | AI6: 25410 | AJ6: 25039 | AK6: 25281 | AL6: 20713 | AM6: 12393 | AN6: 2306 | AO6: 13382 | AP6: 7313 | AQ6: 11935 | AR6: 21956 | AS6: 23684 | AT6: 19011 | AU6: 27293 | AV6: 34545 | AW6: 32120 | AX6: 27294 | AY6: 39427 | AZ6: 39692 | BA6: 39813 | BB6: =BU6-SUM(AY6:BA6) -> 31695 | BC6: 43535 | BD6: 41431 | BE6: 43447 | BF6: =BV6-SUM(BC6:BE6) -> 37167 | BG6: 46669 | BH6: 46736 | BI6: 49668 | BJ6: =BW6-SUM(BG6:BI6) -> 43034 | BK6: 53758 | BL6: 51000 | BN6: =SUM(W6:Z6) -> 68087 | BO6: =SUM(AA6:AD6) -> 81226 | BP6: =SUM(AE6:AH6) -> 92731 | BQ6: =SUM(AI6:AL6) -> 96443 | BR6: 35395 | BS6: 76586 | BT6: =SUM(AU6:AX6) -> 121252 | BU6: 150627 | BV6: 165580 | BW6: 186107
A7: Gross booking value YoY Growth on a non-constant currency basis | Q7: 0.28 | R7: 0.12 | S7: 0.11 | T7: 0.07 | U7: 0.13 | V7: 0.1 | W7: 0.21 | X7: 0.19 | Y7: 0.25 | Z7: 0.26 | AA7: 0.24 | AB7: 0.164 | AC7: 0.18 | AD7: 0.19 | AE7: 0.209 | AF7: 0.149 | AG7: 0.115 | AH7: 0.087 | AI7: 0.016 | AJ7: 0.048 | AK7: 0.041 | AL7: 0.059 | AM7: -0.512 | AN7: -0.908 | AO7: -0.471 | AP7: -0.647 | AQ7: -0.037 | AR7: 8.517 | AS7: 0.77 | AT7: 1.6 | AU7: 1.287 | AV7: 0.573 | AW7: =AW6/AS6-1 -> 0.35618983 | AX7: 0.436 | AY7: 0.445 | AZ7: 0.149 | BA7: =BA6/AW6-1 -> 0.23950809 | BB7: =BB6/AX6-1 -> 0.16124423 | BC7: =BC6/AY6-1 -> 0.10419256 | BD7: =BD6/AZ6-1 -> 0.043812355 | BE7: =BE6/BA6-1 -> 0.091276719 | BF7: =BF6/BB6-1 -> 0.17264553 | BG7: =BG6/BC6-1 -> 0.071988056 | BH7: =BH6/BD6-1 -> 0.12804422 | ... BL7: =BL6/BH6-1 -> 0.091235878 | BN7: 0.23 | BO7: 0.19 | BP7: 0.14 | BQ7: 0.04 | BR7: =BR6/BQ6-1 -> -0.63299566 | BS7: =BS6/BR6-1 -> 1.1637519 | BT7: =BT6/BS6-1 -> 0.58321364 | BU7: =BU6/BT6-1 -> 0.24226405 | BV7: =BV6/BU6-1 -> 0.099271711 | BW7: =BW6/BV6-1 -> 0.12397029
A8: Gross booking value YoY Growth on a constant currency basis | N8: 0.531 | O8: 0.37 | P8: 0.38 | Q8: 0.3 | R8: 0.26 | S8: 0.26 | T8: 0.22 | U8: 0.24 | V8: 0.25 | W8: 0.26 | X8: 0.21 | Y8: 0.26 | Z8: 0.28 | AA8: 0.27 | AB8: 0.19 | AC8: 0.16 | AD8: 0.14 | AE8: 0.12 | AF8: 0.11 | AG8: 0.14 | AH8: 0.13 | AI8: 0.08 | AJ8: 0.1 | AK8: 0.07 | AL8: 0.07 | AM8: -0.5 | AN8: -0.91 | AO8: -0.48 | AP8: -0.65 | AQ8: -0.06 | AR8: 8.02 | AS8: 0.75 | AT8: 1.64 | AU8: 1.38 | AV8: 0.71 | AW8: 0.5 | AX8: 0.56 | AY8: 0.51 | AZ8: 0.15 | BA8: 0.2 | BB8: 0.13 | BC8: 0.1 | BD8: 0.06 | BE8: 0.09 | BF8: 0.18 | BG8: 0.1 | BH8: 0.09 | BI8: 0.1 | BJ8: 0.11 | BK8: 0.08 | BL8: 0.08 | BN8: 0.25 | BO8: 0.19 | BP8: 0.13 | BQ8: 0.08 | BR8: -0.63 | BW8: 0.1
A9: Growth vs.2019 | AQ9: =AQ6/AI6-1 -> -0.53030303 | AR9: =AR6/AJ6-1 -> -0.12312792 | AS9: =AS6/AK6-1 -> -0.06316997 | AT9: =AT6/AL6-1 -> -0.082170617 | AU9: =AU6/AI6-1 -> 0.074104683 | AV9: =AV6/AJ6-1 -> 0.37964775 | AW9: =AW6/AK6-1 -> 0.27051936 | AX9: =AX6/AL6-1 -> 0.31772317 | AY9: =AY6/AI6-1 -> 0.55163322 | AZ9: =AZ6/AJ6-1 -> 0.58520708 | BA9: =BA6/AK6-1 -> 0.57481903 | BB9: =BB6/AL6-1 -> 0.53019843 | BC9: =BC6/AI6-1 -> 0.71330185 | BD9: =BD6/AJ6-1 -> 0.65465873 | BE9: =BE6/AK6-1 -> 0.71856335 | BF9: =BF6/AL6-1 -> 0.79438034 | BG9: =BG6/$AI6-1 -> 0.83663912 | BH9: =BH6/AJ6-1 -> 0.86652822 | BI9: =BI6/AK6-1 -> 0.96463747 | BJ9: =BJ6/AL6-1 -> 1.0776324 | BK9: =BK6/$AI6-1 -> 1.1156238 | BL9: =BL6/$AJ6-1 -> 1.0368226
A10: Revenue / Gross booking ratio | L10: =L30/L6 -> 0.25115059 | M10: =M30/M6 -> 0.22606661 | N10: =N30/N6 -> 0.20111788 | O10: =O30/O6 -> 0.18459495 | P10: =P30/P6 -> 0.17341364 | Q10: =Q30/Q6 -> 0.16783243 | S10: =S30/S6 -> 0.15243295 | T10: =T30/T6 -> 0.20996759 | U10: =U30/U6 -> 0.16645818 | V10: =V30/V6 -> 0.16611416 | W10: =W30/W6 -> 0.12899291 | X10: =X30/X6 -> 0.14309159 | Y10: =Y30/Y6 -> 0.19992156 | Z10: =Z30/Z6 -> 0.15540187 | ... BE10: =BE30/BE6 -> 0.18399429 | BG10: =BG30/BG6 -> 0.10203776 | BH10: =BH30/BH6 -> 0.14545532 | BI10: =BI30/BI6 -> 0.18136426 | BL10: =BL30/BL6 -> 0.14415686 | BN10: =BN30/BN6 -> 0.15778351 | BO10: =BO30/BO6 -> 0.15612097 | BP10: =BP30/BP6 -> 0.15666061 | BQ10: =BQ30/BQ6 -> 0.15621663 | BR10: =BR30/BR6 -> 0.19200452 | BS10: =BS30/BS6 -> 0.14308098 | BT10: =BT30/BT6 -> 0.14094613 | BU10: =BU30/BU6 -> 0.14184044
A11: Gross profit / Gross booking ratio | L11: =L35/L6 -> 0.1354203 | M11: =M35/M6 -> 0.13989235 | N11: =N35/N6 -> 0.14221176 | O11: =O35/O6 -> 0.14328705 | P11: =P35/P6 -> 0.1459102 | Q11: =Q35/Q6 -> 0.15077793 | S11: =S35/S6 -> 0.13990013 | T11: =T35/T6 -> 0.19943714 | U11: =U35/U6 -> 0.15641973 | V11: =V35/V6 -> 0.15472927 | W11: =W35/W6 -> 0.12126644 | X11: =X35/X6 -> 0.13603281 | Y11: =Y35/Y6 -> 0.19442378 | Z11: =Z35/Z6 -> 0.15063268 | ... BE11: =BE35/BE6 -> 0.18399429 | BG11: =BG35/BG6 -> 0.10203776 | BH11: =BH35/BH6 -> 0.14545532 | BI11: =BI35/BI6 -> 0.18136426 | BL11: =BL35/BL6 -> 0.14415686 | BN11: =BN35/BN6 -> 0.15149283 | BO11: =BO35/BO6 -> 0.15303653 | BP11: =BP35/BP6 -> 0.15666061 | BQ11: =BQ35/BQ6 -> 0.15621663 | BR11: =BR35/BR6 -> 0.19200452 | BS11: =BS35/BS6 -> 0.14308098 | BT11: =BT35/BT6 -> 0.14094613 | BU11: =BU35/BU6 -> 0.14184044
A13: Gross booking breakdown by business model
