Workbook

Sheet Tongchengelong
B1: eLong Only | P1: Tongcheng Only | U1: eLong only | V1: Tongcheng-eLong | W1: Tongcheng-eLong | Z1: Tongcheng-eLong | AA1: Tongcheng-eLong | BD1: Tongcheng-eLong
A2: (RMB in thousands, expect for Share/pershare data) | B2: 2015-1H | C2: 2015-2H | D2: 2016-1H | E2: 2016-2H | F2: 2017-1H | G2: 2017-2H | H2: 2018-1H | I2: 2018-2H | K2: 2015 | L2: 2016 | M2: 2017 | N2: 2018 | P2: 2015 | Q2: 2016 | R2: 2017 | S2: 2018.3.9 | U2: 1Q18 | V2: 1Q18E | W2: 2Q18 | X2: 3Q18 | Y2: 4Q18 | Z2: 1Q19 | AA2: 2Q19 | AB2: 3Q19 | AC2: 4Q19 | AD2: 1Q20 | AE2: 2Q20 | AF2: 3Q20 | AG2: 4Q20 | AH2: 1Q21 | AI2: 2Q21 | AJ2: 3Q21 | AK2: 4Q21 | AL2: 1Q22 | AM2: 2Q22 | AN2: 3Q22 | AO2: 4Q22 | AP2: 1Q23 | AQ2: 2Q23 | AR2: 3Q23 | AS2: 4Q23 | AT2: 1Q24 | AU2: 2Q24 | AV2: 3Q24 | AW2: 4Q24 | AX2: 1Q25 | AY2: 2Q25 | AZ2: 3Q25 | BA2: 4Q25 | BB2: 1Q26 | BC2: 2Q26 | BD2: 2018-1H | BE2: 2018-2H | BF2: 2019-1H | BG2: 2019-2H | BI2: 2015 | BJ2: 2016 | BK2: 2017 | BL2: 2018 | BM2: 2019 | BN2: 2020 | BO2: 2021 | BP2: 2022
A3: Transaction Volume | Z3: =Z11/Z4 -> 0.049677187 | AN3: =AN11/AN4 -> 0.050442143 | AO3: =AO11/AO4 -> 0.059057717
A4: GMV【公司仅披露总GMV，不拆分业务线】 | K4: =K5+K6 -> 17105500 | L4: =L5+L6 -> 18347200 | M4: =M5+M6 -> 22551400 | V4: 29000000 | W4: 28900000 | X4: 39100000 | Y4: 34500000 | Z4: 35900000 | AA4: 41300000 | AB4: 47600000 | AC4: 41300000 | AD4: 18200000 | AE4: 22400000 | AF4: 39700000 | AG4: 36100000 | AH4: 33300000 | AI4: 43900000 | AJ4: 41100000 | AK4: 31900000 | AL4: 32400000 | AM4: 24300000 | AN4: 40600000 | AO4: 25400000 | AP4: 57200000 | AQ4: 59700000 | AR4: 71100000 | AS4: 53500000 | AT4: 65900000 | AU4: 62300000 | AV4: 72800000 | AW4: 54700000 | AX4: =AT4*(1+AX77) -> 64582000 | AY4: =AU4*(1+AY77) -> 62923000 | AZ4: =AV4*(1+AZ77) -> 76440000 | BA4: =AW4*(1+BA77) -> 57161500 | BB4: =AX4*(1+BB77) -> 67811100 | BD4: =BD6+BD5 -> 57962900 | BI4: =BI6+BI5 -> 36831500 | BJ4: =BJ6+BJ5 -> 67795600 | BK4: =BK6+BK5 -> 102313600 | BL4: 131500000 | BM4: 166100000 | BN4: 116400000 | BO4: =SUM(AH4:AK4) -> 150200000 | BP4: =SUM(AL4:AO4) -> 122700000
A5: -Transportation ticketing | K5: 3729100 | L5: 2456500 | M5: 2035700 | Z5: =Z4*Z8 -> 30154502 | AA5: =AA4*AA8 -> 33765813 | AB5: =AB4*AB8 -> 38121813 | AC5: 34410000 | AD5: =AD4*AD8 -> 14721594 | AE5: =AE4*AE8 -> 17423618 | AF5: =AF4*AF8 -> 30403937 | AG5: =AG8*AG4 -> 27329524 | AH5: =AH4*AH8 -> 26567686 | AI5: =AI4*AI8 -> 33720448 | AJ5: =AJ4*AJ8 -> 31760015 | AK5: =AK4*AK8 -> 24256434 | AL5: =AL4*AL8 -> 25197751 | AM5: =AM8*AM4 -> 17907268 | AN5: =AN8*AN4 -> 30248720 | AO5: =AO8*AO4 -> 18458214 | AP5: =AP4*AP8 -> 43122298 | AQ5: =AQ4*AQ8 -> 42987733 | AR5: =AR4*AR8 -> 51890606 | AS5: =AS4*AS8 -> 38894412 | AT5: =AT4*AT8 -> 49425000 | AU5: =AU4*AU8 -> 44357600 | AV5: =AV4*AV8 -> 52707200 | AW5: =AW4*AW8 -> 38837000 | ... BB5: =BB4*BB8 -> 48145881 | BD5: 47231000 | BI5: 22553700 | BJ5: 50525100 | BK5: 80013400 | BM5: =BM4-BM6 -> 140002000 | BN5: =SUM(AD5:AG5) -> 89878673 | BO5: =SUM(AH5:AK5) -> 1.1630458e+08 | BP5: =SUM(AL5:AO5) -> 91811953
A6: -Accommodation | K6: 13376400 | L6: 15890700 | M6: 20515700 | Z6: 5205000 | AA6: 5911000 | AB6: 8092000 | AC6: 6890000 | AD6: 2430000 | AE6: 3696000 | AF6: 6193200 | AG6: 7039500 | AH6: 5994000 | AI6: 8341000 | AJ6: 7809000 | AK6: 6539500 | AL6: 5670000 | AM6: 5224500 | AN6: 8404200 | AO6: 5334000 | AP6: 10296000 | AQ6: 11641500 | AR6: 13864500 | AS6: 10860500 | AT6: 11466600 | AU6: =AU4*AU9 -> 12584600 | AV6: 14196000 | AW6: 11760500 | AX6: 12270580 | AY6: =AY4*AY9 -> 13654291 | AZ6: =AZ4*AZ9 -> 16434600 | BA6: =BA4*BA9 -> 13432952 | BB6: =BB4*BB9 -> 13969087 | BD6: 10731900 | BI6: 14277800 | BJ6: 17270500 | BK6: 22300200 | BM6: =SUM(Z6:AC6) -> 26098000 | BN6: =SUM(AD6:AG6) -> 19358700 | BO6: =SUM(AH6:AK6) -> 28683500 | BP6: =SUM(AL6:AO6) -> 24632700
A7: -Others | AT7: =AT4-AT5-AT6 -> 5008400 | AU7: =AU4-AU5-AU6 -> 5357800 | AV7: =AV4-AV5-AV6 -> 5896800 | AW7: =AW4-AW5-AW6 -> 4102500 | AX7: =AX4-AX5-AX6 -> 5166560 | AY7: =AY4-AY5-AY6 -> 5222609 | AZ7: =AZ4-AZ5-AZ6 -> 8790600 | BA7: =BA4-BA5-BA6 -> 4858727.5 | BB7: =BB4-BB5-BB6 -> 5696132.4
A8: 机票占比 为估算，非实际数 | Z8: 0.83995827 | AA8: 0.81757418 | AB8: 0.80087843 | AC8: 0.7952497 | AD8: 0.80887879 | AE8: 0.77784007 | AF8: 0.76584225 | AG8: 0.75705052 | AH8: 0.7978284 | AI8: 0.76811955 | AJ8: 0.77274976 | AK8: 0.76038979 | AL8: 0.77770838 | AM8: 0.7369246 | AN8: 0.74504236 | AO8: 0.72670133 | AP8: 0.75388634 | AQ8: 0.72006253 | AR8: 0.72982569 | AS8: 0.72699836 | AT8: 0.75 | AU8: 0.712 | AV8: 0.724 | AW8: 0.71 | AX8: 0.73 | AY8: 0.7 | AZ8: 0.67 | BA8: 0.68 | BB8: 0.71
A9: 酒店占比 为估算，非实际数 | AS9: =AS6/AS4 -> 0.203 | AT9: =AT6/AT4 -> 0.174 | AU9: 0.202 | AV9: =AV6/AV4 -> 0.195 | AW9: =AW6/AW4 -> 0.215 | AX9: =AX6/AX4 -> 0.19 | AY9: 0.217 | AZ9: 0.215 | BA9: 0.235 | BB9: 0.206
A10: P&L | AH10: From MS | AI10: =35120/43900 -> 0.8
A11: Total Revenue | F11: 1245814 | G11: =M11-F11 -> 1272777 | H11: 1996844 | I11: =N11-H11 -> 3258795 | K11: 1026124 | L11: 2204565 | M11: 2518591 | N11: 5255639 | P11: 580523 | Q11: 1434957 | R11: 2707499 | S11: 835148 | U11: 682364 | V11: =S11+U11 -> 1517512 | W11: 1314480 | X11: 1686397 | Y11: 1572398 | Z11: 1783411 | AA11: 1590898 | AB11: 2062130 | AC11: 1956493 | AD11: 1005116 | AE11: 1200106 | AF11: 1914518 | AG11: 1812851 | AH11: 1613763 | AI11: 2137977 | AJ11: 1939431 | AK11: 1846385 | AL11: 1717999 | AM11: 1318650 | AN11: 2047951 | AO11: 1500066 | AP11: 2586143 | AQ11: 2866269 | AR11: 3299290 | AS11: 3144542 | AT11: 3866278 | AU11: 4245357 | AV11: 4991496 | AW11: 4237555 | AX11: 4377432 | AY11: 4669431 | AZ11: 5509112 | BA11: 4839984 | BB11: 5005792 | BC11: 4987027 | BD11: 2831992 | BE11: =BL11-BD11 -> 2423647 | BF11: 3374309 | BI11: 1607000 | BJ11: 3640000 | BK11: 5226090 | BL11: 5255639 | BM11: 7392932 | BN11: 5932591 | BO11: =SUM(AH11:AK11) -> 7537556 | BP11: =SUM(AL11:AO11) -> 6584666 | BQ11: =BP11*(1+BR11) -> 9942845.7 | BR11: 0.51 | BS11: =BQ11/BM11-1 -> 0.34491236
A12: 1. Core OTA Platform
A13: -Accommodation Reservation | F13: 1187674 | G13: =M13-F13 -> 1173951 | H13: 890568 | I13: =N13-H13 -> 939802 | K13: 907649 | L13: 2094050 | M13: 2361625 | N13: 1830370 | U13: 449586 | W13: 440982 | X13: 515722 | Y13: 424080 | Z13: 489164 | AA13: 553360 | AB13: 693736 | AC13: 621863 | AD13: 229014 | AE13: 384298 | AF13: 684559 | AG13: 647282 | AH13: 458537 | AI13: 742892 | AJ13: 644940 | AK13: 562360 | AL13: 543082 | AM13: 543526 | AN13: 818709 | AO13: 509430 | AP13: 834261 | AQ13: 1055396 | AR13: 1127401 | AS13: 882456 | AT13: 964683 | AU13: 1190879 | AV13: 1377541 | AW13: 1135076 | AX13: 1189642 | AY13: 1371367 | AZ13: 1579472 | BA13: 1310303 | BB13: 1364460 | BC13: 1480655 | BI13: 978000 | BJ13: 2176000 | BK13: 2643000 | BL13: 1830370 | BM13: 2358123 | BN13: 1945153 | BO13: =SUM(AH13:AK13) -> 2408729 | BP13: =SUM(AL13:AO13) -> 2414747
A14: of which, Net commissions earned from accommodation reservation | F14: 861193 | G14: =M14-F14 -> 967562 | H14: 824568 | I14: =N14-H14 -> 817732 | K14: 667963 | L14: 1416691 | M14: 1828755 | N14: 1642300 | BI14: 738000 | BJ14: 1499000 | BK14: 1930000
A15: -Transportation Ticketing | F15: 32122 | G15: =M15-F15 -> 29173 | H15: 1037656 | I15: =N15-H15 -> 2194865 | K15: 89378 | L15: 86650 | M15: 61295 | N15: 3232521 | U15: 208169 | W15: 829487 | X15: 1122150 | Y15: 1072715 | Z15: 1258948 | AA15: 937092 | AB15: 1139621 | AC15: 1181997 | AD15: 686768 | AE15: 725822 | AF15: 1055118 | AG15: 1003421 | AH15: 1023426 | AI15: 1234750 | AJ15: 1124724 | AK15: 1074837 | AL15: 1017219 | AM15: 619521 | AN15: 986646 | AO15: 755548 | AP15: 1382694 | AQ15: 1494582 | AR15: 1679948 | AS15: 1472823 | AT15: 1736504 | AU15: 1742736 | AV15: 2026751 | AW15: 1723040 | AX15: 2000211 | AY15: 1881010 | AZ15: 2208716 | BA15: 1835511 | BB15: 2124018 | BC15: 1838210 | BI15: 599000 | BJ15: 1435000 | BK15: 2530000 | BL15: 3232521 | BM15: 4517658 | BN15: 3471129 | BO15: =SUM(AH15:AK15) -> 4457737 | BP15: =SUM(AL15:AO15) -> 3378934
A16: -Others | F16: 26018 | G16: =M16-F16 -> 69653 | H16: 68620 | I16: =N16-H16 -> 124128 | K16: 29097 | L16: 23865 | M16: 95671 | N16: 192748 | U16: 24609 | W16: 44011 | X16: 48525 | Y16: 75603 | Z16: 35299 | AA16: 100446 | AB16: 228773 | AC16: 152633 | AD16: 89334 | AE16: 89986 | AF16: 174841 | AG16: 162148 | AH16: 131800 | AI16: 160335 | AJ16: 169767 | AK16: 209188 | AL16: 157698 | AM16: 155603 | AN16: 242596 | AO16: 235088 | AP16: 369188 | AQ16: 316291 | AR16: 491941 | AS16: 521945 | AT16: 502157 | AU16: 592344 | AV16: 608518 | AW16: 599216 | AX16: 602577 | AY16: 755398 | AZ16: 820608 | BA16: 916662 | BB16: 961421 | BC16: 1025369 | BI16: 30000 | BJ16: 28000 | BK16: 233000 | BL16: =AW16*1.5 -> 898824 | BM16: 517151 | BN16: 516309 | BO16: =SUM(AH16:AK16) -> 671090 | BP16: =SUM(AL16:AO16) -> 790985
A17: Core OTA Platform Total | AN17: =SUM(AN13:AN16) -> 2047951 | AO17: =SUM(AO13:AO16) -> 1500066 | AP17: =SUM(AP13:AP16) -> 2586143 | AQ17: =SUM(AQ13:AQ16) -> 2866269 | AR17: =SUM(AR13:AR16) -> 3299290 | AS17: =SUM(AS13:AS16) -> 2877224 | AT17: =SUM(AT13:AT16) -> 3203344 | AU17: =SUM(AU13:AU16) -> 3525959 | ... BC17: =SUM(BC13:BC16) -> 4344234
A18: YoY | AT18: =AT17/AP17-1 -> 0.23865695 | AU18: =AU17/AQ17-1 -> 0.23015635 | AV18: =AV17/AR17-1 -> 0.21626471 | AW18: =AW17/AS17-1 -> 0.20162073 | AX18: =AX17/AT17-1 -> 0.1838972 | AY18: =AY17/AU17-1 -> 0.13664821 | AZ18: =AZ17/AV17-1 -> 0.14852086 | BA18: =BA17/AW17-1 -> 0.17503208 | ... BC18: =BC17/AY17-1 -> 0.083951569
A19: 2. 度假 | AS19: 267318 | AT19: 662934 | AU19: 719398 | AV19: 978686 | AW19: =AW11-AW17 -> 780223 | AX19: 585002 | AY19: 661656 | AZ19: 900316 | BA19: 777508 | BB19: 555893 | BC19: 642793
AX20: =AX19/AX11 -> 0.13364045 | AY20: =AY19/AY11 -> 0.14169949 | AZ20: =AZ19/AZ11 -> 0.16342307 | BA20: =BA19/BA11 -> 0.16064268 | BB20: =BB19/BB11 -> 0.11104996 | BC20: =BC19/BC11 -> 0.12889303
A21: Cost of revenue | F21: -465692 | G21: =M21-F21 -> -346089 | H21: -564616 | I21: =N21-H21 -> -1035897 | K21: -639723 | L21: -1032913 | M21: -811781 | N21: -1600513 | P21: -228465 | Q21: -530211 | R21: -858806 | S21: -223013 | U21: -194085 | V21: =S21+U21 -> -417098 | W21: -370531 | X21: -479543 | Y21: -556354 | Z21: -498270 | AA21: -561160 | AB21: -682530 | AC21: -575015 | AD21: -351267 | AE21: -332453 | AF21: -535315 | AG21: -477571 | AH21: -409082 | AI21: -505447 | AJ21: -506590 | AK21: -468562 | AL21: -471610 | AM21: -383230 | AN21: -502871 | AO21: -448929 | AP21: -645282 | AQ21: -703284 | AR21: -839728 | AS21: -969739 | AT21: -1351484 | AU21: -1501022 | AV21: -1826821 | AW21: -1547872 | AX21: -1364955 | AY21: -1633149 | AZ21: -1887277 | BA21: -1652826 | BB21: -1509526 | BC21: -1660405 | BD21: -787629 | BE21: =BL21-BD21 -> -812884 | BI21: -868000 | BJ21: -1563000 | BK21: -1670587 | BL21: -1600513 | BM21: -2316975 | BN21: -1696606 | BO21: =SUM(AH21:AK21) -> -1889681 | BP21: =SUM(AL21:AO21) -> -1806640
A22: Gross Profit | B22: =IFERROR(B11+B21,"n.a.") -> 0 | C22: =IFERROR(C11+C21,"n.a.") -> 0 | D22: =IFERROR(D11+D21,"n.a.") -> 0 | E22: =IFERROR(E11+E21,"n.a.") -> 0 | F22: =IFERROR(F11+F21,"n.a.") -> 780122 | G22: =IFERROR(G11+G21,"n.a.") -> 926688 | H22: =IFERROR(H11+H21,"n.a.") -> 1432228 | I22: =IFERROR(I11+I21,"n.a.") -> 2222898 | K22: =IFERROR(K11+K21,"n.a.") -> 386401 | L22: =IFERROR(L11+L21,"n.a.") -> 1171652 | M22: =IFERROR(M11+M21,"n.a.") -> 1706810 | N22: =IFERROR(N11+N21,"n.a.") -> 3655126 | P22: =IFERROR(P11+P21,"n.a.") -> 352058 | Q22: =IFERROR(Q11+Q21,"n.a.") -> 904746 | R22: =IFERROR(R11+R21,"n.a.") -> 1848693 | S22: =IFERROR(S11+S21,"n.a.") -> 612135 | U22: =IFERROR(U11+U21,"n.a.") -> 488279 | V22: =IFERROR(V11+V21,"n.a.") -> 1100414 | W22: =IFERROR(W11+W21,"n.a.") -> 943949 | X22: =IFERROR(X11+X21,"n.a.") -> 1206854 | Y22: =IFERROR(Y11+Y21,"n.a.") -> 1016044 | Z22: =IFERROR(Z11+Z21,"n.a.") -> 1285141 | AA22: =IFERROR(AA11+AA21,"n.a.") -> 1029738 | AB22: =IFERROR(AB11+AB21,"n.a.") -> 1379600 | ... AS22: =IFERROR(AS11+AS21,"n.a.") -> 2174803 | AT22: 2514794 | AU22: =AU11+AU21 -> 2744335 | AV22: =AV11+AV21 -> 3164675 | AW22: =AW11+AW21 -> 2689683 | AX22: =AX11+AX21 -> 3012477 | AY22: =AY11+AY21 -> 3036282 | AZ22: =AZ11+AZ21 -> 3621835 | BA22: =BA11+BA21 -> 3187158 | BB22: =BB11+BB21 -> 3496266 | BC22: =BC11+BC21 -> 3326622 | BD22: =IFERROR(BD11+BD21,"n.a.") -> 2044363 | BE22: =IFERROR(BE11+BE21,"n.a.") -> 1610763 | BF22: =IFERROR(BF11+BF21,"n.a.") -> 3374309 | BG22: =IFERROR(BG11+BG21,"n.a.") -> 0 | BI22: =IFERROR(BI11+BI21,"n.a.") -> 739000 | BJ22: =IFERROR(BJ11+BJ21,"n.a.") -> 2077000 | BK22: =IFERROR(BK11+BK21,"n.a.") -> 3555503 | BL22: =IFERROR(BL11+BL21,"n.a.") -> 3655126 | BM22: =IFERROR(BM11+BM21,"n.a.") -> 5075957 | BN22: =IFERROR(BN11+BN21,"n.a.") -> 4235985 | BO22: =IFERROR(BO11+BO21,"n.a.") -> 5647875 | BP22: =IFERROR(BP11+BP21,"n.a.") -> 4778026
A23: Service development expenses | F23: -245421 | G23: =M23-F23 -> -276597 | H23: -506734 | I23: =N23-H23 -> -843201 | K23: -399073 | L23: -517648 | M23: -522018 | N23: -1349935 | P23: -164277 | Q23: -371720 | R23: -514800 | S23: -118448 | U23: -189234 | V23: =S23+U23 -> -307682 | W23: -317500 | X23: -403346 | Y23: -439855 | Z23: -430052 | AA23: -352154 | AB23: -358993 | AC23: -371592 | AD23: -287449 | AE23: -300363 | AF23: -301834 | AG23: -355860 | AH23: -306953 | AI23: -330201 | AJ23: -322924 | AK23: -384390 | AL23: -351821 | AM23: -324879 | AN23: -370926 | AO23: -366508 | AP23: -411140 | AQ23: -427826 | AR23: -466330 | AS23: -515273 | AT23: -486775 | AU23: -494281 | AV23: -505072 | AW23: -514766 | AX23: -495120 | AY23: -504524 | AZ23: -514544 | BA23: -524863 | BB23: -524331 | BC23: -528173 | BD23: -656809 | BE23: =BL23-BD23 -> -693126 | BK23: -1191509 | BL23: -1349935 | BM23: -1512792 | BN23: -1245506 | BO23: =SUM(AH23:AK23) -> -1344468 | BP23: =SUM(AL23:AO23) -> -1414134
A24: Selling and marketing expenses | F24: -511960 | G24: =M24-F24 -> -583017 | H24: -706087 | I24: =N24-H24 -> -1135227 | K24: -775464 | L24: -1882779 | M24: -1094977 | N24: -1841314 | P24: -580764 | Q24: -515174 | R24: -670732 | S24: -189827 | U24: -241991 | V24: =S24+U24 -> -431818 | W24: -464096 | X24: -576207 | Y24: -559020 | Z24: -469723 | AA24: -407187 | AB24: -627565 | AC24: -640041 | AD24: -291194 | AE24: -369489 | AF24: -724938 | AG24: -745655 | AH24: -618071 | AI24: -884584 | AJ24: -786927 | AK24: -746874 | AL24: -636961 | AM24: -574681 | AN24: -937280 | AO24: -652322 | AP24: -966236 | AQ24: -1107860 | AR24: -1271545 | AS24: -1127174 | AT24: -1368203 | AU24: -1501710 | AV24: -1467569 | AW24: -1283228 | AX24: -1453540 | AY24: -1538292 | AZ24: -1715364 | BA24: -1574110 | BB24: -1691405 | BC24: -1627575 | BD24: -905094 | BE24: =BL24-BD24 -> -936220 | BK24: -1803050 | BL24: -1841314 | BM24: -2244516 | BN24: -2131276 | BO24: =SUM(AH24:AK24) -> -3036456 | BP24: =SUM(AL24:AO24) -> -2801244
A25: Administrative expenses | F25: -35541 | G25: =M25-F25 -> -61838 | H25: -515878 | I25: =N25-H25 -> -419047 | K25: -272584 | L25: -898337 | M25: -97379 | N25: -934925 | P25: -56830 | Q25: -91119 | R25: -132772 | S25: -23566 | U25: -382129 | V25: =S25+U25 -> -405695 | W25: -133749 | X25: -163476 | Y25: -255571 | Z25: -228322 | AA25: -99805 | AB25: -96270 | AC25: -174281 | AD25: =-208584-116023-AE25 -> -120034 | AE25: =-106328-98245 -> -204573 | AF25: =-101391-11638 -> -113029 | AG25: =BN25-AD25-AE25-AF25 -> -224505 | AH25: =-108346-16811 -> -125157 | AI25: =-126243-11919 -> -138162 | AJ25: =-115779-25579 -> -141358 | AK25: =-221288-36419 -> -257707 | AL25: =-188245+2278 -> -185967 | AM25: =-134877-15322 -> -150199 | AN25: -182789 | AO25: -195230 | AP25: -192266 | AQ25: -207641 | AR25: -196536 | AS25: -114751 | AT25: -265303 | AU25: -272193 | AV25: -327745 | AW25: -340938 | AX25: -307438 | AY25: -277742 | AZ25: -291445 | BA25: -389291 | BB25: -326830 | BC25: -385704 | BD25: -533527 | BE25: 3258795 | BK25: -297681 | BL25: -934925 | BM25: =-594217-39958 -> -634175 | BN25: =-521728-140413 -> -662141 | BO25: =SUM(AH25:AK25) -> -662384 | BP25: =SUM(AL25:AO25) -> -714185
A26: Operating Profit/(Loss) | B26: =IFERROR(B22+B23+B24+B25,"n.a.") -> 0 | C26: =IFERROR(C22+C23+C24+C25,"n.a.") -> 0 | D26: =IFERROR(D22+D23+D24+D25,"n.a.") -> 0 | E26: =IFERROR(E22+E23+E24+E25,"n.a.") -> 0 | F26: =IFERROR(F22+F23+F24+F25,"n.a.") -> -12800 | G26: =IFERROR(G22+G23+G24+G25,"n.a.") -> 5236 | H26: =IFERROR(H22+H23+H24+H25,"n.a.") -> -296471 | I26: =IFERROR(I22+I23+I24+I25,"n.a.") -> -174577 | K26: =IFERROR(K22+K23+K24+K25,"n.a.") -> -1060720 | L26: =IFERROR(L22+L23+L24+L25,"n.a.") -> -2127112 | M26: =IFERROR(M22+M23+M24+M25,"n.a.") -> -7564 | N26: =IFERROR(N22+N23+N24+N25,"n.a.") -> -471048 | P26: =IFERROR(P22+P23+P24+P25,"n.a.") -> -449813 | Q26: =IFERROR(Q22+Q23+Q24+Q25,"n.a.") -> -73267 | R26: =IFERROR(R22+R23+R24+R25,"n.a.") -> 530389 | S26: =IFERROR(S22+S23+S24+S25,"n.a.") -> 280294 | U26: =IFERROR(U22+U23+U24+U25,"n.a.") -> -325075 | V26: =IFERROR(V22+V23+V24+V25,"n.a.") -> -44781 | W26: =IFERROR(W22+W23+W24+W25,"n.a.") -> 28604 | X26: =IFERROR(X22+X23+X24+X25,"n.a.") -> 63825 | Y26: =IFERROR(Y22+Y23+Y24+Y25,"n.a.") -> -238402 | Z26: =IFERROR(Z22+Z23+Z24+Z25,"n.a.") -> 157044 | AA26: =IFERROR(AA22+AA23+AA24+AA25,"n.a.") -> 170592 | AB26: =IFERROR(AB22+AB23+AB24+AB25,"n.a.") -> 296772 | ... AY26: =IFERROR(AY22+AY23+AY24+AY25,"n.a.") -> 715724 | AZ26: 1163166 | BA26: 347616 | BB26: 993042 | BC26: 853398 | BD26: =IFERROR(BD22+BD23+BD24+BD25,"n.a.") -> -51067 | BE26: =IFERROR(BE22+BE23+BE24+BE25,"n.a.") -> 3240212 | BF26: =IFERROR(BF22+BF23+BF24+BF25,"n.a.") -> 3374309 | BG26: =IFERROR(BG22+BG23+BG24+BG25,"n.a.") -> 0 | BI26: =IFERROR(BI22+BI23+BI24+BI25,"n.a.") -> 739000 | BJ26: =IFERROR(BJ22+BJ23+BJ24+BJ25,"n.a.") -> 2077000 | BK26: =IFERROR(BK22+BK23+BK24+BK25,"n.a.") -> 263263 | BL26: =IFERROR(BL22+BL23+BL24+BL25,"n.a.") -> -471048 | BM26: =IFERROR(BM22+BM23+BM24+BM25,"n.a.") -> 684474 | BN26: =IFERROR(BN22+BN23+BN24+BN25,"n.a.") -> 197062 | BO26: =IFERROR(BO22+BO23+BO24+BO25,"n.a.") -> 604567 | BP26: =IFERROR(BP22+BP23+BP24+BP25,"n.a.") -> -151537
A27: Net provision for impairment loss on financial assets | AN27: -4474 | AO27: -10843 | AQ27: 4290 | AR27: -7189 | AS27: 2308 | AT27: 6431 | AU27: 8267 | AV27: 1382 | AW27: 1711 | AX27: -8844 | AY27: 8745 | AZ27: -17594 | BA27: 592 | BB27: -14683 | BC27: -5233
A28: Other income | F28: 4809 | G28: =M28-F28 -> 7996 | H28: 8700 | I28: =N28-H28 -> 24696 | K28: 49006 | L28: 10547 | M28: 12805 | N28: 33396 | P28: 3574 | Q28: 2097 | R28: 7583 | S28: 1001 | U28: 1291 | V28: =S28+U28 -> 2292 | W28: 7409 | X28: 9135 | Y28: 15561 | Z28: 4131 | AA28: 13667 | AB28: 25820 | AC28: 45002 | AD28: 11359 | AE28: 41784 | AF28: 25892 | AG28: 19829 | AH28: 21163 | AI28: 16808 | AJ28: 41044 | AK28: 18582 | AL28: 34679 | AM28: 44782 | AN28: 25595 | AO28: 48712 | AP28: 22656 | AQ28: 40408 | AR28: 27328 | AS28: 32391 | AT28: 14344 | AU28: 27708 | AV28: 37192 | AW28: 25013 | AX28: 17896 | AY28: 17399 | AZ28: 12577 | BA28: 56753 | BB28: 12544 | BC28: 42351 | BD28: 9701 | BE28: =BL28-BD28 -> 23695 | BK28: 20388 | BL28: 33396 | BM28: 88620 | BN28: 98864 | BO28: =SUM(AH28:AK28) -> 97597 | BP28: =SUM(AL28:AO28) -> 153768
A29: Other gains/(losses), net | F29: 3576 | G29: =M29-F29 -> 19034 | H29: 11932 | I29: =N29-H29 -> 35956 | K29: 51107 | L29: 4689 | M29: 22610 | N29: 47888 | P29: 516 | Q29: -1864 | R29: 31545 | S29: 4189 | U29: 3183 | V29: =S29+U29 -> 7372 | W29: 8749 | X29: 4748 | Y29: 31208 | Z29: 2870 | AA29: 7811 | AB29: -474 | AC29: -29780 | AD29: 9662 | AE29: -3991 | AF29: 6029 | AG29: 8851 | AH29: 437 | AI29: 21117 | AJ29: 18867 | AK29: 28815 | AL29: 27836 | AM29: -87654 | AN29: -126173 | AO29: 72450 | AP29: 62717 | AQ29: -80147 | AR29: 37262 | AS29: 43092 | AT29: 563 | AU29: -14569 | AV29: 32276 | AW29: -29525 | AX29: 31019 | AY29: 19240 | AZ29: 18722 | BA29: -442766 | BB29: 16772 | BC29: -10416 | BD29: 16121 | BE29: =BL29-BD29 -> 31767 | BK29: 54155 | BL29: 47888 | BM29: -19573 | BN29: 20551 | BO29: =SUM(AH29:AK29) -> 69236 | BP29: =SUM(AL29:AO29) -> -113541
A30: Finance income | F30: 2900 | G30: =M30-F30 -> 7245 | H30: 4514 | I30: =N30-H30 -> 8374 | K30: 9156 | L30: 8402 | M30: 10145 | N30: 12888 | P30: 2177 | Q30: 2732 | R30: 2955 | S30: 575 | U30: 1701 | V30: =S30+U30 -> 2276 | W30: 2813 | X30: 3919 | Y30: 4455 | Z30: 13987 | AA30: 10455 | AB30: 10791 | AC30: 11871 | AD30: 12222 | AE30: 10445 | AF30: 6123 | AG30: 8851 | AH30: 7844 | AI30: 9403 | AJ30: 12602 | AK30: 9126 | AL30: 7768 | AM30: 9678 | AN30: 19487 | AO30: 21040 | AP30: 27937 | AQ30: 41488 | AR30: 55954 | AS30: 49397 | AT30: 47775 | AU30: 55055 | AV30: 46841 | AW30: 44953 | AX30: 49051 | AY30: 43161 | AZ30: 45445 | BA30: 34071 | BB30: 23263 | BC30: 26467 | BD30: 5089 | BE30: =BL30-BD30 -> 7799 | BK30: 13100 | BL30: 12888 | BM30: 47104 | BN30: 37641 | BO30: =SUM(AH30:AK30) -> 38975 | BP30: =SUM(AL30:AO30) -> 57973
A31: Finance costs | F31: -420 | G31: =M31-F31 -> 257 | H31: -224 | I31: =N31-H31 -> -3112 | K31: -5831 | L31: -4114 | M31: -163 | N31: -3336 | P31: 0 | Q31: 0 | R31: 0 | S31: 0 | U31: -964 | V31: =S31+U31 -> -964 | W31: 740 | X31: -576 | Y31: -2536 | Z31: -2900 | AA31: -3829 | AB31: -2679 | AC31: -3021 | AD31: -2986 | AE31: -2592 | AF31: -3524 | AG31: -5680 | AH31: -4670 | AI31: -4661 | AJ31: -8190 | AK31: -8976 | AL31: -17091 | AM31: -23283 | AN31: -40895 | AO31: -55468 | AP31: -40172 | AQ31: -43215 | AR31: -38712 | AS31: -34951 | AT31: -56341 | AU31: -37929 | AV31: -60267 | AW31: -76358 | AX31: -73758 | AY31: -77710 | AZ31: -76462 | BA31: -116091 | BB31: -56362 | BC31: -57604 | BD31: -224 | BE31: =BL31-BD31 -> -3112 | BK31: -163 | BL31: =N31+S31 -> -3336 | BM31: -12429 | BN31: -14782 | BO31: =SUM(AH31:AK31) -> -26497 | BP31: =SUM(AL31:AO31) -> -136737
A32: Fair value change on investments measured at fair value through profit or loss | F32: -446 | G32: =M32-F32 -> 1309 | H32: 27428 | I32: =N32-H32 -> 51144 | K32: 17646 | L32: -4031 | M32: 863 | N32: 78572 | P32: 0 | Q32: 0 | R32: 0 | S32: 0 | U32: 8573 | V32: =S32+U32 -> 8573 | W32: 18855 | X32: 26807 | Y32: 24337 | Z32: 23407 | AA32: 26104 | AB32: 27666 | AC32: 28829 | AD32: -28865 | AE32: 18155 | AF32: 21689 | AG32: 54466 | AH32: 39307 | AI32: 17251 | AJ32: 38570 | AK32: 28762 | AL32: 3665 | AM32: 28759 | AN32: 11921 | AO32: 58092 | AP32: 25720 | AQ32: 32932 | AR32: 16331 | AS32: -107476 | AT32: 39174 | AU32: 19468 | AV32: 41971 | AW32: -73612 | AX32: 20833 | AY32: 48208 | AZ32: 48979 | BA32: 34143 | BB32: 24709 | BC32: 41526 | BD32: 27428 | BE32: =BL32-BD32 -> 51144 | BK32: 863 | BL32: =N32+S32 -> 78572 | BM32: 106006 | BN32: 65445 | BO32: =SUM(AH32:AK32) -> 123890 | BP32: =SUM(AL32:AO32) -> 102437
A33: Fair value change on redeemable convertible preferred shares measured at fair value through profit or loss | F33: -144664 | G33: =M33-F33 -> 242240 | H33: 907734 | I33: =N33-H33 -> 0 | K33: 0 | L33: -36781 | M33: 97576 | N33: 907734 | P33: 0 | Q33: 0 | R33: 0 | S33: 0 | U33: 907734 | V33: =S33+U33 -> 907734 | W33: 0 | X33: 0 | Y33: 0 | Z33: 0 | AA33: 0 | AB33: 0 | AC33: 0 | AD33: 0 | AE33: 0 | BD33: 907734 | BE33: =BL33-BD33 -> 0 | BK33: 97576 | BL33: =N33+S33 -> 907734 | BM33: 0 | BN33: 0 | BO33: =SUM(AH33:AK33) -> 0
A34: Share of results of associates | F34: -2583 | G34: =M34-F34 -> 332 | H34: -1718 | I34: =N34-H34 -> -2850 | K34: -18177 | L34: -11218 | M34: -2251 | N34: -4568 | P34: 0 | Q34: 0 | R34: 0 | S34: 0 | U34: 851 | V34: =S34+U34 -> 851 | W34: -2569 | X34: -136 | Y34: -2714 | Z34: -3061 | AA34: -3003 | AB34: -5841 | AC34: -786 | AD34: -5854 | AE34: -36 | AF34: 882 | AG34: -2196 | AH34: -7408 | AI34: -18133 | AJ34: -2735 | AK34: -4593 | AL34: 13679 | AM34: -19911 | AN34: -4257 | AO34: -3637 | AP34: -9089 | AQ34: 11139 | AR34: -18269 | AS34: -17183 | AT34: 5871 | AU34: 4977 | AV34: -8363 | AW34: 8114 | AX34: 12486 | AY34: 10978 | AZ34: 27757 | BA34: 4691 | BB34: -4875 | BC34: -13524 | BD34: -1718 | BE34: =BL34-BD34 -> -2850 | BK34: -2251 | BL34: =N34+S34 -> -4568 | BM34: -12691 | BN34: -7204 | BO34: =SUM(AH34:AK34) -> -32869 | BP34: =SUM(AL34:AO34) -> -14126
A35: (Loss)/profit before income tax | B35: =IFERROR(B26+B28+B29+B30+B31+B32+B33+B34,"n.a.") -> 0 | C35: =IFERROR(C26+C28+C29+C30+C31+C32+C33+C34,"n.a.") -> 0 | D35: =IFERROR(D26+D28+D29+D30+D31+D32+D33+D34,"n.a.") -> 0 | E35: =IFERROR(E26+E28+E29+E30+E31+E32+E33+E34,"n.a.") -> 0 | F35: =IFERROR(F26+F28+F29+F30+F31+F32+F33+F34,"n.a.") -> -149628 | G35: =IFERROR(G26+G28+G29+G30+G31+G32+G33+G34,"n.a.") -> 283649 | H35: =IFERROR(H26+H28+H29+H30+H31+H32+H33+H34,"n.a.") -> 661895 | I35: =IFERROR(I26+I28+I29+I30+I31+I32+I33+I34,"n.a.") -> -60369 | K35: =IFERROR(K26+K28+K29+K30+K31+K32+K33+K34,"n.a.") -> -957813 | L35: =IFERROR(L26+L28+L29+L30+L31+L32+L33+L34,"n.a.") -> -2159618 | M35: =IFERROR(M26+M28+M29+M30+M31+M32+M33+M34,"n.a.") -> 134021 | N35: =IFERROR(N26+N28+N29+N30+N31+N32+N33+N34,"n.a.") -> 601526 | P35: =IFERROR(P26+P28+P29+P30+P31+P32+P33+P34,"n.a.") -> -443546 | Q35: =IFERROR(Q26+Q28+Q29+Q30+Q31+Q32+Q33+Q34,"n.a.") -> -70302 | R35: =IFERROR(R26+R28+R29+R30+R31+R32+R33+R34,"n.a.") -> 572472 | S35: =IFERROR(S26+S28+S29+S30+S31+S32+S33+S34,"n.a.") -> 286059 | U35: =IFERROR(U26+U28+U29+U30+U31+U32+U33+U34,"n.a.") -> 597294 | V35: =IFERROR(V26+V28+V29+V30+V31+V32+V33+V34,"n.a.") -> 883353 | W35: =IFERROR(W26+W28+W29+W30+W31+W32+W33+W34,"n.a.") -> 64601 | X35: =IFERROR(X26+X28+X29+X30+X31+X32+X33+X34,"n.a.") -> 107722 | Y35: =IFERROR(Y26+Y28+Y29+Y30+Y31+Y32+Y33+Y34,"n.a.") -> -168091 | Z35: =IFERROR(Z26+Z28+Z29+Z30+Z31+Z32+Z33+Z34,"n.a.") -> 195478 | AA35: =IFERROR(AA26+AA28+AA29+AA30+AA31+AA32+AA33+AA34,"n.a.") -> 221797 | AB35: =IFERROR(AB26+AB28+AB29+AB30+AB31+AB32+AB33+AB34,"n.a.") -> 352055 | ... AL35: =IFERROR(AL26+AL28+AL29+AL30+AL31+AL32+AL33+AL34,"n.a.") -> 142176 | AM35: =IFERROR(AM26+AM27+AM28+AM29+AM30+AM31+AM32+AM33+AM34,"n.a.") -> -161968 | AN35: =IFERROR(AN26+AN27+AN28+AN29+AN30+AN31+AN32+AN33+AN34,"n.a.") -> -64711 | AO35: =IFERROR(AO26+AO27+AO28+AO29+AO30+AO31+AO32+AO33+AO34,"n.a.") -> -32577 | AP35: =IFERROR(AP26+AP27+AP28+AP29+AP30+AP31+AP32+AP33+AP34,"n.a.") -> 460988 | AQ35: =IFERROR(AQ26+AQ27+AQ28+AQ29+AQ30+AQ31+AQ32+AQ33+AQ34,"n.a.") -> 426553 | AR35: =IFERROR(AR26+AR27+AR28+AR29+AR30+AR31+AR32+AR33+AR34,"n.a.") -> 597856 | AS35: =IFERROR(AS26+AS27+AS28+AS29+AS30+AS31+AS32+AS33+AS34,"n.a.") -> 385183 | AT35: =IFERROR(AT26+AT27+AT28+AT29+AT30+AT31+AT32+AT33+AT34,"n.a.") -> 452330 | ... AY35: =IFERROR(AY26+AY27+AY28+AY29+AY30+AY31+AY32+AY33+AY34,"n.a.") -> 785745 | AZ35: 1159906 | BA35: 270287 | BB35: 955068 | BC35: 808737 | BD35: =IFERROR(BD26+BD28+BD29+BD30+BD31+BD32+BD33+BD34,"n.a.") -> 913064 | BE35: =IFERROR(BE26+BE28+BE29+BE30+BE31+BE32+BE33+BE34,"n.a.") -> 3348655 | BF35: =IFERROR(BF26+BF28+BF29+BF30+BF31+BF32+BF33+BF34,"n.a.") -> 3374309 | BG35: =IFERROR(BG26+BG28+BG29+BG30+BG31+BG32+BG33+BG34,"n.a.") -> 0 | BI35: =IFERROR(BI26+BI28+BI29+BI30+BI31+BI32+BI33+BI34,"n.a.") -> 739000 | BJ35: =IFERROR(BJ26+BJ28+BJ29+BJ30+BJ31+BJ32+BJ33+BJ34,"n.a.") -> 2077000 | BK35: =IFERROR(BK26+BK28+BK29+BK30+BK31+BK32+BK33+BK34,"n.a.") -> 446931 | BL35: =IFERROR(BL26+BL28+BL29+BL30+BL31+BL32+BL33+BL34,"n.a.") -> 601526 | BM35: =IFERROR(BM26+BM28+BM29+BM30+BM31+BM32+BM33+BM34,"n.a.") -> 881511 | BN35: =IFERROR(BN26+BN28+BN29+BN30+BN31+BN32+BN33+BN34,"n.a.") -> 397577 | BO35: =IFERROR(BO26+BO28+BO29+BO30+BO31+BO32+BO33+BO34,"n.a.") -> 874899 | BP35: =IFERROR(BP26+BP28+BP29+BP30+BP31+BP32+BP33+BP34,"n.a.") -> -101763
A36: Income tax (expense)/credit | F36: 39718 | G36: =M36-F36 -> 20638 | H36: -12510 | I36: =N36-H36 -> -54477 | K36: -5206 | L36: -978 | M36: 60356 | N36: -66987 | P36: 108437 | Q36: -20796 | R36: -81134 | S36: -61315 | U36: 84801 | V36: =S36+U36 -> 23486 | W36: -97311 | X36: -45827 | Y36: -8650 | Z36: -98038 | AA36: -23636 | AB36: -55441 | AC36: -17874 | AD36: -7899 | AE36: -1865 | AF36: -48541 | AG36: -13739 | AH36: -42045 | AI36: -30134 | AJ36: -55474 | AK36: -33721 | AL36: -44939 | AM36: 26764 | AN36: -29229 | AO36: 914 | AP36: -65129 | AQ36: -66572 | AR36: -82368 | AS36: -74057 | AT36: -52074 | AU36: -109798 | AV36: -152087 | AW36: -95601 | AX36: -126561 | AY36: -143640 | AZ36: -174658 | BA36: -167039 | BB36: -170839 | BC36: -175013 | BD36: -67704 | BE36: =BL36-BD36 -> 717 | BK36: 8027 | BL36: -66987 | BM36: -194989 | BN36: -72044 | BO36: =SUM(AH36:AK36) -> -161374 | BP36: =SUM(AL36:AO36) -> -46490
A37: Net income | V37: =V35+V36 -> 906839 | W37: =W35+W36 -> -32710 | X37: =X35+X36 -> 61895 | Y37: =Y35+Y36 -> -176741 | Z37: =Z35+Z36 -> 97440 | AA37: =AA35+AA36 -> 198161 | AB37: =AB35+AB36 -> 296614 | AC37: =AC35+AC36 -> 229805 | ... BC37: =BC35+BC36 -> 633724
A38: Other comprehensive income/(loss) | F38: -31448 | G38: =M38-F38 -> -15144 | H38: 932 | I38: =N38-H38 -> -15917 | K38: 0 | L38: 36781 | M38: -46592 | N38: -14985 | P38: 0 | Q38: 0 | R38: 0 | S38: 0 | U38: 0 | V38: =S38+U38 -> 0 | BD38: 932 | BE38: =BL38-BD38 -> -932
A39: Non-controlling interests | F39: -1510 | G39: =M39-F39 -> 312 | H39: -400 | I39: =N39-H39 -> 4982 | K39: -46753 | L39: -21329 | M39: -1198 | N39: 4582 | P39: 0 | Q39: 0 | R39: 0 | S39: 0 | U39: -374 | V39: =S39+U39 -> -374 | W39: -26 | X39: -440 | Y39: 5422 | Z39: 118 | AA39: -1119 | AB39: -152 | AC39: -423 | AD39: -1556 | AE39: 398 | AF39: 206 | AG39: -1108 | AH39: -420 | AI39: -117 | AJ39: -4958 | AK39: -4384 | AL39: -3907 | AM39: -3066 | AN39: -3552 | AO39: -7036 | AP39: 1056 | AQ39: 4061 | AR39: 5290 | AS39: 1025 | AT39: 3622 | AU39: -4361 | AV39: 10053 | AW39: 4596 | AX39: 9579 | AY39: 292 | AZ39: 9296 | BA39: 18701 | BB39: 4895 | BC39: 1813 | BD39: -400 | BE39: =BL39-BD39 -> 4982 | BK39: -1198 | BL39: =N39+S39 -> 4582 | BM39: -1575 | BN39: -2060 | BO39: =SUM(AH39:AK39) -> -9879 | BP39: =SUM(AL39:AO39) -> -17561
A40: (Loss)/profit attributable to equity holders of the Company | B40: =IFERROR(B35+B38+B36-B39,"n.a.") -> 0 | C40: =IFERROR(C35+C38+C36-C39,"n.a.") -> 0 | D40: =IFERROR(D35+D38+D36-D39,"n.a.") -> 0 | E40: =IFERROR(E35+E38+E36-E39,"n.a.") -> 0 | F40: =IFERROR(F35+F38+F36-F39,"n.a.") -> -139848 | G40: =IFERROR(G35+G38+G36-G39,"n.a.") -> 288831 | H40: =IFERROR(H35+H38+H36-H39,"n.a.") -> 650717 | I40: =IFERROR(I35+I38+I36-I39,"n.a.") -> -135745 | K40: =IFERROR(K35+K38+K36-K39,"n.a.") -> -916266 | L40: =IFERROR(L35+L38+L36-L39,"n.a.") -> -2102486 | M40: =IFERROR(M35+M38+M36-M39,"n.a.") -> 148983 | N40: =IFERROR(N35+N38+N36-N39,"n.a.") -> 514972 | P40: =IFERROR(P35+P38+P36-P39,"n.a.") -> -335109 | Q40: =IFERROR(Q35+Q38+Q36-Q39,"n.a.") -> -91098 | R40: =IFERROR(R35+R38+R36-R39,"n.a.") -> 491338 | S40: =IFERROR(S35+S38+S36-S39,"n.a.") -> 224744 | U40: =IFERROR(U35+U38+U36-U39,"n.a.") -> 682469 | V40: =IFERROR(V35+V38+V36-V39,"n.a.") -> 907213 | W40: =IFERROR(W35+W38+W36-W39,"n.a.") -> -32684 | X40: =IFERROR(X35+X38+X36-X39,"n.a.") -> 62335 | Y40: =IFERROR(Y35+Y38+Y36-Y39,"n.a.") -> -182163 | Z40: =IFERROR(Z35+Z38+Z36-Z39,"n.a.") -> 97322 | AA40: =IFERROR(AA35+AA38+AA36-AA39,"n.a.") -> 199280 | AB40: =IFERROR(AB35+AB38+AB36-AB39,"n.a.") -> 296766 | ... AY40: =IFERROR(AY35+AY38+AY36-AY39,"n.a.") -> 641813 | AZ40: 975952 | BA40: 84547 | BB40: 779334 | BC40: 631911 | BD40: =IFERROR(BD35+BD38+BD36-BD39,"n.a.") -> 846692 | BE40: =IFERROR(BE35+BE38+BE36-BE39,"n.a.") -> 3343458 | BF40: =IFERROR(BF35+BF38+BF36-BF39,"n.a.") -> 3374309 | BG40: =IFERROR(BG35+BG38+BG36-BG39,"n.a.") -> 0 | BI40: =IFERROR(BI35+BI38+BI36-BI39,"n.a.") -> 739000 | BJ40: =IFERROR(BJ35+BJ38+BJ36-BJ39,"n.a.") -> 2077000 | BK40: =IFERROR(BK35+BK38+BK36-BK39,"n.a.") -> 456156 | BL40: =IFERROR(BL35+BL38+BL36-BL39,"n.a.") -> 529957 | BM40: =IFERROR(BM35+BM38+BM36-BM39,"n.a.") -> 688097 | BN40: =IFERROR(BN35+BN38+BN36-BN39,"n.a.") -> 327593 | BO40: =IFERROR(BO35+BO38+BO36-BO39,"n.a.") -> 723404 | BP40: =IFERROR(BP35+BP38+BP36-BP39,"n.a.") -> -130692
...

Sheet Sheet6
D10: 21Q3 | E10: 22Q3 | F10: YoY
C11: 订单处理成本 | D11: 239662 | E11: 232616 | F11: =E11/D11-1 -> -0.029399738
C12: 雇员福利开支 | D12: 66466 | E12: 83591 | F12: =E12/D12-1 -> 0.25765053
C13: 采购成本 | D13: 38880 | E13: 53060 | F13: =E13/D13-1 -> 0.36471193
C14: 带宽及服务器保管费 | F14: =E14/D14-1 -> #DIV/0! | J14: 21Q2 | K14: 21Q3 | L14: 21Q4 | M14: 22Q1 | N14: 22Q2 | O14: 22Q3
C15: 资产折旧 | F15: =E15/D15-1 -> #DIV/0! | I15: VAS占比酒店收入 | J15: 0.12 | K15: 0.11 | L15: 0.1 | M15: 0.12 | N15: 0.15 | O15: 0.15
C16: 买断成本 | F16: =E16/D16-1 -> #DIV/0!
C17: 其他 | F17: =E17/D17-1 -> #DIV/0!

Sheet Comp
C6: Unit: RMB Mn | E6: 2017 | F6: 2018 | G6: 1Q17 | H6: 2Q17 | I6: 3Q17 | J6: 4Q17 | K6: 1Q18 | L6: 2Q18 | M6: 3Q18 | N6: 4Q18 | O6: 1Q19 | P6: 2Q19 | Q6: 3Q19 | R6: 4Q19
C7: Ctrip domestic air + train
C8: C+Q+Z
D9: GMV | E9: =E21+E33 -> 234949.65 | F9: =F21+F33 -> 302679.11 | G9: =G21+G33 -> 48502.455 | H9: =H21+H33 -> 48416.55 | I9: =I21+I33 -> 65791.709 | J9: =J21+J33 -> 52280.255 | K9: =K21+K33 -> 75115.939 | L9: =L21+L33 -> 68012.504 | ... R9: =R21+R33 -> 78223.633
D10: YoY | F10: =F9/E9-1 -> 0.2882722 | K10: =K9/G9-1 -> 0.54870385 | L10: =L9/H9-1 -> 0.40473668 | M10: =M9/I9-1 -> 0.37176778 | N10: =N9/J9-1 -> 0.33495767 | O10: =O9/K9-1 -> 0.073596012 | P10: =P9/L9-1 -> 0.1125466 | Q10: =Q9/M9-1 -> 0.074652564 | R10: =R9/N9-1 -> 0.12081203
D11: Take rate | E11: =E12/E9 -> 0.034333472 | F11: =F12/F9 -> 0.024466198 | G11: =G12/G9 -> 0.045185704 | H11: =H12/H9 -> 0.039813298 | I11: =I12/I9 -> 0.036944354 | J11: =J12/J9 -> 0.030692693 | K11: =K12/K9 -> 0.0246851 | L11: =L12/L9 -> 0.023895248 | ... R11: =R12/R9 -> 0.023979976
D12: Revenue | E12: =E24+E36 -> 8066.6372 | F12: =F24+F36 -> 7405.407 | G12: =G24+G36 -> 2191.6176 | H12: =H24+H36 -> 1927.6225 | I12: =I24+I36 -> 2430.6322 | J12: =J24+J36 -> 1604.6218 | K12: =K24+K36 -> 1854.2445 | L12: =L24+L36 -> 1625.1757 | ... R12: =R24+R36 -> 1875.8008
D13: YoY | F13: =F12/E12-1 -> -0.081970993 | K13: =K12/G12-1 -> -0.15393795 | L13: =L12/H12-1 -> -0.1569015 | M13: =M12/I12-1 -> -0.11246249 | N13: =N12/J12-1 -> 0.10146401 | O13: =O12/K12-1 -> 0.075462087 | P13: =P12/L12-1 -> 0.081269794 | Q13: =Q12/M12-1 -> -0.011726644 | R13: =R12/N12-1 -> 0.061313546
C15: Air
C16: C+Q domestic
D17: Volume | E17: =SUM(G17:J17) -> 203.07165 | F17: =SUM(K17:N17) -> 242.3365 | G17: ='[1]OP DATA Combined'!L$226 -> 45.102163 | H17: ='[1]OP DATA Combined'!O$226 -> 47.695248 | I17: ='[1]OP DATA Combined'!Q$226 -> 55.730358 | J17: ='[1]OP DATA Combined'!S$226 -> 54.543881 | K17: ='[1]OP DATA Combined'!T$226 -> 59.15375 | L17: ='[1]OP DATA Combined'!U$226 -> 56.384886 | M17: ='[2]OP DATA Combined'!$V$297 -> 64.939151 | N17: ='[1]OP DATA Combined'!W$226 -> 61.85871 | O17: ='[1]OP DATA Combined'!X$226 -> 61.195596 | P17: ='[3]OP DATA Combined'!$Y$292 -> 60.862553 | Q17: ='[2]OP DATA Combined'!$Z$297 -> 70.350445 | R17: 68.84
D18: YoY | F18: =F17/E17-1 -> 0.19335465 | K18: =K17/G17-1 -> 0.31155018 | L18: =L17/H17-1 -> 0.18219085 | M18: =M17/I17-1 -> 0.16523836 | N18: =N17/J17-1 -> 0.13410907 | O18: =O17/K17-1 -> 0.034517609 | P18: =P17/L17-1 -> 0.07941254 | Q18: =Q17/M17-1 -> 0.083328684 | R18: =R17/N17-1 -> 0.11285864
D19: ASP | E19: =E21/E17 -> 818.67878 | F19: =F21/F17 -> 831.43629 | G19: =G21/G17 -> 840.53376 | H19: =H21/H17 -> 800.55276 | I19: =I21/I17 -> 885.85079 | J19: =J21/J17 -> 747.82385 | K19: =K21/K17 -> 849.61964 | L19: =L21/L17 -> 814.86043 | ... Q19: =Q21/Q17 -> 878.48702 | R19: 754
D20: YoY | F20: =F19/E19-1 -> 0.015583049 | K20: =K19/G19-1 -> 0.01080966 | L20: =L19/H19-1 -> 0.017872244 | M20: =M19/I19-1 -> 0.019246359 | N20: =N19/J19-1 -> 0.0084386266 | O20: =O19/K19-1 -> -0.023198278 | P20: =P19/L19-1 -> -0.019437227 | Q20: =Q19/M19-1 -> -0.027038616 | R20: =R19/N19-1 -> -0.00017829388
D21: GMV | E21: =SUM(G21:J21) -> 166250.45 | F21: =SUM(K21:N21) -> 201487.36 | G21: ='[1]OP DATA Combined'!L$243*(1-'[1]OP DATA Combined'!L$356)/1000000 -> 37909.891 | H21: ='[1]OP DATA Combined'!O$243*(1-'[1]OP DATA Combined'!O$356)/1000000 -> 38182.562 | I21: ='[1]OP DATA Combined'!Q$243*(1-'[1]OP DATA Combined'!Q$356)/1000000 -> 49368.782 | J21: ='[1]OP DATA Combined'!S$243*(1-'[1]OP DATA Combined'!S$356)/1000000 -> 40789.215 | K21: ='[1]OP DATA Combined'!T$243*(1-'[1]OP DATA Combined'!T$356)/1000000 -> 50258.188 | L21: ='[1]OP DATA Combined'!U$243*(1-'[1]OP DATA Combined'!U$356)/1000000 -> 45945.813 | M21: ='[2]OP DATA Combined'!$V$314*(1-'[2]OP DATA Combined'!$V$425)/1000000 -> 58633.572 | N21: ='[1]OP DATA Combined'!W$243*(1-'[1]OP DATA Combined'!W$356)/1000000 -> 46649.785 | O21: ='[1]OP DATA Combined'!X$243*(1-'[1]OP DATA Combined'!X$356)/1000000 -> 50786.833 | P21: ='[3]OP DATA Combined'!$Y$309*(1-'[3]OP DATA Combined'!$Y$420)/1000000 -> 48630.507 | Q21: ='[2]OP DATA Combined'!$Z$314*(1-'[2]OP DATA Combined'!$Z$425)/1000000 -> 61801.953 | R21: ='[4]OP DATA Combined'!$AA$315*(1-'[4]OP DATA Combined'!$AA$426)/1000000 -> 51933.486
D22: YoY | F22: =F21/E21-1 -> 0.21195075 | K22: =K21/G21-1 -> 0.32572759 | L22: =L21/H21-1 -> 0.20331926 | M22: =M21/I21-1 -> 0.18766496 | N22: =N21/J21-1 -> 0.14367939 | O22: =O21/K21-1 -> 0.010518582 | P22: =P21/L21-1 -> 0.058431754 | Q22: =Q21/M21-1 -> 0.054036976 | R22: =R21/N21-1 -> 0.11326315
D23: Take rate | E23: =E24/E21 -> 0.037242286 | F23: =F24/F21 -> 0.024091667 | G23: =G24/G21 -> 0.044234106 | H23: =H24/H21 -> 0.040590168 | I23: =I24/I21 -> 0.036180926 | J23: =J24/J21 -> 0.028894693 | K23: =K24/K21 -> 0.022047402 | L23: =L24/L21 -> 0.025033848 | ... R23: =R24/R21 -> 0.023056058
D24: Revenue | E24: =SUM(G24:J24) -> 6191.5468 | F24: =SUM(K24:N24) -> 4854.1663 | G24: ='[1]OP DATA Combined'!L$297/1000000 -> 1676.9101 | H24: ='[1]OP DATA Combined'!O$297/1000000 -> 1549.8366 | I24: ='[1]OP DATA Combined'!Q$297/1000000 -> 1786.2082 | J24: ='[1]OP DATA Combined'!S$297/1000000 -> 1178.5918 | K24: ='[1]OP DATA Combined'!T$297/1000000 -> 1108.0625 | L24: ='[1]OP DATA Combined'!U$297/1000000 -> 1150.2005 | M24: ='[1]OP DATA Combined'!V$297/1000000 -> 1384.6743 | N24: ='[1]OP DATA Combined'!W$297/1000000 -> 1211.229 | O24: ='[1]OP DATA Combined'!X$297/1000000 -> 1118.9678 | P24: ='[3]OP DATA Combined'!$Y$363/1000000 -> 1161.7926 | Q24: ='[2]OP DATA Combined'!$Z$368/1000000 -> 1281.5218 | R24: ='[4]OP DATA Combined'!$AA$369/1000000 -> 1197.3814
D25: YoY | F25: =F24/E24-1 -> -0.21600103 | K25: =K24/G24-1 -> -0.33922369 | L25: =L24/H24-1 -> -0.25785693 | M25: =M24/I24-1 -> -0.22479682 | N25: =N24/J24-1 -> 0.027691675 | O25: =O24/K24-1 -> 0.0098418062 | P25: =P24/L24-1 -> 0.01007829 | Q25: =Q24/M24-1 -> -0.074495872 | R25: =R24/N24-1 -> -0.011432661
C27: Train
C28: CZQ domestic
D29: Volume | E29: 500.38848 | F29: 683.62621 | G29: ='[5]OP DATA Combined'!$L$398 -> 113.3814 | H29: ='[1]OP DATA Combined'!O$398-'[1]OP DATA Combined'!O$399 -> 115.92271 | I29: ='[1]OP DATA Combined'!Q$398-'[1]OP DATA Combined'!Q$399 -> 148.58671 | J29: ='[1]OP DATA Combined'!S$398-'[1]OP DATA Combined'!S$399 -> 121.25867 | K29: ='[1]OP DATA Combined'!T$398-'[1]OP DATA Combined'!T$399 -> 160.6952 | L29: ='[3]OP DATA Combined'!$U$465-'[3]OP DATA Combined'!$U$466 -> 155.4413 | M29: ='[2]OP DATA Combined'!$V$470-'[2]OP DATA Combined'!$V$471 -> 203.08102 | N29: ='[4]OP DATA Combined'!$W$471-'[4]OP DATA Combined'!$W$472 -> 163.00811 | O29: ='[1]OP DATA Combined'!X$398-'[1]OP DATA Combined'!X$399 -> 198.25417 | P29: ='[3]OP DATA Combined'!$Y$465-'[3]OP DATA Combined'!$Y$466 -> 191.16848 | Q29: ='[2]OP DATA Combined'!$Z$470-'[2]OP DATA Combined'!$Z$471 -> 235.41808 | R29: ='[4]OP DATA Combined'!$AA$471-'[4]OP DATA Combined'!$AA$472 -> 180.38649
D30: YoY | F30: =F29/E29-1 -> 0.36619092 | K30: =K29/G29-1 -> 0.41729774 | L30: =L29/H29-1 -> 0.34090459 | M30: =M29/I29-1 -> 0.36675098 | N30: =N29/J29-1 -> 0.34430066 | O30: =O29/K29-1 -> 0.23372803 | P30: =P29/L29-1 -> 0.22984358 | Q30: =Q29/M29-1 -> 0.1592323 | R30: =R29/N29-1 -> 0.10661055
D31: ASP | E31: =E33/E29 -> 137.29173 | F31: =F33/F29 -> 148.02205 | G31: =G33/G29 -> 93.424184 | H31: =H33/H29 -> 88.282854 | I31: =I33/I29 -> 110.52757 | J31: =J33/J29 -> 94.764692 | K31: =K33/K29 -> 154.68882 | L31: =L33/L29 -> 141.96157 | ... R31: =R33/R29 -> 145.74343
D32: YoY | F32: =F31/E31-1 -> 0.078157014 | K32: =K31/G31-1 -> 0.65576851 | L32: =L31/H31-1 -> 0.6080311 | M32: =M31/I31-1 -> 0.40859401 | N32: =N31/J31-1 -> 0.49812418 | O32: =O31/K31-1 -> -0.026424035 | P32: =P31/L31-1 -> -0.0037586868 | Q32: =Q31/M31-1 -> -0.039982225 | R32: =R31/N31-1 -> 0.026584311
D33: GMV | E33: 68699.202 | F33: 101191.75 | G33: ='[1]OP DATA Combined'!L$413/1000000 -> 10592.565 | H33: ='[1]OP DATA Combined'!O$413/1000000 -> 10233.988 | I33: ='[1]OP DATA Combined'!Q$413/1000000 -> 16422.928 | J33: ='[1]OP DATA Combined'!S$413/1000000 -> 11491.04 | K33: ='[1]OP DATA Combined'!T$413/1000000 -> 24857.751 | L33: ='[3]OP DATA Combined'!$U$480/1000000 -> 22066.691 | M33: ='[2]OP DATA Combined'!$V$485/1000000 -> 31617.375 | N33: ='[4]OP DATA Combined'!$W$486/1000000 -> 23142.143 | O33: ='[1]OP DATA Combined'!X$413/1000000 -> 29857.34 | P33: ='[3]OP DATA Combined'!$Y$480/1000000 -> 27036.573 | Q33: ='[2]OP DATA Combined'!$Z$485/1000000 -> 35186.458 | R33: ='[4]OP DATA Combined'!$AA$486/1000000 -> 26290.146
D34: YoY | F34: =F33/E33-1 -> 0.47296833 | K34: =K33/G33-1 -> 1.346717 | L34: =L33/H33-1 -> 1.1562163 | M34: =M33/I33-1 -> 0.92519723 | N34: =N33/J33-1 -> 1.0139293 | O34: =O33/K33-1 -> 0.20112796 | P34: =P33/L33-1 -> 0.22522098 | Q34: =Q33/M33-1 -> 0.11288362 | R34: =R33/N33-1 -> 0.13602903
D35: Take rate | E35: =E36/E33 -> 0.02729421 | F35: =F36/F33 -> 0.025211944 | G35: =G36/G33 -> 0.048591395 | H35: =H36/H33 -> 0.03691483 | I35: =I36/I33 -> 0.039239286 | J35: =J36/J33 -> 0.037074972 | K35: =K36/K33 -> 0.030018082 | L35: =L36/L33 -> 0.02152453 | ... R35: =R36/R33 -> 0.025805081
D36: Revenue | E36: 1875.0904 | F36: 2551.2407 | G36: ='[1]OP DATA Combined'!L$427/1000000 -> 514.70749 | H36: ='[1]OP DATA Combined'!O$427/1000000 -> 377.78592 | I36: ='[1]OP DATA Combined'!Q$427/1000000 -> 644.42395 | J36: ='[1]OP DATA Combined'!S$427/1000000 -> 426.03 | K36: =('[5]OP DATA Combined'!$T$415+'[5]OP DATA Combined'!$T$419+'[5]OP DATA Combined'!$T$424)/1000000 -> 746.18201 | L36: =('[3]OP DATA Combined'!$U$482+'[3]OP DATA Combined'!$U$487+'[3]OP DATA Combined'!$U$492)/1000000 -> 474.97516 | M36: ='[2]OP DATA Combined'!$V$502/1000000 -> 772.60292 | N36: ='[4]OP DATA Combined'!$W$503/1000000 -> 556.20418 | O36: =('[5]OP DATA Combined'!$X$415+'[5]OP DATA Combined'!$X$419+'[5]OP DATA Combined'!$X$424)/1000000 -> 875.20183 | P36: =('[3]OP DATA Combined'!$Y$482+'[3]OP DATA Combined'!$Y$487+'[3]OP DATA Combined'!$Y$492)/1000000 -> 595.4608 | Q36: ='[2]OP DATA Combined'!$Z$502/1000000 -> 850.45782 | R36: ='[4]OP DATA Combined'!$AA$503/1000000 -> 678.41935
D37: YoY | F37: =F36/E36-1 -> 0.36059607 | K37: =K36/G36-1 -> 0.44972051 | L37: =L36/H36-1 -> 0.25726008 | M37: =M36/I36-1 -> 0.19890474 | N37: =N36/J36-1 -> 0.30555167 | O37: =O36/K36-1 -> 0.17290664 | P37: =P36/L36-1 -> 0.25366724 | Q37: =Q36/M36-1 -> 0.10076961 | R37: =R36/N36-1 -> 0.21973076
C39: TCEL transportation
C40: TCEL
D41: GMV | E41: =Tongchengelong!BK5/1000 -> 80013.4 | F41: =E41*(1+F42) -> 110818.56 | K41: =K44/K43 -> 23543.846 | L41: =L53+L65 -> 24517.943 | M41: =M44/M43 -> 31170.833 | N41: =N44/N43 -> 29797.639 | O41: 30607 | P41: 34865 | Q41: 39390 | R41: =Tongchengelong!AC5/1000 -> 34410
D42: YoY | F42: 0.385 | O42: =O41/K41-1 -> 0.3 | P42: =P41/L41-1 -> 0.42201978 | Q42: =Q41/M41-1 -> 0.26368133 | R42: =R41/N41-1 -> 0.15478948
D43: Take rate | E43: =E44/E41 -> 0.031619704 | F43: =F44/F41 -> 0.029169491 | K43: =O43 -> 0.041132682 | L43: =L44/L41 -> 0.033831835 | M43: 0.036 | N43: 0.036 | O43: =O44/O41 -> 0.041132682 | P43: =P44/P41 -> 0.026877728 | Q43: =Q44/Q41 -> 0.028931734 | R43: =R44/R41 -> 0.034350392
D44: Revenue | E44: =Tongchengelong!BK15/1000 -> 2530 | F44: =Tongchengelong!BL15/1000 -> 3232.521 | K44: =O44/(1+O45) -> 968.42154 | L44: =Tongchengelong!W15/1000 -> 829.487 | M44: =Tongchengelong!X15/1000 -> 1122.15 | N44: =Tongchengelong!Y15/1000 -> 1072.715 | O44: =Tongchengelong!Z15/1000 -> 1258.948 | P44: =Tongchengelong!AA15/1000 -> 937.092 | Q44: =Tongchengelong!AB15/1000 -> 1139.621 | R44: =Tongchengelong!AC15/1000 -> 1181.997
D45: YoY | F45: =F44/E44-1 -> 0.27767628 | O45: =Tongchengelong!Z87 -> 0.3 | P45: =P44/L44-1 -> 0.12972476 | Q45: =Q44/M44-1 -> 0.01556922 | R45: =R44/N44-1 -> 0.10187422
C47: Air
C48: TCEL
D49: Volume | E49: 48.5 | F49: =F53/F51 -> 66.986026 | K49: =K53/K51 -> 13.926871 | L49: =(AVERAGE(K77,F77)+0.025)*L17 -> 15.839996 | M49: =(AVERAGE(L77,F77)+0.01)*M17 -> 18.746104 | N49: =(AVERAGE(M77,G77)+0.01)*N17 -> 18.475455 | O49: =O53/O51 -> 16.68142 | P49: =L49*(1+P50) -> 20.433595 | Q49: =M49*(1+Q50) -> 22.682786 | R49: 17
...

Sheet TCEL charts

Sheet 交通业务拆分
C1: Unit: RMB Mn | E1: 1Q19 | F1: 2Q19 | G1: 3Q19 | H1: 4Q19 | I1: 20Q1 | J1: 20Q2 | K1: 20Q3 | L1: 20Q4 | M1: 21Q1 | N1: 21Q2 | O1: 21Q3 | P1: 21Q4 | Q1: 22Q1 | R1: 22Q2 | S1: 22Q3 | T1: 22Q4 | U1: 23Q1 | V1: 23Q2 | W1: 23Q3 | X1: 23Q4 | Y1: 24Q1 | Z1: 24Q2 | AA1: 24Q3 | AB1: 24Q4 | AC1: 25Q1 | AD1: 25Q2 | AE1: 25Q3 | AF1: 25Q4 | AG1: 26Q1 | AI1: 2019 | AJ1: 2020 | AK1: 2021 | AL1: 2022 | AM1: 2023 | AN1: 2024
C2: Check | E2: =E102+E25 -> 1161.5514 | F2: =F102+F25 -> 854.44391 | G2: =G102+G25 -> 1035.7697 | H2: =H102+H25 -> 1096.8187 | I2: =I102+I25 -> 635.53121 | J2: =J102+J25 -> 668.19574 | K2: =K102+K25 -> 930.36048 | L2: =L102+L25 -> 914.99246 | ... AG2: =AG102+AG25 -> 1647.0706 | AI2: =AI102+AI37 -> 3858.2408 | AJ2: =AJ102+AJ37 -> 3149.0799 | AK2: =AK102+AK37 -> 3998.0976 | AL2: =AL102+AL37 -> 2875.672
C3: 汽车票收入（含小交通） | E3: =E14-E2 -> 97.396583 | F3: =F14-F2 -> 82.64809 | G3: =G14-G2 -> 103.85134 | H3: =H14-H2 -> 85.17825 | I3: =I14-I2 -> 51.236791 | J3: =J14-J2 -> 57.626264 | K3: =K14-K2 -> 124.75752 | L3: =L14-L2 -> 88.428541 | ... S3: =S14-S2 -> 73.890877 | T3: =T14-T2-5%*T14 -> 121.62567 | U3: =U14-U2 -> 145.94648 | V3: =V14-V2 -> 173.56896 | W3: =W14-W2 -> 171.48808 | X3: =X14-X2 -> 238.31436 | Y3: =Y14-Y2 -> 190.73712 | Z3: =Z14-Z2 -> 263.41004 | AA3: =AA14-AA2 -> 208.61614 | AB3: =AB14-AB2 -> 295.39188 | ... AG3: =AG14-AG2 -> 476.94741 | AI3: =AI14-AI2 -> 659.41716
C4: 汽车票收入占比 | E4: =E3/E14 -> 0.077363468 | F4: =F3/F14 -> 0.088196346 | G4: =G3/G14 -> 0.091127959 | H4: =H3/H14 -> 0.072063 | I4: =I3/I14 -> 0.074605677 | J4: =J3/J14 -> 0.079394485 | K4: =K3/K14 -> 0.11824035 | L4: =L3/L14 -> 0.088127058 | ... AG4: =AG3/AG14 -> 0.22454961
C5: 汽车票GMV | E5: =E6*E11 -> 0 | F5: =F6*F11 -> 337.65813 | G5: =G6*G11 -> 381.21813 | H5: =H6*H11 -> 344.1 | I5: =I6*I11 -> 147.21594 | J5: =J6*J11 -> 348.47235 | K5: =K6*K11 -> 304.03937 | L5: =L6*L11 -> 546.59048 | ... AG5: =AG6*AG11 -> 2407.294
C6: 汽车票GMV 占比 | E6: =E96 -> 0 | F6: =F96 -> 0.01 | G6: =G96 -> 0.01 | H6: =H96 -> 0.01 | I6: =I96 -> 0.01 | J6: =J96 -> 0.02 | K6: =K96 -> 0.01 | L6: =L96 -> 0.02 | ... AG6: =AG96 -> 0.05
M7: =M3/M5 -> 0.038018232 | N7: =N3/N5 -> 0.043715596 | O7: =O3/O5 -> 0.039924526 | P7: =P3/P5 -> 0.060514178 | Q7: =Q3/Q5 -> 0.056286962 | R7: =R3/R5 -> 0.046429708 | S7: =S3/S5 -> 0.027141967 | T7: =T3/T5 -> 0.054910362 | ... AG7: =AG3/AG5 -> 0.19812595
C8: 同程交通业务 | E8: 1Q19 | F8: 2Q19 | G8: 3Q19 | H8: 4Q19 | I8: 20Q1 | J8: 20Q2 | K8: 20Q3 | L8: 20Q4 | M8: 21Q1 | N8: 21Q2 | O8: 21Q3 | P8: 21Q4 | Q8: 22Q1 | R8: 22Q2 | S8: 22Q3 | T8: 22Q4 | U8: 23Q1 | V8: 23Q2 | W8: 23Q3 | X8: 23Q4 | Y8: 24Q1 | Z8: 24Q2 | AA8: 24Q3 | AB8: 24Q4 | AC8: 25Q1 | AD8: 25Q2 | AE8: 25Q3 | AF8: 25Q4 | AG8: 26Q1 | AI8: 2019 | AJ8: 2020 | AK8: 2021 | AL8: 2022 | AM8: 2023 | AN8: 2024 | AO8: 2025
C9: TCEL (from financials and trans GMV est.)
E10: 30575.377 | F10: 35201.647 | G10: 37987.367 | H10: 34072.5 | I10: 15971.349
D11: GMV (mm) | E11: =Tongchengelong!Z5/1000 -> 30154.502 | F11: =Tongchengelong!AA5/1000 -> 33765.813 | G11: =Tongchengelong!AB5/1000 -> 38121.813 | H11: =Tongchengelong!AC5/1000 -> 34410 | I11: =Tongchengelong!AD5/1000 -> 14721.594 | J11: =Tongchengelong!AE5/1000 -> 17423.618 | K11: =Tongchengelong!AF5/1000 -> 30403.937 | L11: =Tongchengelong!AG5/1000 -> 27329.524 | ... AG11: =Tongchengelong!BB5/1000 -> 48145.881 | AH11: 估算 | AI11: =SUM(E11:H11) -> 136452.13 | AJ11: =SUM(I11:L11) -> 89878.673 | AK11: =SUM(M11:P11) -> 116304.58 | AL11: =SUM(Q11:T11) -> 91811.953 | AM11: =SUM(U11:X11) -> 176895.05 | AN11: =SUM(Y11:AB11) -> 185326.8
A12: 1000 | D12: YoY | J12: =J11/F11-1 -> -0.48398644 | K12: =K11/G11-1 -> -0.20245301 | L12: =L11/H11-1 -> -0.20576798 | M12: =M11/E11-1 -> -0.11894796 | N12: =N11/F11-1 -> -0.0013435286 | O12: =O11/G11-1 -> -0.16688078 | P12: =P11/H11-1 -> -0.29507601 | Q12: =Q11/E11-1 -> -0.16437846 | R12: =R11/F11-1 -> -0.46966278 | S12: =S11/G11-1 -> -0.20652463 | T12: =T11/H11-1 -> -0.46357995 | U12: =U11/E11-1 -> 0.43004512 | V12: =V11/F11-1 -> 0.2731141 | W12: =W11/G11-1 -> 0.36117886 | X12: =X11/H11-1 -> 0.13032293 | Y12: =Y11/U11-1 -> 0.14615876 | Z12: =Z11/V11-1 -> 0.031866455 | AA12: =AA11/W11-1 -> 0.015736832 | AB12: =AB11/X11-1 -> -0.0014760989 | AC12: =AC11/Y11-1 -> -0.046133333 | AD12: =AD11/Z11-1 -> -0.0070224719 | AE12: =AE11/AA11-1 -> -0.028314917 | AF12: =AF11/AB11-1 -> 0.00084507042 | AG12: =AG11/AC11-1 -> 0.021232877 | AH12: From Analyst: 交通LSD | AN12: =AN11/AM11-1 -> 0.047665268
D13: Take rate | E13: =E14/E11 -> 0.041749918 | F13: =F14/F11 -> 0.027752685 | G13: =G14/G11 -> 0.029894197 | H13: =H14/H11 -> 0.034350392 | I13: =I14/I11 -> 0.046650383 | J13: =J14/J11 -> 0.041657365 | K13: =K14/K11 -> 0.034703334 | L13: 0.035 | M13: =M14/M11 -> 0.038521459 | N13: =N14/N11 -> 0.036617248 | O13: =O14/O11 -> 0.035413207 | P13: =P14/P11 -> 0.044311418 | Q13: =Q14/Q11 -> 0.040369435 | R13: =R14/R11 -> 0.034596065 | S13: =S14/S11 -> 0.032617777 | T13: =T14/T11 -> 0.040932888 | ... AG13: =AG14/AG11 -> 0.044116297 | AI13: =AI14/AI11 -> 0.033108007 | AJ13: =AJ14/AJ11 -> 0.038620163 | AK13: =AK14/AK11 -> 0.038328128 | AL13: =AL14/AL11 -> 0.036802768 | AM13: =AM14/AM11 -> 0.034088274 | AN13: =AN14/AN11 -> 0.039006938
D14: Revenue (mm) | E14: =Tongchengelong!Z15/1000 -> 1258.948 | F14: =Tongchengelong!AA15/1000 -> 937.092 | G14: =Tongchengelong!AB15/1000 -> 1139.621 | H14: =Tongchengelong!AC15/1000 -> 1181.997 | I14: =Tongchengelong!AD15/1000 -> 686.768 | J14: =Tongchengelong!AE15/1000 -> 725.822 | K14: =Tongchengelong!AF15/1000 -> 1055.118 | L14: =Tongchengelong!AG15/1000 -> 1003.421 | ... AB14: =Tongchengelong!AW15/1000 -> 1723.04 | AC14: 2000.211 | AD14: =Tongchengelong!AY15/1000 -> 1881.01 | AE14: =Tongchengelong!AZ15/1000 -> 2208.716 | AF14: =Tongchengelong!BA15/1000 -> 1835.511 | AG14: =Tongchengelong!BB15/1000 -> 2124.018 | AH14: 公司公布 | AI14: =+SUM(E14:H14) -> 4517.658 | AJ14: =SUM(I14:L14) -> 3471.129 | AK14: =SUM(M14:P14) -> 4457.737 | AL14: =SUM(Q14:T14) -> 3378.934 | AM14: =SUM(U14:X14) -> 6030.047 | AN14: =SUM(Y14:AB14) -> 7229.031
D15: Air+ Ground | F15: =F25+F102 -> 854.44391 | G15: =G25+G102 -> 1035.7697 | H15: =H25+H102 -> 1096.8187 | I15: =I25+I102 -> 635.53121 | J15: =J25+J102 -> 668.19574 | K15: =K25+K102 -> 930.36048 | L15: =L25+L102 -> 914.99246 | M15: =M25+M102 -> 942.62149 | ... AG15: =AG25+AG102 -> 1647.0706
C16: Air | E16: 1Q19 | F16: 2Q19 | G16: 3Q19 | H16: 4Q19 | I16: 20Q1 | J16: 20Q2 | K16: 20Q3 | L16: 20Q4 | M16: 21Q1 | N16: 21Q2 | O16: 21Q3 | P16: 21Q4 | Q16: 22Q1 | R16: 22Q2 | S16: 22Q3 | T16: 22Q4 | U16: 23Q1 | V16: 23Q2 | W16: 23Q3 | X16: 23Q4 | Y16: 24Q1 | Z16: 24Q2 | AA16: 24Q3 | AB16: 24Q4 | AC16: 25Q1 | AD16: 25Q2 | AE16: 25Q3 | AF16: 25Q4 | AG16: 26Q1 | AI16: 2019 | AJ16: 2020 | AK16: 2021 | AL16: 2022 | AM16: 2023 | AN16: 2024
C17: TCEL-机票整体
D18: GMV (mm) - net | E18: =E11*E20 -> 12966.436 | F18: =F11*F20 -> 15194.616 | G18: =G11*G20 -> 17345.425 | H18: =H11*H20 -> 16344.75 | I18: =I11*I20 -> 6771.9332 | J18: =J11*J20 -> 7840.6279 | K18: =K11*K20 -> 13681.772 | L18: =L11*L20 -> 12571.581 | ... AG18: =AG11*AG20 -> 27443.152 | AI18: =SUM(E18:H18) -> 61851.227 | AJ18: =SUM(I18:L18) -> 40865.914 | AK18: =SUM(M18:P18) -> 54686.267 | AL18: =SUM(Q18:T18) -> 43173.654 | AM18: =SUM(U18:X18) -> 83912.745 | AN18: =SUM(Y18:AB18) -> 90457.127
D19: YoY | I19: =+I18/E18-1 -> -0.47773364 | J19: =+J18/F18-1 -> -0.48398644 | K19: =+K18/G18-1 -> -0.21121727 | L19: =+L18/H18-1 -> -0.23084899 | M19: =M18/E18-1 -> -0.016500044 | N19: =N18/F18-1 -> 0.043041203 | O19: =O18/G18-1 -> -0.13941532 | P19: =P18/H18-1 -> -0.31733677 | Q19: =Q18/E18-1 -> -0.086646222 | R19: =R18/F18-1 -> -0.44609223 | S19: =S18/G18-1 -> -0.17164659 | T19: =T18/H18-1 -> -0.47713162 | U19: =U18/E18-1 -> 0.59632944 | V19: =V18/F18-1 -> 0.3862798 | W19: =W18/G18-1 -> 0.37613687 | X19: =X18/H18-1 -> 0.11842479 | Y19: =Y18/U18-1 -> 0.1342196 | Z19: =Z18/V18-1 -> 0.031866455 | AA19: =AA18/W18-1 -> 0.081980538 | AB19: =AB18/X18-1 -> 0.062259469 | AC19: =AC18/Y18-1 -> -0.036092632 | AD19: =AD18/Z18-1 -> 0.074036918 | AE19: =AE18/AA18-1 -> -0.0084846093 | AF19: =AF18/AB18-1 -> 0.052889014 | AG19: =AG18/AC18-1 -> 0.21271404
D20: % of Trans GMV | E20: 0.43 | F20: 0.45 | G20: 0.455 | H20: 0.475 | I20: 0.46 | J20: 0.45 | K20: 0.45 | L20: 0.46 | M20: 0.48 | N20: 0.47 | O20: 0.47 | P20: 0.46 | Q20: 0.47 | R20: 0.47 | S20: 0.475 | T20: 0.463 | U20: 0.48 | V20: 0.49 | W20: 0.46 | X20: 0.47 | Y20: 0.475 | Z20: 0.49 | AA20: 0.49 | AB20: 0.5 | AC20: 0.48 | AD20: 0.53 | AE20: 0.5 | AF20: 0.526 | AG20: 0.57 | AH20: 估算 | AI20: =AI18/AI11 -> 0.45328151 | AJ20: =AJ18/AJ11 -> 0.45467865 | AK20: =AK18/AK11 -> 0.47019872 | AL20: =AL18/AL11 -> 0.47024001 | AM20: =AM18/AM11 -> 0.47436457 | AN20: =AN18/AN11 -> 0.48809523
D21: Volume (mm) | E21: =E18/E23 -> 18.134875 | F21: =F18/F23 -> 22.021183 | G21: =G18/G23 -> 23.127233 | H21: =H18/H23 -> 24.036397 | I21: =I18/I23 -> 9.9587253 | J21: =J18/J23 -> 12.646174 | K21: =K18/K23 -> 26.3111 | L21: =L18/L23 -> 21.67514 | ... P21: =P18/P23 -> 18.5966 | Q21: =M21*(1-14%) -> 18.278568 | R21: =N21*(1-55%) -> 11.886458 | S21: =O21*(1+-16%) -> 19.027092 | T21: =P21*(1-35%) -> 12.08779 | U21: =E21*(1+U22) -> 24.482082 | V21: =F21*(1+V22) -> 30.389232 | W21: =G21*(1+W22) -> 30.527948 | X21: =H21*(1+X22) -> 28.122585 | Y21: =U21*(1+Y22) -> 33.540452 | Z21: =V21*(1+Z22) -> 35.251509 | AA21: =W21*(1+AA22) -> 37.091457 | AB21: =AB32+AB45 -> 30.895471 | AC21: =AC32+AC45 -> 35.626668 | AD21: =AD32+AD45 -> 36.818086 | AE21: =AE32+AE45 -> 38.210098 | AF21: =AF32+AF45 -> 31.590859 | AG21: =AG32+AG45 -> 36.451347 | AH21: 用增速倒算 | AI21: =SUM(E21:H21) -> 87.319688 | AJ21: =SUM(I21:L21) -> 70.591138 | AK21: =SUM(M21:P21) -> 88.9164 | AL21: =SUM(Q21:T21) -> 61.279908 | AM21: =SUM(U21:X21) -> 113.52185 | AN21: =SUM(Y21:AB21) -> 136.77889
D22: YoY | I22: =I21/E21-1 -> -0.45085229 | J22: =J21/F21-1 -> -0.42572684 | K22: =K21/G21-1 -> 0.1376674 | L22: =L21/H21-1 -> -0.098236746 | M22: =M21/E21-1 -> 0.17200411 | N22: =N21/F21-1 -> 0.19949738 | O22: =O21/G21-1 -> -0.020578888 | P22: =P21/H21-1 -> -0.22631501 | Q22: =Q21/E21-1 -> 0.0079235386 | R22: =R21/F21-1 -> -0.46022618 | S22: =S21/G21-1 -> -0.17728627 | T22: =T21/H21-1 -> -0.49710475 | U22: 0.35 | V22: 0.38 | W22: 0.32 | X22: 0.17 | Y22: 0.37 | Z22: 0.16 | AA22: 0.215 | AB22: =AB21/X21-1 -> 0.0986 | AC22: =AC21/Y21-1 -> 0.0622 | AD22: =AD21/Z21-1 -> 0.04444 | AE22: =AE21/AA21-1 -> 0.030159 | AF22: =AF21/AB21-1 -> 0.022507737 | AG22: =AG21/AC21-1 -> 0.023147806 | AN22: =AN21/AM21-1 -> 0.20486844
D23: ASP | E23: 715 | F23: 690 | G23: 750 | H23: 680 | I23: 680 | J23: 620 | K23: 520 | L23: 580 | M23: 600 | N23: 600 | O23: 659 | P23: 600 | Q23: 706 | R23: =R18/R21 -> 708.06761 | S23: =S18/S21 -> 755.14123 | T23: =T18/T21 -> 707.00708 | U23: =U18/U21 -> 845.46337 | V23: =V18/V21 -> 693.1399 | W23: =W18/W21 -> 781.89595 | X23: =X18/X21 -> 650.02467 | Y23: =Y18/Y21 -> 699.95703 | ... AG23: =AG18/AG21 -> 752.87072
D24: Take rate | E24: 0.04 | F24: 0.035 | G24: 0.032 | H24: 0.0348 | I24: 0.042 | J24: 0.044 | K24: 0.038 | L24: 0.04 | M24: 0.04 | N24: 0.036 | O24: 0.034 | P24: 0.043 | Q24: 0.0375 | R24: 0.0336 | S24: 0.034 | T24: 0.038 | U24: 0.0305 | V24: 0.0345 | W24: 0.032 | X24: 0.036 | Y24: 0.033 | Z24: 0.035 | AA24: 0.0355 | AB24: 0.038 | AC24: 0.038 | AD24: 0.038 | AE24: 0.038 | AF24: 0.041 | AG24: 0.033
D25: Revenue (mm) | E25: =E18*E24 -> 518.65743 | F25: =F18*F24 -> 531.81156 | G25: =G18*G24 -> 555.0536 | H25: =H18*H24 -> 568.7973 | I25: =I18*I24 -> 284.42119 | J25: =J18*J24 -> 344.98763 | K25: =K18*K24 -> 519.90733 | L25: =L24*L18 -> 502.86324 | M25: =M18*M24 -> 510.09956 | N25: =N18*N24 -> 570.54998 | O25: =O18*O24 -> 507.52504 | P25: =P18*P24 -> 479.79227 | Q25: =Q18*Q24 -> 444.11037 | R25: =R18*R24 -> 282.79157 | S25: =S18*S24 -> 488.51683 | T25: =T18*T24 -> 324.75382 | ... AG25: =AG18*AG24 -> 905.62402 | AI25: =SUM(E25:H25) -> 2174.3199 | AJ25: =SUM(I25:L25) -> 1652.1794 | AK25: =SUM(M25:P25) -> 2067.9669 | AL25: =SUM(Q25:T25) -> 1540.1726 | AM25: =SUM(U25:X25) -> 2779.9413 | AN25: =SUM(Y25:AB25) -> 3190.2145
D26: YoY | I26: =+I25/E25-1 -> -0.45162033 | J26: =+J25/F25-1 -> -0.35129724 | K26: =+K25/G25-1 -> -0.063320504 | L26: =L25/H25-1 -> -0.11591838 | M26: =M25/E25-1 -> -0.016500044 | N26: =N25/F25-1 -> 0.072842381 | O26: =O25/G25-1 -> -0.085628773 | P26: =P25/H25-1 -> -0.15647934 | Q26: =Q25/E25-1 -> -0.14373083 | R26: =R25/F25-1 -> -0.46824854 | S26: =S25/G25-1 -> -0.1198745 | T26: =T25/H25-1 -> -0.42905176 | U26: =U25/E25-1 -> 0.2172012 | V26: =V25/F25-1 -> 0.3664758 | W26: =W25/G25-1 -> 0.37613687 | X26: =X25/H25-1 -> 0.15699117 | Y26: =Y25/U25-1 -> 0.22718842 | Z26: =Z25/V25-1 -> 0.046821042 | AA26: =AA25/W25-1 -> 0.20032216 | AB26: =AB25/X25-1 -> 0.12127388 | AC26: =AC25/Y25-1 -> 0.10995394 | AD26: =AD25/Z25-1 -> 0.16609723 | AE26: =AE25/AA25-1 -> 0.061340418 | AF26: =AF25/AB25-1 -> 0.13601183 | AG26: =AG25/AC25-1 -> 0.053146404
D27: 单票收入 | E27: =E25/E21 -> 28.6 | F27: =F25/F21 -> 24.15 | G27: =G25/G21 -> 24 | H27: =H25/H21 -> 23.664 | I27: =I25/I21 -> 28.56 | J27: =J25/J21 -> 27.28 | K27: =K25/K21 -> 19.76 | L27: =L25/L21 -> 23.2 | ... AG27: =AG25/AG21 -> 24.844734 | AI27: =AI25/AI21 -> 24.900683 | AJ27: =AJ25/AJ21 -> 23.404912 | AK27: =AK25/AK21 -> 23.257429 | AL27: =AL25/AL21 -> 25.133402 | AM27: =AM25/AM21 -> 24.488161 | AN27: =AN25/AN21 -> 23.32388
C28: TCEL-国内
D29: GMV (mm) - net | E29: =E18-E42 -> 11604.96 | F29: =F18-F42 -> 13568.792 | G29: =G18-G42 -> 15437.428 | H29: =H18-H42 -> 14465.104 | I29: =I18-I42 -> 6771.9332 | J29: =J18-J42 -> 7840.6279 | K29: =K18-K42 -> 13681.772 | L29: =L18-L42 -> 12571.581 | ... AG29: =AG18-AG42 -> 22091.737 | AI29: =SUM(E29:H29) -> 55076.284 | AJ29: =SUM(I29:L29) -> 40865.914 | AK29: =SUM(M29:P29) -> 54686.267 | AL29: =SUM(Q29:T29) -> 43173.654 | AM29: =SUM(U29:X29) -> 74243.927 | AN29: =SUM(Y29:AB29) -> 74699.754 | BC29: =U11 -> 43122.298
D30: % of Total Air | U30: =1-U43 -> 0.915 | V30: =1-V43 -> 0.885 | W30: =1-W43 -> 0.885 | X30: =1-X43 -> 0.85 | Y30: =1-Y43 -> 0.835 | Z30: =1-Z43 -> 0.825 | AA30: =1-AA43 -> 0.83 | AB30: =1-AB43 -> 0.81 | ... AG30: =1-AG43 -> 0.805
D31: YoY | I31: =I29/E29-1 -> -0.41646217 | J31: =J29/F29-1 -> -0.42215727 | K31: =K29/G29-1 -> -0.11372727 | L31: =L29/H29-1 -> -0.13090281 | M31: =M29/E29-1 -> 0.098882633 | N31: =N29/F29-1 -> 0.16801926 | O31: =O29/G29-1 -> -0.033050917 | P31: =P29/H29-1 -> -0.22862912 | Q31: =Q29/E29-1 -> 0.020507015 | R31: =R29/F29-1 -> -0.37972254 | S31: =S29/G29-1 -> -0.069265831 | T31: =T29/H29-1 -> -0.40918827 | U31: =U29/E29-1 -> 0.6320016 | V31: =V29/F29-1 -> 0.37386072 | W31: =W29/G29-1 -> 0.36840577 | X31: =X29/H29-1 -> 0.074193304 | Y31: =Y29/U29-1 -> 0.035052863 | Z31: =Z29/V29-1 -> -0.038090593 | AA31: =AA29/W29-1 -> 0.01473881 | AB31: =AB29/X29-1 -> 0.012270788 | AC31: =AC29/Y29-1 -> -0.076495934 | AD31: =AD29/Z29-1 -> 0.028471716 | AE31: =AE29/AA29-1 -> -0.062241468 | AF31: =AF29/AB29-1 -> 0.013893125 | AG31: =AG29/AC29-1 -> 0.2202935 | AJ31: =AJ29/AI29-1 -> -0.25801251 | AK31: =AK29/AI29-1 -> -0.0070814071 | AL31: =AL29/AI29-1 -> -0.21611171 | AM31: =AM29/AI29-1 -> 0.3480199 | AN31: =AN29/AM29-1 -> 0.006139576 | BC31: =U14 -> 1382.694
