Workbook

Sheet Sheet1
A1: 编号 | B1: 数据来源 | C1: 频率 | D1: Link | E1: 数据类型
A2: 1 | B2: 民航局 | C2: 每月 | D2: http://www.caac.gov.cn/XWZX/XWFBH/ | E2: 旅客运输量 | F2: CAAC Data | G2: 信息公开-统计数据 每月20号之后
A3: 2 | B3: 四大行 | C3: 每月 | D3: http://www.cninfo.com.cn/new/index | E3: 载运客人次 | F3: Top4 3 tabs
A4: 3 | B4: 出入境管理局 | C4: 每季度 | D4: https://www.nia.gov.cn/n741440/n741567/index.html | E4: 大陆居民出入境 空港出入境
A10: 每月16号左右更新
A11: 600029 | B11: 南方航空 | C11: CSA
A12: 600115 | B12: 中国东航 | C12: CEA
A13: 601111 | B13: 中国国航 | C13: AC

Sheet Summary
AZ2: vs. 2019 | BQ2: 2023 vs. 2019 | DD2: 2026
A3: (YoY Growth) | B3: 16 Q1 | C3: 16 Q2 | D3: 16 Q3 | E3: 16 Q4 | G3: 17 Q1 | H3: 17Q2 | I3: 17Q3 | J3: 17Q4 | L3: 18 Q1 | M3: 18Q2 | N3: 18Q3 | O3: 18Q4 | P3: Dec | Q3: FY18 | R3: 19Q1 | S3: 19Q2 | T3: 19Q3 | U3: 19Q4 | V3: FY19 | W3: Jan | X3: Feb | Y3: Mar | Z3: Apr | AA3: May | AB3: June | AC3: July | AD3: August | AE3: September | AF3: October | AG3: November | AH3: December | AI3: 20Q1 | AJ3: 20Q2 | AK3: 20Q3 | AL3: 20Q4 | AM3: FY20 | AN3: January | AO3: February | AP3: March | AQ3: April | AR3: May | AS3: June | AT3: July | AU3: August | AV3: September | AW3: October | AX3: November | AY3: December | AZ3: 21Q1 | BA3: 21Q2 | BB3: 21Q3 | BC3: 21Q4 | BD3: FY21 | BE3: Jan | BF3: Feb | BG3: Mar | BH3: Apr | BI3: May | BJ3: Jun | BK3: Jul | BL3: Aug | BM3: Sep | BN3: Oct | BO3: Nov | BP3: Dec | BQ3: 22Q1 | BR3: 22Q2 | BS3: 22Q3 | BT3: 22Q4 | BU3: FY2022 | BV3: Jan | BW3: Feb | BX3: Mar | BY3: Apr | BZ3: May | CA3: Jun | CB3: Jul | CC3: Aug | CD3: Sep | CE3: Oct | CF3: Nov | CG3: Dec | CH3: 23Q1 | CI3: 23Q2 | CJ3: 23Q3 | CK3: 23Q4 | CL3: FY2023 | CM3: Jan | CN3: Feb | CO3: Mar | CP3: April | CQ3: May | CR3: June | CS3: July | CT3: August | CU3: September | CV3: October | CW3: November | CX3: December | CY3: 24Q1 | CZ3: 24Q2 | DA3: 24Q3 | DB3: 24Q4 | DC3: FY2024 | DD3: Jan | DE3: Feb | DF3: Mar | DG3: Apr | DH3: May | DI3: Jun | DJ3: Jul | DK3: Aug | DL3: Sep | DM3: Oct | DN3: Nov | DO3: Dec
A4: Air Industry | B4: 0.10750932 | C4: 0.1114922 | D4: 0.12015316 | E4: 0.13852476 | G4: ='CAAC Data'!O216 -> 0 | H4: ='CAAC Data'!P216 -> 0 | I4: ='CAAC Data'!Q216 -> 0 | J4: ='CAAC Data'!R216 -> 0 | L4: ='CAAC Data'!O191 -> 8196 | M4: ='CAAC Data'!P191 -> 323 | N4: ='CAAC Data'!Q191 -> 523 | O4: ='CAAC Data'!R191 -> 514 | P4: ='CAAC Data'!M191 -> 163 | Q4: ='CAAC Data'!N191 -> 9556 | R4: 0.098 | S4: 0.072 | T4: ='CAAC Data'!Q166 -> -0.98001017 | U4: ='CAAC Data'!R166 -> -0.98210377 | V4: ='CAAC Data'!N166 -> -0.98008569 | W4: ='CAAC Data'!B166 -> -0.97662551 | X4: ='CAAC Data'!C166 -> -0.98476477 | Y4: ='CAAC Data'!D166 -> -0.97717499 | Z4: ='CAAC Data'!E166 -> -0.97763158 | AA4: ='CAAC Data'!F166 -> -0.9784447 | AB4: ='CAAC Data'!G166 -> -0.98010196 | AC4: ='CAAC Data'!H166 -> -0.97996965 | AD4: ='CAAC Data'!I166 -> -0.98031665 | ... AH4: ='CAAC Data'!M166 -> -0.98181531 | AI4: ='CAAC Data'!O140 -> -0.94858273 | AJ4: ='CAAC Data'!P140 -> -0.99300254 | AK4: ='CAAC Data'!Q140 -> -0.96613256 | AL4: ='CAAC Data'!R140 -> -0.90744186 | AM4: ='CAAC Data'!N140 -> -0.95755824 | AN4: ='CAAC Data'!B140 -> -0.93574297 | AO4: ='CAAC Data'!C140 -> -0.9320197 | AP4: ='CAAC Data'!D140 -> -0.97751711 | AQ4: ='CAAC Data'!E140 -> -0.99427481 | AR4: ='CAAC Data'!F140 -> -0.99434496 | AS4: ='CAAC Data'!G140 -> -0.99033816 | AT4: ='CAAC Data'!H140 -> -0.98094374 | AU4: ='CAAC Data'!I140 -> -0.96794872 | ... AY4: ='CAAC Data'!M140 -> -0.86781609 | AZ4: ='CAAC Data'!O110 -> 0 | BA4: ='CAAC Data'!P110 -> 0 | BB4: ='CAAC Data'!Q110 -> 0 | BC4: ='CAAC Data'!R110 -> 0 | BD4: ='CAAC Data'!N110 -> 0 | BE4: ='CAAC Data'!B110 -> 0 | BF4: ='CAAC Data'!C110 -> 0 | BG4: ='CAAC Data'!D110 -> 0 | BH4: ='CAAC Data'!E110 -> 0 | BI4: ='CAAC Data'!F110 -> 0 | BJ4: ='CAAC Data'!G110 -> 0 | BK4: ='CAAC Data'!H110 -> 0 | BL4: ='CAAC Data'!I110 -> 0 | ... BP4: ='CAAC Data'!M110 -> 0 | BQ4: ='CAAC Data'!O79 -> 0 | BR4: ='CAAC Data'!P79 -> 0 | BS4: ='CAAC Data'!Q79 -> 0 | BT4: ='CAAC Data'!R79 -> 0 | BU4: ='CAAC Data'!N79 -> 0 | BV4: ='CAAC Data'!B79 -> 0 | BW4: ='CAAC Data'!C79 -> 0 | BX4: ='CAAC Data'!D79 -> 0 | BY4: ='CAAC Data'!E79 -> 0 | BZ4: ='CAAC Data'!F79 -> 0 | CA4: ='CAAC Data'!G79 -> 0 | CB4: ='CAAC Data'!H79 -> 0 | CC4: ='CAAC Data'!I79 -> 0 | ... CG4: ='CAAC Data'!M79 -> 0 | CH4: ='CAAC Data'!O47 -> 0.045926827 | CI4: ='CAAC Data'!P47 -> 0.056233509 | CJ4: ='CAAC Data'!Q47 -> 0.068972533 | CK4: ='CAAC Data'!R47 -> 0.12374124 | CL4: ='CAAC Data'!N47 -> 0.073715271 | CM4: ='CAAC Data'!B47 -> 0.1362963 | CN4: ='CAAC Data'!C47 -> -0.006027122 | CO4: ='CAAC Data'!D47 -> 0.0064505458 | CP4: ='CAAC Data'!E47 -> 0.054934211 | CQ4: ='CAAC Data'!F47 -> 0.062676173 | CR4: ='CAAC Data'!G47 -> 0.051142904 | CS4: ='CAAC Data'!H47 -> 0.076327769 | CT4: ='CAAC Data'!I47 -> 0.064755384 | ... CX4: ='CAAC Data'!M47 -> 0.080961417 | CY4: ='CAAC Data'!#REF! -> #REF! | CZ4: ='CAAC Data'!#REF! -> #REF! | DA4: ='CAAC Data'!#REF! -> #REF! | DB4: ='CAAC Data'!#REF! -> #REF! | DD4: ='CAAC Data'!B4 -> -0.02933925 | DE4: ='CAAC Data'!C4 -> 0.11034348 | DF4: ='CAAC Data'!D4 -> 0.12088282 | DG4: ='CAAC Data'!E4 -> 0.0044149023 | DH4: ='CAAC Data'!F4 -> -0.071382576 | DI4: ='CAAC Data'!G4 -> -0.064506117 | DJ4: ='CAAC Data'!H4 -> 0.039111668 | DK4: ='CAAC Data'!#REF! -> #REF! | DL4: ='CAAC Data'!#REF! -> #REF! | DM4: ='CAAC Data'!#REF! -> #REF! | DN4: ='CAAC Data'!#REF! -> #REF! | DO4: ='CAAC Data'!#REF! -> #REF!
A5: Air Industry Domestic | B5: 0.087711662 | C5: 0.10188276 | D5: 0.10975386 | E5: 0.15565676 | G5: ='CAAC Data'!O220 -> 0 | H5: ='CAAC Data'!P220 -> 0 | I5: ='CAAC Data'!Q220 -> 0 | J5: ='CAAC Data'!R220 -> 0 | L5: ='CAAC Data'!O195 -> 779 | M5: ='CAAC Data'!P195 -> 29 | N5: ='CAAC Data'!Q195 -> 64 | O5: ='CAAC Data'!R195 -> 89 | P5: ='CAAC Data'!M195 -> 32 | Q5: ='CAAC Data'!N195 -> 961 | R5: 0.089 | S5: ='CAAC Data'!P170 -> 6.2758621 | T5: ='CAAC Data'!Q170 -> 1.4375 | U5: ='CAAC Data'!R170 -> 0.29213483 | V5: ='CAAC Data'!N170 -> -0.38501561 | W5: ='CAAC Data'!B170 -> -0.94674556 | X5: ='CAAC Data'!C170 -> -0.63513514 | Y5: 0.027 | Z5: ='CAAC Data'!E170 -> 7.5 | AA5: ='CAAC Data'!F170 -> 8 | AB5: ='CAAC Data'!G170 -> 4.6428571 | AC5: ='CAAC Data'!H170 -> 3.05 | AD5: ='CAAC Data'!I170 -> 0.65 | AE5: ='CAAC Data'!J170 -> 0.75 | AF5: ='CAAC Data'!K170 -> -0.032258065 | AG5: ='CAAC Data'!L170 -> 0.30769231 | AH5: ='CAAC Data'!M170 -> 0.59375 | AI5: ='CAAC Data'!O144 -> 101952 | AJ5: ='CAAC Data'!P144 -> 143412 | AK5: ='CAAC Data'!Q144 -> 107641 | AL5: ='CAAC Data'!R144 -> 87479 | AM5: ='CAAC Data'!N144 -> 440484 | AN5: ='CAAC Data'!B144 -> 30181 | AO5: ='CAAC Data'!C144 -> 23949 | AP5: ='CAAC Data'!D144 -> 47822 | AQ5: ='CAAC Data'!E144 -> 51094 | AR5: ='CAAC Data'!F144 -> 51041 | AS5: ='CAAC Data'!G144 -> 41277 | AT5: ='CAAC Data'!H144 -> 49117 | AU5: ='CAAC Data'!I144 -> 22407 | ... AY5: ='CAAC Data'!M144 -> 27095 | AZ5: ='CAAC Data'!O115 -> -0.52609445 | BA5: ='CAAC Data'!P115 -> -0.73947007 | BB5: ='CAAC Data'!Q115 -> -0.50711955 | BC5: ='CAAC Data'!R115 -> -0.71001843 | BD5: ='CAAC Data'!N115 -> -0.61854955 | BE5: ='CAAC Data'!B115 -> -0.44745661 | BF5: ='CAAC Data'!C115 -> -0.41860811 | BG5: ='CAAC Data'!D115 -> -0.71273176 | BH5: ='CAAC Data'!E115 -> -0.85165104 | BI5: ='CAAC Data'!F115 -> -0.77851364 | BJ5: ='CAAC Data'!G115 -> -0.5880668 | BK5: ='CAAC Data'!H115 -> -0.4267213 | BL5: ='CAAC Data'!I115 -> -0.47250073 | ... BP5: ='CAAC Data'!M115 -> -0.64529947 | BQ5: ='CAAC Data'!O84 -> 0 | BR5: ='CAAC Data'!P84 -> 0 | BS5: ='CAAC Data'!Q84 -> 0 | BT5: ='CAAC Data'!R84 -> 0 | BU5: ='CAAC Data'!N84 -> 0 | BV5: ='CAAC Data'!B84 -> 1.1254141 | BW5: ='CAAC Data'!C84 -> 0.086109365 | BX5: ='CAAC Data'!D84 -> 0.057962963 | BY5: ='CAAC Data'!E84 -> 0.10001313 | BZ5: ='CAAC Data'!F84 -> 0.028304326 | CA5: ='CAAC Data'!G84 -> 0.027428527 | CB5: ='CAAC Data'!H84 -> 0.17531441 | CC5: ='CAAC Data'!I84 -> 0.024604344 | ... CG5: ='CAAC Data'!M84 -> 0.032679472 | CH5: ='CAAC Data'!O52 -> 0 | CI5: ='CAAC Data'!P52 -> 0 | CJ5: ='CAAC Data'!Q52 -> 0 | CK5: ='CAAC Data'!R52 -> 0 | CL5: ='CAAC Data'!N52 -> 0 | CM5: ='CAAC Data'!B52 -> 0 | CN5: ='CAAC Data'!C52 -> 0 | CO5: ='CAAC Data'!D52 -> 0 | CP5: ='CAAC Data'!E52 -> 0 | CQ5: ='CAAC Data'!F52 -> 0 | CR5: ='CAAC Data'!G52 -> 0 | CS5: ='CAAC Data'!H52 -> 0 | CT5: ='CAAC Data'!I52 -> 0 | ... CX5: ='CAAC Data'!M52 -> 0 | CY5: ='CAAC Data'!#REF! -> #REF! | CZ5: ='CAAC Data'!#REF! -> #REF! | DD5: ='CAAC Data'!B8 -> -0.045712414 | DE5: ='CAAC Data'!C8 -> 0.10351801 | DF5: ='CAAC Data'!D8 -> 0.11486692 | DG5: ='CAAC Data'!E8 -> -0.0023648145 | DH5: ='CAAC Data'!F8 -> -0.080633447 | DI5: ='CAAC Data'!G8 -> -0.0705292 | DJ5: ='CAAC Data'!H8 -> 0.040899059 | DK5: ='CAAC Data'!#REF! -> #REF! | DL5: ='CAAC Data'!#REF! -> #REF! | DM5: ='CAAC Data'!#REF! -> #REF! | DN5: ='CAAC Data'!#REF! -> #REF! | DO5: ='CAAC Data'!#REF! -> #REF! | DP5: vs 2025
A6: Air Industry International (含港澳台） | BQ6: ='CAAC Data'!O94 -> 0 | BR6: ='CAAC Data'!P94 -> 0 | BS6: ='CAAC Data'!Q94 -> 0 | BT6: ='CAAC Data'!R94 -> 0 | BU6: ='CAAC Data'!R94 -> 0 | CE6: ='CAAC Data'!K94 -> 0.049954225 | CF6: ='CAAC Data'!L94 -> -0.13124574 | CG6: ='CAAC Data'!M94 -> 0.016844126 | CH6: ='CAAC Data'!O62 -> 0 | CI6: ='CAAC Data'!P62 -> 0 | CJ6: ='CAAC Data'!Q62 -> 0 | CK6: ='CAAC Data'!R62 -> 0 | CL6: ='CAAC Data'!N62 -> 0 | CM6: ='CAAC Data'!B62 -> 0 | CN6: ='CAAC Data'!C62 -> 0 | CO6: ='CAAC Data'!D62 -> 0 | CP6: ='CAAC Data'!E62 -> 0 | CQ6: ='CAAC Data'!F62 -> 0 | CR6: ='CAAC Data'!G62 -> 0 | CS6: ='CAAC Data'!H62 -> 0 | CT6: ='CAAC Data'!I62 -> 0 | ... CX6: ='CAAC Data'!M62 -> 0 | CY6: ='CAAC Data'!O32 -> 0 | CZ6: ='CAAC Data'!P32 -> 0 | DD6: ='CAAC Data'!B15 -> -0.0086832556 | DE6: ='CAAC Data'!C15 -> 0.16704391 | DF6: ='CAAC Data'!D15 -> 0.16710488 | DG6: ='CAAC Data'!E15 -> 0.054802104 | DH6: ='CAAC Data'!F15 -> 0.00083114005 | DI6: ='CAAC Data'!G15 -> -0.019548038 | DJ6: ='CAAC Data'!H15 -> 0.024583964 | DK6: ='CAAC Data'!#REF! -> #REF! | DL6: ='CAAC Data'!#REF! -> #REF! | DM6: ='CAAC Data'!#REF! -> #REF! | DN6: ='CAAC Data'!#REF! -> #REF! | DO6: ='CAAC Data'!#REF! -> #REF! | DP6: vs 2025
A7: Air Industry Regional (港澳台） | B7: 0.05108055 | C7: -0.025937749 | D7: -0.073217726 | E7: -0.09194499 | F7: ='CAAC Data'!N236 -> 0 | G7: ='CAAC Data'!O236 -> 0.022112657 | H7: ='CAAC Data'!P236 -> 0.029057189 | I7: ='CAAC Data'!Q236 -> 0.069778326 | J7: ='CAAC Data'!R236 -> -0.038651436 | K7: ='CAAC Data'!S236 -> 0 | L7: ='CAAC Data'!O211 -> 0.030410506 | M7: ='CAAC Data'!P211 -> 0.0014020428 | N7: ='CAAC Data'!Q211 -> 0.089486101 | O7: ='CAAC Data'!R211 -> -0.07135422 | P7: ='CAAC Data'!M211 -> -0.015226704 | Q7: ='CAAC Data'!N211 -> 0 | R7: 0.138 | S7: ='CAAC Data'!P186 -> 0 | T7: ='CAAC Data'!Q186 -> 0 | U7: ='CAAC Data'!R186 -> 0 | V7: ='CAAC Data'!N186 -> 0 | W7: ='CAAC Data'!B186 -> 0 | X7: ='CAAC Data'!C186 -> 0 | Y7: 0.141 | Z7: ='CAAC Data'!E186 -> 0 | AA7: ='CAAC Data'!F186 -> 0 | AB7: ='CAAC Data'!G186 -> 0 | AC7: ='CAAC Data'!H186 -> 0 | AD7: ='CAAC Data'!I186 -> 0 | AE7: ='CAAC Data'!J186 -> 0 | AF7: ='CAAC Data'!K186 -> 0 | AG7: ='CAAC Data'!L186 -> 0 | AH7: ='CAAC Data'!M186 -> 0 | AI7: ='CAAC Data'!O160 -> -0.94651811 | AJ7: ='CAAC Data'!P160 -> 0.69886364 | AK7: ='CAAC Data'!Q160 -> -0.064735945 | AL7: ='CAAC Data'!R160 -> -0.26699834 | AM7: ='CAAC Data'!N160 -> -0.80327089 | AN7: ='CAAC Data'!B160 -> -0.97550908 | AO7: ='CAAC Data'!C160 -> -0.89520426 | AP7: ='CAAC Data'!D160 -> -0.68330465 | AQ7: ='CAAC Data'!E160 -> 1.253012 | AR7: ='CAAC Data'!F160 -> 0.85087719 | AS7: ='CAAC Data'!G160 -> 0.29032258 | AT7: ='CAAC Data'!H160 -> 0.18994413 | AU7: ='CAAC Data'!I160 -> -0.12307692 | ... AY7: ='CAAC Data'!M160 -> -0.14871795 | AZ7: ='CAAC Data'!O135 -> -0.98485686 | BA7: ='CAAC Data'!P135 -> -0.98295954 | BB7: ='CAAC Data'!Q135 -> -0.97273652 | BC7: ='CAAC Data'!R135 -> -0.95944615 | BD7: ='CAAC Data'!N135 -> -0.97492522 | BE7: ='CAAC Data'!B135 -> -0.98485597 | BF7: ='CAAC Data'!C135 -> -0.98627156 | BG7: ='CAAC Data'!D135 -> -0.98346014 | BH7: ='CAAC Data'!E135 -> -0.98470395 | BI7: ='CAAC Data'!F135 -> -0.983419 | BJ7: ='CAAC Data'!G135 -> -0.98075974 | BK7: ='CAAC Data'!H135 -> -0.97784522 | BL7: ='CAAC Data'!I135 -> -0.97461133 | ... BP7: ='CAAC Data'!M135 -> -0.95129665 | BQ7: ='CAAC Data'!O104 -> 0 | BR7: ='CAAC Data'!P104 -> 0 | BS7: ='CAAC Data'!Q104 -> 0 | BT7: ='CAAC Data'!R104 -> 0 | BU7: ='CAAC Data'!N104 -> 0 | BV7: ='CAAC Data'!B104 -> 0.43506494 | BW7: ='CAAC Data'!C104 -> 0.59728507 | BX7: ='CAAC Data'!D104 -> 0.54957507 | BY7: ='CAAC Data'!E104 -> 0.48263254 | BZ7: ='CAAC Data'!F104 -> 0.21824908 | CA7: ='CAAC Data'!G104 -> 0.2798583 | CB7: ='CAAC Data'!H104 -> 0.32582048 | CC7: ='CAAC Data'!I104 -> 0.087086191 | ... CG7: ='CAAC Data'!M104 -> 0.26242482 | CH7: ='CAAC Data'!O72 -> 5.2979483 | CI7: ='CAAC Data'!P72 -> 1.5384364 | CJ7: ='CAAC Data'!Q72 -> 0.77970901 | CK7: ='CAAC Data'!R72 -> 0.69060615 | CL7: ='CAAC Data'!N72 -> 1.2563591 | CM7: ='CAAC Data'!B72 -> 8.8891403 | CN7: ='CAAC Data'!C72 -> 5.9305949 | CO7: ='CAAC Data'!D72 -> 3.4387569 | CP7: ='CAAC Data'!E72 -> 2.1418002 | CQ7: ='CAAC Data'!F72 -> 1.5809717 | CR7: ='CAAC Data'!G72 -> 1.1182285 | CS7: ='CAAC Data'!H72 -> 0.82821354 | CT7: ='CAAC Data'!I72 -> 0.77558299 | ... CX7: ='CAAC Data'!M72 -> 0.57522568 | CY7: ='CAAC Data'!O41 -> 0.29012421 | CZ7: ='CAAC Data'!P41 -> 0.20717909 | DD7: ='CAAC Data'!B24 -> 0.0024600246 | DE7: ='CAAC Data'!C24 -> 0.26231884 | DF7: ='CAAC Data'!D24 -> 0.14191853 | DG7: ='CAAC Data'!E24 -> 0.027093596 | DH7: ='CAAC Data'!F24 -> -0.013580247 | DI7: ='CAAC Data'!G24 -> -0.036540804 | DJ7: ='CAAC Data'!H24 -> 0.033373063 | DK7: ='CAAC Data'!I33 -> 66989 | DL7: ='CAAC Data'!J33 -> 55483 | DM7: ='CAAC Data'!K33 -> 60000 | DN7: ='CAAC Data'!L33 -> 52651 | DO7: ='CAAC Data'!M33 -> 52939
A8: Air Industry Pure Intl. | B8: 0.31084163 | C8: 0.23291712 | D8: 0.26009922 | E8: 0.11605593 | G8: ='CAAC Data'!O232 -> 0.022639853 | H8: ='CAAC Data'!P232 -> 0.043130155 | I8: ='CAAC Data'!Q232 -> 0.055238865 | J8: ='CAAC Data'!R232 -> -0.038898893 | L8: ='CAAC Data'!O207 -> 0.029829388 | M8: ='CAAC Data'!P207 -> 0.00064462988 | N8: ='CAAC Data'!Q207 -> 0.094348806 | O8: ='CAAC Data'!R207 -> -0.068737491 | P8: ='CAAC Data'!M207 -> -0.015285253 | Q8: ='CAAC Data'!N207 -> 0 | R8: 0.167 | S8: 0.163 | T8: ='CAAC Data'!Q182 -> 0 | U8: ='CAAC Data'!R182 -> 0 | V8: ='CAAC Data'!N182 -> 0 | W8: ='CAAC Data'!B182 -> 0 | X8: ='CAAC Data'!C182 -> 0 | Y8: 0.141 | Z8: ='CAAC Data'!E182 -> 0 | AA8: ='CAAC Data'!F182 -> 0 | AB8: ='CAAC Data'!G182 -> 0 | AC8: ='CAAC Data'!H182 -> 0 | AD8: ='CAAC Data'!I182 -> 0 | AE8: ='CAAC Data'!J182 -> 0 | AF8: ='CAAC Data'!K182 -> 0 | AG8: ='CAAC Data'!L182 -> 0 | AH8: ='CAAC Data'!M182 -> 0 | AI8: ='CAAC Data'!O156 -> -0.28789546 | AJ8: ='CAAC Data'!P156 -> 0.0012250698 | AK8: ='CAAC Data'!Q156 -> -0.31090007 | AL8: ='CAAC Data'!R156 -> -0.39698465 | AM8: ='CAAC Data'!N156 -> -0.25040937 | AN8: ='CAAC Data'!B156 -> -0.3654358 | AO8: ='CAAC Data'!C156 -> -0.50143147 | AP8: ='CAAC Data'!D156 -> 0.0047621054 | AQ8: ='CAAC Data'!E156 -> 0.083358136 | AR8: ='CAAC Data'!F156 -> 0.050167086 | AS8: ='CAAC Data'!G156 -> -0.13052205 | AT8: ='CAAC Data'!H156 -> -0.070687333 | AU8: ='CAAC Data'!I156 -> -0.58935586 | ... AY8: ='CAAC Data'!M156 -> -0.41898527 | AZ8: ='CAAC Data'!O130 -> -0.97964786 | BA8: ='CAAC Data'!P130 -> -0.98443945 | BB8: ='CAAC Data'!Q130 -> -0.97192716 | BC8: ='CAAC Data'!R130 -> -0.95397121 | BD8: ='CAAC Data'!N130 -> -0.97267036 | BE8: ='CAAC Data'!B130 -> -0.97793806 | BF8: ='CAAC Data'!C130 -> -0.97839153 | BG8: ='CAAC Data'!D130 -> -0.98260008 | BH8: ='CAAC Data'!E130 -> -0.98611111 | BI8: ='CAAC Data'!F130 -> -0.98505358 | BJ8: ='CAAC Data'!G130 -> -0.98215289 | BK8: ='CAAC Data'!H130 -> -0.97828913 | BL8: ='CAAC Data'!I130 -> -0.9738266 | ... BP8: ='CAAC Data'!M130 -> -0.94301994 | BQ8: ='CAAC Data'!O99 -> 0 | BR8: ='CAAC Data'!P99 -> 0 | BS8: ='CAAC Data'!Q99 -> 0 | BT8: ='CAAC Data'!R99 -> 0 | BU8: ='CAAC Data'!N99 -> 0 | BV8: ='CAAC Data'!B99 -> 0.6075 | BW8: ='CAAC Data'!C99 -> 0.50855365 | BX8: ='CAAC Data'!D99 -> 0.55051546 | BY8: ='CAAC Data'!E99 -> 0.42220745 | BZ8: ='CAAC Data'!F99 -> 0.18419822 | CA8: ='CAAC Data'!G99 -> 0.23963679 | CB8: ='CAAC Data'!H99 -> 0.29681529 | CC8: ='CAAC Data'!I99 -> 0.080304519 | ... CG8: ='CAAC Data'!M99 -> 0.23157344 | CH8: ='CAAC Data'!O67 -> 4.2691691 | CI8: ='CAAC Data'!P67 -> 1.296595 | CJ8: ='CAAC Data'!Q67 -> 0.68774896 | CK8: ='CAAC Data'!R67 -> 0.59969619 | CL8: ='CAAC Data'!N67 -> 1.102384 | CM8: ='CAAC Data'!B67 -> 6.9688958 | CN8: ='CAAC Data'!C67 -> 4.8649485 | CO8: ='CAAC Data'!D67 -> 2.7307181 | CP8: ='CAAC Data'!E67 -> 1.7545582 | CQ8: ='CAAC Data'!F67 -> 1.3241216 | CR8: ='CAAC Data'!G67 -> 0.96242038 | CS8: ='CAAC Data'!H67 -> 0.71709234 | CT8: ='CAAC Data'!I67 -> 0.68265515 | ... CX8: ='CAAC Data'!M67 -> 0.49851443 | CY8: ='CAAC Data'!O37 -> 167746 | CZ8: ='CAAC Data'!P37 -> 166606 | DD8: ='CAAC Data'!B20 -> -0.0099956541 | DE8: ='CAAC Data'!C20 -> 0.15597103 | DF8: ='CAAC Data'!D20 -> 0.17025472 | DG8: ='CAAC Data'!E20 -> 0.058309947 | DH8: ='CAAC Data'!F20 -> 0.0026525199 | DI8: ='CAAC Data'!G20 -> -0.017365457 | DJ8: ='CAAC Data'!H20 -> 0.023544339 | DK8: ='CAAC Data'!I29 -> 75364 | DL8: ='CAAC Data'!J29 -> 62667 | DM8: ='CAAC Data'!K29 -> 67835 | DN8: ='CAAC Data'!L29 -> 60172 | DO8: ='CAAC Data'!M29 -> 60602
A9: Air Industry Regional + Int'l | G9: ='CAAC Data'!O228 -> 0.03068133 | H9: ='CAAC Data'!P228 -> 0.027006521 | I9: ='CAAC Data'!Q228 -> 0.069131908 | J9: ='CAAC Data'!R228 -> -0.039337384 | L9: ='CAAC Data'!O203 -> 0.041641556 | M9: ='CAAC Data'!P203 -> 0.001853891 | N9: ='CAAC Data'!Q203 -> 0.088492992 | O9: ='CAAC Data'!R203 -> -0.071263948 | R9: ='CAAC Data'!O178 -> 0 | S9: ='CAAC Data'!P178 -> 0 | T9: ='CAAC Data'!Q178 -> 0 | U9: ='CAAC Data'!R178 -> 0 | V9: ='CAAC Data'!N178 -> 0 | DF9: ='CAAC Data'!D26 -> 0
A10: Top 4 | B10: 0.060036962 | C10: 0.05812427 | D10: 0.058366282 | E10: 0.10286248 | G10: 0.14579564 | H10: 0.13840441 | I10: 0.11539155 | J10: 0.16008565 | L10: 0.098091979 | M10: 0.12461765 | N10: 0.095081407 | O10: 0.07717282 | P10: 0.065459285 | Q10: 0.098298189 | R10: ='Top 4 Total'!O91 -> -0.44695507 | S10: 0.058 | T10: ='Top 4 Total'!Q91 -> -0.45452484 | U10: ='Top 4 Total'!R91 -> -0.49685245 | V10: =AVERAGE(R10:U10) -> -0.33508309 | W10: ='Top 4 Total'!B91 -> -0.51938123 | X10: ='Top 4 Total'!C91 -> -0.63160091 | Y10: ='Top 4 Total'!D91 -> -0.19130618 | Z10: ='Top 4 Total'!E91 -> -0.11600694 | AA10: ='Top 4 Total'!F91 -> -0.14135063 | AB10: ='Top 4 Total'!G91 -> -0.25160861 | AC10: ='Top 4 Total'!H91 -> -0.23565579 | AD10: ='Top 4 Total'!I91 -> -0.70111633 | ... AH10: ='Top 4 Total'!M91 -> -0.54550347 | AN10: ='Top 4 Total'!N91 -> 0 | AO10: ='Top 4 Total'!O91 -> -0.44695507 | AP10: ='Top 4 Total'!P91 -> -0.16983369 | AQ10: ='Top 4 Total'!Q91 -> -0.45452484 | AR10: ='Top 4 Total'!R91 -> -0.49685245 | AS10: ='Top 4 Total'!S91 -> -0.39292488 | AT10: ='Top 4 Total'!T91 -> 0 | DF10: ='CAAC Data'!D22 -> 0
A11: Top 4 Domestic | B11: 0.034646531 | C11: 0.041705997 | D11: 0.042045547 | E11: 0.10895083 | G11: 0.15885514 | H11: 0.15682134 | I11: 0.12480783 | J11: 0.16222328 | L11: 0.097018099 | M11: 0.11363947 | N11: 0.091145877 | O11: 0.072192825 | P11: 0.056820942 | Q11: 0.093101817 | R11: ='Top4 Domestic'!O104 -> 11355 | S11: 0.047 | T11: ='Top4 Domestic'!Q104 -> 20841.9 | U11: ='Top4 Domestic'!R104 -> 22528.2 | V11: =AVERAGE(R11:U11) -> 13681.287 | W11: ='Top4 Domestic'!B104 -> 7334 | X11: ='Top4 Domestic'!C104 -> 1255.3 | Y11: ='Top4 Domestic'!D104 -> 2765.7 | Z11: ='Top4 Domestic'!E104 -> 2649.1 | AA11: ='Top4 Domestic'!F104 -> 4044.1 | AB11: ='Top4 Domestic'!G104 -> 4420.5 | AC11: ='Top4 Domestic'!H104 -> 5798.6 | AD11: ='Top4 Domestic'!I104 -> 7267.6 | ... AH11: ='Top4 Domestic'!M104 -> 6690.4 | AN11: ='Top4 Domestic'!N104 -> 0 | AO11: ='Top4 Domestic'!O104 -> 11355 | AP11: ='Top4 Domestic'!P104 -> 11113.7 | AQ11: ='Top4 Domestic'!Q104 -> 20841.9 | AR11: ='Top4 Domestic'!R104 -> 22528.2 | AS11: ='Top4 Domestic'!S104 -> 65838.8 | AT11: ='Top4 Domestic'!T104 -> 0 | DF11: ='CAAC Data'!D28 -> Mar
A12: Top 4 Regional (港澳台） | B12: 0.094145204 | C12: 5.9756404e-05 | D12: -0.04779835 | E12: -0.071659694 | G12: -0.083474674 | H12: 0.0050705334 | I12: 0.094197073 | J12: 0.15460566 | L12: 0.097493155 | M12: 0.13401207 | N12: 0.099752247 | O12: 0.074324106 | P12: 0.086705343 | Q12: 0.10079624 | R12: ='Top4 Intl.+Reg'!O435 -> 0 | S12: ='Top4 Intl.+Reg'!P435 -> 0 | T12: ='Top4 Intl.+Reg'!Q435 -> 0 | U12: ='Top4 Intl.+Reg'!R435 -> 0 | V12: =AVERAGE(R12:U12) -> 0 | W12: ='Top4 Intl.+Reg'!B435 -> 0.06724346 | X12: ='Top4 Intl.+Reg'!C435 -> -0.027838325 | Y12: ='Top4 Intl.+Reg'!D435 -> 0.015203749 | Z12: ='Top4 Intl.+Reg'!E435 -> 0.015444507 | AA12: ='Top4 Intl.+Reg'!F435 -> -0.016853406 | AB12: ='Top4 Intl.+Reg'!G435 -> -0.0026410128 | AC12: ='Top4 Intl.+Reg'!H435 -> 0.071461919 | AD12: ='Top4 Intl.+Reg'!I435 -> 0.026712606 | ... AH12: ='Top4 Intl.+Reg'!M435 -> 0.060531185 | AN12: ='Top4 Intl.+Reg'!N435 -> 0 | AO12: ='Top4 Intl.+Reg'!O435 -> 0 | AP12: ='Top4 Intl.+Reg'!P435 -> 0 | AQ12: ='Top4 Intl.+Reg'!Q435 -> 0 | AR12: ='Top4 Intl.+Reg'!R435 -> 0 | AS12: ='Top4 Intl.+Reg'!S435 -> 0 | AT12: ='Top4 Intl.+Reg'!T435 -> 0 | DF12: ='CAAC Data'!D24 -> 0.14191853
A13: Top 4 International | B13: 0.23300681 | C13: 0.1919311 | D13: 0.20632696 | E13: 0.097730886 | G13: 0.1158186 | H13: 0.037943055 | I13: 0.055793714 | J13: 0.14542448 | L13: 0.10587235 | M13: 0.20714073 | N13: 0.12276586 | O13: 0.11536644 | P13: 0.12183289 | Q13: 0.13623741 | R13: ='Top4 Intl.+Reg'!O418 -> 5707.9 | S13: ='Top4 Intl.+Reg'!P418 -> 5772.1 | T13: ='Top4 Intl.+Reg'!Q418 -> 5677.3 | U13: ='Top4 Intl.+Reg'!R418 -> 5295.7 | V13: =AVERAGE(R13:U13) -> 5613.25 | W13: ='Top4 Intl.+Reg'!B418 -> 1929.6 | X13: ='Top4 Intl.+Reg'!C418 -> 1833.8 | Y13: ='Top4 Intl.+Reg'!D418 -> 1944.5 | Z13: ='Top4 Intl.+Reg'!E418 -> 1978.4 | AA13: ='Top4 Intl.+Reg'!F418 -> 1921.7 | AB13: ='Top4 Intl.+Reg'!G418 -> 1872 | AC13: ='Top4 Intl.+Reg'!H418 -> 1958.8 | AD13: ='Top4 Intl.+Reg'!I418 -> 2006.1 | ... AH13: ='Top4 Intl.+Reg'!M418 -> 1841.3 | AN13: ='Top4 Intl.+Reg'!N418 -> 0 | AO13: ='Top4 Intl.+Reg'!O418 -> 5707.9 | AP13: ='Top4 Intl.+Reg'!P418 -> 5772.1 | AQ13: ='Top4 Intl.+Reg'!Q418 -> 5677.3 | AR13: ='Top4 Intl.+Reg'!R418 -> 5295.7 | AS13: ='Top4 Intl.+Reg'!S418 -> 22453 | AT13: ='Top4 Intl.+Reg'!T418 -> 0 | DF13: ='CAAC Data'!D30 -> 0.035103604
A14: Top 3 | R14: ='Top 4 Total'!O89 -> 0 | S14: ='Top 4 Total'!P89 -> 0 | T14: ='Top 4 Total'!Q89 -> 0 | U14: ='Top 4 Total'!R89 -> 0 | V14: ='Top 4 Total'!S89 -> 0 | W14: ='Top 4 Total'!B89 -> 0 | X14: ='Top 4 Total'!C89 -> 0 | Y14: ='Top 4 Total'!D89 -> 0 | Z14: ='Top 4 Total'!E89 -> 0 | AA14: ='Top 4 Total'!F89 -> 0 | AB14: ='Top 4 Total'!G89 -> 0 | AC14: ='Top 4 Total'!H89 -> 0 | AD14: ='Top 4 Total'!I89 -> 0 | ... AH14: ='Top 4 Total'!M89 -> 0 | AI14: ='Top 4 Total'!O73 -> Q1 | AJ14: ='Top 4 Total'!P73 -> Q2 | AK14: ='Top 4 Total'!Q73 -> Q3 | AL14: ='Top 4 Total'!R73 -> Q4 | AM14: =AVERAGE(AN14:AY14) -> #DIV/0! | AN14: ='Top 4 Total'!B73 -> Jan | AO14: ='Top 4 Total'!C73 -> Feb | AP14: ='Top 4 Total'!D73 -> Mar | AQ14: ='Top 4 Total'!E73 -> Apr | AR14: ='Top 4 Total'!F73 -> May | AS14: ='Top 4 Total'!G73 -> Jun | AT14: ='Top 4 Total'!H73 -> Jul | AU14: ='Top 4 Total'!I73 -> Aug | ... AY14: ='Top 4 Total'!M73 -> Dec | AZ14: ='Top 4 Total'!O57 -> 13134.86 | BA14: ='Top 4 Total'!P57 -> 5540.76 | BB14: ='Top 4 Total'!Q57 -> 15125.74 | BC14: ='Top 4 Total'!R57 -> 8726.25 | BD14: ='Top 4 Total'!S57 -> 42527.61 | BE14: ='Top 4 Total'!B57 -> 5023.59 | BF14: ='Top 4 Total'!C57 -> 5603.48 | BG14: ='Top 4 Total'!D57 -> 2507.79 | BH14: ='Top 4 Total'!E57 -> 868.11 | BI14: ='Top 4 Total'!F57 -> 1512.37 | BJ14: ='Top 4 Total'!G57 -> 3160.28 | BK14: ='Top 4 Total'!H57 -> 5078.55 | BL14: ='Top 4 Total'!I57 -> 5818.63 | ... BP14: ='Top 4 Total'!M57 -> 3168.02 | BQ14: ='Top 4 Total'!O35 -> 0.41717999 | BR14: ='Top 4 Total'!P35 -> 0.14064967 | BS14: ='Top 4 Total'!Q35 -> 0.13820677 | BT14: ='Top 4 Total'!R35 -> 0.12393199 | BU14: ='Top 4 Total'!S35 -> 0.19238501 | BV14: ='Top 4 Total'!B35 -> 0.4922848 | BW14: ='Top 4 Total'!C35 -> 0.47449538 | BX14: ='Top 4 Total'!D35 -> 0.2968554 | BY14: ='Top 4 Total'!E35 -> 0.12948846 | BZ14: ='Top 4 Total'!F35 -> 0.17068663 | CA14: ='Top 4 Total'!G35 -> 0.12200837 | CB14: ='Top 4 Total'!H35 -> 0.11438303 | CC14: ='Top 4 Total'!I35 -> 0.15463699 | ... CG14: ='Top 4 Total'!M35 -> 0.09274874 | CH14: ='Top 4 Total'!O17 -> 116541.11 | CI14: ='Top 4 Total'!P17 -> 117049.74 | CJ14: ='Top 4 Total'!Q17 -> 130088.96 | CK14: ='Top 4 Total'!R17 -> 120568.41 | CL14: ='Top 4 Total'!S17 -> 484248.22 | CM14: ='Top 4 Total'!B17 -> 40678.15 | CN14: ='Top 4 Total'!C17 -> 38459.4 | CO14: ='Top 4 Total'!D17 -> 37403.56 | CP14: ='Top 4 Total'!E17 -> 38384.8 | CQ14: ='Top 4 Total'!F17 -> 40191.38 | CR14: ='Top 4 Total'!G17 -> 38473.56 | CS14: ='Top 4 Total'!H17 -> 44295.37 | CT14: ='Top 4 Total'!I17 -> 46530.34 | ... CX14: ='Top 4 Total'!M17 -> 38641.29 | CY14: ='Top 4 Total'!#REF! -> #REF! | CZ14: ='Top 4 Total'!#REF! -> #REF! | DD14: ='Top 4 Total'!B11 -> -0.029828298 | DE14: ='Top 4 Total'!C11 -> 0.11232105 | DF14: ='Top 4 Total'!D11 -> 0.12057248 | DG14: ='Top 4 Total'!E11 -> 0.0035099831 | DH14: ='Top 4 Total'!F11 -> -0.078124215 | DI14: ='Top 4 Total'!G11 -> -0.067007836 | DJ14: ='Top 4 Total'!H11 -> 0.054061406 | DK14: ='Top 4 Total'!I5 -> 0 | DL14: ='Top 4 Total'!J5 -> 0 | DM14: ='Top 4 Total'!K5 -> 0 | DN14: ='Top 4 Total'!L5 -> 0 | DO14: ='Top 4 Total'!M5 -> 0 | DP14: vs 2025
A15: Top 3 Domestic | R15: ='Top4 Domestic'!O102 -> 14512.04 | S15: ='Top4 Domestic'!P102 -> 16749.43 | T15: ='Top4 Domestic'!Q102 -> 30319.81 | U15: ='Top4 Domestic'!R102 -> 32322.86 | V15: ='Top4 Domestic'!S102 -> 93904.14 | W15: ='Top4 Domestic'!B102 -> 9480.64 | X15: ='Top4 Domestic'!C102 -> 1415.19 | Y15: ='Top4 Domestic'!D102 -> 3616.21 | Z15: ='Top4 Domestic'!E102 -> 3837.93 | AA15: ='Top4 Domestic'!F102 -> 5829.99 | AB15: ='Top4 Domestic'!G102 -> 7081.51 | AC15: ='Top4 Domestic'!H102 -> 8970.47 | AD15: ='Top4 Domestic'!I102 -> 10252.54 | ... AH15: ='Top4 Domestic'!M102 -> 9939.53 | AI15: ='Top4 Domestic'!O77 -> 15338.4 | AJ15: ='Top4 Domestic'!P77 -> 22666 | AK15: ='Top4 Domestic'!Q77 -> 16202.9 | AL15: ='Top4 Domestic'!R77 -> 13661.5 | AM15: =AVERAGE(AN15:AY15) -> 5655.7333 | AN15: ='Top4 Domestic'!B77 -> 4358.4 | AO15: ='Top4 Domestic'!C77 -> 3470.3 | AP15: ='Top4 Domestic'!D77 -> 7509.7 | AQ15: ='Top4 Domestic'!E77 -> 8311.8 | AR15: ='Top4 Domestic'!F77 -> 8192.5 | AS15: ='Top4 Domestic'!G77 -> 6161.7 | AT15: ='Top4 Domestic'!H77 -> 7608.6 | AU15: ='Top4 Domestic'!I77 -> 3156.4 | ... AY15: ='Top4 Domestic'!M77 -> 4181.7 | AZ15: ='Top4 Domestic'!O58 -> 10843.5 | BA15: ='Top4 Domestic'!P58 -> 6208.1 | BB15: ='Top4 Domestic'!Q58 -> 13207.6 | BC15: ='Top4 Domestic'!R58 -> 7551.9 | BD15: ='Top4 Domestic'!S58 -> 37811.1 | BE15: ='Top4 Domestic'!B58 -> 4303.3 | BF15: ='Top4 Domestic'!C58 -> 4321.3 | BG15: ='Top4 Domestic'!D58 -> 2218.9 | BH15: ='Top4 Domestic'!E58 -> 1303.1 | BI15: ='Top4 Domestic'!F58 -> 1780.5 | BJ15: ='Top4 Domestic'!G58 -> 3124.5 | BK15: ='Top4 Domestic'!H58 -> 5172.7 | BL15: ='Top4 Domestic'!I58 -> 5065.7 | ... BP15: ='Top4 Domestic'!M58 -> 2846.7 | BQ15: ='Top4 Domestic'!O35 -> 0.28825738 | BR15: ='Top4 Domestic'!P35 -> 0.056132615 | BS15: ='Top4 Domestic'!Q35 -> 0.085496537 | BT15: ='Top4 Domestic'!R35 -> 0.077640853 | BU15: ='Top4 Domestic'!S35 -> 0.11977382 | BV15: ='Top4 Domestic'!B35 -> 0.34941029 | BW15: ='Top4 Domestic'!C35 -> 0.34008231 | BX15: ='Top4 Domestic'!D35 -> 0.18363574 | BY15: ='Top4 Domestic'!E35 -> 0.029102032 | BZ15: ='Top4 Domestic'!F35 -> 0.088346616 | CA15: ='Top4 Domestic'!G35 -> 0.050526552 | CB15: ='Top4 Domestic'!H35 -> 0.057695584 | CC15: ='Top4 Domestic'!I35 -> 0.10282006 | ... CG15: ='Top4 Domestic'!M35 -> 0.049103381 | CH15: ='Top4 Domestic'!O17 -> 99717.33 | CI15: ='Top4 Domestic'!P17 -> 99766.72 | CJ15: ='Top4 Domestic'!Q17 -> 111451.15 | CK15: ='Top4 Domestic'!R17 -> 102011.03 | CL15: ='Top4 Domestic'!S17 -> 412946.23 | CM15: ='Top4 Domestic'!B17 -> 34540.98 | CN15: ='Top4 Domestic'!C17 -> 33231.44 | CO15: ='Top4 Domestic'!D17 -> 31944.91 | CP15: ='Top4 Domestic'!E17 -> 32605.99 | CQ15: ='Top4 Domestic'!F17 -> 34442.48 | CR15: ='Top4 Domestic'!G17 -> 32718.25 | CS15: ='Top4 Domestic'!H17 -> 38033.01 | CT15: ='Top4 Domestic'!I17 -> 39865.24 | ... CX15: ='Top4 Domestic'!M17 -> 32421.43 | CY15: ='Top4 Domestic'!#REF! -> #REF! | CZ15: ='Top4 Domestic'!#REF! -> #REF! | DD15: ='Top4 Domestic'!B11 -> -0.03753831 | DE15: ='Top4 Domestic'!C11 -> 0.098626481 | DF15: ='Top4 Domestic'!D11 -> 0.11001972 | DG15: ='Top4 Domestic'!E11 -> -0.0071916234 | DH15: ='Top4 Domestic'!F11 -> -0.092958173 | DI15: ='Top4 Domestic'!G11 -> -0.078456519 | DJ15: ='Top4 Domestic'!H11 -> 0.053006849 | DK15: ='Top4 Domestic'!I5 -> 0 | DL15: ='Top4 Domestic'!J5 -> 0 | DM15: ='Top4 Domestic'!K5 -> 0 | DN15: ='Top4 Domestic'!L5 -> 0 | DO15: ='Top4 Domestic'!M5 -> 0
A16: Top 3 International (含港澳台） | BQ16: ='Top4 Intl.+Reg'!O206 -> 0 | BR16: ='Top4 Intl.+Reg'!P206 -> 0 | BS16: ='Top4 Intl.+Reg'!Q206 -> 0 | BT16: ='Top4 Intl.+Reg'!R206 -> 0 | BU16: ='Top4 Intl.+Reg'!S206 -> 0 | CE16: ='Top4 Intl.+Reg'!K206 -> 0 | CF16: ='Top4 Intl.+Reg'!L206 -> 0 | CG16: ='Top4 Intl.+Reg'!M206 -> 0 | CH16: ='Top4 Intl.+Reg'!O149 -> 0 | CI16: ='Top4 Intl.+Reg'!P149 -> 0 | CJ16: ='Top4 Intl.+Reg'!Q149 -> 0 | CK16: ='Top4 Intl.+Reg'!R149 -> 0 | CL16: ='Top4 Intl.+Reg'!S149 -> 0 | CM16: ='Top4 Intl.+Reg'!B149 -> 0 | CN16: ='Top4 Intl.+Reg'!C149 -> 0 | CO16: ='Top4 Intl.+Reg'!D149 -> 0 | CP16: ='Top4 Intl.+Reg'!E149 -> 0 | CQ16: ='Top4 Intl.+Reg'!F149 -> 0 | CR16: ='Top4 Intl.+Reg'!G149 -> 0 | CS16: ='Top4 Intl.+Reg'!H149 -> 0 | CT16: ='Top4 Intl.+Reg'!I149 -> 0 | ... CX16: ='Top4 Intl.+Reg'!M149 -> 0 | CY16: ='Top4 Intl.+Reg'!O93 -> 0 | CZ16: ='Top4 Intl.+Reg'!P93 -> 0 | DD16: ='Top4 Intl.+Reg'!B11 -> 0.01806035 | DE16: ='Top4 Intl.+Reg'!C11 -> 0.19935348 | DF16: ='Top4 Intl.+Reg'!D11 -> 0.1823333 | DG16: ='Top4 Intl.+Reg'!E11 -> 0.063888365 | DH16: ='Top4 Intl.+Reg'!F11 -> 0.010748143 | DI16: ='Top4 Intl.+Reg'!G11 -> -0.036464303 | DJ16: ='Top4 Intl.+Reg'!H11 -> 0.060466022 | DK16: ='Top4 Intl.+Reg'!I55 -> #DIV/0! | DL16: ='Top4 Intl.+Reg'!J55 -> #DIV/0! | DM16: ='Top4 Intl.+Reg'!K55 -> #DIV/0! | DN16: ='Top4 Intl.+Reg'!L55 -> #DIV/0! | DO16: ='Top4 Intl.+Reg'!M55 -> #DIV/0! | DP16: vs 2025
A17: Top 3 Regional (港澳台） | R17: ='Top4 Intl.+Reg'!O433 -> 0 | S17: ='Top4 Intl.+Reg'!P433 -> 0 | T17: ='Top4 Intl.+Reg'!Q433 -> 0 | U17: ='Top4 Intl.+Reg'!R433 -> 0 | V17: ='Top4 Intl.+Reg'!S433 -> 0 | W17: ='Top4 Intl.+Reg'!B433 -> 0.064418261 | X17: ='Top4 Intl.+Reg'!C433 -> -0.007682125 | Y17: ='Top4 Intl.+Reg'!D433 -> -0.022144889 | Z17: ='Top4 Intl.+Reg'!E433 -> 0.0082586739 | AA17: ='Top4 Intl.+Reg'!F433 -> 0.0088129174 | AB17: ='Top4 Intl.+Reg'!G433 -> 0.0060535041 | AC17: ='Top4 Intl.+Reg'!H433 -> 0.035942391 | AD17: ='Top4 Intl.+Reg'!I433 -> 0.016577677 | ... AH17: ='Top4 Intl.+Reg'!M433 -> 0.032647027 | AI17: ='Top4 Intl.+Reg'!O374 -> 0 | AJ17: ='Top4 Intl.+Reg'!P374 -> 0 | AK17: ='Top4 Intl.+Reg'!Q374 -> 0 | AL17: ='Top4 Intl.+Reg'!R374 -> 0 | AM17: =AVERAGE(AN17:AY17) -> -0.12189322 | AN17: ='Top4 Intl.+Reg'!B374 -> 0.06682079 | AO17: ='Top4 Intl.+Reg'!C374 -> -0.82582199 | AP17: ='Top4 Intl.+Reg'!D374 -> -0.53612479 | AQ17: ='Top4 Intl.+Reg'!E374 -> -0.85656909 | AR17: ='Top4 Intl.+Reg'!F374 -> 0.24964404 | AS17: ='Top4 Intl.+Reg'!G374 -> 0.1868591 | AT17: ='Top4 Intl.+Reg'!H374 -> 0.2256 | AU17: ='Top4 Intl.+Reg'!I374 -> 0.010443864 | ... AY17: ='Top4 Intl.+Reg'!M374 -> 0.078726968 | AZ17: ='Top4 Intl.+Reg'!O315 -> -0.92557864 | BA17: ='Top4 Intl.+Reg'!P315 -> 0.43441397 | BB17: ='Top4 Intl.+Reg'!Q315 -> -0.23638223 | BC17: ='Top4 Intl.+Reg'!R315 -> -0.36641675 | BD17: ='Top4 Intl.+Reg'!S315 -> -0.766829 | BE17: ='Top4 Intl.+Reg'!B315 -> -0.96614578 | BF17: ='Top4 Intl.+Reg'!C315 -> -0.83095565 | BG17: ='Top4 Intl.+Reg'!D315 -> -0.53875562 | BH17: ='Top4 Intl.+Reg'!E315 -> 1.0755481 | BI17: ='Top4 Intl.+Reg'!F315 -> 0.50143491 | BJ17: ='Top4 Intl.+Reg'!G315 -> 0.021980122 | BK17: ='Top4 Intl.+Reg'!H315 -> -0.081414474 | BL17: ='Top4 Intl.+Reg'!I315 -> -0.24619151 | ... BP17: ='Top4 Intl.+Reg'!M315 -> -0.26326185 | BQ17: ='Top4 Intl.+Reg'!O244 -> 0 | BR17: ='Top4 Intl.+Reg'!P244 -> 0 | BS17: ='Top4 Intl.+Reg'!Q244 -> 0 | BT17: ='Top4 Intl.+Reg'!R244 -> 0 | BU17: ='Top4 Intl.+Reg'!S244 -> 0 | BV17: ='Top4 Intl.+Reg'!B244 -> 0 | BW17: ='Top4 Intl.+Reg'!C244 -> 0 | BX17: ='Top4 Intl.+Reg'!D244 -> 0 | BY17: ='Top4 Intl.+Reg'!E244 -> 0 | BZ17: ='Top4 Intl.+Reg'!F244 -> 0 | CA17: ='Top4 Intl.+Reg'!G244 -> 0 | CB17: ='Top4 Intl.+Reg'!H244 -> 0 | CC17: ='Top4 Intl.+Reg'!I244 -> 0 | ... CG17: ='Top4 Intl.+Reg'!M244 -> 0 | CH17: ='Top4 Intl.+Reg'!O187 -> 0 | CI17: ='Top4 Intl.+Reg'!P187 -> 0 | CJ17: ='Top4 Intl.+Reg'!Q187 -> 0 | CK17: ='Top4 Intl.+Reg'!R187 -> 0 | CL17: ='Top4 Intl.+Reg'!S187 -> 0 | CM17: ='Top4 Intl.+Reg'!B187 -> 0 | CN17: ='Top4 Intl.+Reg'!C187 -> 0 | CO17: ='Top4 Intl.+Reg'!D187 -> 0 | CP17: ='Top4 Intl.+Reg'!E187 -> 0 | CQ17: ='Top4 Intl.+Reg'!F187 -> 0 | CR17: ='Top4 Intl.+Reg'!G187 -> 0 | CS17: ='Top4 Intl.+Reg'!H187 -> 0 | CT17: ='Top4 Intl.+Reg'!I187 -> 0 | ... CX17: ='Top4 Intl.+Reg'!M187 -> 0 | CY17: ='Top4 Intl.+Reg'!O131 -> 0 | CZ17: ='Top4 Intl.+Reg'!P131 -> 0 | DD17: ='Top4 Intl.+Reg'!B49 -> 0.00045889016 | DE17: ='Top4 Intl.+Reg'!C49 -> 0.27438154 | DF17: ='Top4 Intl.+Reg'!D49 -> 0.15786001 | DG17: ='Top4 Intl.+Reg'!E49 -> 0.032633766 | DH17: ='Top4 Intl.+Reg'!F49 -> -0.022880526 | DI17: ='Top4 Intl.+Reg'!G49 -> -0.071197155 | DJ17: ='Top4 Intl.+Reg'!H49 -> -0.0038010873 | DK17: ='Top4 Intl.+Reg'!I92 -> 0.10926856 | DL17: ='Top4 Intl.+Reg'!J92 -> 0.075556262 | DM17: ='Top4 Intl.+Reg'!K92 -> 0.18840612 | DN17: ='Top4 Intl.+Reg'!L92 -> 0.18056154 | DO17: ='Top4 Intl.+Reg'!M92 -> 0.12629327
A18: Top 3 Pure Intl. | R18: ='Top4 Intl.+Reg'!O416 -> 5592.08 | S18: ='Top4 Intl.+Reg'!P416 -> 5598.34 | T18: ='Top4 Intl.+Reg'!Q416 -> 6143.93 | U18: ='Top4 Intl.+Reg'!R416 -> 5590.59 | V18: ='Top4 Intl.+Reg'!S416 -> 22924.94 | W18: ='Top4 Intl.+Reg'!B416 -> 1891.31 | X18: ='Top4 Intl.+Reg'!C416 -> 1843.97 | Y18: ='Top4 Intl.+Reg'!D416 -> 1856.8 | Z18: ='Top4 Intl.+Reg'!E416 -> 1894.33 | AA18: ='Top4 Intl.+Reg'!F416 -> 1839.95 | AB18: ='Top4 Intl.+Reg'!G416 -> 1864.06 | AC18: ='Top4 Intl.+Reg'!H416 -> 2108.59 | AD18: ='Top4 Intl.+Reg'!I416 -> 2188.96 | ... AH18: ='Top4 Intl.+Reg'!M416 -> 1939.73 | AI18: ='Top4 Intl.+Reg'!O357 -> 2333.91 | AJ18: ='Top4 Intl.+Reg'!P357 -> 128.8 | AK18: ='Top4 Intl.+Reg'!Q357 -> 234.03 | AL18: ='Top4 Intl.+Reg'!R357 -> 251.65 | AM18: =AVERAGE(AN18:AY18) -> 245.69917 | AN18: ='Top4 Intl.+Reg'!B357 -> 1951.9 | AO18: ='Top4 Intl.+Reg'!C357 -> 243.77 | AP18: ='Top4 Intl.+Reg'!D357 -> 138.24 | AQ18: ='Top4 Intl.+Reg'!E357 -> 30.51 | AR18: ='Top4 Intl.+Reg'!F357 -> 41.18 | AS18: ='Top4 Intl.+Reg'!G357 -> 57.11 | AT18: ='Top4 Intl.+Reg'!H357 -> 67.41 | AU18: ='Top4 Intl.+Reg'!I357 -> 77.83 | ... AY18: ='Top4 Intl.+Reg'!M357 -> 82.93 | AZ18: ='Top4 Intl.+Reg'!O290 -> 0 | BA18: ='Top4 Intl.+Reg'!P290 -> 0 | BB18: ='Top4 Intl.+Reg'!Q290 -> 0 | BC18: ='Top4 Intl.+Reg'!R290 -> 0 | BD18: ='Top4 Intl.+Reg'!S290 -> 0 | BE18: ='Top4 Intl.+Reg'!B290 -> 0 | BF18: ='Top4 Intl.+Reg'!C290 -> 0 | BG18: ='Top4 Intl.+Reg'!D290 -> 0 | BH18: ='Top4 Intl.+Reg'!E290 -> 0 | BI18: ='Top4 Intl.+Reg'!F290 -> 0 | BJ18: ='Top4 Intl.+Reg'!G290 -> 0 | BK18: ='Top4 Intl.+Reg'!H290 -> 0 | BL18: ='Top4 Intl.+Reg'!I290 -> 0 | ... BP18: ='Top4 Intl.+Reg'!M290 -> 0 | BQ18: ='Top4 Intl.+Reg'!O225 -> 0 | BR18: ='Top4 Intl.+Reg'!P225 -> 0 | BS18: ='Top4 Intl.+Reg'!Q225 -> 0 | BT18: ='Top4 Intl.+Reg'!R225 -> 0 | BU18: ='Top4 Intl.+Reg'!S225 -> 0 | BV18: ='Top4 Intl.+Reg'!B225 -> 0 | BW18: ='Top4 Intl.+Reg'!C225 -> 0 | BX18: ='Top4 Intl.+Reg'!D225 -> 0 | BY18: ='Top4 Intl.+Reg'!E225 -> 0 | BZ18: ='Top4 Intl.+Reg'!F225 -> 0 | CA18: ='Top4 Intl.+Reg'!G225 -> 0 | CB18: ='Top4 Intl.+Reg'!H225 -> 0 | CC18: ='Top4 Intl.+Reg'!I225 -> 0 | ... CG18: ='Top4 Intl.+Reg'!M225 -> 0 | CH18: ='Top4 Intl.+Reg'!O168 -> 0 | CI18: ='Top4 Intl.+Reg'!P168 -> 0 | CJ18: ='Top4 Intl.+Reg'!Q168 -> 0 | CK18: ='Top4 Intl.+Reg'!R168 -> 0 | CL18: ='Top4 Intl.+Reg'!S168 -> 0 | CM18: ='Top4 Intl.+Reg'!B168 -> 0 | CN18: ='Top4 Intl.+Reg'!C168 -> 0 | CO18: ='Top4 Intl.+Reg'!D168 -> 0 | CP18: ='Top4 Intl.+Reg'!E168 -> 0 | CQ18: ='Top4 Intl.+Reg'!F168 -> 0 | CR18: ='Top4 Intl.+Reg'!G168 -> 0 | CS18: ='Top4 Intl.+Reg'!H168 -> 0 | CT18: ='Top4 Intl.+Reg'!I168 -> 0 | ... CX18: ='Top4 Intl.+Reg'!M168 -> 0 | CY18: ='Top4 Intl.+Reg'!O112 -> 0 | CZ18: ='Top4 Intl.+Reg'!P112 -> 0 | DD18: ='Top4 Intl.+Reg'!B30 -> 0.021074989 | DE18: ='Top4 Intl.+Reg'!C30 -> 0.18665557 | DF18: ='Top4 Intl.+Reg'!D30 -> 0.18665035 | DG18: ='Top4 Intl.+Reg'!E30 -> 0.069471044 | DH18: ='Top4 Intl.+Reg'!F30 -> 0.016724881 | DI18: ='Top4 Intl.+Reg'!G30 -> -0.030402564 | DJ18: ='Top4 Intl.+Reg'!H30 -> 0.071581625 | DK18: ='Top4 Intl.+Reg'!I74 -> 0 | DL18: ='Top4 Intl.+Reg'!J74 -> 0 | DM18: ='Top4 Intl.+Reg'!K74 -> 0 | DN18: ='Top4 Intl.+Reg'!L74 -> 0 | DO18: ='Top4 Intl.+Reg'!M74 -> 0
AZ20: vs. 2019 | BQ20: 2023 vs. 2019 | DD20: 2025
A21: (YoY Growth) | B21: 16 Q1 | C21: 16 Q2 | D21: 16 Q3 | E21: 16 Q4 | G21: 17 Q1 | H21: 17Q2 | I21: 17Q3 | J21: 17Q4 | L21: 18 Q1 | M21: 18Q2 | N21: 18Q3 | O21: 18Q4 | P21: Dec | Q21: FY18 | R21: 19Q1 | S21: 19Q2 | T21: 19Q3 | U21: 19Q4 | V21: FY19 | W21: Jan | X21: Feb | Y21: Mar | Z21: Apr | AA21: May | AB21: June | AC21: July | AD21: August | AE21: September | AF21: October | AG21: November | AH21: December | AI21: 20Q1 | AJ21: 20Q2 | AK21: 20Q3 | AL21: 20Q4 | AM21: FY20 | AN21: January | AO21: February | AP21: March | AQ21: April | AR21: May | AS21: June | AT21: July | AU21: August | AV21: September | AW21: October | AX21: November | AY21: December | AZ21: 21Q1 | BA21: 21Q2 | BB21: 21Q3 | BC21: 21Q4 | BD21: FY21 | BE21: Jan | BF21: Feb | BG21: Mar | BH21: Apr | BI21: May | BJ21: Jun | BK21: Jul | BL21: Aug | BM21: Sep | BN21: Oct | BO21: Nov | BP21: Dec | BQ21: 22Q1 | BR21: 22Q2 | BS21: 22Q3 | BT21: 22Q4 | BU21: FY2022 | BV21: Jan | BW21: Feb | BX21: Mar | BY21: Apr | BZ21: May | CA21: Jun | CB21: Jul | CC21: Aug | CD21: Sep | CE21: Oct | CF21: Nov | CG21: Dec | CH21: 23Q1 | CI21: 23Q2 | CJ21: 23Q3 | CK21: 23Q4 | CL21: FY2023 | CM21: Jan | CN21: Feb | CO21: Mar | CP21: April | CQ21: May | CR21: June | CS21: July | CT21: August | CU21: September | CV21: October | CW21: November | CX21: December | CY21: 24Q1 | CZ21: 24Q2 | DA21: 24Q3 | DB21: 24Q4 | DC21: FY2024 | DD21: Jan | DE21: Feb | DF21: Mar | DG21: Apr | DH21: May | DI21: Jun | DJ21: Jul | DK21: Aug | DL21: Sep | DM21: Oct | DN21: Nov | DO21: Dec
A22: Air Industry | B22: 0.10750932 | C22: 0.1114922 | D22: 0.12015316 | E22: 0.13852476 | G22: ='CAAC Data'!O234 -> 130811 | H22: ='CAAC Data'!P234 -> 134612 | I22: ='CAAC Data'!Q234 -> 144005 | J22: ='CAAC Data'!R234 -> 138439 | L22: ='CAAC Data'!O209 -> 142649 | M22: ='CAAC Data'!P209 -> 142849 | N22: ='CAAC Data'!Q209 -> 155632 | O22: ='CAAC Data'!R209 -> 144527 | P22: ='CAAC Data'!M209 -> 46436 | Q22: ='CAAC Data'!N209 -> 585657 | R22: 0.098 | S22: 0.072 | T22: ='CAAC Data'!Q184 -> -0.24316569 | U22: ='CAAC Data'!R184 -> -0.16128378 | V22: ='CAAC Data'!N184 -> -0.381602 | W22: ='CAAC Data'!B184 -> -0.070281803 | X22: ='CAAC Data'!C184 -> -0.84770025 | Y22: ='CAAC Data'!D184 -> -0.69248599 | Z22: ='CAAC Data'!E184 -> -0.64628598 | AA22: ='CAAC Data'!F184 -> -0.46932629 | AB22: ='CAAC Data'!G184 -> -0.3535377 | AC22: ='CAAC Data'!H184 -> -0.2612358 | AD22: ='CAAC Data'!I184 -> -0.15215667 | ... AH22: ='CAAC Data'!M184 -> -0.092083728 | AI22: ='CAAC Data'!O158 -> 0 | AJ22: ='CAAC Data'!P158 -> 0 | AK22: ='CAAC Data'!Q158 -> 0 | AL22: ='CAAC Data'!R158 -> 0 | AM22: ='CAAC Data'!N158 -> 0 | AN22: ='CAAC Data'!B158 -> 0 | AO22: ='CAAC Data'!C158 -> 0 | AP22: ='CAAC Data'!D158 -> 0 | AQ22: ='CAAC Data'!E158 -> 0 | AR22: ='CAAC Data'!F158 -> 0 | AS22: ='CAAC Data'!G158 -> 0 | AT22: ='CAAC Data'!H158 -> 0 | AU22: ='CAAC Data'!I158 -> 0 | ... AY22: ='CAAC Data'!M158 -> 0 | AZ22: ='CAAC Data'!O128 -> 430 | BA22: ='CAAC Data'!P128 -> 332 | BB22: ='CAAC Data'!Q128 -> 629 | BC22: ='CAAC Data'!R128 -> 940 | BD22: ='CAAC Data'!N128 -> 2331 | BE22: ='CAAC Data'!B128 -> 156 | BF22: ='CAAC Data'!C128 -> 151 | BG22: ='CAAC Data'!D128 -> 123 | BH22: ='CAAC Data'!E128 -> 99 | BI22: ='CAAC Data'!F128 -> 106 | BJ22: ='CAAC Data'!G128 -> 127 | BK22: ='CAAC Data'!H128 -> 167 | BL22: ='CAAC Data'!I128 -> 208 | ... BP22: ='CAAC Data'!M128 -> 400 | BQ22: ='CAAC Data'!O97 -> 6.2488372 | BR22: ='CAAC Data'!P97 -> 22.53012 | BS22: ='CAAC Data'!Q97 -> 18.556439 | BT22: ='CAAC Data'!R97 -> 12.306383 | BU22: ='CAAC Data'!N97 -> 14.331617 | BV22: ='CAAC Data'!B97 -> 3.1217949 | BW22: ='CAAC Data'!C97 -> 5.4238411 | BX22: ='CAAC Data'!D97 -> 11.227642 | BY22: ='CAAC Data'!E97 -> 20.606061 | BZ22: ='CAAC Data'!F97 -> 22.896226 | CA22: ='CAAC Data'!G97 -> 23.724409 | CB22: ='CAAC Data'!H97 -> 23.383234 | CC22: ='CAAC Data'!I97 -> 20.149038 | ... CG22: ='CAAC Data'!M97 -> 10.78 | CH22: ='CAAC Data'!O65 -> 0 | CI22: ='CAAC Data'!P65 -> 0 | CJ22: ='CAAC Data'!Q65 -> 0 | CK22: ='CAAC Data'!R65 -> 0 | CL22: ='CAAC Data'!N65 -> 0 | CM22: ='CAAC Data'!B65 -> 0 | CN22: ='CAAC Data'!C65 -> 0 | CO22: ='CAAC Data'!D65 -> 0 | CP22: ='CAAC Data'!E65 -> 0 | CQ22: ='CAAC Data'!F65 -> 0 | CR22: ='CAAC Data'!G65 -> 0 | CS22: ='CAAC Data'!H65 -> 0 | CT22: ='CAAC Data'!I65 -> 0 | ... CX22: ='CAAC Data'!M65 -> 0 | CY22: ='CAAC Data'!O38 -> 0.028435147 | CZ22: ='CAAC Data'!P38 -> 0.054925711 | DA22: ='CAAC Data'!Q38 -> 0.027645356 | DB22: ='CAAC Data'!R38 -> 0.051480156 | DD22: ='CAAC Data'!B30 -> 0.13220978 | DE22: ='CAAC Data'!C30 -> -0.015412932 | DF22: ='CAAC Data'!D30 -> 0.035103604 | DG22: ='CAAC Data'!E30 -> 0.089008043 | DH22: ='CAAC Data'!F30 -> 0.081534202 | DI22: ='CAAC Data'!G30 -> 0.043535328 | DJ22: ='CAAC Data'!H30 -> 0.038822032 | DK22: ='CAAC Data'!I30 -> 0.033416979 | ... DO22: ='CAAC Data'!M30 -> 0.063622163
A23: Air Industry Domestic | B23: 0.087711662 | C23: 0.10188276 | D23: 0.10975386 | E23: 0.15565676 | G23: ='CAAC Data'!O238 -> 18151 | H23: ='CAAC Data'!P238 -> 18428 | I23: ='CAAC Data'!Q238 -> 19578 | J23: ='CAAC Data'!R238 -> 18745 | L23: ='CAAC Data'!O213 -> 21128 | M23: ='CAAC Data'!P213 -> 21336 | N23: ='CAAC Data'!Q213 -> 22406 | O23: ='CAAC Data'!R213 -> 20422 | P23: ='CAAC Data'!M213 -> 7020 | Q23: ='CAAC Data'!N213 -> 85292 | R23: 0.089 | S23: ='CAAC Data'!P188 -> -0.98350206 | T23: ='CAAC Data'!Q188 -> -0.99616054 | U23: ='CAAC Data'!R188 -> -0.99576477 | V23: ='CAAC Data'!N188 -> -0.87669418 | W23: ='CAAC Data'!B188 -> 0.027860274 | X23: ='CAAC Data'!C188 -> -0.83886663 | Y23: 0.027 | Z23: ='CAAC Data'!E188 -> -0.98835578 | AA23: ='CAAC Data'!F188 -> -0.98392555 | AB23: ='CAAC Data'!G188 -> -0.9782181 | AC23: ='CAAC Data'!H188 -> -0.97672907 | AD23: ='CAAC Data'!I188 -> -0.97546244 | AE23: ='CAAC Data'!J188 -> -0.96852372 | AF23: ='CAAC Data'!K188 -> -0.96776568 | AG23: ='CAAC Data'!L188 -> -0.97139831 | AH23: ='CAAC Data'!M188 -> -0.97222222 | AI23: ='CAAC Data'!O162 -> -0.2039801 | AJ23: ='CAAC Data'!P162 -> 0.24583333 | AK23: ='CAAC Data'!Q162 -> -0.081939799 | AL23: ='CAAC Data'!R162 -> -0.19489982 | AM23: ='CAAC Data'!N162 -> 0 | AN23: ='CAAC Data'!B162 -> -0.97464387 | AO23: ='CAAC Data'!C162 -> -0.33707865 | AP23: ='CAAC Data'!D162 -> 0.55932203 | AQ23: ='CAAC Data'!E162 -> 0.016304348 | AR23: ='CAAC Data'!F162 -> 0.12834225 | AS23: ='CAAC Data'!G162 -> -0.052132701 | AT23: ='CAAC Data'!H162 -> 0.065 | AU23: ='CAAC Data'!I162 -> -0.1971831 | ... AY23: ='CAAC Data'!M162 -> 0.20289855 | AZ23: ='CAAC Data'!O133 -> 274 | BA23: ='CAAC Data'!P133 -> 310 | BB23: ='CAAC Data'!Q133 -> 536 | BC23: ='CAAC Data'!R133 -> 741 | BD23: ='CAAC Data'!N133 -> 1861 | BE23: ='CAAC Data'!B133 -> 92 | BF23: ='CAAC Data'!C133 -> 82 | BG23: ='CAAC Data'!D133 -> 100 | BH23: ='CAAC Data'!E133 -> 93 | BI23: ='CAAC Data'!F133 -> 100 | BJ23: ='CAAC Data'!G133 -> 117 | BK23: ='CAAC Data'!H133 -> 146 | BL23: ='CAAC Data'!I133 -> 178 | ... BP23: ='CAAC Data'!M133 -> 308 | BQ23: ='CAAC Data'!O102 -> 7.1824818 | BR23: ='CAAC Data'!P102 -> 18.764516 | BS23: ='CAAC Data'!Q102 -> 18.106343 | BT23: ='CAAC Data'!R102 -> 13.093117 | BU23: ='CAAC Data'!N102 -> 14.611499 | BV23: ='CAAC Data'!B102 -> 3.8043478 | BW23: ='CAAC Data'!C102 -> 7.6097561 | BX23: ='CAAC Data'!D102 -> 9.94 | BY23: ='CAAC Data'!E102 -> 16.44086 | BZ23: ='CAAC Data'!F102 -> 18.76 | CA23: ='CAAC Data'!G102 -> 20.615385 | CB23: ='CAAC Data'!H102 -> 21.965753 | CC23: ='CAAC Data'!I102 -> 19.477528 | ... CG23: ='CAAC Data'!M102 -> 11.948052 | CH23: ='CAAC Data'!O70 -> 0 | CI23: ='CAAC Data'!P70 -> 0 | CJ23: ='CAAC Data'!Q70 -> 0 | CK23: ='CAAC Data'!R70 -> 0 | CL23: ='CAAC Data'!N70 -> 0 | CM23: ='CAAC Data'!B70 -> 0 | CN23: ='CAAC Data'!C70 -> 0 | CO23: ='CAAC Data'!D70 -> 0 | CP23: ='CAAC Data'!E70 -> 0 | CQ23: ='CAAC Data'!F70 -> 0 | CR23: ='CAAC Data'!G70 -> 0 | CS23: ='CAAC Data'!H70 -> 0 | CT23: ='CAAC Data'!I70 -> 0 | ... CX23: ='CAAC Data'!M70 -> 0 | CY23: ='CAAC Data'!O42 -> 0.002887164 | CZ23: ='CAAC Data'!P42 -> 0.015091864 | DD23: ='CAAC Data'!B34 -> 0.11108344 | DE23: ='CAAC Data'!C34 -> -0.033474203 | DF23: ='CAAC Data'!D34 -> 0.015071692 | DG23: ='CAAC Data'!E34 -> 0.07286766 | DH23: ='CAAC Data'!F34 -> 0.065472596 | DI23: ='CAAC Data'!G34 -> 0.028626936 | DJ23: ='CAAC Data'!H34 -> 0.028079943 | DK23: ='CAAC Data'!I34 -> 0.022342617 | ... DO23: ='CAAC Data'!M34 -> 0.060561744 | DP23: vs 2024
A24: Air Industry International (含港澳台） | BQ24: ='CAAC Data'!O112 -> Q1 | BR24: ='CAAC Data'!P112 -> Q2 | BS24: ='CAAC Data'!Q112 -> Q3 | BT24: ='CAAC Data'!R112 -> Q4 | BU24: ='CAAC Data'!R112 -> Q4 | CE24: ='CAAC Data'!K112 -> Oct | CF24: ='CAAC Data'!L112 -> Nov | CG24: ='CAAC Data'!M112 -> Dec | CH24: ='CAAC Data'!O80 -> Q1 | CI24: ='CAAC Data'!P80 -> Q2 | CJ24: ='CAAC Data'!Q80 -> Q3 | CK24: ='CAAC Data'!R80 -> Q4 | CL24: ='CAAC Data'!N80 -> Year | CM24: ='CAAC Data'!B80 -> Jan | CN24: ='CAAC Data'!C80 -> Feb | CO24: ='CAAC Data'!D80 -> Mar | CP24: ='CAAC Data'!E80 -> Apr | CQ24: ='CAAC Data'!F80 -> May | CR24: ='CAAC Data'!G80 -> Jun | CS24: ='CAAC Data'!H80 -> Jul | CT24: ='CAAC Data'!I80 -> Aug | ... CX24: ='CAAC Data'!M80 -> Dec | CY24: ='CAAC Data'!O50 -> -0.017361111 | CZ24: ='CAAC Data'!P50 -> 0.023031826 | DD24: ='CAAC Data'!B42 -> 0.09121765 | DE24: ='CAAC Data'!C42 -> -0.051659989 | DF24: ='CAAC Data'!D42 -> -0.031546188 | DG24: ='CAAC Data'!E42 -> 0.013748597 | DH24: ='CAAC Data'!F42 -> 0.017907501 | DI24: ='CAAC Data'!G42 -> 0.013631254 | DJ24: ='CAAC Data'!H42 -> 0.031201248 | DK24: ='CAAC Data'!I42 -> 0.053856801 | ... DO24: ='CAAC Data'!M42 -> 0.091737892 | DP24: vs 2019
A25: Air Industry Regional (港澳台） | B25: 0.05108055 | C25: -0.025937749 | D25: -0.073217726 | E25: -0.09194499 | F25: ='CAAC Data'!N254 -> 0 | G25: ='CAAC Data'!O254 -> 0 | H25: ='CAAC Data'!P254 -> 0 | I25: ='CAAC Data'!Q254 -> 0 | J25: ='CAAC Data'!R254 -> 0 | K25: ='CAAC Data'!S254 -> 0 | L25: ='CAAC Data'!O229 -> 0 | M25: ='CAAC Data'!P229 -> 0 | N25: ='CAAC Data'!Q229 -> 0 | O25: ='CAAC Data'!R229 -> 0 | P25: ='CAAC Data'!M229 -> 0 | Q25: ='CAAC Data'!N229 -> 0 | R25: 0.138 | S25: ='CAAC Data'!P204 -> 0 | T25: ='CAAC Data'!Q204 -> 0 | U25: ='CAAC Data'!R204 -> 0 | V25: ='CAAC Data'!N204 -> 0 | W25: ='CAAC Data'!B204 -> 0 | X25: ='CAAC Data'!C204 -> 0 | Y25: 0.141 | Z25: ='CAAC Data'!E204 -> 0 | AA25: ='CAAC Data'!F204 -> 0 | AB25: ='CAAC Data'!G204 -> 0 | AC25: ='CAAC Data'!H204 -> 0 | AD25: ='CAAC Data'!I204 -> 0 | AE25: ='CAAC Data'!J204 -> 0 | AF25: ='CAAC Data'!K204 -> 0 | AG25: ='CAAC Data'!L204 -> 0 | AH25: ='CAAC Data'!M204 -> 0 | AI25: ='CAAC Data'!O178 -> 0 | AJ25: ='CAAC Data'!P178 -> 0 | AK25: ='CAAC Data'!Q178 -> 0 | AL25: ='CAAC Data'!R178 -> 0 | AM25: ='CAAC Data'!N178 -> 0 | AN25: ='CAAC Data'!B178 -> 0 | AO25: ='CAAC Data'!C178 -> 0 | AP25: ='CAAC Data'!D178 -> 0 | AQ25: ='CAAC Data'!E178 -> 0 | AR25: ='CAAC Data'!F178 -> 0 | AS25: ='CAAC Data'!G178 -> 0 | AT25: ='CAAC Data'!H178 -> 0 | AU25: ='CAAC Data'!I178 -> 0 | ... AY25: ='CAAC Data'!M178 -> 0 | AZ25: ='CAAC Data'!O153 -> 0 | BA25: ='CAAC Data'!P153 -> 0 | BB25: ='CAAC Data'!Q153 -> 0 | BC25: ='CAAC Data'!R153 -> 0 | BD25: ='CAAC Data'!N153 -> 0 | BE25: ='CAAC Data'!B153 -> 0 | BF25: ='CAAC Data'!C153 -> 0 | BG25: ='CAAC Data'!D153 -> 0 | BH25: ='CAAC Data'!E153 -> 0 | BI25: ='CAAC Data'!F153 -> 0 | BJ25: ='CAAC Data'!G153 -> 0 | BK25: ='CAAC Data'!H153 -> 0 | BL25: ='CAAC Data'!I153 -> 0 | ... BP25: ='CAAC Data'!M153 -> 0 | BQ25: ='CAAC Data'!O122 -> 0 | BR25: ='CAAC Data'!P122 -> 0 | BS25: ='CAAC Data'!Q122 -> 0 | BT25: ='CAAC Data'!R122 -> 0 | BU25: ='CAAC Data'!N122 -> 0 | BV25: ='CAAC Data'!B122 -> 0 | BW25: ='CAAC Data'!C122 -> 0 | BX25: ='CAAC Data'!D122 -> 0 | BY25: ='CAAC Data'!E122 -> 0 | BZ25: ='CAAC Data'!F122 -> 0 | CA25: ='CAAC Data'!G122 -> 0 | CB25: ='CAAC Data'!H122 -> 0 | CC25: ='CAAC Data'!I122 -> 0 | ... CG25: ='CAAC Data'!M122 -> 0 | CH25: ='CAAC Data'!O90 -> 0 | CI25: ='CAAC Data'!P90 -> 0 | CJ25: ='CAAC Data'!Q90 -> 0 | CK25: ='CAAC Data'!R90 -> 0 | CL25: ='CAAC Data'!N90 -> 0 | CM25: ='CAAC Data'!B90 -> 0 | CN25: ='CAAC Data'!C90 -> 0 | CO25: ='CAAC Data'!D90 -> 0 | CP25: ='CAAC Data'!E90 -> 0 | CQ25: ='CAAC Data'!F90 -> 0 | CR25: ='CAAC Data'!G90 -> 0 | CS25: ='CAAC Data'!H90 -> 0 | CT25: ='CAAC Data'!I90 -> 0 | ... CX25: ='CAAC Data'!M90 -> 0 | CY25: ='CAAC Data'!O59 -> 160804 | CZ25: ='CAAC Data'!P59 -> 155543.5 | DD25: ='CAAC Data'!B51 -> -0.18373494 | DE25: ='CAAC Data'!C51 -> -0.32019704 | DF25: ='CAAC Data'!D51 -> -0.25610948 | DG25: ='CAAC Data'!E51 -> -0.22519084 | DH25: ='CAAC Data'!F51 -> -0.23656927 | DI25: ='CAAC Data'!G51 -> -0.20676329 | DJ25: ='CAAC Data'!H51 -> -0.23865699 | DK25: ='CAAC Data'!I51 -> -0.027777778 | ... DO25: ='CAAC Data'!M51 -> 0.18965517
A26: Air Industry Pure Intl. | B26: 0.31084163 | C26: 0.23291712 | D26: 0.26009922 | E26: 0.11605593 | G26: ='CAAC Data'!O250 -> Q1 | H26: ='CAAC Data'!P250 -> Q2 | I26: ='CAAC Data'!Q250 -> Q3 | J26: ='CAAC Data'!R250 -> Q4 | L26: ='CAAC Data'!O225 -> Q1 | M26: ='CAAC Data'!P225 -> Q2 | N26: ='CAAC Data'!Q225 -> Q3 | O26: ='CAAC Data'!R225 -> Q4 | P26: ='CAAC Data'!M225 -> Dec | Q26: ='CAAC Data'!N225 -> Year | R26: 0.167 | S26: 0.163 | T26: ='CAAC Data'!Q200 -> Q3 | U26: ='CAAC Data'!R200 -> Q4 | V26: ='CAAC Data'!N200 -> Year | W26: ='CAAC Data'!B200 -> Jan | X26: ='CAAC Data'!C200 -> Feb | Y26: 0.141 | Z26: ='CAAC Data'!E200 -> Apr | AA26: ='CAAC Data'!F200 -> May | AB26: ='CAAC Data'!G200 -> Jun | AC26: ='CAAC Data'!H200 -> Jul | AD26: ='CAAC Data'!I200 -> Aug | AE26: ='CAAC Data'!J200 -> Sep | AF26: ='CAAC Data'!K200 -> Oct | AG26: ='CAAC Data'!L200 -> Nov | AH26: ='CAAC Data'!M200 -> Dec | AI26: ='CAAC Data'!O174 -> Q1 | AJ26: ='CAAC Data'!P174 -> Q2 | AK26: ='CAAC Data'!Q174 -> Q3 | AL26: ='CAAC Data'!R174 -> Q4 | AM26: ='CAAC Data'!N174 -> Year | AN26: ='CAAC Data'!B174 -> Jan | AO26: ='CAAC Data'!C174 -> Feb | AP26: ='CAAC Data'!D174 -> Mar | AQ26: ='CAAC Data'!E174 -> Apr | AR26: ='CAAC Data'!F174 -> May | AS26: ='CAAC Data'!G174 -> Jun | AT26: ='CAAC Data'!H174 -> Jul | AU26: ='CAAC Data'!I174 -> Aug | ... AY26: ='CAAC Data'!M174 -> Dec | AZ26: ='CAAC Data'!O148 -> 0 | BA26: ='CAAC Data'!P148 -> 0 | BB26: ='CAAC Data'!Q148 -> 0 | BC26: ='CAAC Data'!R148 -> 0 | BD26: ='CAAC Data'!N148 -> 0 | BE26: ='CAAC Data'!B148 -> 0 | BF26: ='CAAC Data'!C148 -> 0 | BG26: ='CAAC Data'!D148 -> 0 | BH26: ='CAAC Data'!E148 -> 0 | BI26: ='CAAC Data'!F148 -> 0 | BJ26: ='CAAC Data'!G148 -> 0 | BK26: ='CAAC Data'!H148 -> 0 | BL26: ='CAAC Data'!I148 -> 0 | ... BP26: ='CAAC Data'!M148 -> 0 | BQ26: ='CAAC Data'!O117 -> 0 | BR26: ='CAAC Data'!P117 -> 0 | BS26: ='CAAC Data'!Q117 -> 0 | BT26: ='CAAC Data'!R117 -> 0 | BU26: ='CAAC Data'!N117 -> 0 | BV26: ='CAAC Data'!B117 -> 0 | BW26: ='CAAC Data'!C117 -> 0 | BX26: ='CAAC Data'!D117 -> 0 | BY26: ='CAAC Data'!E117 -> 0 | BZ26: ='CAAC Data'!F117 -> 0 | CA26: ='CAAC Data'!G117 -> 0 | CB26: ='CAAC Data'!H117 -> 0 | CC26: ='CAAC Data'!I117 -> 0 | ... CG26: ='CAAC Data'!M117 -> 0 | CH26: ='CAAC Data'!O85 -> 0 | CI26: ='CAAC Data'!P85 -> 0 | CJ26: ='CAAC Data'!Q85 -> 0 | CK26: ='CAAC Data'!R85 -> 0 | CL26: ='CAAC Data'!N85 -> 0 | CM26: ='CAAC Data'!B85 -> 0 | CN26: ='CAAC Data'!C85 -> 0 | CO26: ='CAAC Data'!D85 -> 0 | CP26: ='CAAC Data'!E85 -> 0 | CQ26: ='CAAC Data'!F85 -> 0 | CR26: ='CAAC Data'!G85 -> 0 | CS26: ='CAAC Data'!H85 -> 0 | CT26: ='CAAC Data'!I85 -> 0 | ... CX26: ='CAAC Data'!M85 -> 0 | CY26: ='CAAC Data'!O55 -> 177228 | CZ26: ='CAAC Data'!P55 -> 173486 | DD26: ='CAAC Data'!B47 -> 0.1362963 | DE26: ='CAAC Data'!C47 -> -0.006027122 | DF26: ='CAAC Data'!D47 -> 0.0064505458 | DG26: ='CAAC Data'!E47 -> 0.054934211 | DH26: ='CAAC Data'!F47 -> 0.062676173 | DI26: ='CAAC Data'!G47 -> 0.051142904 | DJ26: ='CAAC Data'!H47 -> 0.076327769 | DK26: ='CAAC Data'!I47 -> 0.064755384 | ... DO26: ='CAAC Data'!M47 -> 0.080961417
A27: Air Industry Regional + Int'l | G27: ='CAAC Data'!O246 -> 2664 | H27: ='CAAC Data'!P246 -> 2791 | I27: ='CAAC Data'!Q246 -> 2947 | J27: ='CAAC Data'!R246 -> 2868 | L27: ='CAAC Data'!O221 -> 3034 | M27: ='CAAC Data'!P221 -> 3144 | N27: ='CAAC Data'!Q221 -> 2746 | O27: ='CAAC Data'!R221 -> 2150 | R27: ='CAAC Data'!O196 -> -0.74324324 | S27: ='CAAC Data'!P196 -> -0.99077608 | T27: ='CAAC Data'!Q196 -> -0.99714362 | U27: ='CAAC Data'!R196 -> -0.99564195 | V27: ='CAAC Data'!N196 -> -0.91322016
A28: Top 4 | B28: 0.060036962 | C28: 0.05812427 | D28: 0.058366282 | E28: 0.10286248 | G28: 0.14579564 | H28: 0.13840441 | I28: 0.11539155 | J28: 0.16008565 | L28: 0.098091979 | M28: 0.12461765 | N28: 0.095081407 | O28: 0.07717282 | P28: 0.065459285 | Q28: 0.098298189 | R28: ='Top 4 Total'!O109 -> -0.5421878 | S28: 0.058 | T28: ='Top 4 Total'!Q109 -> -0.27111561 | U28: ='Top 4 Total'!R109 -> -0.19752605 | V28: =AVERAGE(R28:U28) -> -0.23820737 | W28: ='Top 4 Total'!B109 -> -0.046842394 | X28: ='Top 4 Total'!C109 -> -0.85757162 | Y28: ='Top 4 Total'!D109 -> -0.72302854 | Z28: ='Top 4 Total'!E109 -> -0.71107623 | AA28: ='Top 4 Total'!F109 -> -0.56828482 | AB28: ='Top 4 Total'!G109 -> -0.47586373 | AC28: ='Top 4 Total'!H109 -> -0.37369303 | AD28: ='Top 4 Total'!I109 -> -0.2885702 | ... AH28: ='Top 4 Total'!M109 -> -0.26173441 | AN28: ='Top 4 Total'!N109 -> 0 | AO28: ='Top 4 Total'!O109 -> -0.5421878 | AP28: ='Top 4 Total'!P109 -> -0.5846731 | AQ28: ='Top 4 Total'!Q109 -> -0.27111561 | AR28: ='Top 4 Total'!R109 -> -0.19752605 | AS28: ='Top 4 Total'!S109 -> -0.39512331 | AT28: ='Top 4 Total'!T109 -> 0
A29: Top 4 Domestic | B29: 0.034646531 | C29: 0.041705997 | D29: 0.042045547 | E29: 0.10895083 | G29: 0.15885514 | H29: 0.15682134 | I29: 0.12480783 | J29: 0.16222328 | L29: 0.097018099 | M29: 0.11363947 | N29: 0.091145877 | O29: 0.072192825 | P29: 0.056820942 | Q29: 0.093101817 | R29: ='Top4 Domestic'!O122 -> 0 | S29: 0.047 | T29: ='Top4 Domestic'!Q122 -> 0 | U29: ='Top4 Domestic'!R122 -> 0 | V29: =AVERAGE(R29:U29) -> 0.01175 | W29: ='Top4 Domestic'!B122 -> -1 | X29: ='Top4 Domestic'!C122 -> #DIV/0! | Y29: ='Top4 Domestic'!D122 -> #DIV/0! | Z29: ='Top4 Domestic'!E122 -> #DIV/0! | AA29: ='Top4 Domestic'!F122 -> #DIV/0! | AB29: ='Top4 Domestic'!G122 -> #DIV/0! | AC29: ='Top4 Domestic'!H122 -> #DIV/0! | AD29: ='Top4 Domestic'!I122 -> #DIV/0! | ... AH29: ='Top4 Domestic'!M122 -> #DIV/0! | AN29: ='Top4 Domestic'!N122 -> 0 | AO29: ='Top4 Domestic'!O122 -> 0 | AP29: ='Top4 Domestic'!P122 -> 0 | AQ29: ='Top4 Domestic'!Q122 -> 0 | AR29: ='Top4 Domestic'!R122 -> 0 | AS29: ='Top4 Domestic'!S122 -> 0 | AT29: ='Top4 Domestic'!T122 -> 0
A30: Top 4 Regional (港澳台） | B30: 0.094145204 | C30: 5.9756404e-05 | D30: -0.04779835 | E30: -0.071659694 | G30: -0.083474674 | H30: 0.0050705334 | I30: 0.094197073 | J30: 0.15460566 | L30: 0.097493155 | M30: 0.13401207 | N30: 0.099752247 | O30: 0.074324106 | P30: 0.086705343 | Q30: 0.10079624 | R30: ='Top4 Intl.+Reg'!O453 -> -1 | S30: ='Top4 Intl.+Reg'!P453 -> -1 | T30: ='Top4 Intl.+Reg'!Q453 -> -1 | U30: ='Top4 Intl.+Reg'!R453 -> -1 | V30: =AVERAGE(R30:U30) -> -1 | W30: ='Top4 Intl.+Reg'!B453 -> 0.30513065 | X30: ='Top4 Intl.+Reg'!C453 -> 0.20746758 | Y30: ='Top4 Intl.+Reg'!D453 -> 0.18114638 | Z30: ='Top4 Intl.+Reg'!E453 -> 0.21334841 | AA30: ='Top4 Intl.+Reg'!F453 -> 0.19381585 | AB30: ='Top4 Intl.+Reg'!G453 -> 0.21771282 | AC30: ='Top4 Intl.+Reg'!H453 -> 0.20284157 | AD30: ='Top4 Intl.+Reg'!I453 -> 0.20591061 | ... AH30: ='Top4 Intl.+Reg'!M453 -> -0.085921118 | AN30: ='Top4 Intl.+Reg'!N453 -> 0 | AO30: ='Top4 Intl.+Reg'!O453 -> -1 | AP30: ='Top4 Intl.+Reg'!P453 -> -1 | AQ30: ='Top4 Intl.+Reg'!Q453 -> -1 | AR30: ='Top4 Intl.+Reg'!R453 -> -1 | AS30: ='Top4 Intl.+Reg'!S453 -> -1 | AT30: ='Top4 Intl.+Reg'!T453 -> 0
A31: Top 4 International | B31: 0.23300681 | C31: 0.1919311 | D31: 0.20632696 | E31: 0.097730886 | G31: 0.1158186 | H31: 0.037943055 | I31: 0.055793714 | J31: 0.14542448 | L31: 0.10587235 | M31: 0.20714073 | N31: 0.12276586 | O31: 0.11536644 | P31: 0.12183289 | Q31: 0.13623741 | R31: ='Top4 Intl.+Reg'!O436 -> 0 | S31: ='Top4 Intl.+Reg'!P436 -> 0 | T31: ='Top4 Intl.+Reg'!Q436 -> 0 | U31: ='Top4 Intl.+Reg'!R436 -> 0 | V31: =AVERAGE(R31:U31) -> 0 | W31: ='Top4 Intl.+Reg'!B436 -> 0.060410406 | X31: ='Top4 Intl.+Reg'!C436 -> 0.00039853869 | Y31: ='Top4 Intl.+Reg'!D436 -> 0.025496315 | Z31: ='Top4 Intl.+Reg'!E436 -> 0.063148808 | AA31: ='Top4 Intl.+Reg'!F436 -> -0.019792534 | AB31: ='Top4 Intl.+Reg'!G436 -> 0.067017355 | AC31: ='Top4 Intl.+Reg'!H436 -> 0.10791507 | AD31: ='Top4 Intl.+Reg'!I436 -> 0.066728566 | ... AH31: ='Top4 Intl.+Reg'!M436 -> 0.11537459 | AN31: ='Top4 Intl.+Reg'!N436 -> 0 | AO31: ='Top4 Intl.+Reg'!O436 -> 0 | AP31: ='Top4 Intl.+Reg'!P436 -> 0 | AQ31: ='Top4 Intl.+Reg'!Q436 -> 0 | AR31: ='Top4 Intl.+Reg'!R436 -> 0 | AS31: ='Top4 Intl.+Reg'!S436 -> 0 | AT31: ='Top4 Intl.+Reg'!T436 -> 0
