Workbook

Sheet Top 20
B2: 核心股东持仓情况
B3: · 25Q4 -> 26Q1, Top 20股东持仓较之前季度波动较大
B4: 需关注Capital World 减持19%， Morgan Stanley 减持15%，Wellington减持68%，Capital International减持94%，Schroder UK减持68%，Arga减持27%
B5: 上季度加仓: CSOP 增持20%，Davis 增持31%
B6: · 26Q1 Top 20 view, Rothschild 增持42%， 华夏基金增持23%
B8: Top 20 25Q4 -> 26Q1
B10: Institution Name | C10: 25Q4 Rank | D10: 26Q1 Rank | E10: Rank Change | F10: % S/O 25Q4 | G10: % S/O 26Q1 | H10: % S/O Change
B11: Capital World Investors (U.S.) | C11: =INDEX('SH Summary'!A:A,MATCH(B11,'SH Summary'!C:C,0)) -> 0 | D11: =INDEX('SH Summary'!B:B,MATCH(B11,'SH Summary'!C:C,0)) -> 1 | E11: =C11-D11 -> -1 | F11: =VLOOKUP(B11,'SH Summary'!C:L,9,FALSE) -> 0 | G11: =VLOOKUP(B11,'SH Summary'!C:L,10,FALSE) -> 0.062420518 | H11: =G11/F11-1 -> #DIV/0!
B12: The Vanguard Group, Inc. | C12: =INDEX('SH Summary'!A:A,MATCH(B12,'SH Summary'!C:C,0)) -> 0 | D12: =INDEX('SH Summary'!B:B,MATCH(B12,'SH Summary'!C:C,0)) -> 2 | E12: =C12-D12 -> -2 | F12: =VLOOKUP(B12,'SH Summary'!C:L,9,FALSE) -> 0 | G12: =VLOOKUP(B12,'SH Summary'!C:L,10,FALSE) -> 0.032561846 | H12: =G12/F12-1 -> #DIV/0!
B13: BlackRock Fund Advisors | C13: =INDEX('SH Summary'!A:A,MATCH(B13,'SH Summary'!C:C,0)) -> 0 | D13: =INDEX('SH Summary'!B:B,MATCH(B13,'SH Summary'!C:C,0)) -> 3 | E13: =C13-D13 -> -3 | F13: =VLOOKUP(B13,'SH Summary'!C:L,9,FALSE) -> 0 | G13: =VLOOKUP(B13,'SH Summary'!C:L,10,FALSE) -> 0.026587593 | H13: =G13/F13-1 -> #DIV/0!
B14: Morgan Stanley Investment Management Inc. | C14: =INDEX('SH Summary'!A:A,MATCH(B14,'SH Summary'!C:C,0)) -> 0 | D14: =INDEX('SH Summary'!B:B,MATCH(B14,'SH Summary'!C:C,0)) -> 4 | E14: =C14-D14 -> -4 | F14: =VLOOKUP(B14,'SH Summary'!C:L,9,FALSE) -> 0 | G14: =VLOOKUP(B14,'SH Summary'!C:L,10,FALSE) -> 0.017337715 | H14: =G14/F14-1 -> #DIV/0!
B15: Norges Bank Investment Management (Norway) | C15: =INDEX('SH Summary'!A:A,MATCH(B15,'SH Summary'!C:C,0)) -> 0 | D15: =INDEX('SH Summary'!B:B,MATCH(B15,'SH Summary'!C:C,0)) -> 5 | E15: =C15-D15 -> -5 | F15: =VLOOKUP(B15,'SH Summary'!C:L,9,FALSE) -> 0 | G15: =VLOOKUP(B15,'SH Summary'!C:L,10,FALSE) -> 0.016915321 | H15: =G15/F15-1 -> #DIV/0!
B16: Sanders Capital, LLC | C16: =INDEX('SH Summary'!A:A,MATCH(B16,'SH Summary'!C:C,0)) -> 0 | D16: =INDEX('SH Summary'!B:B,MATCH(B16,'SH Summary'!C:C,0)) -> 6 | E16: =C16-D16 -> -6 | F16: =VLOOKUP(B16,'SH Summary'!C:L,9,FALSE) -> 0 | G16: =VLOOKUP(B16,'SH Summary'!C:L,10,FALSE) -> 0.016395866 | H16: =G16/F16-1 -> #DIV/0!
B17: Wellington Management Company, LLP | C17: =INDEX('SH Summary'!A:A,MATCH(B17,'SH Summary'!C:C,0)) -> 0 | D17: =INDEX('SH Summary'!B:B,MATCH(B17,'SH Summary'!C:C,0)) -> 31 | E17: =C17-D17 -> -31 | F17: =VLOOKUP(B17,'SH Summary'!C:L,9,FALSE) -> 0 | G17: =VLOOKUP(B17,'SH Summary'!C:L,10,FALSE) -> 0.0036509181 | H17: =G17/F17-1 -> #DIV/0!
B18: BlackRock Advisors (U.K.), LTD | C18: =INDEX('SH Summary'!A:A,MATCH(B18,'SH Summary'!C:C,0)) -> 0 | D18: =INDEX('SH Summary'!B:B,MATCH(B18,'SH Summary'!C:C,0)) -> 10 | E18: =C18-D18 -> -10 | F18: =VLOOKUP(B18,'SH Summary'!C:L,9,FALSE) -> 0 | G18: =VLOOKUP(B18,'SH Summary'!C:L,10,FALSE) -> 0.009917748 | H18: =G18/F18-1 -> #DIV/0!
B19: E Fund Management Company, LTD | C19: =INDEX('SH Summary'!A:A,MATCH(B19,'SH Summary'!C:C,0)) -> 0 | D19: =INDEX('SH Summary'!B:B,MATCH(B19,'SH Summary'!C:C,0)) -> 7 | E19: =C19-D19 -> -7 | F19: =VLOOKUP(B19,'SH Summary'!C:L,9,FALSE) -> 0 | G19: =VLOOKUP(B19,'SH Summary'!C:L,10,FALSE) -> 0.010429944 | H19: =G19/F19-1 -> #DIV/0!
B20: Capital International Investors | C20: =INDEX('SH Summary'!A:A,MATCH(B20,'SH Summary'!C:C,0)) -> 0 | D20: =INDEX('SH Summary'!B:B,MATCH(B20,'SH Summary'!C:C,0)) -> 125 | E20: =C20-D20 -> -125 | F20: =VLOOKUP(B20,'SH Summary'!C:L,9,FALSE) -> 0 | G20: =VLOOKUP(B20,'SH Summary'!C:L,10,FALSE) -> 0.00058282755 | H20: =G20/F20-1 -> #DIV/0!
B21: Krane Funds Advisors, LLC | C21: =INDEX('SH Summary'!A:A,MATCH(B21,'SH Summary'!C:C,0)) -> 0 | D21: =INDEX('SH Summary'!B:B,MATCH(B21,'SH Summary'!C:C,0)) -> 11 | E21: =C21-D21 -> -11 | F21: =VLOOKUP(B21,'SH Summary'!C:L,9,FALSE) -> 0 | G21: =VLOOKUP(B21,'SH Summary'!C:L,10,FALSE) -> 0.0091786626 | H21: =G21/F21-1 -> #DIV/0!
B22: Fidelity International Limited - FIL Investment Services (U.K.), LTD | C22: =INDEX('SH Summary'!A:A,MATCH(B22,'SH Summary'!C:C,0)) -> 0 | D22: =INDEX('SH Summary'!B:B,MATCH(B22,'SH Summary'!C:C,0)) -> 13 | E22: =C22-D22 -> -13 | F22: =VLOOKUP(B22,'SH Summary'!C:L,9,FALSE) -> 0 | G22: =VLOOKUP(B22,'SH Summary'!C:L,10,FALSE) -> 0.0084033763 | H22: =G22/F22-1 -> #DIV/0!
... B30: Arga Investment Management, L.P. | C30: =INDEX('SH Summary'!A:A,MATCH(B30,'SH Summary'!C:C,0)) -> 0 | D30: =INDEX('SH Summary'!B:B,MATCH(B30,'SH Summary'!C:C,0)) -> 25 | E30: =C30-D30 -> -25 | F30: =VLOOKUP(B30,'SH Summary'!C:L,9,FALSE) -> 0 | G30: =VLOOKUP(B30,'SH Summary'!C:L,10,FALSE) -> 0.0044093304 | H30: =G30/F30-1 -> #DIV/0!
B32: Top 20 26Q1
B34: Institution Name | C34: 25Q4 Rank | D34: 26Q1 Rank | E34: Rank Change | F34: % S/O 25Q4 | G34: % S/O 26Q1 | H34: % S/O Change
B35: Capital World Investors (U.S.) | C35: =INDEX('SH Summary'!A:A,MATCH(B35,'SH Summary'!C:C,0)) -> 0 | D35: =INDEX('SH Summary'!B:B,MATCH(B35,'SH Summary'!C:C,0)) -> 1 | E35: =C35-D35 -> -1 | F35: =VLOOKUP(B35,'SH Summary'!C:L,9,FALSE) -> 0 | G35: =VLOOKUP(B35,'SH Summary'!C:L,10,FALSE) -> 0.062420518 | H35: =G35/F35-1 -> #DIV/0!
B36: The Vanguard Group, Inc. | C36: =INDEX('SH Summary'!A:A,MATCH(B36,'SH Summary'!C:C,0)) -> 0 | D36: =INDEX('SH Summary'!B:B,MATCH(B36,'SH Summary'!C:C,0)) -> 2 | E36: =C36-D36 -> -2 | F36: =VLOOKUP(B36,'SH Summary'!C:L,9,FALSE) -> 0 | G36: =VLOOKUP(B36,'SH Summary'!C:L,10,FALSE) -> 0.032561846 | H36: =G36/F36-1 -> #DIV/0!
B37: BlackRock Fund Advisors | C37: =INDEX('SH Summary'!A:A,MATCH(B37,'SH Summary'!C:C,0)) -> 0 | D37: =INDEX('SH Summary'!B:B,MATCH(B37,'SH Summary'!C:C,0)) -> 3 | E37: =C37-D37 -> -3 | F37: =VLOOKUP(B37,'SH Summary'!C:L,9,FALSE) -> 0 | G37: =VLOOKUP(B37,'SH Summary'!C:L,10,FALSE) -> 0.026587593 | H37: =G37/F37-1 -> #DIV/0!
B38: Morgan Stanley Investment Management Inc. | C38: =INDEX('SH Summary'!A:A,MATCH(B38,'SH Summary'!C:C,0)) -> 0 | D38: =INDEX('SH Summary'!B:B,MATCH(B38,'SH Summary'!C:C,0)) -> 4 | E38: =C38-D38 -> -4 | F38: =VLOOKUP(B38,'SH Summary'!C:L,9,FALSE) -> 0 | G38: =VLOOKUP(B38,'SH Summary'!C:L,10,FALSE) -> 0.017337715 | H38: =G38/F38-1 -> #DIV/0!
B39: Norges Bank Investment Management (Norway) | C39: =INDEX('SH Summary'!A:A,MATCH(B39,'SH Summary'!C:C,0)) -> 0 | D39: =INDEX('SH Summary'!B:B,MATCH(B39,'SH Summary'!C:C,0)) -> 5 | E39: =C39-D39 -> -5 | F39: =VLOOKUP(B39,'SH Summary'!C:L,9,FALSE) -> 0 | G39: =VLOOKUP(B39,'SH Summary'!C:L,10,FALSE) -> 0.016915321 | H39: =G39/F39-1 -> #DIV/0!
B40: Sanders Capital, LLC | C40: =INDEX('SH Summary'!A:A,MATCH(B40,'SH Summary'!C:C,0)) -> 0 | D40: =INDEX('SH Summary'!B:B,MATCH(B40,'SH Summary'!C:C,0)) -> 6 | E40: =C40-D40 -> -6 | F40: =VLOOKUP(B40,'SH Summary'!C:L,9,FALSE) -> 0 | G40: =VLOOKUP(B40,'SH Summary'!C:L,10,FALSE) -> 0.016395866 | H40: =G40/F40-1 -> #DIV/0!
B41: E Fund Management Company, LTD | C41: =INDEX('SH Summary'!A:A,MATCH(B41,'SH Summary'!C:C,0)) -> 0 | D41: =INDEX('SH Summary'!B:B,MATCH(B41,'SH Summary'!C:C,0)) -> 7 | E41: =C41-D41 -> -7 | F41: =VLOOKUP(B41,'SH Summary'!C:L,9,FALSE) -> 0 | G41: =VLOOKUP(B41,'SH Summary'!C:L,10,FALSE) -> 0.010429944 | H41: =G41/F41-1 -> #DIV/0!
B42: Davis Selected Advisers, L.P. | C42: =INDEX('SH Summary'!A:A,MATCH(B42,'SH Summary'!C:C,0)) -> 0 | D42: =INDEX('SH Summary'!B:B,MATCH(B42,'SH Summary'!C:C,0)) -> 8 | E42: =C42-D42 -> -8 | F42: =VLOOKUP(B42,'SH Summary'!C:L,9,FALSE) -> 0 | G42: =VLOOKUP(B42,'SH Summary'!C:L,10,FALSE) -> 0.010100462 | H42: =G42/F42-1 -> #DIV/0!
B43: CSOP Asset Management, LTD | C43: =INDEX('SH Summary'!A:A,MATCH(B43,'SH Summary'!C:C,0)) -> 0 | D43: =INDEX('SH Summary'!B:B,MATCH(B43,'SH Summary'!C:C,0)) -> 9 | E43: =C43-D43 -> -9 | F43: =VLOOKUP(B43,'SH Summary'!C:L,9,FALSE) -> 0 | G43: =VLOOKUP(B43,'SH Summary'!C:L,10,FALSE) -> 0.010071001 | H43: =G43/F43-1 -> #DIV/0!
B44: BlackRock Advisors (U.K.), LTD | C44: =INDEX('SH Summary'!A:A,MATCH(B44,'SH Summary'!C:C,0)) -> 0 | D44: =INDEX('SH Summary'!B:B,MATCH(B44,'SH Summary'!C:C,0)) -> 10 | E44: =C44-D44 -> -10 | F44: =VLOOKUP(B44,'SH Summary'!C:L,9,FALSE) -> 0 | G44: =VLOOKUP(B44,'SH Summary'!C:L,10,FALSE) -> 0.009917748 | H44: =G44/F44-1 -> #DIV/0!
B45: Krane Funds Advisors, LLC | C45: =INDEX('SH Summary'!A:A,MATCH(B45,'SH Summary'!C:C,0)) -> 0 | D45: =INDEX('SH Summary'!B:B,MATCH(B45,'SH Summary'!C:C,0)) -> 11 | E45: =C45-D45 -> -11 | F45: =VLOOKUP(B45,'SH Summary'!C:L,9,FALSE) -> 0 | G45: =VLOOKUP(B45,'SH Summary'!C:L,10,FALSE) -> 0.0091786626 | H45: =G45/F45-1 -> #DIV/0!
B46: FIL Investment Management (Hong Kong), LTD | C46: =INDEX('SH Summary'!A:A,MATCH(B46,'SH Summary'!C:C,0)) -> 0 | D46: =INDEX('SH Summary'!B:B,MATCH(B46,'SH Summary'!C:C,0)) -> 12 | E46: =C46-D46 -> -12 | F46: =VLOOKUP(B46,'SH Summary'!C:L,9,FALSE) -> 0 | G46: =VLOOKUP(B46,'SH Summary'!C:L,10,FALSE) -> 0.0090069222 | H46: =G46/F46-1 -> #DIV/0!
... B54: Geode Capital Management, LLC | C54: =INDEX('SH Summary'!A:A,MATCH(B54,'SH Summary'!C:C,0)) -> 0 | D54: =INDEX('SH Summary'!B:B,MATCH(B54,'SH Summary'!C:C,0)) -> 20 | E54: =C54-D54 -> -20 | F54: =VLOOKUP(B54,'SH Summary'!C:L,9,FALSE) -> 0 | G54: =VLOOKUP(B54,'SH Summary'!C:L,10,FALSE) -> 0.0051372924 | H54: =G54/F54-1 -> #DIV/0!

Sheet SH Summary
C1: Trip.com Group
C2: 26Q1 Institutional Ownership
F3: 648991284 | G3: updated as of 2026/03/31
D4: 7 | E4: 10 | M4: 9 | N4: 12 | O4: 14 | P4: 16 | Q4: 17 | R4: 18 | S4: 13
A5: 25Q4 Rank | B5: 26Q1 Rank | C5: Institution Name | D5: TCOM | E5: 9961 | F5: Total Shares 26Q1 | G5: Total Shares 25Q4 | H5: QoQ | I5: % S/O 25Q2 | J5: % S/O 25Q3 | K5: % S/O 25Q4 | L5: % S/O 26Q1 | M5: Position Date (TCOM) | N5: Position Date (9961) | O5: Dominant Style | P5: City | Q5: State | R5: Country | S5: Equity AUM $bn
B6: 1 | C6: Capital World Investors (U.S.) | D6: =VLOOKUP($C6,'Data_TCOM+9961'!$A:$U,'SH Summary'!D$4,FALSE) -> 36115209 | E6: =VLOOKUP($C6,'Data_TCOM+9961'!$A:$U,'SH Summary'!E$4,FALSE) -> 4395163 | F6: =D6+E6 -> 40510372 | H6: =F6-G6 -> 40510372 | L6: =F6/$F$3 -> 0.062420518 | M6: =VLOOKUP($C6,'Data_TCOM+9961'!$A:$U,'SH Summary'!M$4,FALSE) -> 03/31/2026 | N6: =VLOOKUP($C6,'Data_TCOM+9961'!$A:$U,'SH Summary'!N$4,FALSE) -> 03/31/2026 | O6: =VLOOKUP($C6,'Data_TCOM+9961'!$A:$U,'SH Summary'!O$4,FALSE) -> Value | P6: =VLOOKUP($C6,'Data_TCOM+9961'!$A:$U,'SH Summary'!P$4,FALSE) -> Los Angeles | Q6: =VLOOKUP($C6,'Data_TCOM+9961'!$A:$U,'SH Summary'!Q$4,FALSE) -> California | R6: =VLOOKUP($C6,'Data_TCOM+9961'!$A:$U,'SH Summary'!R$4,FALSE) -> United States | S6: =VLOOKUP($C6,'Data_TCOM+9961'!$A:$U,'SH Summary'!S$4,FALSE)/1000000000 -> 1022.5949
B7: 2 | C7: The Vanguard Group, Inc. | D7: =VLOOKUP($C7,'Data_TCOM+9961'!$A:$U,'SH Summary'!D$4,FALSE) -> 0 | E7: =VLOOKUP($C7,'Data_TCOM+9961'!$A:$U,'SH Summary'!E$4,FALSE) -> 21132354 | F7: =D7+E7 -> 21132354 | H7: =F7-G7 -> 21132354 | L7: =F7/$F$3 -> 0.032561846 | M7: =VLOOKUP($C7,'Data_TCOM+9961'!$A:$U,'SH Summary'!M$4,FALSE) -> 0 | N7: =VLOOKUP($C7,'Data_TCOM+9961'!$A:$U,'SH Summary'!N$4,FALSE) -> 03/31/2026 | O7: =VLOOKUP($C7,'Data_TCOM+9961'!$A:$U,'SH Summary'!O$4,FALSE) -> Index | P7: =VLOOKUP($C7,'Data_TCOM+9961'!$A:$U,'SH Summary'!P$4,FALSE) -> Malvern | Q7: =VLOOKUP($C7,'Data_TCOM+9961'!$A:$U,'SH Summary'!Q$4,FALSE) -> Pennsylvania | R7: =VLOOKUP($C7,'Data_TCOM+9961'!$A:$U,'SH Summary'!R$4,FALSE) -> United States | S7: =VLOOKUP($C7,'Data_TCOM+9961'!$A:$U,'SH Summary'!S$4,FALSE)/1000000000 -> 7960.9296
B8: 3 | C8: BlackRock Fund Advisors | D8: =VLOOKUP($C8,'Data_TCOM+9961'!$A:$U,'SH Summary'!D$4,FALSE) -> 594873 | E8: =VLOOKUP($C8,'Data_TCOM+9961'!$A:$U,'SH Summary'!E$4,FALSE) -> 16660243 | F8: =D8+E8 -> 17255116 | H8: =F8-G8 -> 17255116 | L8: =F8/$F$3 -> 0.026587593 | M8: =VLOOKUP($C8,'Data_TCOM+9961'!$A:$U,'SH Summary'!M$4,FALSE) -> 03/31/2026 | N8: =VLOOKUP($C8,'Data_TCOM+9961'!$A:$U,'SH Summary'!N$4,FALSE) -> 05/12/2026 | O8: =VLOOKUP($C8,'Data_TCOM+9961'!$A:$U,'SH Summary'!O$4,FALSE) -> Index | P8: =VLOOKUP($C8,'Data_TCOM+9961'!$A:$U,'SH Summary'!P$4,FALSE) -> San Francisco | Q8: =VLOOKUP($C8,'Data_TCOM+9961'!$A:$U,'SH Summary'!Q$4,FALSE) -> California | R8: =VLOOKUP($C8,'Data_TCOM+9961'!$A:$U,'SH Summary'!R$4,FALSE) -> United States | S8: =VLOOKUP($C8,'Data_TCOM+9961'!$A:$U,'SH Summary'!S$4,FALSE)/1000000000 -> 4837.4638
B9: 4 | C9: Morgan Stanley Investment Management Inc. | D9: =VLOOKUP($C9,'Data_TCOM+9961'!$A:$U,'SH Summary'!D$4,FALSE) -> 11223376 | E9: =VLOOKUP($C9,'Data_TCOM+9961'!$A:$U,'SH Summary'!E$4,FALSE) -> 28650 | F9: =D9+E9 -> 11252026 | H9: =F9-G9 -> 11252026 | L9: =F9/$F$3 -> 0.017337715 | M9: =VLOOKUP($C9,'Data_TCOM+9961'!$A:$U,'SH Summary'!M$4,FALSE) -> 03/31/2026 | N9: =VLOOKUP($C9,'Data_TCOM+9961'!$A:$U,'SH Summary'!N$4,FALSE) -> 07/31/2024 | O9: =VLOOKUP($C9,'Data_TCOM+9961'!$A:$U,'SH Summary'!O$4,FALSE) -> Growth | P9: =VLOOKUP($C9,'Data_TCOM+9961'!$A:$U,'SH Summary'!P$4,FALSE) -> New York | Q9: =VLOOKUP($C9,'Data_TCOM+9961'!$A:$U,'SH Summary'!Q$4,FALSE) -> New York | R9: =VLOOKUP($C9,'Data_TCOM+9961'!$A:$U,'SH Summary'!R$4,FALSE) -> United States | S9: =VLOOKUP($C9,'Data_TCOM+9961'!$A:$U,'SH Summary'!S$4,FALSE)/1000000000 -> 117.75848
B10: 5 | C10: Norges Bank Investment Management (Norway) | D10: =VLOOKUP($C10,'Data_TCOM+9961'!$A:$U,'SH Summary'!D$4,FALSE) -> 164868 | E10: =VLOOKUP($C10,'Data_TCOM+9961'!$A:$U,'SH Summary'!E$4,FALSE) -> 10813028 | F10: =D10+E10 -> 10977896 | H10: =F10-G10 -> 10977896 | L10: =F10/$F$3 -> 0.016915321 | M10: =VLOOKUP($C10,'Data_TCOM+9961'!$A:$U,'SH Summary'!M$4,FALSE) -> 12/31/2025 | N10: =VLOOKUP($C10,'Data_TCOM+9961'!$A:$U,'SH Summary'!N$4,FALSE) -> 12/31/2025 | O10: =VLOOKUP($C10,'Data_TCOM+9961'!$A:$U,'SH Summary'!O$4,FALSE) -> Value | P10: =VLOOKUP($C10,'Data_TCOM+9961'!$A:$U,'SH Summary'!P$4,FALSE) -> Oslo | Q10: =VLOOKUP($C10,'Data_TCOM+9961'!$A:$U,'SH Summary'!Q$4,FALSE) -> 0 | R10: =VLOOKUP($C10,'Data_TCOM+9961'!$A:$U,'SH Summary'!R$4,FALSE) -> Norway | S10: =VLOOKUP($C10,'Data_TCOM+9961'!$A:$U,'SH Summary'!S$4,FALSE)/1000000000 -> 1551.8473
B11: 6 | C11: Sanders Capital, LLC | D11: =VLOOKUP($C11,'Data_TCOM+9961'!$A:$U,'SH Summary'!D$4,FALSE) -> 10640774 | E11: =VLOOKUP($C11,'Data_TCOM+9961'!$A:$U,'SH Summary'!E$4,FALSE) -> 0 | F11: =D11+E11 -> 10640774 | H11: =F11-G11 -> 10640774 | L11: =F11/$F$3 -> 0.016395866 | M11: =VLOOKUP($C11,'Data_TCOM+9961'!$A:$U,'SH Summary'!M$4,FALSE) -> 03/31/2026 | N11: =VLOOKUP($C11,'Data_TCOM+9961'!$A:$U,'SH Summary'!N$4,FALSE) -> 0 | O11: =VLOOKUP($C11,'Data_TCOM+9961'!$A:$U,'SH Summary'!O$4,FALSE) -> Value | P11: =VLOOKUP($C11,'Data_TCOM+9961'!$A:$U,'SH Summary'!P$4,FALSE) -> West Palm Beach | Q11: =VLOOKUP($C11,'Data_TCOM+9961'!$A:$U,'SH Summary'!Q$4,FALSE) -> Florida | R11: =VLOOKUP($C11,'Data_TCOM+9961'!$A:$U,'SH Summary'!R$4,FALSE) -> United States | S11: =VLOOKUP($C11,'Data_TCOM+9961'!$A:$U,'SH Summary'!S$4,FALSE)/1000000000 -> 89.446668
B12: 7 | C12: E Fund Management Company, LTD | D12: =VLOOKUP($C12,'Data_TCOM+9961'!$A:$U,'SH Summary'!D$4,FALSE) -> 1294 | E12: =VLOOKUP($C12,'Data_TCOM+9961'!$A:$U,'SH Summary'!E$4,FALSE) -> 6767649 | F12: =D12+E12 -> 6768943 | H12: =F12-G12 -> 6768943 | L12: =F12/$F$3 -> 0.010429944 | M12: =VLOOKUP($C12,'Data_TCOM+9961'!$A:$U,'SH Summary'!M$4,FALSE) -> 12/31/2025 | N12: =VLOOKUP($C12,'Data_TCOM+9961'!$A:$U,'SH Summary'!N$4,FALSE) -> 12/31/2025 | O12: =VLOOKUP($C12,'Data_TCOM+9961'!$A:$U,'SH Summary'!O$4,FALSE) -> Growth | P12: =VLOOKUP($C12,'Data_TCOM+9961'!$A:$U,'SH Summary'!P$4,FALSE) -> Guangzhou | Q12: =VLOOKUP($C12,'Data_TCOM+9961'!$A:$U,'SH Summary'!Q$4,FALSE) -> 0 | R12: =VLOOKUP($C12,'Data_TCOM+9961'!$A:$U,'SH Summary'!R$4,FALSE) -> China (Mainland) | S12: =VLOOKUP($C12,'Data_TCOM+9961'!$A:$U,'SH Summary'!S$4,FALSE)/1000000000 -> 123.95179
B13: 8 | C13: Davis Selected Advisers, L.P. | D13: =VLOOKUP($C13,'Data_TCOM+9961'!$A:$U,'SH Summary'!D$4,FALSE) -> 6555112 | E13: =VLOOKUP($C13,'Data_TCOM+9961'!$A:$U,'SH Summary'!E$4,FALSE) -> 0 | F13: =D13+E13 -> 6555112 | H13: =F13-G13 -> 6555112 | L13: =F13/$F$3 -> 0.010100462 | M13: =VLOOKUP($C13,'Data_TCOM+9961'!$A:$U,'SH Summary'!M$4,FALSE) -> 03/31/2026 | N13: =VLOOKUP($C13,'Data_TCOM+9961'!$A:$U,'SH Summary'!N$4,FALSE) -> 0 | O13: =VLOOKUP($C13,'Data_TCOM+9961'!$A:$U,'SH Summary'!O$4,FALSE) -> Value | P13: =VLOOKUP($C13,'Data_TCOM+9961'!$A:$U,'SH Summary'!P$4,FALSE) -> New York | Q13: =VLOOKUP($C13,'Data_TCOM+9961'!$A:$U,'SH Summary'!Q$4,FALSE) -> New York | R13: =VLOOKUP($C13,'Data_TCOM+9961'!$A:$U,'SH Summary'!R$4,FALSE) -> United States | S13: =VLOOKUP($C13,'Data_TCOM+9961'!$A:$U,'SH Summary'!S$4,FALSE)/1000000000 -> 25.230328
B14: 9 | C14: CSOP Asset Management, LTD | D14: =VLOOKUP($C14,'Data_TCOM+9961'!$A:$U,'SH Summary'!D$4,FALSE) -> 26844 | E14: =VLOOKUP($C14,'Data_TCOM+9961'!$A:$U,'SH Summary'!E$4,FALSE) -> 6509148 | F14: =D14+E14 -> 6535992 | H14: =F14-G14 -> 6535992 | L14: =F14/$F$3 -> 0.010071001 | M14: =VLOOKUP($C14,'Data_TCOM+9961'!$A:$U,'SH Summary'!M$4,FALSE) -> 08/31/2024 | N14: =VLOOKUP($C14,'Data_TCOM+9961'!$A:$U,'SH Summary'!N$4,FALSE) -> 05/14/2026 | O14: =VLOOKUP($C14,'Data_TCOM+9961'!$A:$U,'SH Summary'!O$4,FALSE) -> Value | P14: =VLOOKUP($C14,'Data_TCOM+9961'!$A:$U,'SH Summary'!P$4,FALSE) -> Central | Q14: =VLOOKUP($C14,'Data_TCOM+9961'!$A:$U,'SH Summary'!Q$4,FALSE) -> 0 | R14: =VLOOKUP($C14,'Data_TCOM+9961'!$A:$U,'SH Summary'!R$4,FALSE) -> Hong Kong SAR | S14: =VLOOKUP($C14,'Data_TCOM+9961'!$A:$U,'SH Summary'!S$4,FALSE)/1000000000 -> 20.343937
B15: 10 | C15: BlackRock Advisors (U.K.), LTD | D15: =VLOOKUP($C15,'Data_TCOM+9961'!$A:$U,'SH Summary'!D$4,FALSE) -> 21485 | E15: =VLOOKUP($C15,'Data_TCOM+9961'!$A:$U,'SH Summary'!E$4,FALSE) -> 6415047 | F15: =D15+E15 -> 6436532 | H15: =F15-G15 -> 6436532 | L15: =F15/$F$3 -> 0.009917748 | M15: =VLOOKUP($C15,'Data_TCOM+9961'!$A:$U,'SH Summary'!M$4,FALSE) -> 06/30/2025 | N15: =VLOOKUP($C15,'Data_TCOM+9961'!$A:$U,'SH Summary'!N$4,FALSE) -> 05/12/2026 | O15: =VLOOKUP($C15,'Data_TCOM+9961'!$A:$U,'SH Summary'!O$4,FALSE) -> Index | P15: =VLOOKUP($C15,'Data_TCOM+9961'!$A:$U,'SH Summary'!P$4,FALSE) -> London | Q15: =VLOOKUP($C15,'Data_TCOM+9961'!$A:$U,'SH Summary'!Q$4,FALSE) -> 0 | R15: =VLOOKUP($C15,'Data_TCOM+9961'!$A:$U,'SH Summary'!R$4,FALSE) -> United Kingdom | S15: =VLOOKUP($C15,'Data_TCOM+9961'!$A:$U,'SH Summary'!S$4,FALSE)/1000000000 -> 441.93474
B16: 11 | C16: Krane Funds Advisors, LLC | D16: =VLOOKUP($C16,'Data_TCOM+9961'!$A:$U,'SH Summary'!D$4,FALSE) -> 0 | E16: =VLOOKUP($C16,'Data_TCOM+9961'!$A:$U,'SH Summary'!E$4,FALSE) -> 5956872 | F16: =D16+E16 -> 5956872 | H16: =F16-G16 -> 5956872 | L16: =F16/$F$3 -> 0.0091786626 | M16: =VLOOKUP($C16,'Data_TCOM+9961'!$A:$U,'SH Summary'!M$4,FALSE) -> 0 | N16: =VLOOKUP($C16,'Data_TCOM+9961'!$A:$U,'SH Summary'!N$4,FALSE) -> 05/13/2026 | O16: =VLOOKUP($C16,'Data_TCOM+9961'!$A:$U,'SH Summary'!O$4,FALSE) -> Index | P16: =VLOOKUP($C16,'Data_TCOM+9961'!$A:$U,'SH Summary'!P$4,FALSE) -> New York | Q16: =VLOOKUP($C16,'Data_TCOM+9961'!$A:$U,'SH Summary'!Q$4,FALSE) -> New York | R16: =VLOOKUP($C16,'Data_TCOM+9961'!$A:$U,'SH Summary'!R$4,FALSE) -> United States | S16: =VLOOKUP($C16,'Data_TCOM+9961'!$A:$U,'SH Summary'!S$4,FALSE)/1000000000 -> 9.4875478
B17: 12 | C17: FIL Investment Management (Hong Kong), LTD | D17: =VLOOKUP($C17,'Data_TCOM+9961'!$A:$U,'SH Summary'!D$4,FALSE) -> 0 | E17: =VLOOKUP($C17,'Data_TCOM+9961'!$A:$U,'SH Summary'!E$4,FALSE) -> 5845414 | F17: =D17+E17 -> 5845414 | H17: =F17-G17 -> 5845414 | L17: =F17/$F$3 -> 0.0090069222 | M17: =VLOOKUP($C17,'Data_TCOM+9961'!$A:$U,'SH Summary'!M$4,FALSE) -> 06/30/2025 | N17: =VLOOKUP($C17,'Data_TCOM+9961'!$A:$U,'SH Summary'!N$4,FALSE) -> 03/31/2026 | O17: =VLOOKUP($C17,'Data_TCOM+9961'!$A:$U,'SH Summary'!O$4,FALSE) -> Growth | P17: =VLOOKUP($C17,'Data_TCOM+9961'!$A:$U,'SH Summary'!P$4,FALSE) -> Admiralty | Q17: =VLOOKUP($C17,'Data_TCOM+9961'!$A:$U,'SH Summary'!Q$4,FALSE) -> 0 | R17: =VLOOKUP($C17,'Data_TCOM+9961'!$A:$U,'SH Summary'!R$4,FALSE) -> Hong Kong SAR | S17: =VLOOKUP($C17,'Data_TCOM+9961'!$A:$U,'SH Summary'!S$4,FALSE)/1000000000 -> 22.289992
... B870: 865 | C870: The Huntington Investment Company (Asset Management) | D870: =VLOOKUP($C870,'Data_TCOM+9961'!$A:$U,'SH Summary'!D$4,FALSE) -> 1 | E870: =VLOOKUP($C870,'Data_TCOM+9961'!$A:$U,'SH Summary'!E$4,FALSE) -> 0 | F870: =D870+E870 -> 1 | H870: =F870-G870 -> 1 | L870: =F870/$F$3 -> 1.5408527e-09 | M870: =VLOOKUP($C870,'Data_TCOM+9961'!$A:$U,'SH Summary'!M$4,FALSE) -> 03/31/2026 | N870: =VLOOKUP($C870,'Data_TCOM+9961'!$A:$U,'SH Summary'!N$4,FALSE) -> 0 | O870: =VLOOKUP($C870,'Data_TCOM+9961'!$A:$U,'SH Summary'!O$4,FALSE) -> Growth | P870: =VLOOKUP($C870,'Data_TCOM+9961'!$A:$U,'SH Summary'!P$4,FALSE) -> Columbus | Q870: =VLOOKUP($C870,'Data_TCOM+9961'!$A:$U,'SH Summary'!Q$4,FALSE) -> Ohio | R870: =VLOOKUP($C870,'Data_TCOM+9961'!$A:$U,'SH Summary'!R$4,FALSE) -> United States | S870: =VLOOKUP($C870,'Data_TCOM+9961'!$A:$U,'SH Summary'!S$4,FALSE)/1000000000 -> 18.117657
L871: =F871/$F$3 -> 0
L872: =F872/$F$3 -> 0
F911: =SUM(F6:F910) -> 341246350 | L911: =F911/$F$3 -> 0.52581037
F912: =F911/F3 -> 0.52581037
F913: =50*F912 -> 26.290519

Sheet Data_TCOM+9961
A1: Combined Ownership | B1: Combined Ownership | C1: Combined Ownership | D1: Combined Ownership | E1: Combined Ownership | F1: Combined Ownership | G1: Combined Ownership | H1: Combined Ownership | I1: Combined Ownership | J1: Combined Ownership | K1: Combined Ownership | L1: Combined Ownership | M1: Combined Ownership | N1: Combined Ownership | O1: Combined Ownership | P1: Combined Ownership | Q1: Combined Ownership | R1: Combined Ownership
A2: 1 | B2: 2 | C2: 3 | D2: 4 | E2: 5 | F2: 6 | G2: 7 | H2: 8 | I2: 9 | J2: 10 | K2: 11 | L2: 12 | M2: 13 | N2: 14 | O2: 15 | P2: 16 | Q2: 17 | R2: 18 | S2: 19 | T2: 20 | U2: 21
A3: Institution | B3: Sustainability Considered | C3: Holder Rank (Combined) | D3: Shares (Combined) | E3: Share Change (Combined) | F3: % S/O (Combined) | G3: TCOM Shares | H3: TCOM Share Change | I3: TCOM Reported Date | J3: 9961_XHKG Shares | K3: 9961_XHKG Share Change | L3: 9961_XHKG Reported Date | M3: Equity Assets USD, mm | N3: Style | O3: Turnover | P3: City | Q3: State/Province | R3: Country/Territory | S3: Fund Size | T3: Region | U3: Fund Style
A4: Baidu Holdings, LTD | B4: no | C4: 1 | D4: 45953524 | E4: 0 | F4: 6.67 | J4: 45953524 | K4: 0 | L4: 02/28/2025 | M4: 2925117269 | R4: China (Mainland) | S4: =IF(M4>100000000000, "100bn", IF(M4>50000000000, "50bn - 100bn",IF(M4>1000000000, "1bn - 50bn", IF(M4>500000000, "500mn - 1bn", "500mn")))) -> 1bn - 50bn | T4: =VLOOKUP(R4,Mapping!B:C,2,FALSE) -> CN | U4: =VLOOKUP(N4,Mapping!H:I,2,FALSE) -> #N/A
A5: Capital World Investors (U.S.) | B5: no | C5: 2 | D5: 40510372 | E5: -9927305 | F5: 5.88 | G5: 36115209 | H5: 3305361 | I5: 03/31/2026 | J5: 4395163 | K5: -13232666 | L5: 03/31/2026 | M5: 1022594898625 | N5: Value | O5: 34.246 | P5: Los Angeles | Q5: California | R5: United States | S5: =IF(M5>100000000000, "100bn", IF(M5>50000000000, "50bn - 100bn",IF(M5>1000000000, "1bn - 50bn", IF(M5>500000000, "500mn - 1bn", "500mn")))) -> 100bn | T5: =VLOOKUP(R5,Mapping!B:C,2,FALSE) -> US/CA | U5: =VLOOKUP(N5,Mapping!H:I,2,FALSE) -> Value
A6: The Vanguard Group, Inc. | B6: yes | C6: 3 | D6: 21132354 | E6: 327200 | F6: 3.07 | J6: 21132354 | K6: 327200 | L6: 03/31/2026 | M6: 7960929576394 | N6: Index | O6: 4.761 | P6: Malvern | Q6: Pennsylvania | R6: United States | S6: =IF(M6>100000000000, "100bn", IF(M6>50000000000, "50bn - 100bn",IF(M6>1000000000, "1bn - 50bn", IF(M6>500000000, "500mn - 1bn", "500mn")))) -> 100bn | T6: =VLOOKUP(R6,Mapping!B:C,2,FALSE) -> US/CA | U6: =VLOOKUP(N6,Mapping!H:I,2,FALSE) -> Index
A7: BlackRock Fund Advisors | B7: yes | C7: 4 | D7: 17255116 | E7: -121808 | F7: 2.5 | G7: 594873 | H7: -104775 | I7: 03/31/2026 | J7: 16660243 | K7: -17033 | L7: 05/12/2026 | M7: 4837463753757 | N7: Index | O7: 7.486 | P7: San Francisco | Q7: California | R7: United States | S7: =IF(M7>100000000000, "100bn", IF(M7>50000000000, "50bn - 100bn",IF(M7>1000000000, "1bn - 50bn", IF(M7>500000000, "500mn - 1bn", "500mn")))) -> 100bn | T7: =VLOOKUP(R7,Mapping!B:C,2,FALSE) -> US/CA | U7: =VLOOKUP(N7,Mapping!H:I,2,FALSE) -> Index
A8: Morgan Stanley Investment Management Inc. | B8: yes | C8: 5 | D8: 11252026 | E8: -2058757 | F8: 1.63 | G8: 11223376 | H8: -2087407 | I8: 03/31/2026 | J8: 28650 | K8: 28650 | L8: 07/31/2024 | M8: 117758479640 | N8: Growth | O8: 53.081 | P8: New York | Q8: New York | R8: United States | S8: =IF(M8>100000000000, "100bn", IF(M8>50000000000, "50bn - 100bn",IF(M8>1000000000, "1bn - 50bn", IF(M8>500000000, "500mn - 1bn", "500mn")))) -> 100bn | T8: =VLOOKUP(R8,Mapping!B:C,2,FALSE) -> US/CA | U8: =VLOOKUP(N8,Mapping!H:I,2,FALSE) -> Growth
A9: Norges Bank Investment Management (Norway) | B9: yes | C9: 6 | D9: 10977896 | E9: -925944 | F9: 1.59 | G9: 164868 | H9: -606028 | I9: 12/31/2025 | J9: 10813028 | K9: -319916 | L9: 12/31/2025 | M9: 1551847282513 | N9: Value | O9: 20.194 | P9: Oslo | R9: Norway | S9: =IF(M9>100000000000, "100bn", IF(M9>50000000000, "50bn - 100bn",IF(M9>1000000000, "1bn - 50bn", IF(M9>500000000, "500mn - 1bn", "500mn")))) -> 100bn | T9: =VLOOKUP(R9,Mapping!B:C,2,FALSE) -> EU | U9: =VLOOKUP(N9,Mapping!H:I,2,FALSE) -> Value
A10: Sanders Capital, LLC | B10: no | C10: 7 | D10: 10640774 | E10: 750137 | F10: 1.54 | G10: 10640774 | H10: 750137 | I10: 03/31/2026 | M10: 89446668161 | N10: Value | O10: 26.849 | P10: West Palm Beach | Q10: Florida | R10: United States | S10: =IF(M10>100000000000, "100bn", IF(M10>50000000000, "50bn - 100bn",IF(M10>1000000000, "1bn - 50bn", IF(M10>500000000, "500mn - 1bn", "500mn")))) -> 50bn - 100bn | T10: =VLOOKUP(R10,Mapping!B:C,2,FALSE) -> US/CA | U10: =VLOOKUP(N10,Mapping!H:I,2,FALSE) -> Value
A11: E Fund Management Company, LTD | B11: yes | C11: 8 | D11: 6768943 | E11: 501944 | F11: 0.98 | G11: 1294 | H11: 1294 | I11: 12/31/2025 | J11: 6767649 | K11: 500650 | L11: 12/31/2025 | M11: 123951792127 | N11: Growth | O11: 26.808 | P11: Guangzhou | R11: China (Mainland) | S11: =IF(M11>100000000000, "100bn", IF(M11>50000000000, "50bn - 100bn",IF(M11>1000000000, "1bn - 50bn", IF(M11>500000000, "500mn - 1bn", "500mn")))) -> 100bn | T11: =VLOOKUP(R11,Mapping!B:C,2,FALSE) -> CN | U11: =VLOOKUP(N11,Mapping!H:I,2,FALSE) -> Growth
A12: Davis Selected Advisers, L.P. | B12: no | C12: 9 | D12: 6555112 | E12: 1501723 | F12: 0.95 | G12: 6555112 | H12: 1501723 | I12: 03/31/2026 | M12: 25230328351 | N12: Value | O12: 26.916 | P12: New York | Q12: New York | R12: United States | S12: =IF(M12>100000000000, "100bn", IF(M12>50000000000, "50bn - 100bn",IF(M12>1000000000, "1bn - 50bn", IF(M12>500000000, "500mn - 1bn", "500mn")))) -> 1bn - 50bn | T12: =VLOOKUP(R12,Mapping!B:C,2,FALSE) -> US/CA | U12: =VLOOKUP(N12,Mapping!H:I,2,FALSE) -> Value
A13: CSOP Asset Management, LTD | B13: yes | C13: 10 | D13: 6535992 | E13: -258986 | F13: 0.95 | G13: 26844 | H13: -1062 | I13: 08/31/2024 | J13: 6509148 | K13: -257924 | L13: 05/14/2026 | M13: 20343937181 | N13: Value | O13: 55.36 | P13: Central | R13: Hong Kong SAR | S13: =IF(M13>100000000000, "100bn", IF(M13>50000000000, "50bn - 100bn",IF(M13>1000000000, "1bn - 50bn", IF(M13>500000000, "500mn - 1bn", "500mn")))) -> 1bn - 50bn | T13: =VLOOKUP(R13,Mapping!B:C,2,FALSE) -> HK | U13: =VLOOKUP(N13,Mapping!H:I,2,FALSE) -> Value
A14: BlackRock Advisors (U.K.), LTD | B14: yes | C14: 11 | D14: 6436532 | E14: -105415 | F14: 0.93 | G14: 21485 | H14: -23515 | I14: 06/30/2025 | J14: 6415047 | K14: -81900 | L14: 05/12/2026 | M14: 441934744795 | N14: Index | O14: 16.499 | P14: London | R14: United Kingdom | S14: =IF(M14>100000000000, "100bn", IF(M14>50000000000, "50bn - 100bn",IF(M14>1000000000, "1bn - 50bn", IF(M14>500000000, "500mn - 1bn", "500mn")))) -> 100bn | T14: =VLOOKUP(R14,Mapping!B:C,2,FALSE) -> EU | U14: =VLOOKUP(N14,Mapping!H:I,2,FALSE) -> Index
A15: Krane Funds Advisors, LLC | B15: yes | C15: 12 | D15: 5956872 | E15: 557950 | F15: 0.86 | J15: 5956872 | K15: 557950 | L15: 05/13/2026 | M15: 9487547762 | N15: Index | O15: 40.029 | P15: New York | Q15: New York | R15: United States | S15: =IF(M15>100000000000, "100bn", IF(M15>50000000000, "50bn - 100bn",IF(M15>1000000000, "1bn - 50bn", IF(M15>500000000, "500mn - 1bn", "500mn")))) -> 1bn - 50bn | T15: =VLOOKUP(R15,Mapping!B:C,2,FALSE) -> US/CA | U15: =VLOOKUP(N15,Mapping!H:I,2,FALSE) -> Index
A16: FIL Investment Management (Hong Kong), LTD | B16: yes | C16: 13 | D16: 5845414 | E16: -601235 | F16: 0.85 | G16: 0 | H16: -167735 | I16: 06/30/2025 | J16: 5845414 | K16: -433500 | L16: 03/31/2026 | M16: 22289992322 | N16: Growth | O16: 36.77 | P16: Admiralty | R16: Hong Kong SAR | S16: =IF(M16>100000000000, "100bn", IF(M16>50000000000, "50bn - 100bn",IF(M16>1000000000, "1bn - 50bn", IF(M16>500000000, "500mn - 1bn", "500mn")))) -> 1bn - 50bn | T16: =VLOOKUP(R16,Mapping!B:C,2,FALSE) -> HK | U16: =VLOOKUP(N16,Mapping!H:I,2,FALSE) -> Growth
A17: Fidelity International Limited - FIL Investment Services (U.K.), LTD | B17: yes | C17: 14 | D17: 5453718 | E17: -323506 | F17: 0.79 | G17: 0 | H17: -240490 | I17: 09/30/2025 | J17: 5453718 | K17: -83016 | L17: 03/31/2026 | M17: 152579846744 | N17: Growth | O17: 43.975 | P17: London | R17: United Kingdom | S17: =IF(M17>100000000000, "100bn", IF(M17>50000000000, "50bn - 100bn",IF(M17>1000000000, "1bn - 50bn", IF(M17>500000000, "500mn - 1bn", "500mn")))) -> 100bn | T17: =VLOOKUP(R17,Mapping!B:C,2,FALSE) -> EU | U17: =VLOOKUP(N17,Mapping!H:I,2,FALSE) -> Growth
A18: Schroder Investment Management (Hong Kong), LTD | B18: yes | C18: 15 | D18: 5105592 | E18: -4950 | F18: 0.74 | G18: 1156692 | H18: 0 | I18: 03/31/2026 | J18: 3948900 | K18: -4950 | L18: 04/30/2026 | M18: 20277427178 | N18: GARP | O18: 60.416 | P18: Admiralty | R18: Hong Kong SAR | S18: =IF(M18>100000000000, "100bn", IF(M18>50000000000, "50bn - 100bn",IF(M18>1000000000, "1bn - 50bn", IF(M18>500000000, "500mn - 1bn", "500mn")))) -> 1bn - 50bn | T18: =VLOOKUP(R18,Mapping!B:C,2,FALSE) -> HK | U18: =VLOOKUP(N18,Mapping!H:I,2,FALSE) -> Growth
A19: Rothschild & Co Asset Management Europe SCS | B19: yes | C19: 16 | D19: 4894574 | E19: 1399867 | F19: 0.71 | G19: 4894574 | H19: 1399867 | I19: 03/31/2026 | M19: 14841382794 | N19: GARP | O19: 37.46 | P19: Paris | R19: France | S19: =IF(M19>100000000000, "100bn", IF(M19>50000000000, "50bn - 100bn",IF(M19>1000000000, "1bn - 50bn", IF(M19>500000000, "500mn - 1bn", "500mn")))) -> 1bn - 50bn | T19: =VLOOKUP(R19,Mapping!B:C,2,FALSE) -> EU | U19: =VLOOKUP(N19,Mapping!H:I,2,FALSE) -> Growth
A20: Cantillon Capital Management, LLC (U.S.) | B20: no | C20: 17 | D20: 4589621 | E20: -80157 | F20: 0.67 | G20: 4589621 | H20: -80157 | I20: 03/31/2026 | M20: 16051141096 | N20: GARP | O20: 16.613 | P20: New York | Q20: New York | R20: United States | S20: =IF(M20>100000000000, "100bn", IF(M20>50000000000, "50bn - 100bn",IF(M20>1000000000, "1bn - 50bn", IF(M20>500000000, "500mn - 1bn", "500mn")))) -> 1bn - 50bn | T20: =VLOOKUP(R20,Mapping!B:C,2,FALSE) -> US/CA | U20: =VLOOKUP(N20,Mapping!H:I,2,FALSE) -> Growth
A21: Hang Seng Investment Management, LTD | B21: yes | C21: 18 | D21: 4143897 | E21: -10134 | F21: 0.6 | G21: 9476 | H21: 640 | I21: 03/31/2026 | J21: 4134421 | K21: -10774 | L21: 04/30/2026 | M21: 33631465024 | N21: Index | O21: 19.867 | P21: Central | R21: Hong Kong SAR | S21: =IF(M21>100000000000, "100bn", IF(M21>50000000000, "50bn - 100bn",IF(M21>1000000000, "1bn - 50bn", IF(M21>500000000, "500mn - 1bn", "500mn")))) -> 1bn - 50bn | T21: =VLOOKUP(R21,Mapping!B:C,2,FALSE) -> HK | U21: =VLOOKUP(N21,Mapping!H:I,2,FALSE) -> Index
A22: China Asset Management Corporation, LTD | B22: yes | C22: 19 | D22: 3614450 | E22: -37004 | F22: 0.52 | J22: 3614450 | K22: -37004 | L22: 02/28/2026 | M22: 135091551532 | N22: Aggressive Growth | O22: 22.83 | P22: Beijing | R22: China (Mainland) | S22: =IF(M22>100000000000, "100bn", IF(M22>50000000000, "50bn - 100bn",IF(M22>1000000000, "1bn - 50bn", IF(M22>500000000, "500mn - 1bn", "500mn")))) -> 100bn | T22: =VLOOKUP(R22,Mapping!B:C,2,FALSE) -> CN | U22: =VLOOKUP(N22,Mapping!H:I,2,FALSE) -> Growth
A23: Dimensional Fund Advisors, L.P. (U.S.) | B23: yes | C23: 20 | D23: 3418881 | E23: 64818 | F23: 0.5 | G23: 2353134 | H23: -25232 | I23: 03/31/2026 | J23: 1065747 | K23: 90050 | L23: 05/14/2026 | M23: 707377951370 | N23: Value | O23: 11.636 | P23: Austin | Q23: Texas | R23: United States | S23: =IF(M23>100000000000, "100bn", IF(M23>50000000000, "50bn - 100bn",IF(M23>1000000000, "1bn - 50bn", IF(M23>500000000, "500mn - 1bn", "500mn")))) -> 100bn | T23: =VLOOKUP(R23,Mapping!B:C,2,FALSE) -> US/CA | U23: =VLOOKUP(N23,Mapping!H:I,2,FALSE) -> Value
A24: Geode Capital Management, LLC | B24: yes | C24: 21 | D24: 3334058 | E24: -6309 | F24: 0.48 | G24: 208476 | H24: 2054 | I24: 03/31/2026 | J24: 3125582 | K24: -8363 | L24: 04/30/2026 | M24: 1890862823441 | N24: Index | O24: 6.84 | P24: Boston | Q24: Massachusetts | R24: United States | S24: =IF(M24>100000000000, "100bn", IF(M24>50000000000, "50bn - 100bn",IF(M24>1000000000, "1bn - 50bn", IF(M24>500000000, "500mn - 1bn", "500mn")))) -> 100bn | T24: =VLOOKUP(R24,Mapping!B:C,2,FALSE) -> US/CA | U24: =VLOOKUP(N24,Mapping!H:I,2,FALSE) -> Index
A25: Robeco Institutional Asset Management BV | B25: yes | C25: 22 | D25: 3064434 | E25: 1302323 | F25: 0.44 | G25: 2611584 | H25: 1589575 | I25: 03/31/2026 | J25: 452850 | K25: -287252 | L25: 03/31/2026 | M25: 104891331129 | N25: Value | O25: 41.247 | P25: Rotterdam | R25: Netherlands | S25: =IF(M25>100000000000, "100bn", IF(M25>50000000000, "50bn - 100bn",IF(M25>1000000000, "1bn - 50bn", IF(M25>500000000, "500mn - 1bn", "500mn")))) -> 100bn | T25: =VLOOKUP(R25,Mapping!B:C,2,FALSE) -> EU | U25: =VLOOKUP(N25,Mapping!H:I,2,FALSE) -> Value
A26: J.P. Morgan Asset Management (Asia Pacific), LTD | B26: yes | C26: 23 | D26: 3052493 | E26: -254287 | F26: 0.44 | G26: 1170393 | H26: 0 | I26: 03/31/2026 | J26: 1882100 | K26: -254287 | L26: 03/31/2026 | M26: 36175085005 | N26: Growth | O26: 52.525 | P26: Central | R26: Hong Kong SAR | S26: =IF(M26>100000000000, "100bn", IF(M26>50000000000, "50bn - 100bn",IF(M26>1000000000, "1bn - 50bn", IF(M26>500000000, "500mn - 1bn", "500mn")))) -> 1bn - 50bn | T26: =VLOOKUP(R26,Mapping!B:C,2,FALSE) -> HK | U26: =VLOOKUP(N26,Mapping!H:I,2,FALSE) -> Growth
A27: First Sentier Investors (Hong Kong), LTD | B27: yes | C27: 24 | D27: 2939550 | E27: 5500 | F27: 0.43 | J27: 2939550 | K27: 5500 | L27: 03/31/2026 | M27: 10823127754 | N27: Growth | O27: 31.714 | P27: Central | R27: Hong Kong SAR | S27: =IF(M27>100000000000, "100bn", IF(M27>50000000000, "50bn - 100bn",IF(M27>1000000000, "1bn - 50bn", IF(M27>500000000, "500mn - 1bn", "500mn")))) -> 1bn - 50bn | T27: =VLOOKUP(R27,Mapping!B:C,2,FALSE) -> HK | U27: =VLOOKUP(N27,Mapping!H:I,2,FALSE) -> Growth
A28: Legal & General Investment Management, LTD | B28: yes | C28: 25 | D28: 2899010 | E28: -32391 | F28: 0.42 | G28: 2634410 | H28: -32291 | I28: 03/31/2026 | J28: 264600 | K28: -100 | L28: 05/13/2026 | M28: 516627888777 | N28: Index | O28: 9.411 | P28: London | R28: United Kingdom | S28: =IF(M28>100000000000, "100bn", IF(M28>50000000000, "50bn - 100bn",IF(M28>1000000000, "1bn - 50bn", IF(M28>500000000, "500mn - 1bn", "500mn")))) -> 100bn | T28: =VLOOKUP(R28,Mapping!B:C,2,FALSE) -> EU | U28: =VLOOKUP(N28,Mapping!H:I,2,FALSE) -> Index
A29: Arga Investment Management, L.P. | B29: yes | C29: 26 | D29: 2861617 | E29: -1082568 | F29: 0.42 | G29: 2861617 | H29: -1082568 | I29: 03/31/2026 | M29: 6544176802 | N29: Value | O29: 59.284 | P29: Stamford | Q29: Connecticut | R29: United States | S29: =IF(M29>100000000000, "100bn", IF(M29>50000000000, "50bn - 100bn",IF(M29>1000000000, "1bn - 50bn", IF(M29>500000000, "500mn - 1bn", "500mn")))) -> 1bn - 50bn | T29: =VLOOKUP(R29,Mapping!B:C,2,FALSE) -> US/CA | U29: =VLOOKUP(N29,Mapping!H:I,2,FALSE) -> Value
A30: Principal Global Investors, LLC | B30: yes | C30: 27 | D30: 2768761 | E30: -119877 | F30: 0.4 | G30: 0 | H30: -257077 | I30: 06/30/2025 | J30: 2768761 | K30: 137200 | L30: 05/09/2026 | M30: 206814740967 | N30: Growth | O30: 21.796 | P30: Des Moines | Q30: Iowa | R30: United States | S30: =IF(M30>100000000000, "100bn", IF(M30>50000000000, "50bn - 100bn",IF(M30>1000000000, "1bn - 50bn", IF(M30>500000000, "500mn - 1bn", "500mn")))) -> 100bn | T30: =VLOOKUP(R30,Mapping!B:C,2,FALSE) -> US/CA | U30: =VLOOKUP(N30,Mapping!H:I,2,FALSE) -> Growth
A31: Greenwoods Asset Management, LTD (China) | B31: no | C31: 28 | D31: 2604281 | E31: 2604281 | F31: 0.38 | G31: 2604281 | H31: 2604281 | I31: 03/31/2026 | M31: 4004956787 | N31: Alternative | O31: 73.415 | P31: Shanghai | R31: China (Mainland) | S31: =IF(M31>100000000000, "100bn", IF(M31>50000000000, "50bn - 100bn",IF(M31>1000000000, "1bn - 50bn", IF(M31>500000000, "500mn - 1bn", "500mn")))) -> 1bn - 50bn | T31: =VLOOKUP(R31,Mapping!B:C,2,FALSE) -> CN | U31: =VLOOKUP(N31,Mapping!H:I,2,FALSE) -> Alternative/Specialty
A32: UBS Asset Management Switzerland AG | B32: yes | C32: 29 | D32: 2591763 | E32: 970174 | F32: 0.38 | G32: 938824 | H32: 938824 | I32: 03/31/2026 | J32: 1652939 | K32: 31350 | L32: 05/12/2026 | M32: 333635647497 | N32: Value | O32: 32.088 | P32: Zurich | R32: Switzerland | S32: =IF(M32>100000000000, "100bn", IF(M32>50000000000, "50bn - 100bn",IF(M32>1000000000, "1bn - 50bn", IF(M32>500000000, "500mn - 1bn", "500mn")))) -> 100bn | T32: =VLOOKUP(R32,Mapping!B:C,2,FALSE) -> EU | U32: =VLOOKUP(N32,Mapping!H:I,2,FALSE) -> Value
A33: J.P. Morgan Investment Management, Inc. | B33: yes | C33: 30 | D33: 2457425 | E33: -3489 | F33: 0.36 | G33: 2269598 | H33: -2789 | I33: 03/31/2026 | J33: 187827 | K33: -700 | L33: 05/13/2026 | M33: 846468087667 | N33: Growth | O33: 29.371 | P33: New York | Q33: New York | R33: United States | S33: =IF(M33>100000000000, "100bn", IF(M33>50000000000, "50bn - 100bn",IF(M33>1000000000, "1bn - 50bn", IF(M33>500000000, "500mn - 1bn", "500mn")))) -> 100bn | T33: =VLOOKUP(R33,Mapping!B:C,2,FALSE) -> US/CA | U33: =VLOOKUP(N33,Mapping!H:I,2,FALSE) -> Growth
A34: BlackRock Asset Management North Asia, LTD (Hong Kong) | B34: yes | C34: 31 | D34: 2411675 | E34: 49026 | F34: 0.35 | G34: 268146 | H34: -18060 | I34: 03/31/2026 | J34: 2143529 | K34: 67086 | L34: 05/12/2026 | M34: 29688090454 | N34: Index | O34: 29.223 | P34: Central | R34: Hong Kong SAR | S34: =IF(M34>100000000000, "100bn", IF(M34>50000000000, "50bn - 100bn",IF(M34>1000000000, "1bn - 50bn", IF(M34>500000000, "500mn - 1bn", "500mn")))) -> 1bn - 50bn | T34: =VLOOKUP(R34,Mapping!B:C,2,FALSE) -> HK | U34: =VLOOKUP(N34,Mapping!H:I,2,FALSE) -> Index
A35: Wellington Management Company, LLP | B35: yes | C35: 32 | D35: 2369414 | E35: -5307857 | F35: 0.34 | G35: 1390436 | H35: -5307857 | I35: 03/31/2026 | J35: 978978 | K35: 0 | L35: 04/30/2026 | M35: 593050582169 | N35: Value | O35: 43.659 | P35: Boston | Q35: Massachusetts | R35: United States | S35: =IF(M35>100000000000, "100bn", IF(M35>50000000000, "50bn - 100bn",IF(M35>1000000000, "1bn - 50bn", IF(M35>500000000, "500mn - 1bn", "500mn")))) -> 100bn | T35: =VLOOKUP(R35,Mapping!B:C,2,FALSE) -> US/CA | U35: =VLOOKUP(N35,Mapping!H:I,2,FALSE) -> Value
A36: Brandes Investment Partners, L.P. | B36: yes | C36: 33 | D36: 2346562 | E36: 860162 | F36: 0.34 | G36: 867912 | H36: 838012 | I36: 03/31/2026 | J36: 1478650 | K36: 22150 | L36: 04/30/2026 | M36: 25276657622 | N36: Deep Value | O36: 43.178 | P36: La Jolla | Q36: California | R36: United States | S36: =IF(M36>100000000000, "100bn", IF(M36>50000000000, "50bn - 100bn",IF(M36>1000000000, "1bn - 50bn", IF(M36>500000000, "500mn - 1bn", "500mn")))) -> 1bn - 50bn | T36: =VLOOKUP(R36,Mapping!B:C,2,FALSE) -> US/CA | U36: =VLOOKUP(N36,Mapping!H:I,2,FALSE) -> Value
A37: Aspex Management (HK), LTD | B37: no | C37: 34 | D37: 2329290 | E37: 2329290 | F37: 0.34 | G37: 2329290 | H37: 2329290 | I37: 03/31/2026 | M37: 7574057446 | N37: Growth | O37: 118.608 | P37: Central | R37: Hong Kong SAR | S37: =IF(M37>100000000000, "100bn", IF(M37>50000000000, "50bn - 100bn",IF(M37>1000000000, "1bn - 50bn", IF(M37>500000000, "500mn - 1bn", "500mn")))) -> 1bn - 50bn | T37: =VLOOKUP(R37,Mapping!B:C,2,FALSE) -> HK | U37: =VLOOKUP(N37,Mapping!H:I,2,FALSE) -> Growth
A38: Black Creek Investment Management, Inc. | B38: no | C38: 35 | D38: 2314583 | E38: 1552 | F38: 0.34 | G38: 0 | H38: -2573 | I38: 09/30/2024 | J38: 2314583 | K38: 4125 | L38: 03/31/2026 | M38: 5724272211 | N38: Growth | O38: 33.193 | P38: Toronto | Q38: Ontario | R38: Canada | S38: =IF(M38>100000000000, "100bn", IF(M38>50000000000, "50bn - 100bn",IF(M38>1000000000, "1bn - 50bn", IF(M38>500000000, "500mn - 1bn", "500mn")))) -> 1bn - 50bn | T38: =VLOOKUP(R38,Mapping!B:C,2,FALSE) -> US/CA | U38: =VLOOKUP(N38,Mapping!H:I,2,FALSE) -> Growth
A39: Vontobel Asset Management AG (Switzerland) | B39: yes | C39: 36 | D39: 2266973 | E39: 138350 | F39: 0.33 | G39: 1383213 | H39: 117615 | I39: 03/31/2026 | J39: 883760 | K39: 20735 | L39: 01/31/2026 | M39: 31983266955 | N39: Growth | O39: 34.725 | P39: Zürich | R39: Switzerland | S39: =IF(M39>100000000000, "100bn", IF(M39>50000000000, "50bn - 100bn",IF(M39>1000000000, "1bn - 50bn", IF(M39>500000000, "500mn - 1bn", "500mn")))) -> 1bn - 50bn | T39: =VLOOKUP(R39,Mapping!B:C,2,FALSE) -> EU | U39: =VLOOKUP(N39,Mapping!H:I,2,FALSE) -> Growth
A40: Temasek Holdings Pte., LTD | B40: no | C40: 37 | D40: 2239671 | E40: 0 | F40: 0.32 | G40: 2239671 | H40: 0 | I40: 03/31/2026 | M40: 151489365884 | N40: Value | O40: 11.68 | P40: Singapore | R40: Singapore | S40: =IF(M40>100000000000, "100bn", IF(M40>50000000000, "50bn - 100bn",IF(M40>1000000000, "1bn - 50bn", IF(M40>500000000, "500mn - 1bn", "500mn")))) -> 100bn | T40: =VLOOKUP(R40,Mapping!B:C,2,FALSE) -> SG | U40: =VLOOKUP(N40,Mapping!H:I,2,FALSE) -> Value
...

Sheet 全球投资人地图
B2: 全球投资人地图
B3: updated as of 26Q1
B5: # of Institutions | C5: 5452
B6: Total SH Equity AUM ($bn) | C6: =DATA_ALL!CL5455/1000000000 -> 79423.874
B7: TCOM SH Equity AUM ($bn) | C7: =(C6*1000000000-D18)/1000000000 -> 61377.191
B8: Total TCOM Holding ($bn) | C8: =(DATA_ALL!G5455+DATA_ALL!I5455)/1000000000 -> 20.761221 | D8: *小于Total Market Cap, 由于目前可以抓取到的公开披露信息，cover约53%的股东持仓数据
B9: Holding % | C9: =C8/C7 -> 0.0003382563
C11: Position (in $bn) | D11: Total Equity AUM (in $bn) | E11: Holding % | F11: Avg Holding%
B12: Total Peer (14家) | C12: =C13+C14 -> 824.60342 | D12: =C6 -> 79423.874 | E12: =C12/D12 -> 0.010382312 | F12: =E12/14 -> 0.0007415937
B13: ADR Peer (7家) | C13: =SUM(DATA_ALL!G5455:AF5455)/1000000000 -> 608.09085 | D13: =(D12*1000000000-D16)/1000000000 -> 74954.706 | E13: =C13/D13 -> 0.0081127775 | F13: =E13/7 -> 0.0011589682
B14: Travel Peer (7家) | C14: =SUM(DATA_ALL!AH5455:AX5455)/1000000000 -> 216.51257 | D14: =(D12*1000000000-D17)/1000000000 -> 75590.369 | E14: =C14/D14 -> 0.0028642878 | F14: =E14/7 -> 0.00040918397
D16: 4469167890168 | E16: no ADR holding Equity AUM
D17: 3833504796936 | E17: no Travel holding Equity AUM
D18: 18046683025877 | E18: no TCOM holding

Sheet US&CA
B2: US&CA Top Investors
B3: As of 2026Q1, AUM > $50bn
D5: 85 | E5: 90 | F5: 89 | G5: 7 | H5: 9 | J5: 31240000000 | L5: 11 | M5: =4058000000000/7.83 -> 5.1826309e+11 | N5: 13 | O5: 15 | Q5: 318100000000 | R5: 18 | S5: =507200000000/7.83 -> 6.4776501e+10 | T5: 20 | U5: 22 | W5: 72350000000 | X5: 24 | Y5: 136400000000 | Z5: 26 | AA5: 28 | AC5: 43230000000 | AD5: 30 | AE5: 32 | AG5: 46050000000 | AH5: 34 | AI5: 78850000000 | AJ5: 40 | AK5: 119400000000 | AL5: 42 | AM5: 26130000000 | AN5: 44 | AO5: 4108000000 | AP5: 46 | AQ5: 1101000000 | AR5: 48 | AS5: 217100000 | AT5: 50 | AU5: =38560000000/7.83 -> 4.9246488e+09
C6: Institution/Fund Name | D6: Dominant Style | E6: Equity AUM, $bn | F6: Country | I6: TCOM | L6: ADR Peers | AH6: Travel Peers
D7: Dominant Style | G7: TCOM | H7: 9961 | I7: Position | J7: % Mkt Cap | K7: SH Rank | L7: Tencent Position | M7: Tencent % Mkt Cap | N7: BABA | O7: 9988 | P7: BABA Position | Q7: BABA % Mkt Cap | R7: Meituan Position | S7: Meituan % Mkt Cap | T7: NTES | U7: 9999 | V7: NTES Position | W7: NTES % Mkt Cap | X7: PDD Position | Y7: PDD % Mkt Cap | Z7: JD | AA7: 9618 | AB7: JD Position | AC7: JD % Mkt Cap | AD7: BIDU | AE7: 9888 | AF7: BIDU Position | AG7: BIDU % Mkt Cap | AH7: ABNB Position | AI7: Avg % Mkt Cap | AJ7: BKNG Position | AK7: BKNG % Mkt Cap | AL7: EXPE Position | AM7: EXPE % Mkt Cap | AN7: MMYT Position | AO7: MMYT % Mkt Cap | AP7: TRIP Position | AQ7: TRIP % Mkt Cap | AR7: TRVG Position | AS7: TRVG % Mkt Cap | AT7: TC Position | AU7: TC % Mkt Cap
B8: 1 | C8: The Vanguard Group, Inc. | D8: =VLOOKUP($C8,DATA_ALL!$A:$CU,D$5,FALSE) -> Index | E8: =VLOOKUP($C8,DATA_ALL!$A:$CU,E$5,FALSE)/1000000000 -> 7960.9296 | F8: =VLOOKUP($C8,DATA_ALL!$A:$CU,F$5,FALSE) -> United States | G8: =IF(VLOOKUP($C8,DATA_ALL!$A:$CU,G$5,FALSE)="N/A",0,VLOOKUP($C8,DATA_ALL!$A:$CU,G$5,FALSE)) -> 0 | H8: =VLOOKUP($C8,DATA_ALL!$A:$CU,H$5,FALSE) -> 1026978790 | I8: =G8+H8 -> 1026978790 | J8: =I8/$J$5 -> 0.032873841 | K8: =IFERROR(INDEX('SH Summary'!B:B,MATCH('US&CA'!C8,'SH Summary'!C:C,0)), "N/A") -> 2 | L8: =VLOOKUP($C8,DATA_ALL!$A:$CU,L$5,FALSE) -> 13476680302 | M8: =L8/M$5 -> 0.02600355 | N8: =VLOOKUP($C8,DATA_ALL!$A:$CU,N$5,FALSE) -> 64361 | O8: =VLOOKUP($C8,DATA_ALL!$A:$CU,O$5,FALSE) -> 9594202081 | P8: =N8+O8 -> 9594266442 | Q8: =P8/Q$5 -> 0.030161165 | R8: =VLOOKUP($C8,DATA_ALL!$A:$CU,R$5,FALSE) -> 1990217324 | S8: =R8/S$5 -> 0.030724372 | T8: =VLOOKUP($C8,DATA_ALL!$A:$CU,T$5,FALSE) -> 0 | U8: =VLOOKUP($C8,DATA_ALL!$A:$CU,U$5,FALSE) -> 1399520043 | V8: =T8+U8 -> 1399520043 | W8: =V8/W$5 -> 0.019343746 | X8: =VLOOKUP($C8,DATA_ALL!$A:$CU,X$5,FALSE) -> 3367130490 | Y8: =X8/Y$5 -> 0.024685707 | Z8: =VLOOKUP($C8,DATA_ALL!$A:$CU,Z$5,FALSE) -> 1479 | AA8: =VLOOKUP($C8,DATA_ALL!$A:$CU,AA$5,FALSE) -> 1250721183 | AB8: =Z8+AA8 -> 1250722662 | AC8: =AB8/AC$5 -> 0.028931822 | AD8: =VLOOKUP($C8,DATA_ALL!$A:$CU,AD$5,FALSE) -> 2786 | AE8: =VLOOKUP($C8,DATA_ALL!$A:$CU,AE$5,FALSE) -> 1020628020 | AF8: =AD8+AE8 -> 1020630806 | AG8: =AF8/AG$5 -> 0.022163535 | AH8: =VLOOKUP($C8,DATA_ALL!$A:$CU,AH$5,FALSE) -> 4796747947 | AI8: =AH8/AI$5 -> 0.060833836 | AJ8: =VLOOKUP($C8,DATA_ALL!$A:$CU,AJ$5,FALSE) -> 12543301138 | AK8: =AJ8/AK$5 -> 0.10505277 | AL8: =VLOOKUP($C8,DATA_ALL!$A:$CU,AL$5,FALSE) -> 3381632257 | AM8: =AL8/AM$5 -> 0.1294157 | AN8: =VLOOKUP($C8,DATA_ALL!$A:$CU,AN$5,FALSE) -> 3159582 | AO8: =AN8/AO$5 -> 0.00076912902 | AP8: =VLOOKUP($C8,DATA_ALL!$A:$CU,AP$5,FALSE) -> 134917256 | AQ8: =AP8/AQ$5 -> 0.12254065 | AR8: =VLOOKUP($C8,DATA_ALL!$A:$CU,AR$5,FALSE) -> 0 | AS8: =AR8/AS$5 -> 0 | AT8: =VLOOKUP($C8,DATA_ALL!$A:$CU,AT$5,FALSE) -> 101577826 | AU8: =AT8/AU$5 -> 0.02062641
B9: 2 | C9: BlackRock Fund Advisors | D9: =VLOOKUP($C9,DATA_ALL!$A:$CU,D$5,FALSE) -> Index | E9: =VLOOKUP($C9,DATA_ALL!$A:$CU,E$5,FALSE)/1000000000 -> 4837.4638 | F9: =VLOOKUP($C9,DATA_ALL!$A:$CU,F$5,FALSE) -> United States | G9: =IF(VLOOKUP($C9,DATA_ALL!$A:$CU,G$5,FALSE)="N/A",0,VLOOKUP($C9,DATA_ALL!$A:$CU,G$5,FALSE)) -> 29618727 | H9: =VLOOKUP($C9,DATA_ALL!$A:$CU,H$5,FALSE) -> 858321319 | I9: =G9+H9 -> 887940046 | J9: =I9/$J$5 -> 0.028423177 | K9: =IFERROR(INDEX('SH Summary'!B:B,MATCH('US&CA'!C9,'SH Summary'!C:C,0)), "N/A") -> 3 | L9: =VLOOKUP($C9,DATA_ALL!$A:$CU,L$5,FALSE) -> 8753867028 | M9: =L9/M$5 -> 0.016890778 | N9: =VLOOKUP($C9,DATA_ALL!$A:$CU,N$5,FALSE) -> 108616619 | O9: =VLOOKUP($C9,DATA_ALL!$A:$CU,O$5,FALSE) -> 6864586154 | P9: =N9+O9 -> 6973202773 | Q9: =P9/Q$5 -> 0.021921417 | R9: =VLOOKUP($C9,DATA_ALL!$A:$CU,R$5,FALSE) -> 1363990894 | S9: =R9/S$5 -> 0.021056878 | T9: =VLOOKUP($C9,DATA_ALL!$A:$CU,T$5,FALSE) -> 912423 | U9: =VLOOKUP($C9,DATA_ALL!$A:$CU,U$5,FALSE) -> 1146135089 | V9: =T9+U9 -> 1147047512 | W9: =V9/W$5 -> 0.015854147 | X9: =VLOOKUP($C9,DATA_ALL!$A:$CU,X$5,FALSE) -> 2385668497 | Y9: =X9/Y$5 -> 0.017490238 | Z9: =VLOOKUP($C9,DATA_ALL!$A:$CU,Z$5,FALSE) -> 4585154 | AA9: =VLOOKUP($C9,DATA_ALL!$A:$CU,AA$5,FALSE) -> 994000363 | AB9: =Z9+AA9 -> 998585517 | AC9: =AB9/AC$5 -> 0.023099364 | AD9: =VLOOKUP($C9,DATA_ALL!$A:$CU,AD$5,FALSE) -> 99411598 | AE9: =VLOOKUP($C9,DATA_ALL!$A:$CU,AE$5,FALSE) -> 1070697604 | AF9: =AD9+AE9 -> 1170109202 | AG9: =AF9/AG$5 -> 0.025409538 | AH9: =VLOOKUP($C9,DATA_ALL!$A:$CU,AH$5,FALSE) -> 2507658011 | AI9: =AH9/AI$5 -> 0.031802892 | AJ9: =VLOOKUP($C9,DATA_ALL!$A:$CU,AJ$5,FALSE) -> 6677058071 | AK9: =AJ9/AK$5 -> 0.055921759 | AL9: =VLOOKUP($C9,DATA_ALL!$A:$CU,AL$5,FALSE) -> 1620974559 | AM9: =AL9/AM$5 -> 0.062035 | AN9: =VLOOKUP($C9,DATA_ALL!$A:$CU,AN$5,FALSE) -> 4662592 | AO9: =AN9/AO$5 -> 0.0011350029 | AP9: =VLOOKUP($C9,DATA_ALL!$A:$CU,AP$5,FALSE) -> 165075526 | AQ9: =AP9/AQ$5 -> 0.14993236 | AR9: =VLOOKUP($C9,DATA_ALL!$A:$CU,AR$5,FALSE) -> 0 | AS9: =AR9/AS$5 -> 0 | AT9: =VLOOKUP($C9,DATA_ALL!$A:$CU,AT$5,FALSE) -> 76002098 | AU9: =AT9/AU$5 -> 0.015432999
B10: 3 | C10: State Street Investment Management | D10: =VLOOKUP($C10,DATA_ALL!$A:$CU,D$5,FALSE) -> Index | E10: =VLOOKUP($C10,DATA_ALL!$A:$CU,E$5,FALSE)/1000000000 -> 3127.6536 | F10: =VLOOKUP($C10,DATA_ALL!$A:$CU,F$5,FALSE) -> United States | G10: =IF(VLOOKUP($C10,DATA_ALL!$A:$CU,G$5,FALSE)="N/A",0,VLOOKUP($C10,DATA_ALL!$A:$CU,G$5,FALSE)) -> 718221 | H10: =VLOOKUP($C10,DATA_ALL!$A:$CU,H$5,FALSE) -> 68099849 | I10: =G10+H10 -> 68818070 | J10: =I10/$J$5 -> 0.0022028832 | K10: =IFERROR(INDEX('SH Summary'!B:B,MATCH('US&CA'!C10,'SH Summary'!C:C,0)), "N/A") -> 53 | L10: =VLOOKUP($C10,DATA_ALL!$A:$CU,L$5,FALSE) -> 872445888 | M10: =L10/M$5 -> 0.0016834035 | N10: =VLOOKUP($C10,DATA_ALL!$A:$CU,N$5,FALSE) -> 60529933 | O10: =VLOOKUP($C10,DATA_ALL!$A:$CU,O$5,FALSE) -> 704013706 | P10: =N10+O10 -> 764543639 | Q10: =P10/Q$5 -> 0.0024034695 | R10: =VLOOKUP($C10,DATA_ALL!$A:$CU,R$5,FALSE) -> 128450102 | S10: =R10/S$5 -> 0.0019829738 | T10: =VLOOKUP($C10,DATA_ALL!$A:$CU,T$5,FALSE) -> 3903012 | U10: =VLOOKUP($C10,DATA_ALL!$A:$CU,U$5,FALSE) -> 104596181 | V10: =T10+U10 -> 108499193 | W10: =V10/W$5 -> 0.0014996433 | X10: =VLOOKUP($C10,DATA_ALL!$A:$CU,X$5,FALSE) -> 1229603159 | Y10: =X10/Y$5 -> 0.0090146859 | Z10: =VLOOKUP($C10,DATA_ALL!$A:$CU,Z$5,FALSE) -> 4435145 | AA10: =VLOOKUP($C10,DATA_ALL!$A:$CU,AA$5,FALSE) -> 101549754 | AB10: =Z10+AA10 -> 105984899 | AC10: =AB10/AC$5 -> 0.0024516516 | AD10: =VLOOKUP($C10,DATA_ALL!$A:$CU,AD$5,FALSE) -> 9633707 | AE10: =VLOOKUP($C10,DATA_ALL!$A:$CU,AE$5,FALSE) -> 91757505 | AF10: =AD10+AE10 -> 101391212 | AG10: =AF10/AG$5 -> 0.0022017636 | AH10: =VLOOKUP($C10,DATA_ALL!$A:$CU,AH$5,FALSE) -> 2239349506 | AI10: =AH10/AI$5 -> 0.028400121 | AJ10: =VLOOKUP($C10,DATA_ALL!$A:$CU,AJ$5,FALSE) -> 5982005815 | AK10: =AJ10/AK$5 -> 0.050100551 | AL10: =VLOOKUP($C10,DATA_ALL!$A:$CU,AL$5,FALSE) -> 1291250709 | AM10: =AL10/AM$5 -> 0.049416407 | AN10: =VLOOKUP($C10,DATA_ALL!$A:$CU,AN$5,FALSE) -> 3801529 | AO10: =AN10/AO$5 -> 0.00092539654 | AP10: =VLOOKUP($C10,DATA_ALL!$A:$CU,AP$5,FALSE) -> 52111890 | AQ10: =AP10/AQ$5 -> 0.047331417 | AR10: =VLOOKUP($C10,DATA_ALL!$A:$CU,AR$5,FALSE) -> 0 | AS10: =AR10/AS$5 -> 0 | AT10: =VLOOKUP($C10,DATA_ALL!$A:$CU,AT$5,FALSE) -> 5136158 | AU10: =AT10/AU$5 -> 0.0010429491
B11: 4 | C11: Fidelity Management & Research Company, LLC | D11: =VLOOKUP($C11,DATA_ALL!$A:$CU,D$5,FALSE) -> Growth | E11: =VLOOKUP($C11,DATA_ALL!$A:$CU,E$5,FALSE)/1000000000 -> 1923.7785 | F11: =VLOOKUP($C11,DATA_ALL!$A:$CU,F$5,FALSE) -> United States | G11: =IF(VLOOKUP($C11,DATA_ALL!$A:$CU,G$5,FALSE)="N/A",0,VLOOKUP($C11,DATA_ALL!$A:$CU,G$5,FALSE)) -> 35144471 | H11: =VLOOKUP($C11,DATA_ALL!$A:$CU,H$5,FALSE) -> 7035115 | I11: =G11+H11 -> 42179586 | J11: =I11/$J$5 -> 0.0013501788 | K11: =IFERROR(INDEX('SH Summary'!B:B,MATCH('US&CA'!C11,'SH Summary'!C:C,0)), "N/A") -> 72 | L11: =VLOOKUP($C11,DATA_ALL!$A:$CU,L$5,FALSE) -> 2435922618 | M11: =L11/M$5 -> 0.0047001661 | N11: =VLOOKUP($C11,DATA_ALL!$A:$CU,N$5,FALSE) -> 692326420 | O11: =VLOOKUP($C11,DATA_ALL!$A:$CU,O$5,FALSE) -> 117834936 | P11: =N11+O11 -> 810161356 | Q11: =P11/Q$5 -> 0.0025468763 | R11: =VLOOKUP($C11,DATA_ALL!$A:$CU,R$5,FALSE) -> 6917848 | S11: =R11/S$5 -> 0.00010679564 | T11: =VLOOKUP($C11,DATA_ALL!$A:$CU,T$5,FALSE) -> 30443650 | U11: =VLOOKUP($C11,DATA_ALL!$A:$CU,U$5,FALSE) -> 30113333 | V11: =T11+U11 -> 60556983 | W11: =V11/W$5 -> 0.00083700046 | X11: =VLOOKUP($C11,DATA_ALL!$A:$CU,X$5,FALSE) -> 261077972 | Y11: =X11/Y$5 -> 0.0019140614 | Z11: =VLOOKUP($C11,DATA_ALL!$A:$CU,Z$5,FALSE) -> 7966513 | AA11: =VLOOKUP($C11,DATA_ALL!$A:$CU,AA$5,FALSE) -> 373591 | AB11: =Z11+AA11 -> 8340104 | AC11: =AB11/AC$5 -> 0.00019292399 | AD11: =VLOOKUP($C11,DATA_ALL!$A:$CU,AD$5,FALSE) -> 1913861 | AE11: =VLOOKUP($C11,DATA_ALL!$A:$CU,AE$5,FALSE) -> 8917061 | AF11: =AD11+AE11 -> 10830922 | AG11: =AF11/AG$5 -> 0.00023519917 | AH11: =VLOOKUP($C11,DATA_ALL!$A:$CU,AH$5,FALSE) -> 854168780 | AI11: =AH11/AI$5 -> 0.010832832 | AJ11: =VLOOKUP($C11,DATA_ALL!$A:$CU,AJ$5,FALSE) -> 1259315133 | AK11: =AJ11/AK$5 -> 0.010547028 | AL11: =VLOOKUP($C11,DATA_ALL!$A:$CU,AL$5,FALSE) -> 306660248 | AM11: =AL11/AM$5 -> 0.011735945 | AN11: =VLOOKUP($C11,DATA_ALL!$A:$CU,AN$5,FALSE) -> 45190446 | AO11: =AN11/AO$5 -> 0.011000595 | AP11: =VLOOKUP($C11,DATA_ALL!$A:$CU,AP$5,FALSE) -> 60869 | AQ11: =AP11/AQ$5 -> 5.5285195e-05 | AR11: =VLOOKUP($C11,DATA_ALL!$A:$CU,AR$5,FALSE) -> 0 | AS11: =AR11/AS$5 -> 0 | AT11: =VLOOKUP($C11,DATA_ALL!$A:$CU,AT$5,FALSE) -> 0 | AU11: =AT11/AU$5 -> 0
B12: 5 | C12: Geode Capital Management, LLC | D12: =VLOOKUP($C12,DATA_ALL!$A:$CU,D$5,FALSE) -> Index | E12: =VLOOKUP($C12,DATA_ALL!$A:$CU,E$5,FALSE)/1000000000 -> 1890.8628 | F12: =VLOOKUP($C12,DATA_ALL!$A:$CU,F$5,FALSE) -> United States | G12: =IF(VLOOKUP($C12,DATA_ALL!$A:$CU,G$5,FALSE)="N/A",0,VLOOKUP($C12,DATA_ALL!$A:$CU,G$5,FALSE)) -> 10380020 | H12: =VLOOKUP($C12,DATA_ALL!$A:$CU,H$5,FALSE) -> 152783674 | I12: =G12+H12 -> 163163694 | J12: =I12/$J$5 -> 0.0052229095 | K12: =IFERROR(INDEX('SH Summary'!B:B,MATCH('US&CA'!C12,'SH Summary'!C:C,0)), "N/A") -> 20 | L12: =VLOOKUP($C12,DATA_ALL!$A:$CU,L$5,FALSE) -> 2237948674 | M12: =L12/M$5 -> 0.004318171 | N12: =VLOOKUP($C12,DATA_ALL!$A:$CU,N$5,FALSE) -> 0 | O12: =VLOOKUP($C12,DATA_ALL!$A:$CU,O$5,FALSE) -> 1496259102 | P12: =N12+O12 -> 1496259102 | Q12: =P12/Q$5 -> 0.0047037381 | R12: =VLOOKUP($C12,DATA_ALL!$A:$CU,R$5,FALSE) -> 266774512 | S12: =R12/S$5 -> 0.0041183841 | T12: =VLOOKUP($C12,DATA_ALL!$A:$CU,T$5,FALSE) -> 7923561 | U12: =VLOOKUP($C12,DATA_ALL!$A:$CU,U$5,FALSE) -> 196254479 | V12: =T12+U12 -> 204178040 | W12: =V12/W$5 -> 0.0028220876 | X12: =VLOOKUP($C12,DATA_ALL!$A:$CU,X$5,FALSE) -> 700232081 | Y12: =X12/Y$5 -> 0.0051336663 | Z12: =VLOOKUP($C12,DATA_ALL!$A:$CU,Z$5,FALSE) -> 11906952 | AA12: =VLOOKUP($C12,DATA_ALL!$A:$CU,AA$5,FALSE) -> 332317094 | AB12: =Z12+AA12 -> 344224046 | AC12: =AB12/AC$5 -> 0.0079626196 | AD12: =VLOOKUP($C12,DATA_ALL!$A:$CU,AD$5,FALSE) -> 10521056 | AE12: =VLOOKUP($C12,DATA_ALL!$A:$CU,AE$5,FALSE) -> 273988693 | AF12: =AD12+AE12 -> 284509749 | AG12: =AF12/AG$5 -> 0.006178279 | AH12: =VLOOKUP($C12,DATA_ALL!$A:$CU,AH$5,FALSE) -> 1313449519 | AI12: =AH12/AI$5 -> 0.016657572 | AJ12: =VLOOKUP($C12,DATA_ALL!$A:$CU,AJ$5,FALSE) -> 3751980354 | AK12: =AJ12/AK$5 -> 0.031423621 | AL12: =VLOOKUP($C12,DATA_ALL!$A:$CU,AL$5,FALSE) -> 928927962 | AM12: =AL12/AM$5 -> 0.035550247 | AN12: =VLOOKUP($C12,DATA_ALL!$A:$CU,AN$5,FALSE) -> 14582590 | AO12: =AN12/AO$5 -> 0.0035498028 | AP12: =VLOOKUP($C12,DATA_ALL!$A:$CU,AP$5,FALSE) -> 30292916 | AQ12: =AP12/AQ$5 -> 0.027514002 | AR12: =VLOOKUP($C12,DATA_ALL!$A:$CU,AR$5,FALSE) -> 29721 | AS12: =AR12/AS$5 -> 0.00013690005 | AT12: =VLOOKUP($C12,DATA_ALL!$A:$CU,AT$5,FALSE) -> 17509966 | AU12: =AT12/AU$5 -> 0.0035555766
B13: 6 | C13: Morgan Stanley & Company, LLC | D13: =VLOOKUP($C13,DATA_ALL!$A:$CU,D$5,FALSE) -> Broker | E13: =VLOOKUP($C13,DATA_ALL!$A:$CU,E$5,FALSE)/1000000000 -> 1040.2347 | F13: =VLOOKUP($C13,DATA_ALL!$A:$CU,F$5,FALSE) -> United States | G13: =IF(VLOOKUP($C13,DATA_ALL!$A:$CU,G$5,FALSE)="N/A",0,VLOOKUP($C13,DATA_ALL!$A:$CU,G$5,FALSE)) -> 48313677 | H13: =VLOOKUP($C13,DATA_ALL!$A:$CU,H$5,FALSE) -> 0 | I13: =G13+H13 -> 48313677 | J13: =I13/$J$5 -> 0.0015465326 | K13: =IFERROR(INDEX('SH Summary'!B:B,MATCH('US&CA'!C13,'SH Summary'!C:C,0)), "N/A") -> 66 | L13: =VLOOKUP($C13,DATA_ALL!$A:$CU,L$5,FALSE) -> 0 | M13: =L13/M$5 -> 0 | N13: =VLOOKUP($C13,DATA_ALL!$A:$CU,N$5,FALSE) -> 600585049 | O13: =VLOOKUP($C13,DATA_ALL!$A:$CU,O$5,FALSE) -> 0 | P13: =N13+O13 -> 600585049 | Q13: =P13/Q$5 -> 0.0018880385 | R13: =VLOOKUP($C13,DATA_ALL!$A:$CU,R$5,FALSE) -> 0 | S13: =R13/S$5 -> 0 | T13: =VLOOKUP($C13,DATA_ALL!$A:$CU,T$5,FALSE) -> 46568831 | U13: =VLOOKUP($C13,DATA_ALL!$A:$CU,U$5,FALSE) -> 0 | V13: =T13+U13 -> 46568831 | W13: =V13/W$5 -> 0.00064366041 | X13: =VLOOKUP($C13,DATA_ALL!$A:$CU,X$5,FALSE) -> 509740359 | Y13: =X13/Y$5 -> 0.0037370994 | Z13: =VLOOKUP($C13,DATA_ALL!$A:$CU,Z$5,FALSE) -> 76065306 | AA13: =VLOOKUP($C13,DATA_ALL!$A:$CU,AA$5,FALSE) -> 0 | AB13: =Z13+AA13 -> 76065306 | AC13: =AB13/AC$5 -> 0.0017595491 | AD13: =VLOOKUP($C13,DATA_ALL!$A:$CU,AD$5,FALSE) -> 71150806 | AE13: =VLOOKUP($C13,DATA_ALL!$A:$CU,AE$5,FALSE) -> 0 | AF13: =AD13+AE13 -> 71150806 | AG13: =AF13/AG$5 -> 0.0015450772 | AH13: =VLOOKUP($C13,DATA_ALL!$A:$CU,AH$5,FALSE) -> 234082458 | AI13: =AH13/AI$5 -> 0.0029687059 | AJ13: =VLOOKUP($C13,DATA_ALL!$A:$CU,AJ$5,FALSE) -> 816107377 | AK13: =AJ13/AK$5 -> 0.0068350702 | AL13: =VLOOKUP($C13,DATA_ALL!$A:$CU,AL$5,FALSE) -> 186588443 | AM13: =AL13/AM$5 -> 0.0071407747 | AN13: =VLOOKUP($C13,DATA_ALL!$A:$CU,AN$5,FALSE) -> 45723245 | AO13: =AN13/AO$5 -> 0.011130293 | AP13: =VLOOKUP($C13,DATA_ALL!$A:$CU,AP$5,FALSE) -> 12022710 | AQ13: =AP13/AQ$5 -> 0.010919809 | AR13: =VLOOKUP($C13,DATA_ALL!$A:$CU,AR$5,FALSE) -> 845512 | AS13: =AR13/AS$5 -> 0.0038945739 | AT13: =VLOOKUP($C13,DATA_ALL!$A:$CU,AT$5,FALSE) -> 0 | AU13: =AT13/AU$5 -> 0
B14: 7 | C14: Capital World Investors (U.S.) | D14: =VLOOKUP($C14,DATA_ALL!$A:$CU,D$5,FALSE) -> Value | E14: =VLOOKUP($C14,DATA_ALL!$A:$CU,E$5,FALSE)/1000000000 -> 1022.5949 | F14: =VLOOKUP($C14,DATA_ALL!$A:$CU,F$5,FALSE) -> United States | G14: =IF(VLOOKUP($C14,DATA_ALL!$A:$CU,G$5,FALSE)="N/A",0,VLOOKUP($C14,DATA_ALL!$A:$CU,G$5,FALSE)) -> 1798176256 | H14: =VLOOKUP($C14,DATA_ALL!$A:$CU,H$5,FALSE) -> 213593771 | I14: =G14+H14 -> 2011770027 | J14: =I14/$J$5 -> 0.064397248 | K14: =IFERROR(INDEX('SH Summary'!B:B,MATCH('US&CA'!C14,'SH Summary'!C:C,0)), "N/A") -> 1 | L14: =VLOOKUP($C14,DATA_ALL!$A:$CU,L$5,FALSE) -> 3767409476 | M14: =L14/M$5 -> 0.0072692992 | N14: =VLOOKUP($C14,DATA_ALL!$A:$CU,N$5,FALSE) -> 521674850 | O14: =VLOOKUP($C14,DATA_ALL!$A:$CU,O$5,FALSE) -> 633177438 | P14: =N14+O14 -> 1154852288 | Q14: =P14/Q$5 -> 0.0036304693 | R14: =VLOOKUP($C14,DATA_ALL!$A:$CU,R$5,FALSE) -> 84785617 | S14: =R14/S$5 -> 0.0013088947 | T14: =VLOOKUP($C14,DATA_ALL!$A:$CU,T$5,FALSE) -> 60580585 | U14: =VLOOKUP($C14,DATA_ALL!$A:$CU,U$5,FALSE) -> 1087319590 | V14: =T14+U14 -> 1147900175 | W14: =V14/W$5 -> 0.015865932 | X14: =VLOOKUP($C14,DATA_ALL!$A:$CU,X$5,FALSE) -> 0 | Y14: =X14/Y$5 -> 0 | Z14: =VLOOKUP($C14,DATA_ALL!$A:$CU,Z$5,FALSE) -> 0 | AA14: =VLOOKUP($C14,DATA_ALL!$A:$CU,AA$5,FALSE) -> 0 | AB14: =Z14+AA14 -> 0 | AC14: =AB14/AC$5 -> 0 | AD14: =VLOOKUP($C14,DATA_ALL!$A:$CU,AD$5,FALSE) -> 133513583 | AE14: =VLOOKUP($C14,DATA_ALL!$A:$CU,AE$5,FALSE) -> 342567255 | AF14: =AD14+AE14 -> 476080838 | AG14: =AF14/AG$5 -> 0.010338346 | AH14: =VLOOKUP($C14,DATA_ALL!$A:$CU,AH$5,FALSE) -> 0 | AI14: =AH14/AI$5 -> 0 | AJ14: =VLOOKUP($C14,DATA_ALL!$A:$CU,AJ$5,FALSE) -> 3238413942 | AK14: =AJ14/AK$5 -> 0.027122395 | AL14: =VLOOKUP($C14,DATA_ALL!$A:$CU,AL$5,FALSE) -> 0 | AM14: =AL14/AM$5 -> 0 | AN14: =VLOOKUP($C14,DATA_ALL!$A:$CU,AN$5,FALSE) -> 0 | AO14: =AN14/AO$5 -> 0 | AP14: =VLOOKUP($C14,DATA_ALL!$A:$CU,AP$5,FALSE) -> 0 | AQ14: =AP14/AQ$5 -> 0 | AR14: =VLOOKUP($C14,DATA_ALL!$A:$CU,AR$5,FALSE) -> 0 | AS14: =AR14/AS$5 -> 0 | AT14: =VLOOKUP($C14,DATA_ALL!$A:$CU,AT$5,FALSE) -> 0 | AU14: =AT14/AU$5 -> 0
